{"op":"mcm","clk":"1346766644","pt":1588232835158,"mc":[{"id":"1.170349309","rc":[{"batb":[[1,1.02,5000],[2,1.01,1.53]],"ltp":0.0,"tv":0.0,"id":24550116},{"batb":[[1,1.02,5000],[2,1.01,1.53]],"ltp":0.0,"tv":0.0,"id":27138257},{"batb":[[1,1.02,5000],[2,1.01,1.53]],"ltp":0.0,"tv":0.0,"id":26357500},{"batb":[[1,1.02,5000],[2,1.01,1.53]],"ltp":0.0,"tv":0.0,"id":27129637},{"batb":[[1,1.02,5000],[2,1.01,1.53]],"ltp":0.0,"tv":0.0,"id":20893387}]}]}
{"op":"mcm","clk":"1346784662","pt":1588233437537,"mc":[{"id":"1.170349309","rc":[{"batb":[[1,1.01,1.53],[2,1.01,0]],"ltp":0.0,"tv":0.0,"id":24550116},{"batb":[[1,1.01,1.53],[2,1.01,0]],"ltp":0.0,"tv":0.0,"id":27138257},{"batb":[[1,1.01,1.53],[2,1.01,0]],"ltp":0.0,"tv":0.0,"id":26357500},{"batb":[[1,1.01,1.53],[2,1.01,0]],"ltp":0.0,"tv":0.0,"id":27129637},{"batb":[[1,1.01,1.53],[2,1.01,0]],"ltp":0.0,"tv":0.0,"id":20893387}]}]}
{"op":"mcm","clk":"1346784997","pt":1588233452636,"mc":[{"id":"1.170349309","rc":[{"batb":[[1,1.02,5000],[2,1.01,1.53]],"ltp":0.0,"tv":0.0,"id":24550116},{"batb":[[1,1.02,5000],[2,1.01,1.53]],"ltp":0.0,"tv":0.0,"id":27138257},{"batb":[[1,1.02,5000],[2,1.01,1.53]],"ltp":0.0,"tv":0.0,"id":26357500},{"batb":[[1,1.02,5000],[2,1.01,1.53]],"ltp":0.0,"tv":0.0,"id":27129637},{"batb":[[1,1.02,5000],[2,1.01,1.53]],"ltp":0.0,"tv":0.0,"id":20893387}]}]}
{"op":"mcm","clk":"1346798122","pt":1588234055356,"mc":[{"id":"1.170349309","rc":[{"batb":[[1,1.01,1.53],[2,1.01,0]],"ltp":0.0,"tv":0.0,"id":24550116},{"batb":[[1,1.01,1.53],[2,1.01,0]],"ltp":0.0,"tv":0.0,"id":27138257},{"batb":[[1,1.01,1.53],[2,1.01,0]],"ltp":0.0,"tv":0.0,"id":26357500},{"batb":[[1,1.01,1.53],[2,1.01,0]],"ltp":0.0,"tv":0.0,"id":27129637},{"batb":[[1,1.01,1.53],[2,1.01,0]],"ltp":0.0,"tv":0.0,"id":20893387}]}]}
{"op":"mcm","clk":"1346798477","pt":1588234070377,"mc":[{"id":"1.170349309","rc":[{"batb":[[1,1.02,5000],[2,1.01,1.53]],"ltp":0.0,"tv":0.0,"id":24550116},{"batb":[[1,1.02,5000],[2,1.01,1.53]],"ltp":0.0,"tv":0.0,"id":27138257},{"batb":[[1,1.02,5000],[2,1.01,1.53]],"ltp":0.0,"tv":0.0,"id":26357500},{"batb":[[1,1.02,5000],[2,1.01,1.53]],"ltp":0.0,"tv":0.0,"id":27129637},{"batb":[[1,1.02,5000],[2,1.01,1.53]],"ltp":0.0,"tv":0.0,"id":20893387}]}]}
{"op":"mcm","clk":"1346810912","pt":1588234673264,"mc":[{"id":"1.170349309","rc":[{"batb":[[1,1.01,1.53],[2,1.01,0]],"ltp":0.0,"tv":0.0,"id":24550116},{"batb":[[1,1.01,1.53],[2,1.01,0]],"ltp":0.0,"tv":0.0,"id":27138257},{"batb":[[1,1.01,1.53],[2,1.01,0]],"ltp":0.0,"tv":0.0,"id":26357500},{"batb":[[1,1.01,1.53],[2,1.01,0]],"ltp":0.0,"tv":0.0,"id":27129637},{"batb":[[1,1.01,1.53],[2,1.01,0]],"ltp":0.0,"tv":0.0,"id":20893387}]}]}
{"op":"mcm","clk":"1346811185","pt":1588234688260,"mc":[{"id":"1.170349309","rc":[{"batb":[[1,1.02,5000],[2,1.01,1.53]],"ltp":0.0,"tv":0.0,"id":24550116},{"batb":[[1,1.02,5000],[2,1.01,1.53]],"ltp":0.0,"tv":0.0,"id":27138257},{"batb":[[1,1.02,5000],[2,1.01,1.53]],"ltp":0.0,"tv":0.0,"id":26357500},{"batb":[[1,1.02,5000],[2,1.01,1.53]],"ltp":0.0,"tv":0.0,"id":27129637},{"batb":[[1,1.02,5000],[2,1.01,1.53]],"ltp":0.0,"tv":0.0,"id":20893387}]}]}
{"op":"mcm","clk":"1346821993","pt":1588235291354,"mc":[{"id":"1.170349309","rc":[{"batb":[[1,1.01,1.53],[2,1.01,0]],"ltp":0.0,"tv":0.0,"id":24550116},{"batb":[[1,1.01,1.53],[2,1.01,0]],"ltp":0.0,"tv":0.0,"id":27138257},{"batb":[[1,1.01,1.53],[2,1.01,0]],"ltp":0.0,"tv":0.0,"id":26357500},{"batb":[[1,1.01,1.53],[2,1.01,0]],"ltp":0.0,"tv":0.0,"id":27129637},{"batb":[[1,1.01,1.53],[2,1.01,0]],"ltp":0.0,"tv":0.0,"id":20893387}]}]}
{"op":"mcm","clk":"1346822135","pt":1588235306374,"mc":[{"id":"1.170349309","rc":[{"batb":[[1,1.02,5000],[2,1.01,1.53]],"ltp":0.0,"tv":0.0,"id":24550116},{"batb":[[1,1.02,5000],[2,1.01,1.53]],"ltp":0.0,"tv":0.0,"id":27138257},{"batb":[[1,1.02,5000],[2,1.01,1.53]],"ltp":0.0,"tv":0.0,"id":26357500},{"batb":[[1,1.02,5000],[2,1.01,1.53]],"ltp":0.0,"tv":0.0,"id":27129637},{"batb":[[1,1.02,5000],[2,1.01,1.53]],"ltp":0.0,"tv":0.0,"id":20893387}]}]}
{"op":"mcm","clk":"1346831849","pt":1588235909203,"mc":[{"id":"1.170349309","rc":[{"batb":[[1,1.01,1.53],[2,1.01,0]],"ltp":0.0,"tv":0.0,"id":24550116},{"batb":[[1,1.01,1.53],[2,1.01,0]],"ltp":0.0,"tv":0.0,"id":27138257},{"batb":[[1,1.01,1.53],[2,1.01,0]],"ltp":0.0,"tv":0.0,"id":26357500},{"batb":[[1,1.01,1.53],[2,1.01,0]],"ltp":0.0,"tv":0.0,"id":27129637},{"batb":[[1,1.01,1.53],[2,1.01,0]],"ltp":0.0,"tv":0.0,"id":20893387}]}]}
{"op":"mcm","clk":"1346832227","pt":1588235924187,"mc":[{"id":"1.170349309","rc":[{"batb":[[1,1.02,5000],[2,1.01,1.53]],"ltp":0.0,"tv":0.0,"id":24550116},{"batb":[[1,1.02,5000],[2,1.01,1.53]],"ltp":0.0,"tv":0.0,"id":27138257},{"batb":[[1,1.02,5000],[2,1.01,1.53]],"ltp":0.0,"tv":0.0,"id":26357500},{"batb":[[1,1.02,5000],[2,1.01,1.53]],"ltp":0.0,"tv":0.0,"id":27129637},{"batb":[[1,1.02,5000],[2,1.01,1.53]],"ltp":0.0,"tv":0.0,"id":20893387}]}]}
{"op":"mcm","clk":"1346846112","pt":1588236526972,"mc":[{"id":"1.170349309","rc":[{"batb":[[1,1.01,1.53],[2,1.01,0]],"ltp":0.0,"tv":0.0,"id":24550116},{"batb":[[1,1.01,1.53],[2,1.01,0]],"ltp":0.0,"tv":0.0,"id":27138257},{"batb":[[1,1.01,1.53],[2,1.01,0]],"ltp":0.0,"tv":0.0,"id":26357500},{"batb":[[1,1.01,1.53],[2,1.01,0]],"ltp":0.0,"tv":0.0,"id":27129637},{"batb":[[1,1.01,1.53],[2,1.01,0]],"ltp":0.0,"tv":0.0,"id":20893387}]}]}
{"op":"mcm","clk":"1346846360","pt":1588236542099,"mc":[{"id":"1.170349309","rc":[{"batb":[[1,1.02,5000],[2,1.01,1.53]],"ltp":0.0,"tv":0.0,"id":24550116},{"batb":[[1,1.02,5000],[2,1.01,1.53]],"ltp":0.0,"tv":0.0,"id":27138257},{"batb":[[1,1.02,5000],[2,1.01,1.53]],"ltp":0.0,"tv":0.0,"id":26357500},{"batb":[[1,1.02,5000],[2,1.01,1.53]],"ltp":0.0,"tv":0.0,"id":27129637},{"batb":[[1,1.02,5000],[2,1.01,1.53]],"ltp":0.0,"tv":0.0,"id":20893387}]}]}
{"op":"mcm","clk":"1346856513","pt":1588237145012,"mc":[{"id":"1.170349309","rc":[{"batb":[[1,1.01,1.53],[2,1.01,0]],"ltp":0.0,"tv":0.0,"id":24550116},{"batb":[[1,1.01,1.53],[2,1.01,0]],"ltp":0.0,"tv":0.0,"id":27138257},{"batb":[[1,1.01,1.53],[2,1.01,0]],"ltp":0.0,"tv":0.0,"id":26357500},{"batb":[[1,1.01,1.53],[2,1.01,0]],"ltp":0.0,"tv":0.0,"id":27129637},{"batb":[[1,1.01,1.53],[2,1.01,0]],"ltp":0.0,"tv":0.0,"id":20893387}]}]}
{"op":"mcm","clk":"1346856792","pt":1588237160008,"mc":[{"id":"1.170349309","rc":[{"batb":[[1,1.02,5000],[2,1.01,1.53]],"ltp":0.0,"tv":0.0,"id":24550116},{"batb":[[1,1.02,5000],[2,1.01,1.53]],"ltp":0.0,"tv":0.0,"id":27138257},{"batb":[[1,1.02,5000],[2,1.01,1.53]],"ltp":0.0,"tv":0.0,"id":26357500},{"batb":[[1,1.02,5000],[2,1.01,1.53]],"ltp":0.0,"tv":0.0,"id":27129637},{"batb":[[1,1.02,5000],[2,1.01,1.53]],"ltp":0.0,"tv":0.0,"id":20893387}]}]}
{"op":"mcm","clk":"1346867058","pt":1588237759487,"mc":[{"id":"1.170349309","rc":[{"batb":[[2,1.01,1.53]],"batl":[[0,1000,1.52]],"ltp":0.0,"tv":0.0,"id":24550116},{"batb":[[1,1.01,1.53]],"batl":[[1,1000,1.52]],"ltp":1.09,"tv":203.48,"id":27376858},{"batb":[[2,1.01,1.53]],"batl":[[0,1000,1.53]],"ltp":0.0,"tv":0.0,"id":27138257},{"batb":[[1,1.01,1.53]],"batl":[[1,1000,1.53]],"ltp":1.28,"tv":160.0,"id":27661463},{"batb":[[2,1.01,1.53]],"batl":[[1,1000,1.55]],"ltp":0.0,"tv":0.0,"id":26357500},{"batb":[[2,1.01,1.53]],"batl":[[0,1000,1.52]],"ltp":0.0,"tv":0.0,"id":27129637},{"batb":[[1,1.01,1.53]],"batl":[[1,1000,1.52]],"ltp":7.4,"tv":4.0,"id":26148884},{"batb":[[2,1.01,1.53]],"batl":[[0,1000,1.56]],"ltp":0.0,"tv":0.0,"id":20893387}]}]}
{"op":"mcm","clk":"1346867539","pt":1588237762953,"mc":[{"id":"1.170349309","rc":[{"batb":[[1,1.01,1.53],[2,1.01,0]],"ltp":0.0,"tv":0.0,"id":24550116},{"batb":[[1,1.01,1.53],[2,1.01,0]],"ltp":0.0,"tv":0.0,"id":27138257},{"batb":[[1,1.01,1.53],[2,1.01,0]],"ltp":0.0,"tv":0.0,"id":26357500},{"batb":[[1,1.01,1.53],[2,1.01,0]],"ltp":0.0,"tv":0.0,"id":27129637},{"batb":[[1,1.01,1.53],[2,1.01,0]],"ltp":0.0,"tv":0.0,"id":20893387}]}]}
{"op":"mcm","clk":"1346867726","pt":1588237777935,"mc":[{"id":"1.170349309","rc":[{"batb":[[1,1.02,5000],[2,1.01,1.53]],"ltp":0.0,"tv":0.0,"id":24550116},{"batb":[[1,1.02,5000],[2,1.01,1.53]],"ltp":0.0,"tv":0.0,"id":27138257},{"batb":[[1,1.02,5000],[2,1.01,1.53]],"ltp":0.0,"tv":0.0,"id":26357500},{"batb":[[1,1.02,5000],[2,1.01,1.53]],"ltp":0.0,"tv":0.0,"id":27129637},{"batb":[[1,1.02,5000],[2,1.01,1.53]],"ltp":0.0,"tv":0.0,"id":20893387}]}]}
{"op":"mcm","clk":"1346877635","pt":1588238381109,"mc":[{"id":"1.170349309","rc":[{"batb":[[1,1.01,1.53],[2,1.01,0]],"ltp":0.0,"tv":0.0,"id":24550116},{"batb":[[1,1.01,1.53],[2,1.01,0]],"ltp":0.0,"tv":0.0,"id":27138257},{"batb":[[1,1.01,1.53],[2,1.01,0]],"ltp":0.0,"tv":0.0,"id":26357500},{"batb":[[1,1.01,1.53],[2,1.01,0]],"ltp":0.0,"tv":0.0,"id":27129637},{"batb":[[1,1.01,1.53],[2,1.01,0]],"ltp":0.0,"tv":0.0,"id":20893387}]}]}
{"op":"mcm","clk":"1346877954","pt":1588238396241,"mc":[{"id":"1.170349309","rc":[{"batb":[[1,1.02,5000],[2,1.01,1.53]],"ltp":0.0,"tv":0.0,"id":24550116},{"batb":[[1,1.02,5000],[2,1.01,1.53]],"ltp":0.0,"tv":0.0,"id":27138257},{"batb":[[1,1.02,5000],[2,1.01,1.53]],"ltp":0.0,"tv":0.0,"id":26357500},{"batb":[[1,1.02,5000],[2,1.01,1.53]],"ltp":0.0,"tv":0.0,"id":27129637},{"batb":[[1,1.02,5000],[2,1.01,1.53]],"ltp":0.0,"tv":0.0,"id":20893387}]}]}
{"op":"mcm","clk":"1346884839","pt":1588238999160,"mc":[{"id":"1.170349309","rc":[{"batb":[[1,1.01,1.53],[2,1.01,0]],"ltp":0.0,"tv":0.0,"id":24550116},{"batb":[[1,1.01,1.53],[2,1.01,0]],"ltp":0.0,"tv":0.0,"id":27138257},{"batb":[[1,1.01,1.53],[2,1.01,0]],"ltp":0.0,"tv":0.0,"id":26357500},{"batb":[[1,1.01,1.53],[2,1.01,0]],"ltp":0.0,"tv":0.0,"id":27129637},{"batb":[[1,1.01,1.53],[2,1.01,0]],"ltp":0.0,"tv":0.0,"id":20893387}]}]}
{"op":"mcm","clk":"1346884973","pt":1588239014157,"mc":[{"id":"1.170349309","rc":[{"batb":[[1,1.02,5000],[2,1.01,1.53]],"ltp":0.0,"tv":0.0,"id":24550116},{"batb":[[1,1.02,5000],[2,1.01,1.53]],"ltp":0.0,"tv":0.0,"id":27138257},{"batb":[[1,1.02,5000],[2,1.01,1.53]],"ltp":0.0,"tv":0.0,"id":26357500},{"batb":[[1,1.02,5000],[2,1.01,1.53]],"ltp":0.0,"tv":0.0,"id":27129637},{"batb":[[1,1.02,5000],[2,1.01,1.53]],"ltp":0.0,"tv":0.0,"id":20893387}]}]}
{"op":"mcm","clk":"1346891796","pt":1588239617044,"mc":[{"id":"1.170349309","rc":[{"batb":[[1,1.01,1.53],[2,1.01,0]],"ltp":0.0,"tv":0.0,"id":24550116},{"batb":[[1,1.01,1.53],[2,1.01,0]],"ltp":0.0,"tv":0.0,"id":27138257},{"batb":[[1,1.01,1.53],[2,1.01,0]],"ltp":0.0,"tv":0.0,"id":26357500},{"batb":[[1,1.01,1.53],[2,1.01,0]],"ltp":0.0,"tv":0.0,"id":27129637},{"batb":[[1,1.01,1.53],[2,1.01,0]],"ltp":0.0,"tv":0.0,"id":20893387}]}]}
{"op":"mcm","clk":"1346892051","pt":1588239632145,"mc":[{"id":"1.170349309","rc":[{"batb":[[1,1.02,5000],[2,1.01,1.53]],"ltp":0.0,"tv":0.0,"id":24550116},{"batb":[[1,1.02,5000],[2,1.01,1.53]],"ltp":0.0,"tv":0.0,"id":27138257},{"batb":[[1,1.02,5000],[2,1.01,1.53]],"ltp":0.0,"tv":0.0,"id":26357500},{"batb":[[1,1.02,5000],[2,1.01,1.53]],"ltp":0.0,"tv":0.0,"id":27129637},{"batb":[[1,1.02,5000],[2,1.01,1.53]],"ltp":0.0,"tv":0.0,"id":20893387}]}]}
{"op":"mcm","clk":"1346900111","pt":1588240234745,"mc":[{"id":"1.170349309","rc":[{"batb":[[1,1.01,1.53],[2,1.01,0]],"ltp":0.0,"tv":0.0,"id":24550116},{"batb":[[1,1.01,1.53],[2,1.01,0]],"ltp":0.0,"tv":0.0,"id":27138257},{"batb":[[1,1.01,1.53],[2,1.01,0]],"ltp":0.0,"tv":0.0,"id":26357500},{"batb":[[1,1.01,1.53],[2,1.01,0]],"ltp":0.0,"tv":0.0,"id":27129637},{"batb":[[1,1.01,1.53],[2,1.01,0]],"ltp":0.0,"tv":0.0,"id":20893387}]}]}
{"op":"mcm","clk":"1346900238","pt":1588240249729,"mc":[{"id":"1.170349309","rc":[{"batb":[[1,1.02,5000],[2,1.01,1.53]],"ltp":0.0,"tv":0.0,"id":24550116},{"batb":[[1,1.02,5000],[2,1.01,1.53]],"ltp":0.0,"tv":0.0,"id":27138257},{"batb":[[1,1.02,5000],[2,1.01,1.53]],"ltp":0.0,"tv":0.0,"id":26357500},{"batb":[[1,1.02,5000],[2,1.01,1.53]],"ltp":0.0,"tv":0.0,"id":27129637},{"batb":[[1,1.02,5000],[2,1.01,1.53]],"ltp":0.0,"tv":0.0,"id":20893387}]}]}
{"op":"mcm","clk":"1346908575","pt":1588240852495,"mc":[{"id":"1.170349309","rc":[{"batb":[[1,1.01,1.53],[2,1.01,0]],"ltp":0.0,"tv":0.0,"id":24550116},{"batb":[[1,1.01,1.53],[2,1.01,0]],"ltp":0.0,"tv":0.0,"id":27138257},{"batb":[[1,1.01,1.53],[2,1.01,0]],"ltp":0.0,"tv":0.0,"id":26357500},{"batb":[[1,1.01,1.53],[2,1.01,0]],"ltp":0.0,"tv":0.0,"id":27129637},{"batb":[[1,1.01,1.53],[2,1.01,0]],"ltp":0.0,"tv":0.0,"id":20893387}]}]}
{"op":"mcm","clk":"1346908890","pt":1588240867519,"mc":[{"id":"1.170349309","rc":[{"batb":[[1,1.02,5000],[2,1.01,1.53]],"ltp":0.0,"tv":0.0,"id":24550116},{"batb":[[1,1.02,5000],[2,1.01,1.53]],"ltp":0.0,"tv":0.0,"id":27138257},{"batb":[[1,1.02,5000],[2,1.01,1.53]],"ltp":0.0,"tv":0.0,"id":26357500},{"batb":[[1,1.02,5000],[2,1.01,1.53]],"ltp":0.0,"tv":0.0,"id":27129637},{"batb":[[1,1.02,5000],[2,1.01,1.53]],"ltp":0.0,"tv":0.0,"id":20893387}]}]}
{"op":"mcm","clk":"1346920262","pt":1588241470352,"mc":[{"id":"1.170349309","rc":[{"batb":[[1,1.01,1.53],[2,1.01,0]],"ltp":0.0,"tv":0.0,"id":24550116},{"batb":[[1,1.01,1.53],[2,1.01,0]],"ltp":0.0,"tv":0.0,"id":27138257},{"batb":[[1,1.01,1.53],[2,1.01,0]],"ltp":0.0,"tv":0.0,"id":26357500},{"batb":[[1,1.01,1.53],[2,1.01,0]],"ltp":0.0,"tv":0.0,"id":27129637},{"batb":[[1,1.01,1.53],[2,1.01,0]],"ltp":0.0,"tv":0.0,"id":20893387}]}]}
{"op":"mcm","clk":"1346920351","pt":1588241485363,"mc":[{"id":"1.170349309","rc":[{"batb":[[1,1.02,5000],[2,1.01,1.53]],"ltp":0.0,"tv":0.0,"id":24550116},{"batb":[[1,1.02,5000],[2,1.01,1.53]],"ltp":0.0,"tv":0.0,"id":27138257},{"batb":[[1,1.02,5000],[2,1.01,1.53]],"ltp":0.0,"tv":0.0,"id":26357500},{"batb":[[1,1.02,5000],[2,1.01,1.53]],"ltp":0.0,"tv":0.0,"id":27129637},{"batb":[[1,1.02,5000],[2,1.01,1.53]],"ltp":0.0,"tv":0.0,"id":20893387}]}]}
{"op":"mcm","clk":"1346928759","pt":1588242088104,"mc":[{"id":"1.170349309","rc":[{"batb":[[1,1.01,1.53],[2,1.01,0]],"ltp":0.0,"tv":0.0,"id":24550116},{"batb":[[1,1.01,1.53],[2,1.01,0]],"ltp":0.0,"tv":0.0,"id":27138257},{"batb":[[1,1.01,1.53],[2,1.01,0]],"ltp":0.0,"tv":0.0,"id":26357500},{"batb":[[1,1.01,1.53],[2,1.01,0]],"ltp":0.0,"tv":0.0,"id":27129637},{"batb":[[1,1.01,1.53],[2,1.01,0]],"ltp":0.0,"tv":0.0,"id":20893387}]}]}
{"op":"mcm","clk":"1346929103","pt":1588242103146,"mc":[{"id":"1.170349309","rc":[{"batb":[[1,1.02,5000],[2,1.01,1.53]],"ltp":0.0,"tv":0.0,"id":24550116},{"batb":[[1,1.02,5000],[2,1.01,1.53]],"ltp":0.0,"tv":0.0,"id":27138257},{"batb":[[1,1.02,5000],[2,1.01,1.53]],"ltp":0.0,"tv":0.0,"id":26357500},{"batb":[[1,1.02,5000],[2,1.01,1.53]],"ltp":0.0,"tv":0.0,"id":27129637},{"batb":[[1,1.02,5000],[2,1.01,1.53]],"ltp":0.0,"tv":0.0,"id":20893387}]}]}
{"op":"mcm","clk":"1346942960","pt":1588242705929,"mc":[{"id":"1.170349309","rc":[{"batb":[[1,1.01,1.53],[2,1.01,0]],"ltp":0.0,"tv":0.0,"id":24550116},{"batb":[[1,1.01,1.53],[2,1.01,0]],"ltp":0.0,"tv":0.0,"id":27138257},{"batb":[[1,1.01,1.53],[2,1.01,0]],"ltp":0.0,"tv":0.0,"id":26357500},{"batb":[[1,1.01,1.53],[2,1.01,0]],"ltp":0.0,"tv":0.0,"id":27129637},{"batb":[[1,1.01,1.53],[2,1.01,0]],"ltp":0.0,"tv":0.0,"id":20893387}]}]}
{"op":"mcm","clk":"1346943123","pt":1588242721076,"mc":[{"id":"1.170349309","rc":[{"batb":[[1,1.02,5000],[2,1.01,1.53]],"ltp":0.0,"tv":0.0,"id":24550116},{"batb":[[1,1.02,5000],[2,1.01,1.53]],"ltp":0.0,"tv":0.0,"id":27138257},{"batb":[[1,1.02,5000],[2,1.01,1.53]],"ltp":0.0,"tv":0.0,"id":26357500},{"batb":[[1,1.02,5000],[2,1.01,1.53]],"ltp":0.0,"tv":0.0,"id":27129637},{"batb":[[1,1.02,5000],[2,1.01,1.53]],"ltp":0.0,"tv":0.0,"id":20893387}]}]}
{"op":"mcm","clk":"1346955835","pt":1588243323705,"mc":[{"id":"1.170349309","rc":[{"batb":[[1,1.01,1.53],[2,1.01,0]],"ltp":0.0,"tv":0.0,"id":24550116},{"batb":[[1,1.01,1.53],[2,1.01,0]],"ltp":0.0,"tv":0.0,"id":27138257},{"batb":[[1,1.01,1.53],[2,1.01,0]],"ltp":0.0,"tv":0.0,"id":26357500},{"batb":[[1,1.01,1.53],[2,1.01,0]],"ltp":0.0,"tv":0.0,"id":27129637},{"batb":[[1,1.01,1.53],[2,1.01,0]],"ltp":0.0,"tv":0.0,"id":20893387}]}]}
{"op":"mcm","clk":"1346956288","pt":1588243338759,"mc":[{"id":"1.170349309","rc":[{"batb":[[1,1.02,5000],[2,1.01,1.53]],"ltp":0.0,"tv":0.0,"id":24550116},{"batb":[[1,1.02,5000],[2,1.01,1.53]],"ltp":0.0,"tv":0.0,"id":27138257},{"batb":[[1,1.02,5000],[2,1.01,1.53]],"ltp":0.0,"tv":0.0,"id":26357500},{"batb":[[1,1.02,5000],[2,1.01,1.53]],"ltp":0.0,"tv":0.0,"id":27129637},{"batb":[[1,1.02,5000],[2,1.01,1.53]],"ltp":0.0,"tv":0.0,"id":20893387}]}]}
{"op":"mcm","clk":"1346975120","pt":1588243941586,"mc":[{"id":"1.170349309","rc":[{"batb":[[1,1.01,1.53],[2,1.01,0]],"ltp":0.0,"tv":0.0,"id":24550116},{"batb":[[1,1.01,1.53],[2,1.01,0]],"ltp":0.0,"tv":0.0,"id":27138257},{"batb":[[1,1.01,1.53],[2,1.01,0]],"ltp":0.0,"tv":0.0,"id":26357500},{"batb":[[1,1.01,1.53],[2,1.01,0]],"ltp":0.0,"tv":0.0,"id":27129637},{"batb":[[1,1.01,1.53],[2,1.01,0]],"ltp":0.0,"tv":0.0,"id":20893387}]}]}
{"op":"mcm","clk":"1346975497","pt":1588243956724,"mc":[{"id":"1.170349309","rc":[{"batb":[[1,1.02,5000],[2,1.01,1.53]],"ltp":0.0,"tv":0.0,"id":24550116},{"batb":[[1,1.02,5000],[2,1.01,1.53]],"ltp":0.0,"tv":0.0,"id":27138257},{"batb":[[1,1.02,5000],[2,1.01,1.53]],"ltp":0.0,"tv":0.0,"id":26357500},{"batb":[[1,1.02,5000],[2,1.01,1.53]],"ltp":0.0,"tv":0.0,"id":27129637},{"batb":[[1,1.02,5000],[2,1.01,1.53]],"ltp":0.0,"tv":0.0,"id":20893387}]}]}
{"op":"mcm","clk":"1346992999","pt":1588244559423,"mc":[{"id":"1.170349309","rc":[{"batb":[[1,1.01,1.53],[2,1.01,0]],"batl":[[0,1000,1.51]],"ltp":0.0,"tv":0.0,"id":24550116},{"trd":[[1.09,203.48]],"batb":[[1,1.01,1.53]],"batl":[[1,1000,1.52]],"ltp":1.09,"tv":203.47,"id":27376858},{"batb":[[1,1.01,1.53],[2,1.01,0]],"batl":[[0,1000,1.53]],"ltp":0.0,"tv":0.0,"id":27138257},{"batb":[[1,1.01,1.53]],"batl":[[1,1000,1.53]],"ltp":1.28,"tv":160.0,"id":27661463},{"batb":[[1,1.01,1.53],[2,1.01,0]],"batl":[[1,1000,1.54]],"ltp":0.0,"tv":0.0,"id":26357500},{"batb":[[1,1.01,1.53],[2,1.01,0]],"batl":[[0,1000,1.51]],"ltp":0.0,"tv":0.0,"id":27129637},{"batb":[[1,1.01,1.53]],"batl":[[1,1000,1.52]],"ltp":7.4,"tv":4.0,"id":26148884},{"batb":[[1,1.01,1.53],[2,1.01,0]],"batl":[[0,1000,1.56]],"ltp":0.0,"tv":0.0,"id":20893387}],"tv":367.47}]}
{"op":"mcm","clk":"1346993603","pt":1588244574562,"mc":[{"id":"1.170349309","rc":[{"batb":[[1,1.02,5000],[2,1.01,1.53]],"ltp":0.0,"tv":0.0,"id":24550116},{"batb":[[1,1.02,5000],[2,1.01,1.53]],"ltp":0.0,"tv":0.0,"id":27138257},{"batb":[[1,1.02,5000],[2,1.01,1.53]],"ltp":0.0,"tv":0.0,"id":26357500},{"batb":[[1,1.02,5000],[2,1.01,1.53]],"ltp":0.0,"tv":0.0,"id":27129637},{"batb":[[1,1.02,5000],[2,1.01,1.53]],"ltp":0.0,"tv":0.0,"id":20893387}]}]}
{"op":"mcm","clk":"1347015379","pt":1588245177071,"mc":[{"id":"1.170349309","rc":[{"batb":[[1,1.01,1.53],[2,1.01,0]],"ltp":0.0,"tv":0.0,"id":24550116},{"batb":[[1,1.01,1.53],[2,1.01,0]],"ltp":0.0,"tv":0.0,"id":27138257},{"batb":[[1,1.01,1.53],[2,1.01,0]],"ltp":0.0,"tv":0.0,"id":26357500},{"batb":[[1,1.01,1.53],[2,1.01,0]],"ltp":0.0,"tv":0.0,"id":27129637},{"batb":[[1,1.01,1.53],[2,1.01,0]],"ltp":0.0,"tv":0.0,"id":20893387}]}]}
{"op":"mcm","clk":"1347015784","pt":1588245192078,"mc":[{"id":"1.170349309","rc":[{"batb":[[1,1.02,5000],[2,1.01,1.53]],"ltp":0.0,"tv":0.0,"id":24550116},{"batb":[[1,1.02,5000],[2,1.01,1.53]],"ltp":0.0,"tv":0.0,"id":27138257},{"batb":[[1,1.02,5000],[2,1.01,1.53]],"ltp":0.0,"tv":0.0,"id":26357500},{"batb":[[1,1.02,5000],[2,1.01,1.53]],"ltp":0.0,"tv":0.0,"id":27129637},{"batb":[[1,1.02,5000],[2,1.01,1.53]],"ltp":0.0,"tv":0.0,"id":20893387}]}]}
{"op":"mcm","clk":"1347023979","pt":1588245794577,"mc":[{"id":"1.170349309","rc":[{"batb":[[1,1.01,1.53],[2,1.01,0]],"ltp":0.0,"tv":0.0,"id":24550116},{"batb":[[1,1.01,1.53],[2,1.01,0]],"ltp":0.0,"tv":0.0,"id":27138257},{"batb":[[1,1.01,1.53],[2,1.01,0]],"ltp":0.0,"tv":0.0,"id":26357500},{"batb":[[1,1.01,1.53],[2,1.01,0]],"ltp":0.0,"tv":0.0,"id":27129637},{"batb":[[1,1.01,1.53],[2,1.01,0]],"ltp":0.0,"tv":0.0,"id":20893387}]}]}
{"op":"mcm","clk":"1347024284","pt":1588245809696,"mc":[{"id":"1.170349309","rc":[{"batb":[[1,1.02,5000],[2,1.01,1.53]],"ltp":0.0,"tv":0.0,"id":24550116},{"batb":[[1,1.02,5000],[2,1.01,1.53]],"ltp":0.0,"tv":0.0,"id":27138257},{"batb":[[1,1.02,5000],[2,1.01,1.53]],"ltp":0.0,"tv":0.0,"id":26357500},{"batb":[[1,1.02,5000],[2,1.01,1.53]],"ltp":0.0,"tv":0.0,"id":27129637},{"batb":[[1,1.02,5000],[2,1.01,1.53]],"ltp":0.0,"tv":0.0,"id":20893387}]}]}
{"op":"mcm","clk":"1347040947","pt":1588246412106,"mc":[{"id":"1.170349309","rc":[{"batb":[[1,1.01,1.53],[2,1.01,0]],"ltp":0.0,"tv":0.0,"id":24550116},{"batb":[[1,1.01,1.53],[2,1.01,0]],"ltp":0.0,"tv":0.0,"id":27138257},{"batb":[[1,1.01,1.53],[2,1.01,0]],"ltp":0.0,"tv":0.0,"id":26357500},{"batb":[[1,1.01,1.53],[2,1.01,0]],"ltp":0.0,"tv":0.0,"id":27129637},{"batb":[[1,1.01,1.53],[2,1.01,0]],"ltp":0.0,"tv":0.0,"id":20893387}]}]}
{"op":"mcm","clk":"1347041379","pt":1588246427211,"mc":[{"id":"1.170349309","rc":[{"batb":[[1,1.02,5000],[2,1.01,1.53]],"ltp":0.0,"tv":0.0,"id":24550116},{"batb":[[1,1.02,5000],[2,1.01,1.53]],"ltp":0.0,"tv":0.0,"id":27138257},{"batb":[[1,1.02,5000],[2,1.01,1.53]],"ltp":0.0,"tv":0.0,"id":26357500},{"batb":[[1,1.02,5000],[2,1.01,1.53]],"ltp":0.0,"tv":0.0,"id":27129637},{"batb":[[1,1.02,5000],[2,1.01,1.53]],"ltp":0.0,"tv":0.0,"id":20893387}]}]}
{"op":"mcm","clk":"1347052290","pt":1588247029866,"mc":[{"id":"1.170349309","rc":[{"batb":[[1,1.01,1.53],[2,1.01,0]],"ltp":0.0,"tv":0.0,"id":24550116},{"batb":[[1,1.01,1.53],[2,1.01,0]],"ltp":0.0,"tv":0.0,"id":27138257},{"batb":[[1,1.01,1.53],[2,1.01,0]],"ltp":0.0,"tv":0.0,"id":26357500},{"batb":[[1,1.01,1.53],[2,1.01,0]],"ltp":0.0,"tv":0.0,"id":27129637},{"batb":[[1,1.01,1.53],[2,1.01,0]],"ltp":0.0,"tv":0.0,"id":20893387}]}]}
{"op":"mcm","clk":"1347052719","pt":1588247044793,"mc":[{"id":"1.170349309","rc":[{"batb":[[1,1.02,5000],[2,1.01,1.53]],"ltp":0.0,"tv":0.0,"id":24550116},{"batb":[[1,1.02,5000],[2,1.01,1.53]],"ltp":0.0,"tv":0.0,"id":27138257},{"batb":[[1,1.02,5000],[2,1.01,1.53]],"ltp":0.0,"tv":0.0,"id":26357500},{"batb":[[1,1.02,5000],[2,1.01,1.53]],"ltp":0.0,"tv":0.0,"id":27129637},{"batb":[[1,1.02,5000],[2,1.01,1.53]],"ltp":0.0,"tv":0.0,"id":20893387}]}]}
{"op":"mcm","clk":"1347072151","pt":1588247647448,"mc":[{"id":"1.170349309","rc":[{"batb":[[1,1.01,1.53],[2,1.01,0]],"ltp":0.0,"tv":0.0,"id":24550116},{"batb":[[1,1.01,1.53],[2,1.01,0]],"ltp":0.0,"tv":0.0,"id":27138257},{"batb":[[1,1.01,1.53],[2,1.01,0]],"ltp":0.0,"tv":0.0,"id":26357500},{"batb":[[1,1.01,1.53],[2,1.01,0]],"ltp":0.0,"tv":0.0,"id":27129637},{"batb":[[1,1.01,1.53],[2,1.01,0]],"ltp":0.0,"tv":0.0,"id":20893387}]}]}
{"op":"mcm","clk":"1347073237","pt":1588247662379,"mc":[{"id":"1.170349309","rc":[{"batb":[[1,1.02,5000],[2,1.01,1.53]],"ltp":0.0,"tv":0.0,"id":24550116},{"batb":[[1,1.02,5000],[2,1.01,1.53]],"ltp":0.0,"tv":0.0,"id":27138257},{"batb":[[1,1.02,5000],[2,1.01,1.53]],"ltp":0.0,"tv":0.0,"id":26357500},{"batb":[[1,1.02,5000],[2,1.01,1.53]],"ltp":0.0,"tv":0.0,"id":27129637},{"batb":[[1,1.02,5000],[2,1.01,1.53]],"ltp":0.0,"tv":0.0,"id":20893387}]}]}
{"op":"mcm","clk":"1347084468","pt":1588248265584,"mc":[{"id":"1.170349309","rc":[{"batb":[[1,1.01,1.53],[2,1.01,0]],"ltp":0.0,"tv":0.0,"id":24550116},{"batb":[[1,1.01,1.53],[2,1.01,0]],"ltp":0.0,"tv":0.0,"id":27138257},{"batb":[[1,1.01,1.53],[2,1.01,0]],"ltp":0.0,"tv":0.0,"id":26357500},{"batb":[[1,1.01,1.53],[2,1.01,0]],"ltp":0.0,"tv":0.0,"id":27129637},{"batb":[[1,1.01,1.53],[2,1.01,0]],"ltp":0.0,"tv":0.0,"id":20893387}]}]}
{"op":"mcm","clk":"1347084751","pt":1588248280614,"mc":[{"id":"1.170349309","rc":[{"batb":[[1,1.02,5000],[2,1.01,1.53]],"ltp":0.0,"tv":0.0,"id":24550116},{"batb":[[1,1.02,5000],[2,1.01,1.53]],"ltp":0.0,"tv":0.0,"id":27138257},{"batb":[[1,1.02,5000],[2,1.01,1.53]],"ltp":0.0,"tv":0.0,"id":26357500},{"batb":[[1,1.02,5000],[2,1.01,1.53]],"ltp":0.0,"tv":0.0,"id":27129637},{"batb":[[1,1.02,5000],[2,1.01,1.53]],"ltp":0.0,"tv":0.0,"id":20893387}]}]}
{"op":"mcm","clk":"1347100117","pt":1588248883808,"mc":[{"id":"1.170349309","rc":[{"batb":[[1,1.01,1.53],[2,1.01,0]],"ltp":0.0,"tv":0.0,"id":24550116},{"batb":[[1,1.01,1.53],[2,1.01,0]],"ltp":0.0,"tv":0.0,"id":27138257},{"batb":[[1,1.01,1.53],[2,1.01,0]],"ltp":0.0,"tv":0.0,"id":26357500},{"batb":[[1,1.01,1.53],[2,1.01,0]],"ltp":0.0,"tv":0.0,"id":27129637},{"batb":[[1,1.01,1.53],[2,1.01,0]],"ltp":0.0,"tv":0.0,"id":20893387}]}]}
{"op":"mcm","clk":"1347100464","pt":1588248898706,"mc":[{"id":"1.170349309","rc":[{"batb":[[1,1.02,5000],[2,1.01,1.53]],"ltp":0.0,"tv":0.0,"id":24550116},{"batb":[[1,1.02,5000],[2,1.01,1.53]],"ltp":0.0,"tv":0.0,"id":27138257},{"batb":[[1,1.02,5000],[2,1.01,1.53]],"ltp":0.0,"tv":0.0,"id":26357500},{"batb":[[1,1.02,5000],[2,1.01,1.53]],"ltp":0.0,"tv":0.0,"id":27129637},{"batb":[[1,1.02,5000],[2,1.01,1.53]],"ltp":0.0,"tv":0.0,"id":20893387}]}]}
{"op":"mcm","clk":"1347111393","pt":1588249501698,"mc":[{"id":"1.170349309","rc":[{"batb":[[1,1.01,1.53],[2,1.01,0]],"ltp":0.0,"tv":0.0,"id":24550116},{"batb":[[1,1.01,1.53],[2,1.01,0]],"ltp":0.0,"tv":0.0,"id":27138257},{"batb":[[1,1.01,1.53],[2,1.01,0]],"ltp":0.0,"tv":0.0,"id":26357500},{"batb":[[1,1.01,1.53],[2,1.01,0]],"ltp":0.0,"tv":0.0,"id":27129637},{"batb":[[1,1.01,1.53],[2,1.01,0]],"ltp":0.0,"tv":0.0,"id":20893387}]}]}
{"op":"mcm","clk":"1347111678","pt":1588249516693,"mc":[{"id":"1.170349309","rc":[{"batb":[[1,1.02,5000],[2,1.01,1.53]],"ltp":0.0,"tv":0.0,"id":24550116},{"batb":[[1,1.02,5000],[2,1.01,1.53]],"ltp":0.0,"tv":0.0,"id":27138257},{"batb":[[1,1.02,5000],[2,1.01,1.53]],"ltp":0.0,"tv":0.0,"id":26357500},{"batb":[[1,1.02,5000],[2,1.01,1.53]],"ltp":0.0,"tv":0.0,"id":27129637},{"batb":[[1,1.02,5000],[2,1.01,1.53]],"ltp":0.0,"tv":0.0,"id":20893387}]}]}
{"op":"mcm","clk":"1347123739","pt":1588250119034,"mc":[{"id":"1.170349309","rc":[{"batb":[[1,1.01,1.53],[2,1.01,0]],"ltp":0.0,"tv":0.0,"id":24550116},{"batb":[[1,1.01,1.53],[2,1.01,0]],"ltp":0.0,"tv":0.0,"id":27138257},{"batb":[[1,1.01,1.53],[2,1.01,0]],"ltp":0.0,"tv":0.0,"id":26357500},{"batb":[[1,1.01,1.53],[2,1.01,0]],"ltp":0.0,"tv":0.0,"id":27129637},{"batb":[[1,1.01,1.53],[2,1.01,0]],"ltp":0.0,"tv":0.0,"id":20893387}]}]}
{"op":"mcm","clk":"1347123886","pt":1588250133955,"mc":[{"id":"1.170349309","rc":[{"batb":[[1,1.02,5000],[2,1.01,1.53]],"ltp":0.0,"tv":0.0,"id":24550116},{"batb":[[1,1.02,5000],[2,1.01,1.53]],"ltp":0.0,"tv":0.0,"id":27138257},{"batb":[[1,1.02,5000],[2,1.01,1.53]],"ltp":0.0,"tv":0.0,"id":26357500},{"batb":[[1,1.02,5000],[2,1.01,1.53]],"ltp":0.0,"tv":0.0,"id":27129637},{"batb":[[1,1.02,5000],[2,1.01,1.53]],"ltp":0.0,"tv":0.0,"id":20893387}]}]}
{"op":"mcm","clk":"1347129846","pt":1588250736627,"mc":[{"id":"1.170349309","rc":[{"batb":[[1,1.01,1.53],[2,1.01,0]],"ltp":0.0,"tv":0.0,"id":24550116},{"batb":[[1,1.01,1.53],[2,1.01,0]],"ltp":0.0,"tv":0.0,"id":27138257},{"batb":[[1,1.01,1.53],[2,1.01,0]],"ltp":0.0,"tv":0.0,"id":26357500},{"batb":[[1,1.01,1.53],[2,1.01,0]],"ltp":0.0,"tv":0.0,"id":27129637},{"batb":[[1,1.01,1.53],[2,1.01,0]],"ltp":0.0,"tv":0.0,"id":20893387}]}]}
{"op":"mcm","clk":"1347130019","pt":1588250751557,"mc":[{"id":"1.170349309","rc":[{"batb":[[1,1.02,5000],[2,1.01,1.53]],"ltp":0.0,"tv":0.0,"id":24550116},{"batb":[[1,1.02,5000],[2,1.01,1.53]],"ltp":0.0,"tv":0.0,"id":27138257},{"batb":[[1,1.02,5000],[2,1.01,1.53]],"ltp":0.0,"tv":0.0,"id":26357500},{"batb":[[1,1.02,5000],[2,1.01,1.53]],"ltp":0.0,"tv":0.0,"id":27129637},{"batb":[[1,1.02,5000],[2,1.01,1.53]],"ltp":0.0,"tv":0.0,"id":20893387}]}]}
{"op":"mcm","clk":"1347136929","pt":1588251354756,"mc":[{"id":"1.170349309","rc":[{"batb":[[1,1.01,1.53],[2,1.01,0]],"ltp":0.0,"tv":0.0,"id":24550116},{"batb":[[1,1.01,1.53],[2,1.01,0]],"ltp":0.0,"tv":0.0,"id":27138257},{"batb":[[1,1.01,1.53],[2,1.01,0]],"ltp":0.0,"tv":0.0,"id":26357500},{"batb":[[1,1.01,1.53],[2,1.01,0]],"ltp":0.0,"tv":0.0,"id":27129637},{"batb":[[1,1.01,1.53],[2,1.01,0]],"ltp":0.0,"tv":0.0,"id":20893387}]}]}
{"op":"mcm","clk":"1347137082","pt":1588251369751,"mc":[{"id":"1.170349309","rc":[{"batb":[[1,1.02,5000],[2,1.01,1.53]],"ltp":0.0,"tv":0.0,"id":24550116},{"batb":[[1,1.02,5000],[2,1.01,1.53]],"ltp":0.0,"tv":0.0,"id":27138257},{"batb":[[1,1.02,5000],[2,1.01,1.53]],"ltp":0.0,"tv":0.0,"id":26357500},{"batb":[[1,1.02,5000],[2,1.01,1.53]],"ltp":0.0,"tv":0.0,"id":27129637},{"batb":[[1,1.02,5000],[2,1.01,1.53]],"ltp":0.0,"tv":0.0,"id":20893387}]}]}
{"op":"mcm","clk":"1347142494","pt":1588251972836,"mc":[{"id":"1.170349309","rc":[{"batb":[[1,1.01,1.53],[2,1.01,0]],"ltp":0.0,"tv":0.0,"id":24550116},{"batb":[[1,1.01,1.53]],"ltp":1.09,"tv":203.47,"id":27376858},{"batb":[[1,1.01,1.53],[2,1.01,0]],"ltp":0.0,"tv":0.0,"id":27138257},{"batb":[[1,1.01,1.53]],"ltp":1.28,"tv":160.0,"id":27661463},{"batb":[[1,1.01,1.53],[2,1.01,0]],"ltp":0.0,"tv":0.0,"id":26357500},{"batb":[[1,1.01,1.53],[2,1.01,0]],"ltp":0.0,"tv":0.0,"id":27129637},{"batb":[[1,1.01,1.53]],"ltp":7.4,"tv":4.0,"id":26148884},{"batb":[[1,1.01,1.53],[2,1.01,0]],"ltp":0.0,"tv":0.0,"id":20893387}]}]}
{"op":"mcm","clk":"1347142653","pt":1588251987799,"mc":[{"id":"1.170349309","rc":[{"batb":[[1,1.02,5000],[2,1.01,1.53]],"ltp":0.0,"tv":0.0,"id":24550116},{"batb":[[1,1.02,5000],[2,1.01,1.53]],"ltp":0.0,"tv":0.0,"id":27138257},{"batb":[[1,1.02,5000],[2,1.01,1.53]],"ltp":0.0,"tv":0.0,"id":26357500},{"batb":[[1,1.02,5000],[2,1.01,1.53]],"ltp":0.0,"tv":0.0,"id":27129637},{"batb":[[1,1.02,5000],[2,1.01,1.53]],"ltp":0.0,"tv":0.0,"id":20893387}]}]}
{"op":"mcm","clk":"1347147486","pt":1588252590464,"mc":[{"id":"1.170349309","rc":[{"batb":[[1,1.01,1.53],[2,1.01,0]],"ltp":0.0,"tv":0.0,"id":24550116},{"batb":[[1,1.01,1.53],[2,1.01,0]],"ltp":0.0,"tv":0.0,"id":27138257},{"batb":[[1,1.01,1.53],[2,1.01,0]],"ltp":0.0,"tv":0.0,"id":26357500},{"batb":[[1,1.01,1.53],[2,1.01,0]],"ltp":0.0,"tv":0.0,"id":27129637},{"batb":[[1,1.01,1.53],[2,1.01,0]],"ltp":0.0,"tv":0.0,"id":20893387}]}]}
{"op":"mcm","clk":"1347147661","pt":1588252605439,"mc":[{"id":"1.170349309","rc":[{"batb":[[1,1.02,5000],[2,1.01,1.53]],"ltp":0.0,"tv":0.0,"id":24550116},{"batb":[[1,1.02,5000],[2,1.01,1.53]],"ltp":0.0,"tv":0.0,"id":27138257},{"batb":[[1,1.02,5000],[2,1.01,1.53]],"ltp":0.0,"tv":0.0,"id":26357500},{"batb":[[1,1.02,5000],[2,1.01,1.53]],"ltp":0.0,"tv":0.0,"id":27129637},{"batb":[[1,1.02,5000],[2,1.01,1.53]],"ltp":0.0,"tv":0.0,"id":20893387}]}]}
{"op":"mcm","clk":"1347153397","pt":1588253208071,"mc":[{"id":"1.170349309","rc":[{"batb":[[1,1.01,1.53],[2,1.01,0]],"ltp":0.0,"tv":0.0,"id":24550116},{"batb":[[1,1.01,1.53],[2,1.01,0]],"ltp":0.0,"tv":0.0,"id":27138257},{"batb":[[1,1.01,1.53],[2,1.01,0]],"ltp":0.0,"tv":0.0,"id":26357500},{"batb":[[1,1.01,1.53],[2,1.01,0]],"ltp":0.0,"tv":0.0,"id":27129637},{"batb":[[1,1.01,1.53],[2,1.01,0]],"ltp":0.0,"tv":0.0,"id":20893387}]}]}
{"op":"mcm","clk":"1347153561","pt":1588253223211,"mc":[{"id":"1.170349309","rc":[{"batb":[[1,1.02,5000],[2,1.01,1.53]],"ltp":0.0,"tv":0.0,"id":24550116},{"batb":[[1,1.02,5000],[2,1.01,1.53]],"ltp":0.0,"tv":0.0,"id":27138257},{"batb":[[1,1.02,5000],[2,1.01,1.53]],"ltp":0.0,"tv":0.0,"id":26357500},{"batb":[[1,1.02,5000],[2,1.01,1.53]],"ltp":0.0,"tv":0.0,"id":27129637},{"batb":[[1,1.02,5000],[2,1.01,1.53]],"ltp":0.0,"tv":0.0,"id":20893387}]}]}
{"op":"mcm","clk":"1347158197","pt":1588253856762,"mc":[{"id":"1.170349309","rc":[{"batb":[[1,1.01,1.53],[2,1.01,0]],"ltp":0.0,"tv":0.0,"id":24550116},{"batb":[[1,1.01,1.53],[2,1.01,0]],"ltp":0.0,"tv":0.0,"id":27138257},{"batb":[[1,1.01,1.53],[2,1.01,0]],"ltp":0.0,"tv":0.0,"id":26357500},{"batb":[[1,1.01,1.53],[2,1.01,0]],"ltp":0.0,"tv":0.0,"id":27129637},{"batb":[[1,1.01,1.53],[2,1.01,0]],"ltp":0.0,"tv":0.0,"id":20893387}]}]}
{"op":"mcm","clk":"1347158312","pt":1588253871688,"mc":[{"id":"1.170349309","rc":[{"batb":[[1,1.02,5000],[2,1.01,1.53]],"ltp":0.0,"tv":0.0,"id":24550116},{"batb":[[1,1.02,5000],[2,1.01,1.53]],"ltp":0.0,"tv":0.0,"id":27138257},{"batb":[[1,1.02,5000],[2,1.01,1.53]],"ltp":0.0,"tv":0.0,"id":26357500},{"batb":[[1,1.02,5000],[2,1.01,1.53]],"ltp":0.0,"tv":0.0,"id":27129637},{"batb":[[1,1.02,5000],[2,1.01,1.53]],"ltp":0.0,"tv":0.0,"id":20893387}]}]}
{"op":"mcm","clk":"1347163208","pt":1588254490038,"mc":[{"id":"1.170349309","rc":[{"batb":[[1,1.01,1.53],[2,1.01,0]],"ltp":0.0,"tv":0.0,"id":24550116},{"batb":[[1,1.01,1.53],[2,1.01,0]],"ltp":0.0,"tv":0.0,"id":27138257},{"batb":[[1,1.01,1.53],[2,1.01,0]],"ltp":0.0,"tv":0.0,"id":26357500},{"batb":[[1,1.01,1.53],[2,1.01,0]],"ltp":0.0,"tv":0.0,"id":27129637},{"batb":[[1,1.01,1.53],[2,1.01,0]],"ltp":0.0,"tv":0.0,"id":20893387}]}]}
{"op":"mcm","clk":"1347163280","pt":1588254505089,"mc":[{"id":"1.170349309","rc":[{"batb":[[1,1.02,5000],[2,1.01,1.53]],"ltp":0.0,"tv":0.0,"id":24550116},{"batb":[[1,1.02,5000],[2,1.01,1.53]],"ltp":0.0,"tv":0.0,"id":27138257},{"batb":[[1,1.02,5000],[2,1.01,1.53]],"ltp":0.0,"tv":0.0,"id":26357500},{"batb":[[1,1.02,5000],[2,1.01,1.53]],"ltp":0.0,"tv":0.0,"id":27129637},{"batb":[[1,1.02,5000],[2,1.01,1.53]],"ltp":0.0,"tv":0.0,"id":20893387}]}]}
{"op":"mcm","clk":"1347166210","pt":1588255107770,"mc":[{"id":"1.170349309","rc":[{"batb":[[1,1.01,1.53],[2,1.01,0]],"ltp":0.0,"tv":0.0,"id":24550116},{"batb":[[1,1.01,1.53],[2,1.01,0]],"ltp":0.0,"tv":0.0,"id":27138257},{"batb":[[1,1.01,1.53],[2,1.01,0]],"ltp":0.0,"tv":0.0,"id":26357500},{"batb":[[1,1.01,1.53],[2,1.01,0]],"ltp":0.0,"tv":0.0,"id":27129637},{"batb":[[1,1.01,1.53],[2,1.01,0]],"ltp":0.0,"tv":0.0,"id":20893387}]}]}
{"op":"mcm","clk":"1347166306","pt":1588255122718,"mc":[{"id":"1.170349309","rc":[{"batb":[[1,1.02,5000],[2,1.01,1.53]],"ltp":0.0,"tv":0.0,"id":24550116},{"batb":[[1,1.02,5000],[2,1.01,1.53]],"ltp":0.0,"tv":0.0,"id":27138257},{"batb":[[1,1.02,5000],[2,1.01,1.53]],"ltp":0.0,"tv":0.0,"id":26357500},{"batb":[[1,1.02,5000],[2,1.01,1.53]],"ltp":0.0,"tv":0.0,"id":27129637},{"batb":[[1,1.02,5000],[2,1.01,1.53]],"ltp":0.0,"tv":0.0,"id":20893387}]}]}
{"op":"mcm","clk":"1347168580","pt":1588255759480,"mc":[{"id":"1.170349309","rc":[{"batb":[[2,1.01,1.5]],"batl":[[0,1000,1.51]],"ltp":0.0,"tv":0.0,"id":24550116},{"trd":[[1.09,203.48]],"batb":[[1,1.01,1.5]],"batl":[[1,1000,1.52]],"ltp":1.09,"tv":203.47,"id":27376858},{"batb":[[2,1.01,1.5]],"batl":[[0,1000,1.53]],"ltp":0.0,"tv":0.0,"id":27138257},{"batb":[[1,1.01,1.5]],"batl":[[1,1000,1.53]],"ltp":1.28,"tv":160.0,"id":27661463},{"batb":[[2,1.01,1.5]],"batl":[[1,1000,1.54]],"ltp":0.0,"tv":0.0,"id":26357500},{"batb":[[2,1.01,1.5]],"batl":[[0,1000,1.51]],"ltp":0.0,"tv":0.0,"id":27129637},{"batb":[[1,1.01,1.5]],"batl":[[1,1000,1.52]],"ltp":7.4,"tv":4.0,"id":26148884},{"batb":[[2,1.01,1.5]],"batl":[[0,1000,1.56]],"ltp":0.0,"tv":0.0,"id":20893387}],"tv":367.47}]}
{"op":"mcm","clk":"1347169042","pt":1588255770206,"mc":[{"id":"1.170349309","rc":[{"batb":[[1,1.01,1.5],[2,1.01,0]],"ltp":0.0,"tv":0.0,"id":24550116},{"batb":[[1,1.01,1.5],[2,1.01,0]],"ltp":0.0,"tv":0.0,"id":27138257},{"batb":[[1,1.01,1.5],[2,1.01,0]],"ltp":0.0,"tv":0.0,"id":26357500},{"batb":[[1,1.01,1.5],[2,1.01,0]],"ltp":0.0,"tv":0.0,"id":27129637},{"batb":[[1,1.01,1.5],[2,1.01,0]],"ltp":0.0,"tv":0.0,"id":20893387}]}]}
{"op":"mcm","clk":"1347169130","pt":1588255785254,"mc":[{"id":"1.170349309","rc":[{"batb":[[1,1.02,5000],[2,1.01,1.5]],"ltp":0.0,"tv":0.0,"id":24550116},{"batb":[[1,1.02,5000],[2,1.01,1.5]],"ltp":0.0,"tv":0.0,"id":27138257},{"batb":[[1,1.02,5000],[2,1.01,1.5]],"ltp":0.0,"tv":0.0,"id":26357500},{"batb":[[1,1.02,5000],[2,1.01,1.5]],"ltp":0.0,"tv":0.0,"id":27129637},{"batb":[[1,1.02,5000],[2,1.01,1.5]],"ltp":0.0,"tv":0.0,"id":20893387}]}]}
{"op":"mcm","clk":"1347171772","pt":1588256403273,"mc":[{"id":"1.170349309","rc":[{"batb":[[1,1.01,1.5],[2,1.01,0]],"ltp":0.0,"tv":0.0,"id":24550116},{"batb":[[1,1.01,1.5],[2,1.01,0]],"ltp":0.0,"tv":0.0,"id":27138257},{"batb":[[1,1.01,1.5],[2,1.01,0]],"ltp":0.0,"tv":0.0,"id":26357500},{"batb":[[1,1.01,1.5],[2,1.01,0]],"ltp":0.0,"tv":0.0,"id":27129637},{"batb":[[1,1.01,1.5],[2,1.01,0]],"ltp":0.0,"tv":0.0,"id":20893387}]}]}
{"op":"mcm","clk":"1347171818","pt":1588256418197,"mc":[{"id":"1.170349309","rc":[{"batb":[[1,1.02,5000],[2,1.01,1.5]],"ltp":0.0,"tv":0.0,"id":24550116},{"batb":[[1,1.02,5000],[2,1.01,1.5]],"ltp":0.0,"tv":0.0,"id":27138257},{"batb":[[1,1.02,5000],[2,1.01,1.5]],"ltp":0.0,"tv":0.0,"id":26357500},{"batb":[[1,1.02,5000],[2,1.01,1.5]],"ltp":0.0,"tv":0.0,"id":27129637},{"batb":[[1,1.02,5000],[2,1.01,1.5]],"ltp":0.0,"tv":0.0,"id":20893387}]}]}
{"op":"mcm","clk":"1347175726","pt":1588257020941,"mc":[{"id":"1.170349309","rc":[{"batb":[[1,1.01,1.5],[2,1.01,0]],"ltp":0.0,"tv":0.0,"id":24550116},{"batb":[[1,1.01,1.5],[2,1.01,0]],"ltp":0.0,"tv":0.0,"id":27138257},{"batb":[[1,1.01,1.5],[2,1.01,0]],"ltp":0.0,"tv":0.0,"id":26357500},{"batb":[[1,1.01,1.5],[2,1.01,0]],"ltp":0.0,"tv":0.0,"id":27129637},{"batb":[[1,1.01,1.5],[2,1.01,0]],"ltp":0.0,"tv":0.0,"id":20893387}]}]}
{"op":"mcm","clk":"1347175818","pt":1588257035989,"mc":[{"id":"1.170349309","rc":[{"batb":[[1,1.02,5000],[2,1.01,1.5]],"ltp":0.0,"tv":0.0,"id":24550116},{"batb":[[1,1.02,5000],[2,1.01,1.5]],"ltp":0.0,"tv":0.0,"id":27138257},{"batb":[[1,1.02,5000],[2,1.01,1.5]],"ltp":0.0,"tv":0.0,"id":26357500},{"batb":[[1,1.02,5000],[2,1.01,1.5]],"ltp":0.0,"tv":0.0,"id":27129637},{"batb":[[1,1.02,5000],[2,1.01,1.5]],"ltp":0.0,"tv":0.0,"id":20893387}]}]}
{"op":"mcm","clk":"1347179274","pt":1588257669175,"mc":[{"id":"1.170349309","rc":[{"batb":[[1,1.01,1.5],[2,1.01,0]],"ltp":0.0,"tv":0.0,"id":24550116},{"batb":[[1,1.01,1.5],[2,1.01,0]],"ltp":0.0,"tv":0.0,"id":27138257},{"batb":[[1,1.01,1.5],[2,1.01,0]],"ltp":0.0,"tv":0.0,"id":26357500},{"batb":[[1,1.01,1.5],[2,1.01,0]],"ltp":0.0,"tv":0.0,"id":27129637},{"batb":[[1,1.01,1.5],[2,1.01,0]],"ltp":0.0,"tv":0.0,"id":20893387}]}]}
{"op":"mcm","clk":"1347179373","pt":1588257684097,"mc":[{"id":"1.170349309","rc":[{"batb":[[1,1.02,5000],[2,1.01,1.5]],"ltp":0.0,"tv":0.0,"id":24550116},{"batb":[[1,1.02,5000],[2,1.01,1.5]],"ltp":0.0,"tv":0.0,"id":27138257},{"batb":[[1,1.02,5000],[2,1.01,1.5]],"ltp":0.0,"tv":0.0,"id":26357500},{"batb":[[1,1.02,5000],[2,1.01,1.5]],"ltp":0.0,"tv":0.0,"id":27129637},{"batb":[[1,1.02,5000],[2,1.01,1.5]],"ltp":0.0,"tv":0.0,"id":20893387}]}]}
{"op":"mcm","clk":"1347182033","pt":1588258287119,"mc":[{"id":"1.170349309","rc":[{"batb":[[1,1.01,1.5],[2,1.01,0]],"ltp":0.0,"tv":0.0,"id":24550116},{"batb":[[1,1.01,1.5],[2,1.01,0]],"ltp":0.0,"tv":0.0,"id":27138257},{"batb":[[1,1.01,1.5],[2,1.01,0]],"ltp":0.0,"tv":0.0,"id":26357500},{"batb":[[1,1.01,1.5],[2,1.01,0]],"ltp":0.0,"tv":0.0,"id":27129637},{"batb":[[1,1.01,1.5],[2,1.01,0]],"ltp":0.0,"tv":0.0,"id":20893387}]}]}
{"op":"mcm","clk":"1347182121","pt":1588258302130,"mc":[{"id":"1.170349309","rc":[{"batb":[[1,1.02,5000],[2,1.01,1.5]],"ltp":0.0,"tv":0.0,"id":24550116},{"batb":[[1,1.02,5000],[2,1.01,1.5]],"ltp":0.0,"tv":0.0,"id":27138257},{"batb":[[1,1.02,5000],[2,1.01,1.5]],"ltp":0.0,"tv":0.0,"id":26357500},{"batb":[[1,1.02,5000],[2,1.01,1.5]],"ltp":0.0,"tv":0.0,"id":27129637},{"batb":[[1,1.02,5000],[2,1.01,1.5]],"ltp":0.0,"tv":0.0,"id":20893387}]}]}
{"op":"mcm","clk":"1347185339","pt":1588258905004,"mc":[{"id":"1.170349309","rc":[{"batb":[[1,1.01,1.5],[2,1.01,0]],"batl":[[0,1000,1.5]],"ltp":0.0,"tv":0.0,"id":24550116},{"batl":[[1,1000,1.51]],"ltp":1.09,"tv":203.47,"id":27376858},{"batb":[[1,1.01,1.5],[2,1.01,0]],"batl":[[0,1000,1.51]],"ltp":0.0,"tv":0.0,"id":27138257},{"batl":[[1,1000,1.51]],"ltp":1.28,"tv":160.0,"id":27661463},{"batb":[[1,1.01,1.5],[2,1.01,0]],"batl":[[1,1000,1.53]],"ltp":0.0,"tv":0.0,"id":26357500},{"batb":[[1,1.01,1.5],[2,1.01,0]],"batl":[[0,1000,1.5]],"ltp":0.0,"tv":0.0,"id":27129637},{"batl":[[1,1000,1.51]],"ltp":7.4,"tv":4.0,"id":26148884},{"batb":[[1,1.01,1.5],[2,1.01,0]],"batl":[[0,1000,1.55]],"ltp":0.0,"tv":0.0,"id":20893387}]}]}
{"op":"mcm","clk":"1347185448","pt":1588258919927,"mc":[{"id":"1.170349309","rc":[{"batb":[[1,1.02,5000],[2,1.01,1.49]],"ltp":0.0,"tv":0.0,"id":24550116},{"batb":[[1,1.01,1.49]],"ltp":1.09,"tv":203.47,"id":27376858},{"batb":[[1,1.02,5000],[2,1.01,1.49]],"ltp":0.0,"tv":0.0,"id":27138257},{"batb":[[1,1.01,1.49]],"ltp":1.28,"tv":160.0,"id":27661463},{"batb":[[1,1.02,5000],[2,1.01,1.49]],"ltp":0.0,"tv":0.0,"id":26357500},{"batb":[[1,1.02,5000],[2,1.01,1.49]],"ltp":0.0,"tv":0.0,"id":27129637},{"batb":[[1,1.01,1.49]],"ltp":7.4,"tv":4.0,"id":26148884},{"batb":[[1,1.02,5000],[2,1.01,1.49]],"ltp":0.0,"tv":0.0,"id":20893387}]}]}
{"op":"mcm","clk":"1347190091","pt":1588259522977,"mc":[{"id":"1.170349309","rc":[{"batb":[[1,1.01,1.49],[2,1.01,0]],"ltp":0.0,"tv":0.0,"id":24550116},{"batb":[[1,1.01,1.49],[2,1.01,0]],"ltp":0.0,"tv":0.0,"id":27138257},{"batb":[[1,1.01,1.49],[2,1.01,0]],"ltp":0.0,"tv":0.0,"id":26357500},{"batb":[[1,1.01,1.49],[2,1.01,0]],"ltp":0.0,"tv":0.0,"id":27129637},{"batb":[[1,1.01,1.49],[2,1.01,0]],"ltp":0.0,"tv":0.0,"id":20893387}]}]}
{"op":"mcm","clk":"1347190262","pt":1588259537903,"mc":[{"id":"1.170349309","rc":[{"batb":[[1,1.02,5000],[2,1.01,1.49]],"ltp":0.0,"tv":0.0,"id":24550116},{"batb":[[1,1.02,5000],[2,1.01,1.49]],"ltp":0.0,"tv":0.0,"id":27138257},{"batb":[[1,1.02,5000],[2,1.01,1.49]],"ltp":0.0,"tv":0.0,"id":26357500},{"batb":[[1,1.02,5000],[2,1.01,1.49]],"ltp":0.0,"tv":0.0,"id":27129637},{"batb":[[1,1.02,5000],[2,1.01,1.49]],"ltp":0.0,"tv":0.0,"id":20893387}]}]}
{"op":"mcm","clk":"1347197173","pt":1588260140792,"mc":[{"id":"1.170349309","rc":[{"batb":[[1,1.01,1.49],[2,1.01,0]],"ltp":0.0,"tv":0.0,"id":24550116},{"batb":[[1,1.01,1.49],[2,1.01,0]],"ltp":0.0,"tv":0.0,"id":27138257},{"batb":[[1,1.01,1.49],[2,1.01,0]],"ltp":0.0,"tv":0.0,"id":26357500},{"batb":[[1,1.01,1.49],[2,1.01,0]],"ltp":0.0,"tv":0.0,"id":27129637},{"batb":[[1,1.01,1.49],[2,1.01,0]],"ltp":0.0,"tv":0.0,"id":20893387}]}]}
{"op":"mcm","clk":"1347197350","pt":1588260155819,"mc":[{"id":"1.170349309","rc":[{"batb":[[1,1.02,5000],[2,1.01,1.49]],"ltp":0.0,"tv":0.0,"id":24550116},{"batb":[[1,1.02,5000],[2,1.01,1.49]],"ltp":0.0,"tv":0.0,"id":27138257},{"batb":[[1,1.02,5000],[2,1.01,1.49]],"ltp":0.0,"tv":0.0,"id":26357500},{"batb":[[1,1.02,5000],[2,1.01,1.49]],"ltp":0.0,"tv":0.0,"id":27129637},{"batb":[[1,1.02,5000],[2,1.01,1.49]],"ltp":0.0,"tv":0.0,"id":20893387}]}]}
{"op":"mcm","clk":"1347204160","pt":1588260758674,"mc":[{"id":"1.170349309","rc":[{"batb":[[1,1.01,1.49],[2,1.01,0]],"ltp":0.0,"tv":0.0,"id":24550116},{"batb":[[1,1.01,1.49],[2,1.01,0]],"ltp":0.0,"tv":0.0,"id":27138257},{"batb":[[1,1.01,1.49],[2,1.01,0]],"ltp":0.0,"tv":0.0,"id":26357500},{"batb":[[1,1.01,1.49],[2,1.01,0]],"ltp":0.0,"tv":0.0,"id":27129637},{"batb":[[1,1.01,1.49],[2,1.01,0]],"ltp":0.0,"tv":0.0,"id":20893387}]}]}
{"op":"mcm","clk":"1347204285","pt":1588260773734,"mc":[{"id":"1.170349309","rc":[{"batb":[[1,1.02,5000],[2,1.01,1.49]],"ltp":0.0,"tv":0.0,"id":24550116},{"batb":[[1,1.02,5000],[2,1.01,1.49]],"ltp":0.0,"tv":0.0,"id":27138257},{"batb":[[1,1.02,5000],[2,1.01,1.49]],"ltp":0.0,"tv":0.0,"id":26357500},{"batb":[[1,1.02,5000],[2,1.01,1.49]],"ltp":0.0,"tv":0.0,"id":27129637},{"batb":[[1,1.02,5000],[2,1.01,1.49]],"ltp":0.0,"tv":0.0,"id":20893387}]}]}
{"op":"mcm","clk":"1347213061","pt":1588261377185,"mc":[{"id":"1.170349309","rc":[{"batb":[[1,1.01,1.49],[2,1.01,0]],"ltp":0.0,"tv":0.0,"id":24550116},{"batb":[[1,1.01,1.49],[2,1.01,0]],"ltp":0.0,"tv":0.0,"id":27138257},{"batb":[[1,1.01,1.49],[2,1.01,0]],"ltp":0.0,"tv":0.0,"id":26357500},{"batb":[[1,1.01,1.49],[2,1.01,0]],"ltp":0.0,"tv":0.0,"id":27129637},{"batb":[[1,1.01,1.49],[2,1.01,0]],"ltp":0.0,"tv":0.0,"id":20893387}]}]}
{"op":"mcm","clk":"1347213290","pt":1588261392097,"mc":[{"id":"1.170349309","rc":[{"batb":[[1,1.02,5000],[2,1.01,1.49]],"ltp":0.0,"tv":0.0,"id":24550116},{"batb":[[1,1.02,5000],[2,1.01,1.49]],"ltp":0.0,"tv":0.0,"id":27138257},{"batb":[[1,1.02,5000],[2,1.01,1.49]],"ltp":0.0,"tv":0.0,"id":26357500},{"batb":[[1,1.02,5000],[2,1.01,1.49]],"ltp":0.0,"tv":0.0,"id":27129637},{"batb":[[1,1.02,5000],[2,1.01,1.49]],"ltp":0.0,"tv":0.0,"id":20893387}]}]}
{"op":"mcm","clk":"1347221146","pt":1588261995430,"mc":[{"id":"1.170349309","rc":[{"batb":[[1,1.01,1.49],[2,1.01,0]],"ltp":0.0,"tv":0.0,"id":24550116},{"batb":[[1,1.01,1.49],[2,1.01,0]],"ltp":0.0,"tv":0.0,"id":27138257},{"batb":[[1,1.01,1.49],[2,1.01,0]],"ltp":0.0,"tv":0.0,"id":26357500},{"batb":[[1,1.01,1.49],[2,1.01,0]],"ltp":0.0,"tv":0.0,"id":27129637},{"batb":[[1,1.01,1.49],[2,1.01,0]],"ltp":0.0,"tv":0.0,"id":20893387}]}]}
{"op":"mcm","clk":"1347221264","pt":1588262010358,"mc":[{"id":"1.170349309","rc":[{"batb":[[1,1.02,5000],[2,1.01,1.49]],"ltp":0.0,"tv":0.0,"id":24550116},{"batb":[[1,1.02,5000],[2,1.01,1.49]],"ltp":0.0,"tv":0.0,"id":27138257},{"batb":[[1,1.02,5000],[2,1.01,1.49]],"ltp":0.0,"tv":0.0,"id":26357500},{"batb":[[1,1.02,5000],[2,1.01,1.49]],"ltp":0.0,"tv":0.0,"id":27129637},{"batb":[[1,1.02,5000],[2,1.01,1.49]],"ltp":0.0,"tv":0.0,"id":20893387}]}]}
{"op":"mcm","clk":"1347227461","pt":1588262613240,"mc":[{"id":"1.170349309","rc":[{"batb":[[1,1.01,1.49],[2,1.01,0]],"batl":[[0,1000,1.5]],"ltp":0.0,"tv":0.0,"id":24550116},{"trd":[[1.09,203.48]],"batb":[[1,1.01,1.49]],"batl":[[1,1000,1.51]],"ltp":1.09,"tv":203.47,"id":27376858},{"batb":[[1,1.01,1.49],[2,1.01,0]],"batl":[[0,1000,1.52]],"ltp":0.0,"tv":0.0,"id":27138257},{"batb":[[1,1.01,1.49]],"batl":[[1,1000,1.52]],"ltp":1.28,"tv":160.0,"id":27661463},{"batb":[[1,1.01,1.49],[2,1.01,0]],"batl":[[1,1000,1.53]],"ltp":0.0,"tv":0.0,"id":26357500},{"batb":[[1,1.01,1.49],[2,1.01,0]],"batl":[[0,1000,1.5]],"ltp":0.0,"tv":0.0,"id":27129637},{"batb":[[1,1.01,1.49]],"batl":[[1,1000,1.51]],"ltp":7.4,"tv":4.0,"id":26148884},{"batb":[[1,1.01,1.49],[2,1.01,0]],"batl":[[0,1000,1.55]],"ltp":0.0,"tv":0.0,"id":20893387}],"tv":367.47}]}
{"op":"mcm","clk":"1347227604","pt":1588262628225,"mc":[{"id":"1.170349309","rc":[{"batb":[[1,1.02,5000],[2,1.01,1.49]],"ltp":0.0,"tv":0.0,"id":24550116},{"batb":[[1,1.02,5000],[2,1.01,1.49]],"ltp":0.0,"tv":0.0,"id":27138257},{"batb":[[1,1.02,5000],[2,1.01,1.49]],"ltp":0.0,"tv":0.0,"id":26357500},{"batb":[[1,1.02,5000],[2,1.01,1.49]],"ltp":0.0,"tv":0.0,"id":27129637},{"batb":[[1,1.02,5000],[2,1.01,1.49]],"ltp":0.0,"tv":0.0,"id":20893387}]}]}
{"op":"mcm","clk":"1347234526","pt":1588263231317,"mc":[{"id":"1.170349309","rc":[{"batb":[[1,1.01,1.49],[2,1.01,0]],"ltp":0.0,"tv":0.0,"id":24550116},{"batb":[[1,1.01,1.49],[2,1.01,0]],"ltp":0.0,"tv":0.0,"id":27138257},{"batb":[[1,1.01,1.49],[2,1.01,0]],"ltp":0.0,"tv":0.0,"id":26357500},{"batb":[[1,1.01,1.49],[2,1.01,0]],"ltp":0.0,"tv":0.0,"id":27129637},{"batb":[[1,1.01,1.49],[2,1.01,0]],"ltp":0.0,"tv":0.0,"id":20893387}]}]}
{"op":"mcm","clk":"1347234711","pt":1588263246235,"mc":[{"id":"1.170349309","rc":[{"batb":[[1,1.02,5000],[2,1.01,1.49]],"ltp":0.0,"tv":0.0,"id":24550116},{"batb":[[1,1.02,5000],[2,1.01,1.49]],"ltp":0.0,"tv":0.0,"id":27138257},{"batb":[[1,1.02,5000],[2,1.01,1.49]],"ltp":0.0,"tv":0.0,"id":26357500},{"batb":[[1,1.02,5000],[2,1.01,1.49]],"ltp":0.0,"tv":0.0,"id":27129637},{"batb":[[1,1.02,5000],[2,1.01,1.49]],"ltp":0.0,"tv":0.0,"id":20893387}]}]}
{"op":"mcm","clk":"1347243262","pt":1588263849343,"mc":[{"id":"1.170349309","rc":[{"batb":[[1,1.01,1.49],[2,1.01,0]],"ltp":0.0,"tv":0.0,"id":24550116},{"batb":[[1,1.01,1.49],[2,1.01,0]],"ltp":0.0,"tv":0.0,"id":27138257},{"batb":[[1,1.01,1.49],[2,1.01,0]],"ltp":0.0,"tv":0.0,"id":26357500},{"batb":[[1,1.01,1.49],[2,1.01,0]],"ltp":0.0,"tv":0.0,"id":27129637},{"batb":[[1,1.01,1.49],[2,1.01,0]],"ltp":0.0,"tv":0.0,"id":20893387}]}]}
{"op":"mcm","clk":"1347244316","pt":1588263864350,"mc":[{"id":"1.170349309","rc":[{"batb":[[1,1.02,5000],[2,1.01,1.49]],"ltp":0.0,"tv":0.0,"id":24550116},{"batb":[[1,1.02,5000],[2,1.01,1.49]],"ltp":0.0,"tv":0.0,"id":27138257},{"batb":[[1,1.02,5000],[2,1.01,1.49]],"ltp":0.0,"tv":0.0,"id":26357500},{"batb":[[1,1.02,5000],[2,1.01,1.49]],"ltp":0.0,"tv":0.0,"id":27129637},{"batb":[[1,1.02,5000],[2,1.01,1.49]],"ltp":0.0,"tv":0.0,"id":20893387}]}]}
{"op":"mcm","clk":"1347249831","pt":1588264467150,"mc":[{"id":"1.170349309","rc":[{"batb":[[1,1.01,1.49],[2,1.01,0]],"ltp":0.0,"tv":0.0,"id":24550116},{"batb":[[1,1.01,1.49],[2,1.01,0]],"ltp":0.0,"tv":0.0,"id":27138257},{"batb":[[1,1.01,1.49],[2,1.01,0]],"ltp":0.0,"tv":0.0,"id":26357500},{"batb":[[1,1.01,1.49],[2,1.01,0]],"ltp":0.0,"tv":0.0,"id":27129637},{"batb":[[1,1.01,1.49],[2,1.01,0]],"ltp":0.0,"tv":0.0,"id":20893387}]}]}
{"op":"mcm","clk":"1347249887","pt":1588264482175,"mc":[{"id":"1.170349309","rc":[{"batb":[[1,1.02,5000],[2,1.01,1.49]],"ltp":0.0,"tv":0.0,"id":24550116},{"batb":[[1,1.02,5000],[2,1.01,1.49]],"ltp":0.0,"tv":0.0,"id":27138257},{"batb":[[1,1.02,5000],[2,1.01,1.49]],"ltp":0.0,"tv":0.0,"id":26357500},{"batb":[[1,1.02,5000],[2,1.01,1.49]],"ltp":0.0,"tv":0.0,"id":27129637},{"batb":[[1,1.02,5000],[2,1.01,1.49]],"ltp":0.0,"tv":0.0,"id":20893387}]}]}
{"op":"mcm","clk":"1347255531","pt":1588265085010,"mc":[{"id":"1.170349309","rc":[{"batb":[[1,1.01,1.49],[2,1.01,0]],"ltp":0.0,"tv":0.0,"id":24550116},{"batb":[[1,1.01,1.49],[2,1.01,0]],"ltp":0.0,"tv":0.0,"id":27138257},{"batb":[[1,1.01,1.49],[2,1.01,0]],"ltp":0.0,"tv":0.0,"id":26357500},{"batb":[[1,1.01,1.49],[2,1.01,0]],"ltp":0.0,"tv":0.0,"id":27129637},{"batb":[[1,1.01,1.49],[2,1.01,0]],"ltp":0.0,"tv":0.0,"id":20893387}]}]}
{"op":"mcm","clk":"1347255646","pt":1588265099956,"mc":[{"id":"1.170349309","rc":[{"batb":[[1,1.02,5000],[2,1.01,1.49]],"ltp":0.0,"tv":0.0,"id":24550116},{"batb":[[1,1.02,5000],[2,1.01,1.49]],"ltp":0.0,"tv":0.0,"id":27138257},{"batb":[[1,1.02,5000],[2,1.01,1.49]],"ltp":0.0,"tv":0.0,"id":26357500},{"batb":[[1,1.02,5000],[2,1.01,1.49]],"ltp":0.0,"tv":0.0,"id":27129637},{"batb":[[1,1.02,5000],[2,1.01,1.49]],"ltp":0.0,"tv":0.0,"id":20893387}]}]}
{"op":"mcm","clk":"1347262515","pt":1588265702354,"mc":[{"id":"1.170349309","rc":[{"batb":[[1,1.01,1.49],[2,1.01,0]],"ltp":0.0,"tv":0.0,"id":24550116},{"batb":[[1,1.01,1.49],[2,1.01,0]],"ltp":0.0,"tv":0.0,"id":27138257},{"batb":[[1,1.01,1.49],[2,1.01,0]],"ltp":0.0,"tv":0.0,"id":26357500},{"batb":[[1,1.01,1.49],[2,1.01,0]],"ltp":0.0,"tv":0.0,"id":27129637},{"batb":[[1,1.01,1.49],[2,1.01,0]],"ltp":0.0,"tv":0.0,"id":20893387}]}]}
{"op":"mcm","clk":"1347262604","pt":1588265717375,"mc":[{"id":"1.170349309","rc":[{"batb":[[1,1.02,5000],[2,1.01,1.49]],"ltp":0.0,"tv":0.0,"id":24550116},{"batb":[[1,1.02,5000],[2,1.01,1.49]],"ltp":0.0,"tv":0.0,"id":27138257},{"batb":[[1,1.02,5000],[2,1.01,1.49]],"ltp":0.0,"tv":0.0,"id":26357500},{"batb":[[1,1.02,5000],[2,1.01,1.49]],"ltp":0.0,"tv":0.0,"id":27129637},{"batb":[[1,1.02,5000],[2,1.01,1.49]],"ltp":0.0,"tv":0.0,"id":20893387}]}]}
{"op":"mcm","clk":"1347266758","pt":1588266320512,"mc":[{"id":"1.170349309","rc":[{"batb":[[1,1.01,1.49],[2,1.01,0]],"ltp":0.0,"tv":0.0,"id":24550116},{"batb":[[1,1.01,1.49],[2,1.01,0]],"ltp":0.0,"tv":0.0,"id":27138257},{"batb":[[1,1.01,1.49],[2,1.01,0]],"ltp":0.0,"tv":0.0,"id":26357500},{"batb":[[1,1.01,1.49],[2,1.01,0]],"ltp":0.0,"tv":0.0,"id":27129637},{"batb":[[1,1.01,1.49],[2,1.01,0]],"ltp":0.0,"tv":0.0,"id":20893387}]}]}
{"op":"mcm","clk":"1347266915","pt":1588266335495,"mc":[{"id":"1.170349309","rc":[{"batb":[[1,1.02,5000],[2,1.01,1.49]],"ltp":0.0,"tv":0.0,"id":24550116},{"batb":[[1,1.02,5000],[2,1.01,1.49]],"ltp":0.0,"tv":0.0,"id":27138257},{"batb":[[1,1.02,5000],[2,1.01,1.49]],"ltp":0.0,"tv":0.0,"id":26357500},{"batb":[[1,1.02,5000],[2,1.01,1.49]],"ltp":0.0,"tv":0.0,"id":27129637},{"batb":[[1,1.02,5000],[2,1.01,1.49]],"ltp":0.0,"tv":0.0,"id":20893387}]}]}
{"op":"mcm","clk":"1347275123","pt":1588266938634,"mc":[{"id":"1.170349309","rc":[{"batb":[[1,1.01,1.49],[2,1.01,0]],"ltp":0.0,"tv":0.0,"id":24550116},{"batb":[[1,1.01,1.49],[2,1.01,0]],"ltp":0.0,"tv":0.0,"id":27138257},{"batb":[[1,1.01,1.49],[2,1.01,0]],"ltp":0.0,"tv":0.0,"id":26357500},{"batb":[[1,1.01,1.49],[2,1.01,0]],"ltp":0.0,"tv":0.0,"id":27129637},{"batb":[[1,1.01,1.49],[2,1.01,0]],"ltp":0.0,"tv":0.0,"id":20893387}]}]}
{"op":"mcm","clk":"1347275249","pt":1588266953538,"mc":[{"id":"1.170349309","rc":[{"batb":[[1,1.02,5000],[2,1.01,1.49]],"ltp":0.0,"tv":0.0,"id":24550116},{"batb":[[1,1.02,5000],[2,1.01,1.49]],"ltp":0.0,"tv":0.0,"id":27138257},{"batb":[[1,1.02,5000],[2,1.01,1.49]],"ltp":0.0,"tv":0.0,"id":26357500},{"batb":[[1,1.02,5000],[2,1.01,1.49]],"ltp":0.0,"tv":0.0,"id":27129637},{"batb":[[1,1.02,5000],[2,1.01,1.49]],"ltp":0.0,"tv":0.0,"id":20893387}]}]}
{"op":"mcm","clk":"1347281827","pt":1588267556092,"mc":[{"id":"1.170349309","rc":[{"batb":[[1,1.01,1.49],[2,1.01,0]],"ltp":0.0,"tv":0.0,"id":24550116},{"batb":[[1,1.01,1.49],[2,1.01,0]],"ltp":0.0,"tv":0.0,"id":27138257},{"batb":[[1,1.01,1.49],[2,1.01,0]],"ltp":0.0,"tv":0.0,"id":26357500},{"batb":[[1,1.01,1.49],[2,1.01,0]],"ltp":0.0,"tv":0.0,"id":27129637},{"batb":[[1,1.01,1.49],[2,1.01,0]],"ltp":0.0,"tv":0.0,"id":20893387}]}]}
{"op":"mcm","clk":"1347282009","pt":1588267571112,"mc":[{"id":"1.170349309","rc":[{"batb":[[1,1.02,5000],[2,1.01,1.49]],"ltp":0.0,"tv":0.0,"id":24550116},{"batb":[[1,1.02,5000],[2,1.01,1.49]],"ltp":0.0,"tv":0.0,"id":27138257},{"batb":[[1,1.02,5000],[2,1.01,1.49]],"ltp":0.0,"tv":0.0,"id":26357500},{"batb":[[1,1.02,5000],[2,1.01,1.49]],"ltp":0.0,"tv":0.0,"id":27129637},{"batb":[[1,1.02,5000],[2,1.01,1.49]],"ltp":0.0,"tv":0.0,"id":20893387}]}]}
{"op":"mcm","clk":"1347290416","pt":1588268174826,"mc":[{"id":"1.170349309","rc":[{"batb":[[1,1.01,1.49],[2,1.01,0]],"batl":[[0,1000,1.5]],"ltp":0.0,"tv":0.0,"id":24550116},{"trd":[[1.09,203.48]],"batb":[[1,1.01,1.49]],"batl":[[1,1000,1.51]],"ltp":1.09,"tv":203.47,"id":27376858},{"batb":[[1,1.01,1.49],[2,1.01,0]],"batl":[[0,1000,1.52]],"ltp":0.0,"tv":0.0,"id":27138257},{"batb":[[1,1.01,1.49]],"batl":[[1,1000,1.52]],"ltp":1.28,"tv":160.0,"id":27661463},{"batb":[[1,1.01,1.49],[2,1.01,0]],"batl":[[1,1000,1.53]],"ltp":0.0,"tv":0.0,"id":26357500},{"batb":[[1,1.01,1.49],[2,1.01,0]],"batl":[[0,1000,1.5]],"ltp":0.0,"tv":0.0,"id":27129637},{"batb":[[1,1.01,1.49]],"batl":[[1,1000,1.51]],"ltp":7.4,"tv":4.0,"id":26148884},{"batb":[[1,1.01,1.49],[2,1.01,0]],"batl":[[0,1000,1.55]],"ltp":0.0,"tv":0.0,"id":20893387}],"tv":367.47}]}
{"op":"mcm","clk":"1347290724","pt":1588268189847,"mc":[{"id":"1.170349309","rc":[{"batb":[[1,1.02,5000],[2,1.01,1.49]],"ltp":0.0,"tv":0.0,"id":24550116},{"batb":[[1,1.02,5000],[2,1.01,1.49]],"ltp":0.0,"tv":0.0,"id":27138257},{"batb":[[1,1.02,5000],[2,1.01,1.49]],"ltp":0.0,"tv":0.0,"id":26357500},{"batb":[[1,1.02,5000],[2,1.01,1.49]],"ltp":0.0,"tv":0.0,"id":27129637},{"batb":[[1,1.02,5000],[2,1.01,1.49]],"ltp":0.0,"tv":0.0,"id":20893387}]}]}
{"op":"mcm","clk":"1347298379","pt":1588268793539,"mc":[{"id":"1.170349309","rc":[{"batb":[[1,1.01,1.49],[2,1.01,0]],"ltp":0.0,"tv":0.0,"id":24550116},{"batb":[[1,1.01,1.49],[2,1.01,0]],"ltp":0.0,"tv":0.0,"id":27138257},{"batb":[[1,1.01,1.49],[2,1.01,0]],"ltp":0.0,"tv":0.0,"id":26357500},{"batb":[[1,1.01,1.49],[2,1.01,0]],"ltp":0.0,"tv":0.0,"id":27129637},{"batb":[[1,1.01,1.49],[2,1.01,0]],"ltp":0.0,"tv":0.0,"id":20893387}]}]}
{"op":"mcm","clk":"1347298526","pt":1588268808584,"mc":[{"id":"1.170349309","rc":[{"batb":[[1,1.02,5000],[2,1.01,1.49]],"ltp":0.0,"tv":0.0,"id":24550116},{"batb":[[1,1.02,5000],[2,1.01,1.49]],"ltp":0.0,"tv":0.0,"id":27138257},{"batb":[[1,1.02,5000],[2,1.01,1.49]],"ltp":0.0,"tv":0.0,"id":26357500},{"batb":[[1,1.02,5000],[2,1.01,1.49]],"ltp":0.0,"tv":0.0,"id":27129637},{"batb":[[1,1.02,5000],[2,1.01,1.49]],"ltp":0.0,"tv":0.0,"id":20893387}]}]}
{"op":"mcm","clk":"1347305679","pt":1588269412052,"mc":[{"id":"1.170349309","rc":[{"batb":[[1,1.01,1.49],[2,1.01,0]],"ltp":0.0,"tv":0.0,"id":24550116},{"batb":[[1,1.01,1.49],[2,1.01,0]],"ltp":0.0,"tv":0.0,"id":27138257},{"batb":[[1,1.01,1.49],[2,1.01,0]],"ltp":0.0,"tv":0.0,"id":26357500},{"batb":[[1,1.01,1.49],[2,1.01,0]],"ltp":0.0,"tv":0.0,"id":27129637},{"batb":[[1,1.01,1.49],[2,1.01,0]],"ltp":0.0,"tv":0.0,"id":20893387}]}]}
{"op":"mcm","clk":"1347305883","pt":1588269427164,"mc":[{"id":"1.170349309","rc":[{"batb":[[1,1.02,5000],[2,1.01,1.49]],"ltp":0.0,"tv":0.0,"id":24550116},{"batb":[[1,1.02,5000],[2,1.01,1.49]],"ltp":0.0,"tv":0.0,"id":27138257},{"batb":[[1,1.02,5000],[2,1.01,1.49]],"ltp":0.0,"tv":0.0,"id":26357500},{"batb":[[1,1.02,5000],[2,1.01,1.49]],"ltp":0.0,"tv":0.0,"id":27129637},{"batb":[[1,1.02,5000],[2,1.01,1.49]],"ltp":0.0,"tv":0.0,"id":20893387}]}]}
{"op":"mcm","clk":"1347312596","pt":1588270030908,"mc":[{"id":"1.170349309","rc":[{"batb":[[1,1.01,1.49],[2,1.01,0]],"ltp":0.0,"tv":0.0,"id":24550116},{"batb":[[1,1.01,1.49],[2,1.01,0]],"ltp":0.0,"tv":0.0,"id":27138257},{"batb":[[1,1.01,1.49],[2,1.01,0]],"ltp":0.0,"tv":0.0,"id":26357500},{"batb":[[1,1.01,1.49],[2,1.01,0]],"ltp":0.0,"tv":0.0,"id":27129637},{"batb":[[1,1.01,1.49],[2,1.01,0]],"ltp":0.0,"tv":0.0,"id":20893387}]}]}
{"op":"mcm","clk":"1347312688","pt":1588270045901,"mc":[{"id":"1.170349309","rc":[{"batb":[[1,1.02,5000],[2,1.01,1.49]],"ltp":0.0,"tv":0.0,"id":24550116},{"batb":[[1,1.02,5000],[2,1.01,1.49]],"ltp":0.0,"tv":0.0,"id":27138257},{"batb":[[1,1.02,5000],[2,1.01,1.49]],"ltp":0.0,"tv":0.0,"id":26357500},{"batb":[[1,1.02,5000],[2,1.01,1.49]],"ltp":0.0,"tv":0.0,"id":27129637},{"batb":[[1,1.02,5000],[2,1.01,1.49]],"ltp":0.0,"tv":0.0,"id":20893387}]}]}
{"op":"mcm","clk":"1347319924","pt":1588270649416,"mc":[{"id":"1.170349309","rc":[{"batb":[[1,1.01,1.49],[2,1.01,0]],"ltp":0.0,"tv":0.0,"id":24550116},{"batb":[[1,1.01,1.49],[2,1.01,0]],"ltp":0.0,"tv":0.0,"id":27138257},{"batb":[[1,1.01,1.49],[2,1.01,0]],"ltp":0.0,"tv":0.0,"id":26357500},{"batb":[[1,1.01,1.49],[2,1.01,0]],"ltp":0.0,"tv":0.0,"id":27129637},{"batb":[[1,1.01,1.49],[2,1.01,0]],"ltp":0.0,"tv":0.0,"id":20893387}]}]}
{"op":"mcm","clk":"1347320168","pt":1588270664421,"mc":[{"id":"1.170349309","rc":[{"batb":[[1,1.02,5000],[2,1.01,1.49]],"ltp":0.0,"tv":0.0,"id":24550116},{"batb":[[1,1.02,5000],[2,1.01,1.49]],"ltp":0.0,"tv":0.0,"id":27138257},{"batb":[[1,1.02,5000],[2,1.01,1.49]],"ltp":0.0,"tv":0.0,"id":26357500},{"batb":[[1,1.02,5000],[2,1.01,1.49]],"ltp":0.0,"tv":0.0,"id":27129637},{"batb":[[1,1.02,5000],[2,1.01,1.49]],"ltp":0.0,"tv":0.0,"id":20893387}]}]}
{"op":"mcm","clk":"1347327207","pt":1588271267936,"mc":[{"id":"1.170349309","rc":[{"batb":[[1,1.01,1.49],[2,1.01,0]],"ltp":0.0,"tv":0.0,"id":24550116},{"batb":[[1,1.01,1.49],[2,1.01,0]],"ltp":0.0,"tv":0.0,"id":27138257},{"batb":[[1,1.01,1.49],[2,1.01,0]],"ltp":0.0,"tv":0.0,"id":26357500},{"batb":[[1,1.01,1.49],[2,1.01,0]],"ltp":0.0,"tv":0.0,"id":27129637},{"batb":[[1,1.01,1.49],[2,1.01,0]],"ltp":0.0,"tv":0.0,"id":20893387}]}]}
{"op":"mcm","clk":"1347327296","pt":1588271283098,"mc":[{"id":"1.170349309","rc":[{"batb":[[1,1.02,5000],[2,1.01,1.49]],"ltp":0.0,"tv":0.0,"id":24550116},{"batb":[[1,1.02,5000],[2,1.01,1.49]],"ltp":0.0,"tv":0.0,"id":27138257},{"batb":[[1,1.02,5000],[2,1.01,1.49]],"ltp":0.0,"tv":0.0,"id":26357500},{"batb":[[1,1.02,5000],[2,1.01,1.49]],"ltp":0.0,"tv":0.0,"id":27129637},{"batb":[[1,1.02,5000],[2,1.01,1.49]],"ltp":0.0,"tv":0.0,"id":20893387}]}]}
{"op":"mcm","clk":"1347330987","pt":1588271886353,"mc":[{"id":"1.170349309","rc":[{"batb":[[1,1.01,1.49],[2,1.01,0]],"ltp":0.0,"tv":0.0,"id":24550116},{"batb":[[1,1.01,1.49],[2,1.01,0]],"ltp":0.0,"tv":0.0,"id":27138257},{"batb":[[1,1.01,1.49],[2,1.01,0]],"ltp":0.0,"tv":0.0,"id":26357500},{"batb":[[1,1.01,1.49],[2,1.01,0]],"ltp":0.0,"tv":0.0,"id":27129637},{"batb":[[1,1.01,1.49],[2,1.01,0]],"ltp":0.0,"tv":0.0,"id":20893387}]}]}
{"op":"mcm","clk":"1347331087","pt":1588271901403,"mc":[{"id":"1.170349309","rc":[{"batb":[[1,1.02,5000],[2,1.01,1.49]],"ltp":0.0,"tv":0.0,"id":24550116},{"batb":[[1,1.02,5000],[2,1.01,1.49]],"ltp":0.0,"tv":0.0,"id":27138257},{"batb":[[1,1.02,5000],[2,1.01,1.49]],"ltp":0.0,"tv":0.0,"id":26357500},{"batb":[[1,1.02,5000],[2,1.01,1.49]],"ltp":0.0,"tv":0.0,"id":27129637},{"batb":[[1,1.02,5000],[2,1.01,1.49]],"ltp":0.0,"tv":0.0,"id":20893387}]}]}
{"op":"mcm","clk":"1347335451","pt":1588272505145,"mc":[{"id":"1.170349309","rc":[{"batb":[[1,1.01,1.49],[2,1.01,0]],"ltp":0.0,"tv":0.0,"id":24550116},{"batb":[[1,1.01,1.49],[2,1.01,0]],"ltp":0.0,"tv":0.0,"id":27138257},{"batb":[[1,1.01,1.49],[2,1.01,0]],"ltp":0.0,"tv":0.0,"id":26357500},{"batb":[[1,1.01,1.49],[2,1.01,0]],"ltp":0.0,"tv":0.0,"id":27129637},{"batb":[[1,1.01,1.49],[2,1.01,0]],"ltp":0.0,"tv":0.0,"id":20893387}]}]}
{"op":"mcm","clk":"1347335523","pt":1588272520181,"mc":[{"id":"1.170349309","rc":[{"batb":[[1,1.02,5000],[2,1.01,1.49]],"ltp":0.0,"tv":0.0,"id":24550116},{"batb":[[1,1.02,5000],[2,1.01,1.49]],"ltp":0.0,"tv":0.0,"id":27138257},{"batb":[[1,1.02,5000],[2,1.01,1.49]],"ltp":0.0,"tv":0.0,"id":26357500},{"batb":[[1,1.02,5000],[2,1.01,1.49]],"ltp":0.0,"tv":0.0,"id":27129637},{"batb":[[1,1.02,5000],[2,1.01,1.49]],"ltp":0.0,"tv":0.0,"id":20893387}]}]}
{"op":"mcm","clk":"1347339396","pt":1588273123903,"mc":[{"id":"1.170349309","rc":[{"batb":[[1,1.01,1.49],[2,1.01,0]],"ltp":0.0,"tv":0.0,"id":24550116},{"batb":[[1,1.01,1.49],[2,1.01,0]],"ltp":0.0,"tv":0.0,"id":27138257},{"batb":[[1,1.01,1.49],[2,1.01,0]],"ltp":0.0,"tv":0.0,"id":26357500},{"batb":[[1,1.01,1.49],[2,1.01,0]],"ltp":0.0,"tv":0.0,"id":27129637},{"batb":[[1,1.01,1.49],[2,1.01,0]],"ltp":0.0,"tv":0.0,"id":20893387}]}]}
{"op":"mcm","clk":"1347339464","pt":1588273138995,"mc":[{"id":"1.170349309","rc":[{"batb":[[1,1.02,5000],[2,1.01,1.49]],"ltp":0.0,"tv":0.0,"id":24550116},{"batb":[[1,1.02,5000],[2,1.01,1.49]],"ltp":0.0,"tv":0.0,"id":27138257},{"batb":[[1,1.02,5000],[2,1.01,1.49]],"ltp":0.0,"tv":0.0,"id":26357500},{"batb":[[1,1.02,5000],[2,1.01,1.49]],"ltp":0.0,"tv":0.0,"id":27129637},{"batb":[[1,1.02,5000],[2,1.01,1.49]],"ltp":0.0,"tv":0.0,"id":20893387}]}]}
{"op":"mcm","clk":"1347343451","pt":1588273742487,"mc":[{"id":"1.170349309","rc":[{"batb":[[1,1.01,1.49],[2,1.01,0]],"batl":[[0,1000,1.5]],"ltp":0.0,"tv":0.0,"id":24550116},{"batl":[[1,1000,1.51]],"ltp":1.09,"tv":203.47,"id":27376858},{"batb":[[1,1.01,1.49],[2,1.01,0]],"batl":[[0,1000,1.52]],"ltp":0.0,"tv":0.0,"id":27138257},{"batl":[[1,1000,1.52]],"ltp":1.28,"tv":160.0,"id":27661463},{"batb":[[1,1.01,1.49],[2,1.01,0]],"batl":[[1,1000,1.53]],"ltp":0.0,"tv":0.0,"id":26357500},{"batb":[[1,1.01,1.49],[2,1.01,0]],"batl":[[0,1000,1.5]],"ltp":0.0,"tv":0.0,"id":27129637},{"batl":[[1,1000,1.51]],"ltp":7.4,"tv":4.0,"id":26148884},{"batb":[[1,1.01,1.49],[2,1.01,0]],"batl":[[0,1000,1.55]],"ltp":0.0,"tv":0.0,"id":20893387}]}]}
{"op":"mcm","clk":"1347343622","pt":1588273757578,"mc":[{"id":"1.170349309","rc":[{"batb":[[1,1.02,5000],[2,1.01,1.49]],"ltp":0.0,"tv":0.0,"id":24550116},{"batb":[[1,1.02,5000],[2,1.01,1.49]],"ltp":0.0,"tv":0.0,"id":27138257},{"batb":[[1,1.02,5000],[2,1.01,1.49]],"ltp":0.0,"tv":0.0,"id":26357500},{"batb":[[1,1.02,5000],[2,1.01,1.49]],"ltp":0.0,"tv":0.0,"id":27129637},{"batb":[[1,1.02,5000],[2,1.01,1.49]],"ltp":0.0,"tv":0.0,"id":20893387}]}]}
{"op":"mcm","clk":"1347352847","pt":1588274361339,"mc":[{"id":"1.170349309","rc":[{"batb":[[1,1.01,1.49],[2,1.01,0]],"ltp":0.0,"tv":0.0,"id":24550116},{"batb":[[1,1.01,1.49],[2,1.01,0]],"ltp":0.0,"tv":0.0,"id":27138257},{"batb":[[1,1.01,1.49],[2,1.01,0]],"ltp":0.0,"tv":0.0,"id":26357500},{"batb":[[1,1.01,1.49],[2,1.01,0]],"ltp":0.0,"tv":0.0,"id":27129637},{"batb":[[1,1.01,1.49],[2,1.01,0]],"ltp":0.0,"tv":0.0,"id":20893387}]}]}
{"op":"mcm","clk":"1347353176","pt":1588274376365,"mc":[{"id":"1.170349309","rc":[{"batb":[[1,1.02,5000],[2,1.01,1.49]],"ltp":0.0,"tv":0.0,"id":24550116},{"batb":[[1,1.02,5000],[2,1.01,1.49]],"ltp":0.0,"tv":0.0,"id":27138257},{"batb":[[1,1.02,5000],[2,1.01,1.49]],"ltp":0.0,"tv":0.0,"id":26357500},{"batb":[[1,1.02,5000],[2,1.01,1.49]],"ltp":0.0,"tv":0.0,"id":27129637},{"batb":[[1,1.02,5000],[2,1.01,1.49]],"ltp":0.0,"tv":0.0,"id":20893387}]}]}
{"op":"mcm","clk":"1347365685","pt":1588274979788,"mc":[{"id":"1.170349309","rc":[{"batb":[[1,1.01,1.49],[2,1.01,0]],"ltp":0.0,"tv":0.0,"id":24550116},{"batb":[[1,1.01,1.49],[2,1.01,0]],"ltp":0.0,"tv":0.0,"id":27138257},{"batb":[[1,1.01,1.49],[2,1.01,0]],"ltp":0.0,"tv":0.0,"id":26357500},{"batb":[[1,1.01,1.49],[2,1.01,0]],"ltp":0.0,"tv":0.0,"id":27129637},{"batb":[[1,1.01,1.49],[2,1.01,0]],"ltp":0.0,"tv":0.0,"id":20893387}]}]}
{"op":"mcm","clk":"1347365954","pt":1588274994819,"mc":[{"id":"1.170349309","rc":[{"batb":[[1,1.02,5000],[2,1.01,1.49]],"ltp":0.0,"tv":0.0,"id":24550116},{"batb":[[1,1.02,5000],[2,1.01,1.49]],"ltp":0.0,"tv":0.0,"id":27138257},{"batb":[[1,1.02,5000],[2,1.01,1.49]],"ltp":0.0,"tv":0.0,"id":26357500},{"batb":[[1,1.02,5000],[2,1.01,1.49]],"ltp":0.0,"tv":0.0,"id":27129637},{"batb":[[1,1.02,5000],[2,1.01,1.49]],"ltp":0.0,"tv":0.0,"id":20893387}]}]}
{"op":"mcm","clk":"1347375204","pt":1588275809859,"mc":[{"id":"1.170349309","rc":[{"batb":[[1,1.01,1.49],[2,1.01,0]],"ltp":0.0,"tv":0.0,"id":24550116},{"batb":[[1,1.01,1.49],[2,1.01,0]],"ltp":0.0,"tv":0.0,"id":27138257},{"batb":[[1,1.01,1.49],[2,1.01,0]],"ltp":0.0,"tv":0.0,"id":26357500},{"batb":[[1,1.01,1.49],[2,1.01,0]],"ltp":0.0,"tv":0.0,"id":27129637},{"batb":[[1,1.01,1.49],[2,1.01,0]],"ltp":0.0,"tv":0.0,"id":20893387}]}]}
{"op":"mcm","clk":"1347375307","pt":1588275824808,"mc":[{"id":"1.170349309","rc":[{"batb":[[1,1.02,5000],[2,1.01,1.49]],"ltp":0.0,"tv":0.0,"id":24550116},{"batb":[[1,1.02,5000],[2,1.01,1.49]],"ltp":0.0,"tv":0.0,"id":27138257},{"batb":[[1,1.02,5000],[2,1.01,1.49]],"ltp":0.0,"tv":0.0,"id":26357500},{"batb":[[1,1.02,5000],[2,1.01,1.49]],"ltp":0.0,"tv":0.0,"id":27129637},{"batb":[[1,1.02,5000],[2,1.01,1.49]],"ltp":0.0,"tv":0.0,"id":20893387}]}]}
{"op":"mcm","clk":"1347405958","pt":1588278601546,"mc":[{"id":"1.170349309","rc":[{"batb":[[1,1.01,1.49],[2,1.01,0]],"ltp":0.0,"tv":0.0,"id":24550116},{"batb":[[1,1.01,1.49],[2,1.01,0]],"ltp":0.0,"tv":0.0,"id":27138257},{"batb":[[1,1.01,1.49],[2,1.01,0]],"ltp":0.0,"tv":0.0,"id":26357500},{"batb":[[1,1.01,1.49],[2,1.01,0]],"ltp":0.0,"tv":0.0,"id":27129637},{"batb":[[1,1.01,1.49],[2,1.01,0]],"ltp":0.0,"tv":0.0,"id":20893387}]}]}
{"op":"mcm","clk":"1347406146","pt":1588278616436,"mc":[{"id":"1.170349309","rc":[{"batb":[[1,1.02,5000],[2,1.01,1.49]],"ltp":0.0,"tv":0.0,"id":24550116},{"batb":[[1,1.02,5000],[2,1.01,1.49]],"ltp":0.0,"tv":0.0,"id":27138257},{"batb":[[1,1.02,5000],[2,1.01,1.49]],"ltp":0.0,"tv":0.0,"id":26357500},{"batb":[[1,1.02,5000],[2,1.01,1.49]],"ltp":0.0,"tv":0.0,"id":27129637},{"batb":[[1,1.02,5000],[2,1.01,1.49]],"ltp":0.0,"tv":0.0,"id":20893387}]}]}
{"op":"mcm","clk":"1347444473","pt":1588280959466,"mc":[{"id":"1.170349309","rc":[{"batb":[[2,1.01,1.48]],"ltp":0.0,"tv":0.0,"id":24550116},{"batb":[[1,1.01,1.48]],"ltp":1.09,"tv":203.47,"id":27376858},{"batb":[[2,1.01,1.48]],"ltp":0.0,"tv":0.0,"id":27138257},{"batb":[[1,1.01,1.48]],"ltp":1.28,"tv":160.0,"id":27661463},{"batb":[[2,1.01,1.48]],"ltp":0.0,"tv":0.0,"id":26357500},{"batb":[[2,1.01,1.48]],"ltp":0.0,"tv":0.0,"id":27129637},{"batb":[[1,1.01,1.48]],"ltp":7.4,"tv":4.0,"id":26148884},{"batb":[[2,1.01,1.48]],"ltp":0.0,"tv":0.0,"id":20893387}]}]}
{"op":"mcm","clk":"1347445278","pt":1588280970643,"mc":[{"id":"1.170349309","rc":[{"batb":[[1,1.01,1.48],[2,1.01,0]],"ltp":0.0,"tv":0.0,"id":24550116},{"batb":[[1,1.01,1.48],[2,1.01,0]],"ltp":0.0,"tv":0.0,"id":27138257},{"batb":[[1,1.01,1.48],[2,1.01,0]],"ltp":0.0,"tv":0.0,"id":26357500},{"batb":[[1,1.01,1.48],[2,1.01,0]],"ltp":0.0,"tv":0.0,"id":27129637},{"batb":[[1,1.01,1.48],[2,1.01,0]],"ltp":0.0,"tv":0.0,"id":20893387}]}]}
{"op":"mcm","clk":"1347445646","pt":1588280985664,"mc":[{"id":"1.170349309","rc":[{"batb":[[1,1.02,5000],[2,1.01,1.48]],"ltp":0.0,"tv":0.0,"id":24550116},{"batb":[[1,1.02,5000],[2,1.01,1.48]],"ltp":0.0,"tv":0.0,"id":27138257},{"batb":[[1,1.02,5000],[2,1.01,1.48]],"ltp":0.0,"tv":0.0,"id":26357500},{"batb":[[1,1.02,5000],[2,1.01,1.48]],"ltp":0.0,"tv":0.0,"id":27129637},{"batb":[[1,1.02,5000],[2,1.01,1.48]],"ltp":0.0,"tv":0.0,"id":20893387}]}]}
{"op":"mcm","clk":"1347493378","pt":1588284001423,"mc":[{"id":"1.170349309","rc":[{"batb":[[1,1.01,1.48],[2,1.01,0]],"ltp":0.0,"tv":0.0,"id":24550116},{"batb":[[1,1.01,1.48],[2,1.01,0]],"ltp":0.0,"tv":0.0,"id":27138257},{"batb":[[1,1.01,1.48],[2,1.01,0]],"ltp":0.0,"tv":0.0,"id":26357500},{"batb":[[1,1.01,1.48],[2,1.01,0]],"ltp":0.0,"tv":0.0,"id":27129637},{"batb":[[1,1.01,1.48],[2,1.01,0]],"ltp":0.0,"tv":0.0,"id":20893387}]}]}
{"op":"mcm","clk":"1347493447","pt":1588284016428,"mc":[{"id":"1.170349309","rc":[{"batb":[[1,1.02,5000],[2,1.01,1.48]],"ltp":0.0,"tv":0.0,"id":24550116},{"batb":[[1,1.02,5000],[2,1.01,1.48]],"ltp":0.0,"tv":0.0,"id":27138257},{"batb":[[1,1.02,5000],[2,1.01,1.48]],"ltp":0.0,"tv":0.0,"id":26357500},{"batb":[[1,1.02,5000],[2,1.01,1.48]],"ltp":0.0,"tv":0.0,"id":27129637},{"batb":[[1,1.02,5000],[2,1.01,1.48]],"ltp":0.0,"tv":0.0,"id":20893387}]}]}
{"op":"mcm","clk":"1347497317","pt":1588284634188,"mc":[{"id":"1.170349309","rc":[{"batb":[[1,1.01,1.48],[2,1.01,0]],"ltp":0.0,"tv":0.0,"id":24550116},{"batb":[[1,1.01,1.48],[2,1.01,0]],"ltp":0.0,"tv":0.0,"id":27138257},{"batb":[[1,1.01,1.48],[2,1.01,0]],"ltp":0.0,"tv":0.0,"id":26357500},{"batb":[[1,1.01,1.48],[2,1.01,0]],"ltp":0.0,"tv":0.0,"id":27129637},{"batb":[[1,1.01,1.48],[2,1.01,0]],"ltp":0.0,"tv":0.0,"id":20893387}]}]}
{"op":"mcm","clk":"1347497387","pt":1588284649097,"mc":[{"id":"1.170349309","rc":[{"batb":[[1,1.02,5000],[2,1.01,1.48]],"ltp":0.0,"tv":0.0,"id":24550116},{"batb":[[1,1.02,5000],[2,1.01,1.48]],"ltp":0.0,"tv":0.0,"id":27138257},{"batb":[[1,1.02,5000],[2,1.01,1.48]],"ltp":0.0,"tv":0.0,"id":26357500},{"batb":[[1,1.02,5000],[2,1.01,1.48]],"ltp":0.0,"tv":0.0,"id":27129637},{"batb":[[1,1.02,5000],[2,1.01,1.48]],"ltp":0.0,"tv":0.0,"id":20893387}]}]}
{"op":"mcm","clk":"1347500240","pt":1588285251991,"mc":[{"id":"1.170349309","rc":[{"batb":[[1,1.01,1.48],[2,1.01,0]],"ltp":0.0,"tv":0.0,"id":24550116},{"batb":[[1,1.01,1.48],[2,1.01,0]],"ltp":0.0,"tv":0.0,"id":27138257},{"batb":[[1,1.01,1.48],[2,1.01,0]],"ltp":0.0,"tv":0.0,"id":26357500},{"batb":[[1,1.01,1.48],[2,1.01,0]],"ltp":0.0,"tv":0.0,"id":27129637},{"batb":[[1,1.01,1.48],[2,1.01,0]],"ltp":0.0,"tv":0.0,"id":20893387}]}]}
{"op":"mcm","clk":"1347500357","pt":1588285266910,"mc":[{"id":"1.170349309","rc":[{"batb":[[1,1.02,5000],[2,1.01,1.48]],"ltp":0.0,"tv":0.0,"id":24550116},{"batb":[[1,1.02,5000],[2,1.01,1.48]],"ltp":0.0,"tv":0.0,"id":27138257},{"batb":[[1,1.02,5000],[2,1.01,1.48]],"ltp":0.0,"tv":0.0,"id":26357500},{"batb":[[1,1.02,5000],[2,1.01,1.48]],"ltp":0.0,"tv":0.0,"id":27129637},{"batb":[[1,1.02,5000],[2,1.01,1.48]],"ltp":0.0,"tv":0.0,"id":20893387}]}]}
{"op":"mcm","clk":"1347506001","pt":1588285870259,"mc":[{"id":"1.170349309","rc":[{"batb":[[1,1.01,1.48],[2,1.01,0]],"ltp":0.0,"tv":0.0,"id":24550116},{"batb":[[1,1.01,1.48],[2,1.01,0]],"ltp":0.0,"tv":0.0,"id":27138257},{"batb":[[1,1.01,1.48],[2,1.01,0]],"ltp":0.0,"tv":0.0,"id":26357500},{"batb":[[1,1.01,1.48],[2,1.01,0]],"ltp":0.0,"tv":0.0,"id":27129637},{"batb":[[1,1.01,1.48],[2,1.01,0]],"ltp":0.0,"tv":0.0,"id":20893387}]}]}
{"op":"mcm","clk":"1347506152","pt":1588285885182,"mc":[{"id":"1.170349309","rc":[{"batb":[[1,1.02,5000],[2,1.01,1.48]],"ltp":0.0,"tv":0.0,"id":24550116},{"batb":[[1,1.02,5000],[2,1.01,1.48]],"ltp":0.0,"tv":0.0,"id":27138257},{"batb":[[1,1.02,5000],[2,1.01,1.48]],"ltp":0.0,"tv":0.0,"id":26357500},{"batb":[[1,1.02,5000],[2,1.01,1.48]],"ltp":0.0,"tv":0.0,"id":27129637},{"batb":[[1,1.02,5000],[2,1.01,1.48]],"ltp":0.0,"tv":0.0,"id":20893387}]}]}
{"op":"mcm","clk":"1347510081","pt":1588286487987,"mc":[{"id":"1.170349309","rc":[{"batb":[[1,1.01,1.48],[2,1.01,0]],"ltp":0.0,"tv":0.0,"id":24550116},{"batb":[[1,1.01,1.48],[2,1.01,0]],"ltp":0.0,"tv":0.0,"id":27138257},{"batb":[[1,1.01,1.48],[2,1.01,0]],"ltp":0.0,"tv":0.0,"id":26357500},{"batb":[[1,1.01,1.48],[2,1.01,0]],"ltp":0.0,"tv":0.0,"id":27129637},{"batb":[[1,1.01,1.48],[2,1.01,0]],"ltp":0.0,"tv":0.0,"id":20893387}]}]}
{"op":"mcm","clk":"1347510192","pt":1588286503003,"mc":[{"id":"1.170349309","rc":[{"batb":[[1,1.02,5000],[2,1.01,1.48]],"ltp":0.0,"tv":0.0,"id":24550116},{"batb":[[1,1.02,5000],[2,1.01,1.48]],"ltp":0.0,"tv":0.0,"id":27138257},{"batb":[[1,1.02,5000],[2,1.01,1.48]],"ltp":0.0,"tv":0.0,"id":26357500},{"batb":[[1,1.02,5000],[2,1.01,1.48]],"ltp":0.0,"tv":0.0,"id":27129637},{"batb":[[1,1.02,5000],[2,1.01,1.48]],"ltp":0.0,"tv":0.0,"id":20893387}]}]}
{"op":"mcm","clk":"1347515366","pt":1588287106134,"mc":[{"id":"1.170349309","rc":[{"batb":[[1,1.01,1.48],[2,1.01,0]],"ltp":0.0,"tv":0.0,"id":24550116},{"batb":[[1,1.01,1.48],[2,1.01,0]],"ltp":0.0,"tv":0.0,"id":27138257},{"batb":[[1,1.01,1.48],[2,1.01,0]],"ltp":0.0,"tv":0.0,"id":26357500},{"batb":[[1,1.01,1.48],[2,1.01,0]],"ltp":0.0,"tv":0.0,"id":27129637},{"batb":[[1,1.01,1.48],[2,1.01,0]],"ltp":0.0,"tv":0.0,"id":20893387}]}]}
{"op":"mcm","clk":"1347515491","pt":1588287121054,"mc":[{"id":"1.170349309","rc":[{"batb":[[1,1.02,5000],[2,1.01,1.48]],"ltp":0.0,"tv":0.0,"id":24550116},{"batb":[[1,1.02,5000],[2,1.01,1.48]],"ltp":0.0,"tv":0.0,"id":27138257},{"batb":[[1,1.02,5000],[2,1.01,1.48]],"ltp":0.0,"tv":0.0,"id":26357500},{"batb":[[1,1.02,5000],[2,1.01,1.48]],"ltp":0.0,"tv":0.0,"id":27129637},{"batb":[[1,1.02,5000],[2,1.01,1.48]],"ltp":0.0,"tv":0.0,"id":20893387}]}]}
{"op":"mcm","clk":"1347522617","pt":1588287723971,"mc":[{"id":"1.170349309","rc":[{"batb":[[1,1.01,1.48],[2,1.01,0]],"batl":[[0,1000,1.5]],"ltp":0.0,"tv":0.0,"id":24550116},{"batb":[[1,1.01,1.48]],"batl":[[1,1000,1.51]],"ltp":1.09,"tv":203.47,"id":27376858},{"batb":[[1,1.01,1.48],[2,1.01,0]],"batl":[[0,1000,1.52]],"ltp":0.0,"tv":0.0,"id":27138257},{"batb":[[1,1.01,1.48]],"batl":[[1,1000,1.52]],"ltp":1.28,"tv":160.0,"id":27661463},{"batb":[[1,1.01,1.48],[2,1.01,0]],"batl":[[1,1000,1.53]],"ltp":0.0,"tv":0.0,"id":26357500},{"batb":[[1,1.01,1.48],[2,1.01,0]],"batl":[[0,1000,1.5]],"ltp":0.0,"tv":0.0,"id":27129637},{"batb":[[1,1.01,1.48]],"batl":[[1,1000,1.51]],"ltp":7.4,"tv":4.0,"id":26148884},{"batb":[[1,1.01,1.48],[2,1.01,0]],"batl":[[0,1000,1.55]],"ltp":0.0,"tv":0.0,"id":20893387}]}]}
{"op":"mcm","clk":"1347522673","pt":1588287738868,"mc":[{"id":"1.170349309","rc":[{"batb":[[1,1.02,5000],[2,1.01,1.48]],"ltp":0.0,"tv":0.0,"id":24550116},{"batb":[[1,1.02,5000],[2,1.01,1.48]],"ltp":0.0,"tv":0.0,"id":27138257},{"batb":[[1,1.02,5000],[2,1.01,1.48]],"ltp":0.0,"tv":0.0,"id":26357500},{"batb":[[1,1.02,5000],[2,1.01,1.48]],"ltp":0.0,"tv":0.0,"id":27129637},{"batb":[[1,1.02,5000],[2,1.01,1.48]],"ltp":0.0,"tv":0.0,"id":20893387}]}]}
{"op":"mcm","clk":"1347526938","pt":1588288341811,"mc":[{"id":"1.170349309","rc":[{"batb":[[1,1.01,1.48],[2,1.01,0]],"ltp":0.0,"tv":0.0,"id":24550116},{"batb":[[1,1.01,1.48],[2,1.01,0]],"ltp":0.0,"tv":0.0,"id":27138257},{"batb":[[1,1.01,1.48],[2,1.01,0]],"ltp":0.0,"tv":0.0,"id":26357500},{"batb":[[1,1.01,1.48],[2,1.01,0]],"ltp":0.0,"tv":0.0,"id":27129637},{"batb":[[1,1.01,1.48],[2,1.01,0]],"ltp":0.0,"tv":0.0,"id":20893387}]}]}
{"op":"mcm","clk":"1347527021","pt":1588288356840,"mc":[{"id":"1.170349309","rc":[{"batb":[[1,1.02,5000],[2,1.01,1.48]],"ltp":0.0,"tv":0.0,"id":24550116},{"batb":[[1,1.02,5000],[2,1.01,1.48]],"ltp":0.0,"tv":0.0,"id":27138257},{"batb":[[1,1.02,5000],[2,1.01,1.48]],"ltp":0.0,"tv":0.0,"id":26357500},{"batb":[[1,1.02,5000],[2,1.01,1.48]],"ltp":0.0,"tv":0.0,"id":27129637},{"batb":[[1,1.02,5000],[2,1.01,1.48]],"ltp":0.0,"tv":0.0,"id":20893387}]}]}
{"op":"mcm","clk":"1347530137","pt":1588288819592,"mc":[{"id":"1.170349309","marketDefinition":{"bspMarket":false,"turnInPlayEnabled":false,"persistenceEnabled":false,"marketBaseRate":5.0,"eventId":"29717254","eventTypeId":"7","numberOfWinners":2,"bettingType":"ODDS","marketType":"OTHER_PLACE","marketTime":"2020-04-28T18:15:00.000Z","suspendTime":"2020-04-28T18:15:00.000Z","bspReconciled":false,"complete":true,"inPlay":false,"crossMatching":false,"runnersVoidable":false,"numberOfActiveRunners":8,"betDelay":0,"status":"SUSPENDED","runners":[{"adjustmentFactor":26.84,"status":"ACTIVE","sortPriority":1,"id":27661463,"name":"Therunawayrocket"},{"adjustmentFactor":43.93,"status":"ACTIVE","sortPriority":2,"id":26148884,"name":"Pray For Jake"},{"adjustmentFactor":6.14,"status":"ACTIVE","sortPriority":3,"id":24550116,"name":"Letsplayagame"},{"adjustmentFactor":14.93,"status":"ACTIVE","sortPriority":4,"id":26357500,"name":"Times Flying By"},{"adjustmentFactor":6.14,"status":"ACTIVE","sortPriority":5,"id":20893387,"name":"Authoratif"},{"adjustmentFactor":44.81,"status":"ACTIVE","sortPriority":6,"id":27376858,"name":"Fresh One"},{"adjustmentFactor":7.75,"status":"ACTIVE","sortPriority":7,"id":27129637,"name":"Situatenshady"},{"adjustmentFactor":6.14,"status":"ACTIVE","sortPriority":8,"id":27138257,"name":"Rainbows Treasure"}],"regulators":["MR_INT"],"countryCode":"US","discountAllowed":true,"timezone":"US/Eastern","openDate":"2020-02-22T23:52:24.000Z","version":3237281742,"name":"2 TBP","eventName":"Market del"}}]}
{"op":"mcm","clk":"1347531391","pt":1588288959976,"mc":[{"id":"1.170349309","rc":[{"batb":[[1,1.01,1.48],[2,1.01,0]],"ltp":0.0,"tv":0.0,"id":24550116},{"batb":[[1,1.01,1.48],[2,1.01,0]],"ltp":0.0,"tv":0.0,"id":27138257},{"batb":[[1,1.01,1.48],[2,1.01,0]],"ltp":0.0,"tv":0.0,"id":26357500},{"batb":[[1,1.01,1.48],[2,1.01,0]],"ltp":0.0,"tv":0.0,"id":27129637},{"batb":[[1,1.01,1.48],[2,1.01,0]],"ltp":0.0,"tv":0.0,"id":20893387}]}]}
{"op":"mcm","clk":"1347591722","pt":1588298959510,"mc":[{"id":"1.170349309","rc":[{"batl":[[0,1000,1.5]],"ltp":0.0,"tv":0.0,"id":24550116},{"trd":[[1.09,203.48]],"batl":[[1,1000,1.51]],"ltp":1.09,"tv":203.48,"id":27376858},{"batl":[[0,1000,1.52]],"ltp":0.0,"tv":0.0,"id":27138257},{"batl":[[1,1000,1.52]],"ltp":1.28,"tv":160.0,"id":27661463},{"batl":[[1,1000,1.54]],"ltp":0.0,"tv":0.0,"id":26357500},{"batl":[[0,1000,1.5]],"ltp":0.0,"tv":0.0,"id":27129637},{"batl":[[1,1000,1.51]],"ltp":7.4,"tv":4.0,"id":26148884},{"batl":[[0,1000,1.55]],"ltp":0.0,"tv":0.0,"id":20893387}],"tv":367.48}]}
{"op":"mcm","clk":"1347741107","pt":1588316959537,"mc":[{"id":"1.170349309","rc":[{"batl":[[0,1000,1.51]],"ltp":0.0,"tv":0.0,"id":24550116},{"trd":[[1.09,203.49]],"batl":[[1,1000,1.51]],"ltp":1.09,"tv":203.48,"id":27376858},{"batl":[[0,1000,1.52]],"ltp":0.0,"tv":0.0,"id":27138257},{"batl":[[1,1000,1.52]],"ltp":1.28,"tv":160.0,"id":27661463},{"batl":[[1,1000,1.54]],"ltp":0.0,"tv":0.0,"id":26357500},{"batl":[[0,1000,1.51]],"ltp":0.0,"tv":0.0,"id":27129637},{"batl":[[1,1000,1.51]],"ltp":7.4,"tv":4.0,"id":26148884},{"batl":[[0,1000,1.55]],"ltp":0.0,"tv":0.0,"id":20893387}],"tv":367.48}]}
{"op":"mcm","clk":"1347742707","pt":1588317317529,"mc":[{"id":"1.170349309","tv":0.0}]}
{"op":"mcm","clk":"1347742719","pt":1588317318661,"mc":[{"id":"1.170349309","marketDefinition":{"bspMarket":false,"turnInPlayEnabled":false,"persistenceEnabled":false,"marketBaseRate":5.0,"eventId":"29717254","eventTypeId":"7","numberOfWinners":2,"bettingType":"ODDS","marketType":"OTHER_PLACE","marketTime":"2020-04-28T18:15:00.000Z","suspendTime":"2020-04-28T18:15:00.000Z","bspReconciled":false,"complete":true,"inPlay":false,"crossMatching":false,"runnersVoidable":false,"numberOfActiveRunners":0,"betDelay":0,"status":"CLOSED","settledTime":"2020-05-01T07:15:16.000Z","runners":[{"adjustmentFactor":26.84,"status":"REMOVED","sortPriority":1,"removalDate":"2020-05-01T07:15:16.000Z","id":27661463,"name":"Therunawayrocket"},{"adjustmentFactor":43.93,"status":"REMOVED","sortPriority":2,"removalDate":"2020-05-01T07:15:16.000Z","id":26148884,"name":"Pray For Jake"},{"adjustmentFactor":6.14,"status":"REMOVED","sortPriority":3,"removalDate":"2020-05-01T07:15:16.000Z","id":24550116,"name":"Letsplayagame"},{"adjustmentFactor":14.93,"status":"REMOVED","sortPriority":4,"id":26357500,"name":"Times Flying By"},{"adjustmentFactor":6.14,"status":"REMOVED","sortPriority":5,"removalDate":"2020-05-01T07:15:16.000Z","id":20893387,"name":"Authoratif"},{"adjustmentFactor":44.81,"status":"REMOVED","sortPriority":6,"removalDate":"2020-05-01T07:15:16.000Z","id":27376858,"name":"Fresh One"},{"adjustmentFactor":7.75,"status":"REMOVED","sortPriority":7,"removalDate":"2020-05-01T07:15:16.000Z","id":27129637,"name":"Situatenshady"},{"adjustmentFactor":6.14,"status":"REMOVED","sortPriority":8,"removalDate":"2020-05-01T07:15:16.000Z","id":27138257,"name":"Rainbows Treasure"}],"regulators":["MR_INT"],"countryCode":"US","discountAllowed":true,"timezone":"US/Eastern","openDate":"2020-02-22T23:52:24.000Z","version":3237302458,"name":"2 TBP","eventName":"Market del"}}]}
