{"op":"mcm","clk":"1344685516","pt":1588094456489,"mc":[{"id":"1.170349309","marketDefinition":{"bspMarket":false,"turnInPlayEnabled":false,"persistenceEnabled":false,"marketBaseRate":5.0,"eventId":"29717254","eventTypeId":"7","numberOfWinners":2,"bettingType":"ODDS","marketType":"OTHER_PLACE","marketTime":"2020-04-28T18:15:00.000Z","suspendTime":"2020-04-28T18:15:00.000Z","bspReconciled":false,"complete":true,"inPlay":false,"crossMatching":false,"runnersVoidable":false,"numberOfActiveRunners":8,"betDelay":0,"status":"OPEN","runners":[{"adjustmentFactor":26.84,"status":"ACTIVE","sortPriority":1,"id":27661463,"name":"Therunawayrocket"},{"adjustmentFactor":43.93,"status":"ACTIVE","sortPriority":2,"id":26148884,"name":"Pray For Jake"},{"adjustmentFactor":6.14,"status":"ACTIVE","sortPriority":3,"id":24550116,"name":"Letsplayagame"},{"adjustmentFactor":14.93,"status":"ACTIVE","sortPriority":4,"id":26357500,"name":"Times Flying By"},{"adjustmentFactor":6.14,"status":"ACTIVE","sortPriority":5,"id":20893387,"name":"Authoratif"},{"adjustmentFactor":44.81,"status":"ACTIVE","sortPriority":6,"id":27376858,"name":"Fresh One"},{"adjustmentFactor":7.75,"status":"ACTIVE","sortPriority":7,"id":27129637,"name":"Situatenshady"},{"adjustmentFactor":6.14,"status":"ACTIVE","sortPriority":8,"id":27138257,"name":"Rainbows Treasure"}],"regulators":["MR_INT"],"countryCode":"US","discountAllowed":false,"timezone":"US/Eastern","openDate":"2020-02-22T23:52:24.000Z","version":3237042817,"name":"2 TBP","eventName":"Market del"}}]}
{"op":"mcm","clk":"1344685550","pt":1588094459458,"mc":[{"id":"1.170349309","marketDefinition":{"bspMarket":false,"turnInPlayEnabled":false,"persistenceEnabled":false,"marketBaseRate":5.0,"eventId":"29717254","eventTypeId":"7","numberOfWinners":2,"bettingType":"ODDS","marketType":"OTHER_PLACE","marketTime":"2020-04-28T18:15:00.000Z","suspendTime":"2020-04-28T18:15:00.000Z","bspReconciled":false,"complete":true,"inPlay":false,"crossMatching":false,"runnersVoidable":false,"numberOfActiveRunners":8,"betDelay":0,"status":"OPEN","runners":[{"adjustmentFactor":26.84,"status":"ACTIVE","sortPriority":1,"id":27661463,"name":"Therunawayrocket"},{"adjustmentFactor":43.93,"status":"ACTIVE","sortPriority":2,"id":26148884,"name":"Pray For Jake"},{"adjustmentFactor":6.14,"status":"ACTIVE","sortPriority":3,"id":24550116,"name":"Letsplayagame"},{"adjustmentFactor":14.93,"status":"ACTIVE","sortPriority":4,"id":26357500,"name":"Times Flying By"},{"adjustmentFactor":6.14,"status":"ACTIVE","sortPriority":5,"id":20893387,"name":"Authoratif"},{"adjustmentFactor":44.81,"status":"ACTIVE","sortPriority":6,"id":27376858,"name":"Fresh One"},{"adjustmentFactor":7.75,"status":"ACTIVE","sortPriority":7,"id":27129637,"name":"Situatenshady"},{"adjustmentFactor":6.14,"status":"ACTIVE","sortPriority":8,"id":27138257,"name":"Rainbows Treasure"}],"regulators":["MR_INT"],"countryCode":"US","discountAllowed":true,"timezone":"US/Eastern","openDate":"2020-02-22T23:52:24.000Z","version":3237042817,"name":"2 TBP","eventName":"Market del"}}]}
{"op":"mcm","clk":"1344699403","pt":1588095491301,"mc":[{"id":"1.170349309","rc":[{"batb":[[0,2.2,1.74],[1,2.18,20.76]],"ltp":0.0,"tv":0.0,"id":24550116},{"batb":[[0,1.09,272.22]],"batl":[[0,6.2,3.85]],"ltp":0.0,"tv":0.0,"id":27376858},{"batb":[[0,2.2,1.74],[1,2.18,20.76]],"ltp":0.0,"tv":0.0,"id":27138257},{"batb":[[0,1.28,87.5]],"batl":[[0,7.4,3.85]],"ltp":0.0,"tv":0.0,"id":27661463},{"batb":[[0,1.58,1.74],[1,1.57,42.98]],"batl":[[0,29,3.85]],"ltp":0.0,"tv":0.0,"id":26357500},{"batb":[[0,2.08,1.74],[1,2.06,23.11]],"ltp":0.0,"tv":0.0,"id":27129637},{"batb":[[0,1.09,272.22]],"batl":[[0,7.4,3.85]],"ltp":0.0,"tv":0.0,"id":26148884},{"batb":[[0,2.2,1.74],[1,2.18,20.76]],"ltp":0.0,"tv":0.0,"id":20893387}]}]}
{"op":"mcm","clk":"1344711729","pt":1588096297622,"mc":[{"id":"1.170349309","rc":[{"batl":[[0,1000,1.61]],"ltp":0.0,"tv":0.0,"id":24550116},{"batl":[[1,1000,1.61]],"ltp":0.0,"tv":0.0,"id":27376858},{"batl":[[0,1000,1.61]],"ltp":0.0,"tv":0.0,"id":27138257},{"batl":[[1,1000,1.61]],"ltp":0.0,"tv":0.0,"id":27661463},{"batl":[[1,1000,1.61]],"ltp":0.0,"tv":0.0,"id":26357500},{"batl":[[0,1000,1.61]],"ltp":0.0,"tv":0.0,"id":27129637},{"batl":[[1,1000,1.61]],"ltp":0.0,"tv":0.0,"id":26148884},{"batl":[[0,1000,1.61]],"ltp":0.0,"tv":0.0,"id":20893387}]}]}
{"op":"mcm","clk":"1344714254","pt":1588096478385,"mc":[{"id":"1.170349309","rc":[{"batl":[[0,1000,1.52]],"ltp":0.0,"tv":0.0,"id":24550116},{"batl":[[1,1000,1.53]],"ltp":0.0,"tv":0.0,"id":27376858},{"batl":[[0,1000,1.54]],"ltp":0.0,"tv":0.0,"id":27138257},{"batl":[[1,1000,1.54]],"ltp":0.0,"tv":0.0,"id":27661463},{"batl":[[1,1000,1.55]],"ltp":0.0,"tv":0.0,"id":26357500},{"batl":[[0,1000,1.52]],"ltp":0.0,"tv":0.0,"id":27129637},{"batl":[[1,1000,1.53]],"ltp":0.0,"tv":0.0,"id":26148884},{"batl":[[0,1000,1.57]],"ltp":0.0,"tv":0.0,"id":20893387}]}]}
{"op":"mcm","clk":"1344716645","pt":1588096767117,"mc":[{"id":"1.170349309","rc":[{"batb":[[2,1.01,38.02]],"ltp":0.0,"tv":0.0,"id":24550116},{"batb":[[1,1.01,41.75]],"ltp":0.0,"tv":0.0,"id":27376858},{"batb":[[2,1.01,37.88]],"ltp":0.0,"tv":0.0,"id":27138257},{"batb":[[1,1.01,38.19]],"ltp":0.0,"tv":0.0,"id":27661463},{"batb":[[2,1.01,42.68]],"ltp":0.0,"tv":0.0,"id":26357500},{"batb":[[2,1.01,39.82]],"ltp":0.0,"tv":0.0,"id":27129637},{"batb":[[1,1.01,41]],"ltp":0.0,"tv":0.0,"id":26148884},{"batb":[[2,1.01,38.87]],"ltp":0.0,"tv":0.0,"id":20893387}]}]}
{"op":"mcm","clk":"1344724826","pt":1588097520371,"mc":[{"id":"1.170349309","rc":[{"batb":[[2,1.59,31]],"ltp":0.0,"tv":0.0,"id":24550116},{"batb":[[1,1.04,48],[2,1.01,41.75]],"ltp":0.0,"tv":0.0,"id":27376858},{"batb":[[2,1.59,31]],"ltp":0.0,"tv":0.0,"id":27138257},{"batb":[[1,1.14,44],[2,1.01,38.19]],"ltp":0.0,"tv":0.0,"id":27661463},{"batb":[[2,1.28,39]],"ltp":0.0,"tv":0.0,"id":26357500},{"batb":[[2,1.53,33]],"ltp":0.0,"tv":0.0,"id":27129637},{"batb":[[1,1.04,48],[2,1.01,41]],"ltp":0.0,"tv":0.0,"id":26148884},{"batb":[[2,1.59,31]],"ltp":0.0,"tv":0.0,"id":20893387}]}]}
{"op":"mcm","clk":"1344725771","pt":1588097603222,"mc":[{"id":"1.170349309","rc":[{"batb":[[0,2.18,20.76],[1,1.59,31],[2,1.01,38.02]],"ltp":0.0,"tv":0.0,"id":24550116},{"batb":[[0,2.18,20.76],[1,1.59,31],[2,1.01,37.88]],"ltp":0.0,"tv":0.0,"id":27138257},{"batb":[[0,1.57,42.98],[1,1.28,39],[2,1.01,42.68]],"ltp":0.0,"tv":0.0,"id":26357500},{"batb":[[0,2.06,23.11],[1,1.53,33],[2,1.01,39.82]],"ltp":0.0,"tv":0.0,"id":27129637},{"batb":[[0,2.18,20.76],[1,1.59,31],[2,1.01,38.87]],"ltp":0.0,"tv":0.0,"id":20893387}]}]}
{"op":"mcm","clk":"1344726245","pt":1588097643951,"mc":[{"id":"1.170349309","rc":[{"batb":[[1,1.88,2.38],[2,1.59,31]],"ltp":0.0,"tv":0.0,"id":24550116},{"batb":[[1,1.06,4.22],[2,1.04,48]],"ltp":0.0,"tv":0.0,"id":27376858},{"batb":[[1,1.88,2.38],[2,1.59,31]],"ltp":0.0,"tv":0.0,"id":27138257},{"batb":[[1,1.2,3.73],[2,1.14,44]],"ltp":0.0,"tv":0.0,"id":27661463},{"batb":[[1,1.42,3.15],[2,1.28,39]],"ltp":0.0,"tv":0.0,"id":26357500},{"batb":[[1,1.78,2.51],[2,1.53,33]],"ltp":0.0,"tv":0.0,"id":27129637},{"batb":[[1,1.06,4.22],[2,1.04,48]],"ltp":0.0,"tv":0.0,"id":26148884},{"batb":[[1,1.88,2.38],[2,1.59,31]],"ltp":0.0,"tv":0.0,"id":20893387}]}]}
{"op":"mcm","clk":"1344727889","pt":1588097971400,"mc":[{"id":"1.170349309","rc":[{"batb":[[2,1.39,180]],"ltp":0.0,"tv":0.0,"id":24550116},{"batb":[[2,1.01,289.75]],"ltp":0.0,"tv":0.0,"id":27376858},{"batb":[[2,1.39,180]],"ltp":0.0,"tv":0.0,"id":27138257},{"batb":[[2,1.02,245]],"ltp":0.0,"tv":0.0,"id":27661463},{"batb":[[2,1.16,216]],"ltp":0.0,"tv":0.0,"id":26357500},{"batb":[[2,1.33,188]],"ltp":0.0,"tv":0.0,"id":27129637},{"batb":[[2,1.01,289]],"ltp":0.0,"tv":0.0,"id":26148884},{"batb":[[2,1.39,180]],"ltp":0.0,"tv":0.0,"id":20893387}]}]}
{"op":"mcm","clk":"1344727892","pt":1588097971961,"mc":[{"id":"1.170349309","rc":[{"batb":[[2,1.27,197]],"ltp":0.0,"tv":0.0,"id":24550116},{"batb":[[2,1.01,41.75]],"ltp":0.0,"tv":0.0,"id":27376858},{"batb":[[2,1.27,197]],"ltp":0.0,"tv":0.0,"id":27138257},{"batb":[[2,1.01,38.19]],"ltp":0.0,"tv":0.0,"id":27661463},{"batb":[[2,1.04,240]],"ltp":0.0,"tv":0.0,"id":26357500},{"batb":[[2,1.21,207]],"ltp":0.0,"tv":0.0,"id":27129637},{"batb":[[2,1.01,41]],"ltp":0.0,"tv":0.0,"id":26148884},{"batb":[[2,1.27,197]],"ltp":0.0,"tv":0.0,"id":20893387}]}]}
{"op":"mcm","clk":"1344727962","pt":1588097987097,"mc":[{"id":"1.170349309","rc":[{"batb":[[2,1.15,217]],"ltp":0.0,"tv":0.0,"id":24550116},{"batb":[[2,1.15,217]],"ltp":0.0,"tv":0.0,"id":27138257},{"batb":[[2,1.02,5000]],"ltp":0.0,"tv":0.0,"id":26357500},{"batb":[[2,1.09,229]],"ltp":0.0,"tv":0.0,"id":27129637},{"batb":[[2,1.15,217]],"ltp":0.0,"tv":0.0,"id":20893387}]}]}
{"op":"mcm","clk":"1344728025","pt":1588098002099,"mc":[{"id":"1.170349309","rc":[{"batb":[[2,1.03,243]],"ltp":0.0,"tv":0.0,"id":24550116},{"batb":[[2,1.03,243]],"ltp":0.0,"tv":0.0,"id":27138257},{"batb":[[2,1.02,5000]],"ltp":0.0,"tv":0.0,"id":27129637},{"batb":[[2,1.03,243]],"ltp":0.0,"tv":0.0,"id":20893387}]}]}
{"op":"mcm","clk":"1344728128","pt":1588098017316,"mc":[{"id":"1.170349309","rc":[{"batb":[[2,1.02,5000]],"ltp":0.0,"tv":0.0,"id":24550116},{"batb":[[2,1.02,5000]],"ltp":0.0,"tv":0.0,"id":27138257},{"batb":[[2,1.02,5000]],"ltp":0.0,"tv":0.0,"id":20893387}]}]}
{"op":"mcm","clk":"1344730554","pt":1588098273498,"mc":[{"id":"1.170349309","rc":[{"batb":[[2,1.01,38.02]],"ltp":0.0,"tv":0.0,"id":24550116},{"batb":[[2,1.01,37.88]],"ltp":0.0,"tv":0.0,"id":27138257},{"batb":[[2,1.01,42.68]],"ltp":0.0,"tv":0.0,"id":26357500},{"batb":[[2,1.01,39.82]],"ltp":0.0,"tv":0.0,"id":27129637},{"batb":[[2,1.01,38.87]],"ltp":0.0,"tv":0.0,"id":20893387}]}]}
{"op":"mcm","clk":"1344730679","pt":1588098288420,"mc":[{"id":"1.170349309","rc":[{"batb":[[2,1.02,5000]],"ltp":0.0,"tv":0.0,"id":24550116},{"batb":[[2,1.02,5000]],"ltp":0.0,"tv":0.0,"id":27138257},{"batb":[[2,1.02,5000]],"ltp":0.0,"tv":0.0,"id":26357500},{"batb":[[2,1.02,5000]],"ltp":0.0,"tv":0.0,"id":27129637},{"batb":[[2,1.02,5000]],"ltp":0.0,"tv":0.0,"id":20893387}]}]}
{"op":"mcm","clk":"1344735451","pt":1588098707479,"mc":[{"id":"1.170349309","rc":[{"trd":[[1.09,3.48]],"batb":[[0,1.09,270.48]],"ltp":1.09,"tv":3.48,"id":27376858}],"tv":3.48}]}
{"op":"mcm","clk":"1344737585","pt":1588098891693,"mc":[{"id":"1.170349309","rc":[{"batb":[[2,1.01,38.02]],"ltp":0.0,"tv":0.0,"id":24550116},{"batb":[[2,1.01,37.88]],"ltp":0.0,"tv":0.0,"id":27138257},{"batb":[[2,1.01,42.68]],"ltp":0.0,"tv":0.0,"id":26357500},{"batb":[[2,1.01,39.82]],"ltp":0.0,"tv":0.0,"id":27129637},{"batb":[[2,1.01,38.87]],"ltp":0.0,"tv":0.0,"id":20893387}]}]}
{"op":"mcm","clk":"1344737781","pt":1588098906695,"mc":[{"id":"1.170349309","rc":[{"batb":[[2,1.02,5000]],"ltp":0.0,"tv":0.0,"id":24550116},{"batb":[[2,1.02,5000]],"ltp":0.0,"tv":0.0,"id":27138257},{"batb":[[2,1.02,5000]],"ltp":0.0,"tv":0.0,"id":26357500},{"batb":[[2,1.02,5000]],"ltp":0.0,"tv":0.0,"id":27129637},{"batb":[[2,1.02,5000]],"ltp":0.0,"tv":0.0,"id":20893387}]}]}
{"op":"mcm","clk":"1344743577","pt":1588099509356,"mc":[{"id":"1.170349309","rc":[{"batb":[[2,1.01,38.02]],"ltp":0.0,"tv":0.0,"id":24550116},{"batb":[[2,1.01,37.88]],"ltp":0.0,"tv":0.0,"id":27138257},{"batb":[[2,1.01,42.68]],"ltp":0.0,"tv":0.0,"id":26357500},{"batb":[[2,1.01,39.82]],"ltp":0.0,"tv":0.0,"id":27129637},{"batb":[[2,1.01,38.87]],"ltp":0.0,"tv":0.0,"id":20893387}]}]}
{"op":"mcm","clk":"1344743830","pt":1588099524425,"mc":[{"id":"1.170349309","rc":[{"batb":[[2,1.02,5000]],"ltp":0.0,"tv":0.0,"id":24550116},{"batb":[[2,1.02,5000]],"ltp":0.0,"tv":0.0,"id":27138257},{"batb":[[2,1.02,5000]],"ltp":0.0,"tv":0.0,"id":26357500},{"batb":[[2,1.02,5000]],"ltp":0.0,"tv":0.0,"id":27129637},{"batb":[[2,1.02,5000]],"ltp":0.0,"tv":0.0,"id":20893387}]}]}
{"op":"mcm","clk":"1344754678","pt":1588100127633,"mc":[{"id":"1.170349309","rc":[{"batb":[[2,1.01,38.02]],"ltp":0.0,"tv":0.0,"id":24550116},{"batb":[[2,1.01,37.88]],"ltp":0.0,"tv":0.0,"id":27138257},{"batb":[[2,1.01,42.68]],"ltp":0.0,"tv":0.0,"id":26357500},{"batb":[[2,1.01,39.82]],"ltp":0.0,"tv":0.0,"id":27129637},{"batb":[[2,1.01,38.87]],"ltp":0.0,"tv":0.0,"id":20893387}]}]}
{"op":"mcm","clk":"1344754946","pt":1588100142573,"mc":[{"id":"1.170349309","rc":[{"batb":[[2,1.02,5000]],"ltp":0.0,"tv":0.0,"id":24550116},{"batb":[[2,1.02,5000]],"ltp":0.0,"tv":0.0,"id":27138257},{"batb":[[2,1.02,5000]],"ltp":0.0,"tv":0.0,"id":26357500},{"batb":[[2,1.02,5000]],"ltp":0.0,"tv":0.0,"id":27129637},{"batb":[[2,1.02,5000]],"ltp":0.0,"tv":0.0,"id":20893387}]}]}
{"op":"mcm","clk":"1344763113","pt":1588100745435,"mc":[{"id":"1.170349309","rc":[{"batb":[[2,1.01,38.02]],"ltp":0.0,"tv":0.0,"id":24550116},{"batb":[[2,1.01,37.88]],"ltp":0.0,"tv":0.0,"id":27138257},{"batb":[[2,1.01,42.68]],"ltp":0.0,"tv":0.0,"id":26357500},{"batb":[[2,1.01,39.82]],"ltp":0.0,"tv":0.0,"id":27129637},{"batb":[[2,1.01,38.87]],"ltp":0.0,"tv":0.0,"id":20893387}]}]}
{"op":"mcm","clk":"1344763359","pt":1588100760336,"mc":[{"id":"1.170349309","rc":[{"batb":[[2,1.02,5000]],"ltp":0.0,"tv":0.0,"id":24550116},{"batb":[[2,1.02,5000]],"ltp":0.0,"tv":0.0,"id":27138257},{"batb":[[2,1.02,5000]],"ltp":0.0,"tv":0.0,"id":26357500},{"batb":[[2,1.02,5000]],"ltp":0.0,"tv":0.0,"id":27129637},{"batb":[[2,1.02,5000]],"ltp":0.0,"tv":0.0,"id":20893387}]}]}
{"op":"mcm","clk":"1344773904","pt":1588101363291,"mc":[{"id":"1.170349309","rc":[{"batb":[[2,1.01,38.02]],"ltp":0.0,"tv":0.0,"id":24550116},{"batb":[[2,1.01,37.88]],"ltp":0.0,"tv":0.0,"id":27138257},{"batb":[[2,1.01,42.68]],"ltp":0.0,"tv":0.0,"id":26357500},{"batb":[[2,1.01,39.82]],"ltp":0.0,"tv":0.0,"id":27129637},{"batb":[[2,1.01,38.87]],"ltp":0.0,"tv":0.0,"id":20893387}]}]}
{"op":"mcm","clk":"1344774133","pt":1588101378395,"mc":[{"id":"1.170349309","rc":[{"batb":[[2,1.02,5000]],"ltp":0.0,"tv":0.0,"id":24550116},{"batb":[[2,1.02,5000]],"ltp":0.0,"tv":0.0,"id":27138257},{"batb":[[2,1.02,5000]],"ltp":0.0,"tv":0.0,"id":26357500},{"batb":[[2,1.02,5000]],"ltp":0.0,"tv":0.0,"id":27129637},{"batb":[[2,1.02,5000]],"ltp":0.0,"tv":0.0,"id":20893387}]}]}
{"op":"mcm","clk":"1344781106","pt":1588101981197,"mc":[{"id":"1.170349309","rc":[{"batb":[[2,1.01,38.02]],"ltp":0.0,"tv":0.0,"id":24550116},{"batb":[[2,1.01,37.88]],"ltp":0.0,"tv":0.0,"id":27138257},{"batb":[[2,1.01,42.68]],"ltp":0.0,"tv":0.0,"id":26357500},{"batb":[[2,1.01,39.82]],"ltp":0.0,"tv":0.0,"id":27129637},{"batb":[[2,1.01,38.87]],"ltp":0.0,"tv":0.0,"id":20893387}]}]}
{"op":"mcm","clk":"1344781332","pt":1588101996219,"mc":[{"id":"1.170349309","rc":[{"batb":[[2,1.02,5000]],"ltp":0.0,"tv":0.0,"id":24550116},{"batb":[[2,1.02,5000]],"ltp":0.0,"tv":0.0,"id":27138257},{"batb":[[2,1.02,5000]],"ltp":0.0,"tv":0.0,"id":26357500},{"batb":[[2,1.02,5000]],"ltp":0.0,"tv":0.0,"id":27129637},{"batb":[[2,1.02,5000]],"ltp":0.0,"tv":0.0,"id":20893387}]}]}
{"op":"mcm","clk":"1344793353","pt":1588102598819,"mc":[{"id":"1.170349309","rc":[{"batb":[[2,1.01,38.02]],"ltp":0.0,"tv":0.0,"id":24550116},{"batb":[[2,1.01,37.88]],"ltp":0.0,"tv":0.0,"id":27138257},{"batb":[[2,1.01,42.68]],"ltp":0.0,"tv":0.0,"id":26357500},{"batb":[[2,1.01,39.82]],"ltp":0.0,"tv":0.0,"id":27129637},{"batb":[[2,1.01,38.87]],"ltp":0.0,"tv":0.0,"id":20893387}]}]}
{"op":"mcm","clk":"1344793484","pt":1588102613845,"mc":[{"id":"1.170349309","rc":[{"batb":[[2,1.02,5000]],"ltp":0.0,"tv":0.0,"id":24550116},{"batb":[[2,1.02,5000]],"ltp":0.0,"tv":0.0,"id":27138257},{"batb":[[2,1.02,5000]],"ltp":0.0,"tv":0.0,"id":26357500},{"batb":[[2,1.02,5000]],"ltp":0.0,"tv":0.0,"id":27129637},{"batb":[[2,1.02,5000]],"ltp":0.0,"tv":0.0,"id":20893387}]}]}
{"op":"mcm","clk":"1344799896","pt":1588103216691,"mc":[{"id":"1.170349309","rc":[{"batb":[[2,1.01,38.02]],"ltp":0.0,"tv":0.0,"id":24550116},{"batb":[[2,1.01,37.88]],"ltp":0.0,"tv":0.0,"id":27138257},{"batb":[[2,1.01,42.68]],"ltp":0.0,"tv":0.0,"id":26357500},{"batb":[[2,1.01,39.82]],"ltp":0.0,"tv":0.0,"id":27129637},{"batb":[[2,1.01,38.87]],"ltp":0.0,"tv":0.0,"id":20893387}]}]}
{"op":"mcm","clk":"1344799953","pt":1588103231691,"mc":[{"id":"1.170349309","rc":[{"batb":[[2,1.02,5000]],"ltp":0.0,"tv":0.0,"id":24550116},{"batb":[[2,1.02,5000]],"ltp":0.0,"tv":0.0,"id":27138257},{"batb":[[2,1.02,5000]],"ltp":0.0,"tv":0.0,"id":26357500},{"batb":[[2,1.02,5000]],"ltp":0.0,"tv":0.0,"id":27129637},{"batb":[[2,1.02,5000]],"ltp":0.0,"tv":0.0,"id":20893387}]}]}
{"op":"mcm","clk":"1344802048","pt":1588103834826,"mc":[{"id":"1.170349309","rc":[{"batb":[[2,1.01,38.02]],"ltp":0.0,"tv":0.0,"id":24550116},{"batb":[[2,1.01,37.88]],"ltp":0.0,"tv":0.0,"id":27138257},{"batb":[[2,1.01,42.68]],"ltp":0.0,"tv":0.0,"id":26357500},{"batb":[[2,1.01,39.82]],"ltp":0.0,"tv":0.0,"id":27129637},{"batb":[[2,1.01,38.87]],"ltp":0.0,"tv":0.0,"id":20893387}]}]}
{"op":"mcm","clk":"1344802070","pt":1588103849934,"mc":[{"id":"1.170349309","rc":[{"batb":[[2,1.02,5000]],"ltp":0.0,"tv":0.0,"id":24550116},{"batb":[[2,1.02,5000]],"ltp":0.0,"tv":0.0,"id":27138257},{"batb":[[2,1.02,5000]],"ltp":0.0,"tv":0.0,"id":26357500},{"batb":[[2,1.02,5000]],"ltp":0.0,"tv":0.0,"id":27129637},{"batb":[[2,1.02,5000]],"ltp":0.0,"tv":0.0,"id":20893387}]}]}
{"op":"mcm","clk":"1344803412","pt":1588104453085,"mc":[{"id":"1.170349309","rc":[{"batb":[[2,1.01,38.51]],"ltp":0.0,"tv":0.0,"id":24550116},{"batb":[[2,1.01,42.3]],"ltp":1.09,"tv":3.48,"id":27376858},{"batb":[[2,1.01,38.38]],"ltp":0.0,"tv":0.0,"id":27138257},{"batb":[[2,1.01,38.69]],"ltp":0.0,"tv":0.0,"id":27661463},{"batb":[[2,1.01,43.24]],"ltp":0.0,"tv":0.0,"id":26357500},{"batb":[[2,1.01,40.34]],"ltp":0.0,"tv":0.0,"id":27129637},{"batb":[[2,1.01,41.53]],"ltp":0.0,"tv":0.0,"id":26148884},{"batb":[[2,1.01,39.38]],"ltp":0.0,"tv":0.0,"id":20893387}]}]}
{"op":"mcm","clk":"1344803445","pt":1588104468190,"mc":[{"id":"1.170349309","rc":[{"batb":[[2,1.02,5000]],"ltp":0.0,"tv":0.0,"id":24550116},{"batb":[[2,1.02,5000]],"ltp":0.0,"tv":0.0,"id":27138257},{"batb":[[2,1.02,5000]],"ltp":0.0,"tv":0.0,"id":26357500},{"batb":[[2,1.02,5000]],"ltp":0.0,"tv":0.0,"id":27129637},{"batb":[[2,1.02,5000]],"ltp":0.0,"tv":0.0,"id":20893387}]}]}
{"op":"mcm","clk":"1344805307","pt":1588105070962,"mc":[{"id":"1.170349309","rc":[{"batb":[[2,1.01,38.51]],"ltp":0.0,"tv":0.0,"id":24550116},{"batb":[[2,1.01,38.38]],"ltp":0.0,"tv":0.0,"id":27138257},{"batb":[[2,1.01,43.24]],"ltp":0.0,"tv":0.0,"id":26357500},{"batb":[[2,1.01,40.34]],"ltp":0.0,"tv":0.0,"id":27129637},{"batb":[[2,1.01,39.38]],"ltp":0.0,"tv":0.0,"id":20893387}]}]}
{"op":"mcm","clk":"1344805331","pt":1588105085871,"mc":[{"id":"1.170349309","rc":[{"batb":[[2,1.02,5000]],"ltp":0.0,"tv":0.0,"id":24550116},{"batb":[[2,1.02,5000]],"ltp":0.0,"tv":0.0,"id":27138257},{"batb":[[2,1.02,5000]],"ltp":0.0,"tv":0.0,"id":26357500},{"batb":[[2,1.02,5000]],"ltp":0.0,"tv":0.0,"id":27129637},{"batb":[[2,1.02,5000]],"ltp":0.0,"tv":0.0,"id":20893387}]}]}
{"op":"mcm","clk":"1344807238","pt":1588105688649,"mc":[{"id":"1.170349309","rc":[{"batb":[[2,1.01,38.51]],"ltp":0.0,"tv":0.0,"id":24550116},{"batb":[[2,1.01,38.38]],"ltp":0.0,"tv":0.0,"id":27138257},{"batb":[[2,1.01,43.24]],"ltp":0.0,"tv":0.0,"id":26357500},{"batb":[[2,1.01,40.34]],"ltp":0.0,"tv":0.0,"id":27129637},{"batb":[[2,1.01,39.38]],"ltp":0.0,"tv":0.0,"id":20893387}]}]}
{"op":"mcm","clk":"1344807261","pt":1588105703747,"mc":[{"id":"1.170349309","rc":[{"batb":[[2,1.02,5000]],"ltp":0.0,"tv":0.0,"id":24550116},{"batb":[[2,1.02,5000]],"ltp":0.0,"tv":0.0,"id":27138257},{"batb":[[2,1.02,5000]],"ltp":0.0,"tv":0.0,"id":26357500},{"batb":[[2,1.02,5000]],"ltp":0.0,"tv":0.0,"id":27129637},{"batb":[[2,1.02,5000]],"ltp":0.0,"tv":0.0,"id":20893387}]}]}
{"op":"mcm","clk":"1344811184","pt":1588106306907,"mc":[{"id":"1.170349309","rc":[{"batb":[[2,1.01,38.51]],"ltp":0.0,"tv":0.0,"id":24550116},{"batb":[[2,1.01,38.38]],"ltp":0.0,"tv":0.0,"id":27138257},{"batb":[[2,1.01,43.24]],"ltp":0.0,"tv":0.0,"id":26357500},{"batb":[[2,1.01,40.34]],"ltp":0.0,"tv":0.0,"id":27129637},{"batb":[[2,1.01,39.38]],"ltp":0.0,"tv":0.0,"id":20893387}]}]}
{"op":"mcm","clk":"1344811331","pt":1588106322068,"mc":[{"id":"1.170349309","rc":[{"batb":[[2,1.02,5000]],"ltp":0.0,"tv":0.0,"id":24550116},{"batb":[[2,1.02,5000]],"ltp":0.0,"tv":0.0,"id":27138257},{"batb":[[2,1.02,5000]],"ltp":0.0,"tv":0.0,"id":26357500},{"batb":[[2,1.02,5000]],"ltp":0.0,"tv":0.0,"id":27129637},{"batb":[[2,1.02,5000]],"ltp":0.0,"tv":0.0,"id":20893387}]}]}
{"op":"mcm","clk":"1344816987","pt":1588106924509,"mc":[{"id":"1.170349309","rc":[{"batb":[[2,1.01,38.51]],"ltp":0.0,"tv":0.0,"id":24550116},{"batb":[[2,1.01,38.38]],"ltp":0.0,"tv":0.0,"id":27138257},{"batb":[[2,1.01,43.24]],"ltp":0.0,"tv":0.0,"id":26357500},{"batb":[[2,1.01,40.34]],"ltp":0.0,"tv":0.0,"id":27129637},{"batb":[[2,1.01,39.38]],"ltp":0.0,"tv":0.0,"id":20893387}]}]}
{"op":"mcm","clk":"1344817152","pt":1588106939530,"mc":[{"id":"1.170349309","rc":[{"batb":[[2,1.02,5000]],"ltp":0.0,"tv":0.0,"id":24550116},{"batb":[[2,1.02,5000]],"ltp":0.0,"tv":0.0,"id":27138257},{"batb":[[2,1.02,5000]],"ltp":0.0,"tv":0.0,"id":26357500},{"batb":[[2,1.02,5000]],"ltp":0.0,"tv":0.0,"id":27129637},{"batb":[[2,1.02,5000]],"ltp":0.0,"tv":0.0,"id":20893387}]}]}
{"op":"mcm","clk":"1344820483","pt":1588107542111,"mc":[{"id":"1.170349309","rc":[{"batb":[[2,1.01,38.51]],"ltp":0.0,"tv":0.0,"id":24550116},{"batb":[[2,1.01,38.38]],"ltp":0.0,"tv":0.0,"id":27138257},{"batb":[[2,1.01,43.24]],"ltp":0.0,"tv":0.0,"id":26357500},{"batb":[[2,1.01,40.34]],"ltp":0.0,"tv":0.0,"id":27129637},{"batb":[[2,1.01,39.38]],"ltp":0.0,"tv":0.0,"id":20893387}]}]}
{"op":"mcm","clk":"1344820557","pt":1588107557262,"mc":[{"id":"1.170349309","rc":[{"batb":[[2,1.02,5000]],"ltp":0.0,"tv":0.0,"id":24550116},{"batb":[[2,1.02,5000]],"ltp":0.0,"tv":0.0,"id":27138257},{"batb":[[2,1.02,5000]],"ltp":0.0,"tv":0.0,"id":26357500},{"batb":[[2,1.02,5000]],"ltp":0.0,"tv":0.0,"id":27129637},{"batb":[[2,1.02,5000]],"ltp":0.0,"tv":0.0,"id":20893387}]}]}
{"op":"mcm","clk":"1344825069","pt":1588108159793,"mc":[{"id":"1.170349309","rc":[{"batb":[[2,1.01,38.51]],"ltp":0.0,"tv":0.0,"id":24550116},{"batb":[[2,1.01,38.38]],"ltp":0.0,"tv":0.0,"id":27138257},{"batb":[[2,1.01,43.24]],"ltp":0.0,"tv":0.0,"id":26357500},{"batb":[[2,1.01,40.34]],"ltp":0.0,"tv":0.0,"id":27129637},{"batb":[[2,1.01,39.38]],"ltp":0.0,"tv":0.0,"id":20893387}]}]}
{"op":"mcm","clk":"1344825183","pt":1588108174858,"mc":[{"id":"1.170349309","rc":[{"batb":[[2,1.02,5000]],"ltp":0.0,"tv":0.0,"id":24550116},{"batb":[[2,1.02,5000]],"ltp":0.0,"tv":0.0,"id":27138257},{"batb":[[2,1.02,5000]],"ltp":0.0,"tv":0.0,"id":26357500},{"batb":[[2,1.02,5000]],"ltp":0.0,"tv":0.0,"id":27129637},{"batb":[[2,1.02,5000]],"ltp":0.0,"tv":0.0,"id":20893387}]}]}
{"op":"mcm","clk":"1344830998","pt":1588108777499,"mc":[{"id":"1.170349309","rc":[{"batb":[[2,1.01,38.51]],"ltp":0.0,"tv":0.0,"id":24550116},{"batb":[[2,1.01,38.38]],"ltp":0.0,"tv":0.0,"id":27138257},{"batb":[[2,1.01,43.24]],"ltp":0.0,"tv":0.0,"id":26357500},{"batb":[[2,1.01,40.34]],"ltp":0.0,"tv":0.0,"id":27129637},{"batb":[[2,1.01,39.38]],"ltp":0.0,"tv":0.0,"id":20893387}]}]}
{"op":"mcm","clk":"1344831159","pt":1588108792644,"mc":[{"id":"1.170349309","rc":[{"batb":[[2,1.02,5000]],"ltp":0.0,"tv":0.0,"id":24550116},{"batb":[[2,1.02,5000]],"ltp":0.0,"tv":0.0,"id":27138257},{"batb":[[2,1.02,5000]],"ltp":0.0,"tv":0.0,"id":26357500},{"batb":[[2,1.02,5000]],"ltp":0.0,"tv":0.0,"id":27129637},{"batb":[[2,1.02,5000]],"ltp":0.0,"tv":0.0,"id":20893387}]}]}
{"op":"mcm","clk":"1344835465","pt":1588109395152,"mc":[{"id":"1.170349309","rc":[{"batb":[[2,1.01,38.51]],"ltp":0.0,"tv":0.0,"id":24550116},{"batb":[[2,1.01,38.38]],"ltp":0.0,"tv":0.0,"id":27138257},{"batb":[[2,1.01,43.24]],"ltp":0.0,"tv":0.0,"id":26357500},{"batb":[[2,1.01,40.34]],"ltp":0.0,"tv":0.0,"id":27129637},{"batb":[[2,1.01,39.38]],"ltp":0.0,"tv":0.0,"id":20893387}]}]}
{"op":"mcm","clk":"1344835479","pt":1588109410046,"mc":[{"id":"1.170349309","rc":[{"batb":[[2,1.02,5000]],"ltp":0.0,"tv":0.0,"id":24550116},{"batb":[[2,1.02,5000]],"ltp":0.0,"tv":0.0,"id":27138257},{"batb":[[2,1.02,5000]],"ltp":0.0,"tv":0.0,"id":26357500},{"batb":[[2,1.02,5000]],"ltp":0.0,"tv":0.0,"id":27129637},{"batb":[[2,1.02,5000]],"ltp":0.0,"tv":0.0,"id":20893387}]}]}
{"op":"mcm","clk":"1344837443","pt":1588110012993,"mc":[{"id":"1.170349309","rc":[{"batb":[[2,1.01,38.51]],"ltp":0.0,"tv":0.0,"id":24550116},{"batb":[[2,1.01,38.38]],"ltp":0.0,"tv":0.0,"id":27138257},{"batb":[[2,1.01,43.24]],"ltp":0.0,"tv":0.0,"id":26357500},{"batb":[[2,1.01,40.34]],"ltp":0.0,"tv":0.0,"id":27129637},{"batb":[[2,1.01,39.38]],"ltp":0.0,"tv":0.0,"id":20893387}]}]}
{"op":"mcm","clk":"1344837511","pt":1588110028131,"mc":[{"id":"1.170349309","rc":[{"batb":[[2,1.02,5000]],"ltp":0.0,"tv":0.0,"id":24550116},{"batb":[[2,1.02,5000]],"ltp":0.0,"tv":0.0,"id":27138257},{"batb":[[2,1.02,5000]],"ltp":0.0,"tv":0.0,"id":26357500},{"batb":[[2,1.02,5000]],"ltp":0.0,"tv":0.0,"id":27129637},{"batb":[[2,1.02,5000]],"ltp":0.0,"tv":0.0,"id":20893387}]}]}
{"op":"mcm","clk":"1344840358","pt":1588110630997,"mc":[{"id":"1.170349309","rc":[{"batb":[[2,1.01,38.51]],"ltp":0.0,"tv":0.0,"id":24550116},{"batb":[[2,1.01,38.38]],"ltp":0.0,"tv":0.0,"id":27138257},{"batb":[[2,1.01,43.24]],"ltp":0.0,"tv":0.0,"id":26357500},{"batb":[[2,1.01,40.34]],"ltp":0.0,"tv":0.0,"id":27129637},{"batb":[[2,1.01,39.38]],"ltp":0.0,"tv":0.0,"id":20893387}]}]}
{"op":"mcm","clk":"1344840411","pt":1588110645983,"mc":[{"id":"1.170349309","rc":[{"batb":[[2,1.02,5000]],"ltp":0.0,"tv":0.0,"id":24550116},{"batb":[[2,1.02,5000]],"ltp":0.0,"tv":0.0,"id":27138257},{"batb":[[2,1.02,5000]],"ltp":0.0,"tv":0.0,"id":26357500},{"batb":[[2,1.02,5000]],"ltp":0.0,"tv":0.0,"id":27129637},{"batb":[[2,1.02,5000]],"ltp":0.0,"tv":0.0,"id":20893387}]}]}
{"op":"mcm","clk":"1344844054","pt":1588111248519,"mc":[{"id":"1.170349309","rc":[{"batb":[[2,1.01,38.7]],"batl":[[0,1000,1.52]],"ltp":0.0,"tv":0.0,"id":24550116},{"batb":[[2,1.01,42.51]],"batl":[[1,1000,1.53]],"ltp":1.09,"tv":3.48,"id":27376858},{"batb":[[2,1.01,38.56]],"batl":[[0,1000,1.54]],"ltp":0.0,"tv":0.0,"id":27138257},{"batb":[[2,1.01,38.88]],"batl":[[1,1000,1.54]],"ltp":0.0,"tv":0.0,"id":27661463},{"batb":[[2,1.01,43.45]],"batl":[[1,1000,1.55]],"ltp":0.0,"tv":0.0,"id":26357500},{"batb":[[2,1.01,40.54]],"batl":[[0,1000,1.52]],"ltp":0.0,"tv":0.0,"id":27129637},{"batb":[[2,1.01,41.74]],"batl":[[1,1000,1.53]],"ltp":0.0,"tv":0.0,"id":26148884},{"batb":[[2,1.01,39.57]],"batl":[[0,1000,1.57]],"ltp":0.0,"tv":0.0,"id":20893387}]}]}
{"op":"mcm","clk":"1344844167","pt":1588111263511,"mc":[{"id":"1.170349309","rc":[{"batb":[[2,1.02,5000]],"ltp":0.0,"tv":0.0,"id":24550116},{"batb":[[2,1.02,5000]],"ltp":0.0,"tv":0.0,"id":27138257},{"batb":[[2,1.02,5000]],"ltp":0.0,"tv":0.0,"id":26357500},{"batb":[[2,1.02,5000]],"ltp":0.0,"tv":0.0,"id":27129637},{"batb":[[2,1.02,5000]],"ltp":0.0,"tv":0.0,"id":20893387}]}]}
{"op":"mcm","clk":"1344847460","pt":1588111865976,"mc":[{"id":"1.170349309","rc":[{"batb":[[2,1.01,38.7]],"ltp":0.0,"tv":0.0,"id":24550116},{"batb":[[2,1.01,38.56]],"ltp":0.0,"tv":0.0,"id":27138257},{"batb":[[2,1.01,43.45]],"ltp":0.0,"tv":0.0,"id":26357500},{"batb":[[2,1.01,40.54]],"ltp":0.0,"tv":0.0,"id":27129637},{"batb":[[2,1.01,39.57]],"ltp":0.0,"tv":0.0,"id":20893387}]}]}
{"op":"mcm","clk":"1344847507","pt":1588111881114,"mc":[{"id":"1.170349309","rc":[{"batb":[[2,1.02,5000]],"ltp":0.0,"tv":0.0,"id":24550116},{"batb":[[2,1.02,5000]],"ltp":0.0,"tv":0.0,"id":27138257},{"batb":[[2,1.02,5000]],"ltp":0.0,"tv":0.0,"id":26357500},{"batb":[[2,1.02,5000]],"ltp":0.0,"tv":0.0,"id":27129637},{"batb":[[2,1.02,5000]],"ltp":0.0,"tv":0.0,"id":20893387}]}]}
{"op":"mcm","clk":"1344849650","pt":1588112483017,"mc":[{"id":"1.170349309","rc":[{"batb":[[2,1.01,38.7]],"ltp":0.0,"tv":0.0,"id":24550116},{"batb":[[2,1.01,38.56]],"ltp":0.0,"tv":0.0,"id":27138257},{"batb":[[2,1.01,43.45]],"ltp":0.0,"tv":0.0,"id":26357500},{"batb":[[2,1.01,40.54]],"ltp":0.0,"tv":0.0,"id":27129637},{"batb":[[2,1.01,39.57]],"ltp":0.0,"tv":0.0,"id":20893387}]}]}
{"op":"mcm","clk":"1344849672","pt":1588112498050,"mc":[{"id":"1.170349309","rc":[{"batb":[[2,1.02,5000]],"ltp":0.0,"tv":0.0,"id":24550116},{"batb":[[2,1.02,5000]],"ltp":0.0,"tv":0.0,"id":27138257},{"batb":[[2,1.02,5000]],"ltp":0.0,"tv":0.0,"id":26357500},{"batb":[[2,1.02,5000]],"ltp":0.0,"tv":0.0,"id":27129637},{"batb":[[2,1.02,5000]],"ltp":0.0,"tv":0.0,"id":20893387}]}]}
{"op":"mcm","clk":"1344850997","pt":1588113099774,"mc":[{"id":"1.170349309","rc":[{"batb":[[2,1.01,38.7]],"ltp":0.0,"tv":0.0,"id":24550116},{"batb":[[2,1.01,38.56]],"ltp":0.0,"tv":0.0,"id":27138257},{"batb":[[2,1.01,43.45]],"ltp":0.0,"tv":0.0,"id":26357500},{"batb":[[2,1.01,40.54]],"ltp":0.0,"tv":0.0,"id":27129637},{"batb":[[2,1.01,39.57]],"ltp":0.0,"tv":0.0,"id":20893387}]}]}
{"op":"mcm","clk":"1344851005","pt":1588113114784,"mc":[{"id":"1.170349309","rc":[{"batb":[[2,1.02,5000]],"ltp":0.0,"tv":0.0,"id":24550116},{"batb":[[2,1.02,5000]],"ltp":0.0,"tv":0.0,"id":27138257},{"batb":[[2,1.02,5000]],"ltp":0.0,"tv":0.0,"id":26357500},{"batb":[[2,1.02,5000]],"ltp":0.0,"tv":0.0,"id":27129637},{"batb":[[2,1.02,5000]],"ltp":0.0,"tv":0.0,"id":20893387}]}]}
{"op":"mcm","clk":"1344851861","pt":1588113717183,"mc":[{"id":"1.170349309","rc":[{"batb":[[2,1.01,38.7]],"ltp":0.0,"tv":0.0,"id":24550116},{"batb":[[2,1.01,38.56]],"ltp":0.0,"tv":0.0,"id":27138257},{"batb":[[2,1.01,43.45]],"ltp":0.0,"tv":0.0,"id":26357500},{"batb":[[2,1.01,40.54]],"ltp":0.0,"tv":0.0,"id":27129637},{"batb":[[2,1.01,39.57]],"ltp":0.0,"tv":0.0,"id":20893387}]}]}
{"op":"mcm","clk":"1344851875","pt":1588113732059,"mc":[{"id":"1.170349309","rc":[{"batb":[[2,1.02,5000]],"ltp":0.0,"tv":0.0,"id":24550116},{"batb":[[2,1.02,5000]],"ltp":0.0,"tv":0.0,"id":27138257},{"batb":[[2,1.02,5000]],"ltp":0.0,"tv":0.0,"id":26357500},{"batb":[[2,1.02,5000]],"ltp":0.0,"tv":0.0,"id":27129637},{"batb":[[2,1.02,5000]],"ltp":0.0,"tv":0.0,"id":20893387}]}]}
{"op":"mcm","clk":"1344852333","pt":1588114334044,"mc":[{"id":"1.170349309","rc":[{"batb":[[2,1.01,38.7]],"ltp":0.0,"tv":0.0,"id":24550116},{"batb":[[2,1.01,38.56]],"ltp":0.0,"tv":0.0,"id":27138257},{"batb":[[2,1.01,43.45]],"ltp":0.0,"tv":0.0,"id":26357500},{"batb":[[2,1.01,40.54]],"ltp":0.0,"tv":0.0,"id":27129637},{"batb":[[2,1.01,39.57]],"ltp":0.0,"tv":0.0,"id":20893387}]}]}
{"op":"mcm","clk":"1344852341","pt":1588114349153,"mc":[{"id":"1.170349309","rc":[{"batb":[[2,1.02,5000]],"ltp":0.0,"tv":0.0,"id":24550116},{"batb":[[2,1.02,5000]],"ltp":0.0,"tv":0.0,"id":27138257},{"batb":[[2,1.02,5000]],"ltp":0.0,"tv":0.0,"id":26357500},{"batb":[[2,1.02,5000]],"ltp":0.0,"tv":0.0,"id":27129637},{"batb":[[2,1.02,5000]],"ltp":0.0,"tv":0.0,"id":20893387}]}]}
{"op":"mcm","clk":"1344853635","pt":1588114951399,"mc":[{"id":"1.170349309","rc":[{"batb":[[2,1.01,38.7]],"ltp":0.0,"tv":0.0,"id":24550116},{"batb":[[2,1.01,38.56]],"ltp":0.0,"tv":0.0,"id":27138257},{"batb":[[2,1.01,43.45]],"ltp":0.0,"tv":0.0,"id":26357500},{"batb":[[2,1.01,40.54]],"ltp":0.0,"tv":0.0,"id":27129637},{"batb":[[2,1.01,39.57]],"ltp":0.0,"tv":0.0,"id":20893387}]}]}
{"op":"mcm","clk":"1344853652","pt":1588114966400,"mc":[{"id":"1.170349309","rc":[{"batb":[[2,1.02,5000]],"ltp":0.0,"tv":0.0,"id":24550116},{"batb":[[2,1.02,5000]],"ltp":0.0,"tv":0.0,"id":27138257},{"batb":[[2,1.02,5000]],"ltp":0.0,"tv":0.0,"id":26357500},{"batb":[[2,1.02,5000]],"ltp":0.0,"tv":0.0,"id":27129637},{"batb":[[2,1.02,5000]],"ltp":0.0,"tv":0.0,"id":20893387}]}]}
{"op":"mcm","clk":"1344854836","pt":1588115568771,"mc":[{"id":"1.170349309","rc":[{"batb":[[2,1.01,38.7]],"ltp":0.0,"tv":0.0,"id":24550116},{"batb":[[2,1.01,38.56]],"ltp":0.0,"tv":0.0,"id":27138257},{"batb":[[2,1.01,43.45]],"ltp":0.0,"tv":0.0,"id":26357500},{"batb":[[2,1.01,40.54]],"ltp":0.0,"tv":0.0,"id":27129637},{"batb":[[2,1.01,39.57]],"ltp":0.0,"tv":0.0,"id":20893387}]}]}
{"op":"mcm","clk":"1344854854","pt":1588115583789,"mc":[{"id":"1.170349309","rc":[{"batb":[[2,1.02,5000]],"ltp":0.0,"tv":0.0,"id":24550116},{"batb":[[2,1.02,5000]],"ltp":0.0,"tv":0.0,"id":27138257},{"batb":[[2,1.02,5000]],"ltp":0.0,"tv":0.0,"id":26357500},{"batb":[[2,1.02,5000]],"ltp":0.0,"tv":0.0,"id":27129637},{"batb":[[2,1.02,5000]],"ltp":0.0,"tv":0.0,"id":20893387}]}]}
{"op":"mcm","clk":"1344855529","pt":1588116185575,"mc":[{"id":"1.170349309","rc":[{"batb":[[2,1.01,38.7]],"ltp":0.0,"tv":0.0,"id":24550116},{"batb":[[2,1.01,38.56]],"ltp":0.0,"tv":0.0,"id":27138257},{"batb":[[2,1.01,43.45]],"ltp":0.0,"tv":0.0,"id":26357500},{"batb":[[2,1.01,40.54]],"ltp":0.0,"tv":0.0,"id":27129637},{"batb":[[2,1.01,39.57]],"ltp":0.0,"tv":0.0,"id":20893387}]}]}
{"op":"mcm","clk":"1344855540","pt":1588116200593,"mc":[{"id":"1.170349309","rc":[{"batb":[[2,1.02,5000]],"ltp":0.0,"tv":0.0,"id":24550116},{"batb":[[2,1.02,5000]],"ltp":0.0,"tv":0.0,"id":27138257},{"batb":[[2,1.02,5000]],"ltp":0.0,"tv":0.0,"id":26357500},{"batb":[[2,1.02,5000]],"ltp":0.0,"tv":0.0,"id":27129637},{"batb":[[2,1.02,5000]],"ltp":0.0,"tv":0.0,"id":20893387}]}]}
{"op":"mcm","clk":"1344856870","pt":1588116802905,"mc":[{"id":"1.170349309","rc":[{"batb":[[2,1.01,38.7]],"ltp":0.0,"tv":0.0,"id":24550116},{"batb":[[2,1.01,38.56]],"ltp":0.0,"tv":0.0,"id":27138257},{"batb":[[2,1.01,43.45]],"ltp":0.0,"tv":0.0,"id":26357500},{"batb":[[2,1.01,40.54]],"ltp":0.0,"tv":0.0,"id":27129637},{"batb":[[2,1.01,39.57]],"ltp":0.0,"tv":0.0,"id":20893387}]}]}
{"op":"mcm","clk":"1344856885","pt":1588116818043,"mc":[{"id":"1.170349309","rc":[{"batb":[[2,1.02,5000]],"ltp":0.0,"tv":0.0,"id":24550116},{"batb":[[2,1.02,5000]],"ltp":0.0,"tv":0.0,"id":27138257},{"batb":[[2,1.02,5000]],"ltp":0.0,"tv":0.0,"id":26357500},{"batb":[[2,1.02,5000]],"ltp":0.0,"tv":0.0,"id":27129637},{"batb":[[2,1.02,5000]],"ltp":0.0,"tv":0.0,"id":20893387}]}]}
{"op":"mcm","clk":"1344859419","pt":1588117420213,"mc":[{"id":"1.170349309","rc":[{"batb":[[2,1.01,38.7]],"ltp":0.0,"tv":0.0,"id":24550116},{"batb":[[2,1.01,38.56]],"ltp":0.0,"tv":0.0,"id":27138257},{"batb":[[2,1.01,43.45]],"ltp":0.0,"tv":0.0,"id":26357500},{"batb":[[2,1.01,40.54]],"ltp":0.0,"tv":0.0,"id":27129637},{"batb":[[2,1.01,39.57]],"ltp":0.0,"tv":0.0,"id":20893387}]}]}
{"op":"mcm","clk":"1344859470","pt":1588117435232,"mc":[{"id":"1.170349309","rc":[{"batb":[[2,1.02,5000]],"ltp":0.0,"tv":0.0,"id":24550116},{"batb":[[2,1.02,5000]],"ltp":0.0,"tv":0.0,"id":27138257},{"batb":[[2,1.02,5000]],"ltp":0.0,"tv":0.0,"id":26357500},{"batb":[[2,1.02,5000]],"ltp":0.0,"tv":0.0,"id":27129637},{"batb":[[2,1.02,5000]],"ltp":0.0,"tv":0.0,"id":20893387}]}]}
{"op":"mcm","clk":"1344861374","pt":1588118037632,"mc":[{"id":"1.170349309","rc":[{"batb":[[2,1.01,38.7]],"ltp":0.0,"tv":0.0,"id":24550116},{"batb":[[2,1.01,38.56]],"ltp":0.0,"tv":0.0,"id":27138257},{"batb":[[2,1.01,43.45]],"ltp":0.0,"tv":0.0,"id":26357500},{"batb":[[2,1.01,40.54]],"ltp":0.0,"tv":0.0,"id":27129637},{"batb":[[2,1.01,39.57]],"ltp":0.0,"tv":0.0,"id":20893387}]}]}
{"op":"mcm","clk":"1344861442","pt":1588118052634,"mc":[{"id":"1.170349309","rc":[{"batb":[[2,1.02,5000]],"ltp":0.0,"tv":0.0,"id":24550116},{"batb":[[2,1.02,5000]],"ltp":0.0,"tv":0.0,"id":27138257},{"batb":[[2,1.02,5000]],"ltp":0.0,"tv":0.0,"id":26357500},{"batb":[[2,1.02,5000]],"ltp":0.0,"tv":0.0,"id":27129637},{"batb":[[2,1.02,5000]],"ltp":0.0,"tv":0.0,"id":20893387}]}]}
{"op":"mcm","clk":"1344863478","pt":1588118654749,"mc":[{"id":"1.170349309","rc":[{"batb":[[2,1.01,38.62]],"batl":[[0,1000,1.52]],"ltp":0.0,"tv":0.0,"id":24550116},{"batb":[[2,1.01,42.42]],"batl":[[1,1000,1.53]],"ltp":1.09,"tv":3.48,"id":27376858},{"batb":[[2,1.01,38.49]],"batl":[[0,1000,1.54]],"ltp":0.0,"tv":0.0,"id":27138257},{"batb":[[2,1.01,38.8]],"batl":[[1,1000,1.54]],"ltp":0.0,"tv":0.0,"id":27661463},{"batb":[[2,1.01,43.36]],"batl":[[1,1000,1.55]],"ltp":0.0,"tv":0.0,"id":26357500},{"batb":[[2,1.01,40.46]],"batl":[[0,1000,1.52]],"ltp":0.0,"tv":0.0,"id":27129637},{"batb":[[2,1.01,41.65]],"batl":[[1,1000,1.53]],"ltp":0.0,"tv":0.0,"id":26148884},{"batb":[[2,1.01,39.49]],"batl":[[0,1000,1.57]],"ltp":0.0,"tv":0.0,"id":20893387}]}]}
{"op":"mcm","clk":"1344863487","pt":1588118669764,"mc":[{"id":"1.170349309","rc":[{"batb":[[2,1.02,5000]],"ltp":0.0,"tv":0.0,"id":24550116},{"batb":[[2,1.02,5000]],"ltp":0.0,"tv":0.0,"id":27138257},{"batb":[[2,1.02,5000]],"ltp":0.0,"tv":0.0,"id":26357500},{"batb":[[2,1.02,5000]],"ltp":0.0,"tv":0.0,"id":27129637},{"batb":[[2,1.02,5000]],"ltp":0.0,"tv":0.0,"id":20893387}]}]}
{"op":"mcm","clk":"1344865153","pt":1588119272249,"mc":[{"id":"1.170349309","rc":[{"batb":[[2,1.01,38.62]],"ltp":0.0,"tv":0.0,"id":24550116},{"batb":[[2,1.01,38.49]],"ltp":0.0,"tv":0.0,"id":27138257},{"batb":[[2,1.01,43.36]],"ltp":0.0,"tv":0.0,"id":26357500},{"batb":[[2,1.01,40.46]],"ltp":0.0,"tv":0.0,"id":27129637},{"batb":[[2,1.01,39.49]],"ltp":0.0,"tv":0.0,"id":20893387}]}]}
{"op":"mcm","clk":"1344865194","pt":1588119287209,"mc":[{"id":"1.170349309","rc":[{"batb":[[2,1.02,5000]],"ltp":0.0,"tv":0.0,"id":24550116},{"batb":[[2,1.02,5000]],"ltp":0.0,"tv":0.0,"id":27138257},{"batb":[[2,1.02,5000]],"ltp":0.0,"tv":0.0,"id":26357500},{"batb":[[2,1.02,5000]],"ltp":0.0,"tv":0.0,"id":27129637},{"batb":[[2,1.02,5000]],"ltp":0.0,"tv":0.0,"id":20893387}]}]}
{"op":"mcm","clk":"1344867321","pt":1588119889741,"mc":[{"id":"1.170349309","rc":[{"batb":[[2,1.01,38.62]],"ltp":0.0,"tv":0.0,"id":24550116},{"batb":[[2,1.01,38.49]],"ltp":0.0,"tv":0.0,"id":27138257},{"batb":[[2,1.01,43.36]],"ltp":0.0,"tv":0.0,"id":26357500},{"batb":[[2,1.01,40.46]],"ltp":0.0,"tv":0.0,"id":27129637},{"batb":[[2,1.01,39.49]],"ltp":0.0,"tv":0.0,"id":20893387}]}]}
{"op":"mcm","clk":"1344867359","pt":1588119904656,"mc":[{"id":"1.170349309","rc":[{"batb":[[2,1.02,5000]],"ltp":0.0,"tv":0.0,"id":24550116},{"batb":[[2,1.02,5000]],"ltp":0.0,"tv":0.0,"id":27138257},{"batb":[[2,1.02,5000]],"ltp":0.0,"tv":0.0,"id":26357500},{"batb":[[2,1.02,5000]],"ltp":0.0,"tv":0.0,"id":27129637},{"batb":[[2,1.02,5000]],"ltp":0.0,"tv":0.0,"id":20893387}]}]}
{"op":"mcm","clk":"1344868099","pt":1588120506899,"mc":[{"id":"1.170349309","rc":[{"batb":[[2,1.01,38.62]],"ltp":0.0,"tv":0.0,"id":24550116},{"batb":[[2,1.01,38.49]],"ltp":0.0,"tv":0.0,"id":27138257},{"batb":[[2,1.01,43.36]],"ltp":0.0,"tv":0.0,"id":26357500},{"batb":[[2,1.01,40.46]],"ltp":0.0,"tv":0.0,"id":27129637},{"batb":[[2,1.01,39.49]],"ltp":0.0,"tv":0.0,"id":20893387}]}]}
{"op":"mcm","clk":"1344868177","pt":1588120521902,"mc":[{"id":"1.170349309","rc":[{"batb":[[2,1.02,5000]],"ltp":0.0,"tv":0.0,"id":24550116},{"batb":[[2,1.02,5000]],"ltp":0.0,"tv":0.0,"id":27138257},{"batb":[[2,1.02,5000]],"ltp":0.0,"tv":0.0,"id":26357500},{"batb":[[2,1.02,5000]],"ltp":0.0,"tv":0.0,"id":27129637},{"batb":[[2,1.02,5000]],"ltp":0.0,"tv":0.0,"id":20893387}]}]}
{"op":"mcm","clk":"1344869953","pt":1588121124364,"mc":[{"id":"1.170349309","rc":[{"batb":[[2,1.01,38.62]],"ltp":0.0,"tv":0.0,"id":24550116},{"batb":[[2,1.01,38.49]],"ltp":0.0,"tv":0.0,"id":27138257},{"batb":[[2,1.01,43.36]],"ltp":0.0,"tv":0.0,"id":26357500},{"batb":[[2,1.01,40.46]],"ltp":0.0,"tv":0.0,"id":27129637},{"batb":[[2,1.01,39.49]],"ltp":0.0,"tv":0.0,"id":20893387}]}]}
{"op":"mcm","clk":"1344870120","pt":1588121184376,"mc":[{"id":"1.170349309","rc":[{"batb":[[2,1.02,5000]],"ltp":0.0,"tv":0.0,"id":24550116},{"batb":[[2,1.02,5000]],"ltp":0.0,"tv":0.0,"id":27138257},{"batb":[[2,1.02,5000]],"ltp":0.0,"tv":0.0,"id":26357500},{"batb":[[2,1.02,5000]],"ltp":0.0,"tv":0.0,"id":27129637},{"batb":[[2,1.02,5000]],"ltp":0.0,"tv":0.0,"id":20893387}]}]}
{"op":"mcm","clk":"1344872069","pt":1588121801556,"mc":[{"id":"1.170349309","rc":[{"batb":[[2,1.01,38.62]],"ltp":0.0,"tv":0.0,"id":24550116},{"batb":[[2,1.01,38.49]],"ltp":0.0,"tv":0.0,"id":27138257},{"batb":[[2,1.01,43.36]],"ltp":0.0,"tv":0.0,"id":26357500},{"batb":[[2,1.01,40.46]],"ltp":0.0,"tv":0.0,"id":27129637},{"batb":[[2,1.01,39.49]],"ltp":0.0,"tv":0.0,"id":20893387}]}]}
{"op":"mcm","clk":"1344872185","pt":1588121891758,"mc":[{"id":"1.170349309","rc":[{"batb":[[2,1.02,5000]],"ltp":0.0,"tv":0.0,"id":24550116},{"batb":[[2,1.02,5000]],"ltp":0.0,"tv":0.0,"id":27138257},{"batb":[[2,1.02,5000]],"ltp":0.0,"tv":0.0,"id":26357500},{"batb":[[2,1.02,5000]],"ltp":0.0,"tv":0.0,"id":27129637},{"batb":[[2,1.02,5000]],"ltp":0.0,"tv":0.0,"id":20893387}]}]}
{"op":"mcm","clk":"1344873366","pt":1588122494162,"mc":[{"id":"1.170349309","rc":[{"batb":[[2,1.01,38.62]],"ltp":0.0,"tv":0.0,"id":24550116},{"batb":[[2,1.01,38.49]],"ltp":0.0,"tv":0.0,"id":27138257},{"batb":[[2,1.01,43.36]],"ltp":0.0,"tv":0.0,"id":26357500},{"batb":[[2,1.01,40.46]],"ltp":0.0,"tv":0.0,"id":27129637},{"batb":[[2,1.01,39.49]],"ltp":0.0,"tv":0.0,"id":20893387}]}]}
{"op":"mcm","clk":"1344873394","pt":1588122509213,"mc":[{"id":"1.170349309","rc":[{"batb":[[2,1.02,5000]],"ltp":0.0,"tv":0.0,"id":24550116},{"batb":[[2,1.02,5000]],"ltp":0.0,"tv":0.0,"id":27138257},{"batb":[[2,1.02,5000]],"ltp":0.0,"tv":0.0,"id":26357500},{"batb":[[2,1.02,5000]],"ltp":0.0,"tv":0.0,"id":27129637},{"batb":[[2,1.02,5000]],"ltp":0.0,"tv":0.0,"id":20893387}]}]}
{"op":"mcm","clk":"1344875613","pt":1588123111765,"mc":[{"id":"1.170349309","rc":[{"batb":[[2,1.01,38.62]],"ltp":0.0,"tv":0.0,"id":24550116},{"batb":[[2,1.01,38.49]],"ltp":0.0,"tv":0.0,"id":27138257},{"batb":[[2,1.01,43.36]],"ltp":0.0,"tv":0.0,"id":26357500},{"batb":[[2,1.01,40.46]],"ltp":0.0,"tv":0.0,"id":27129637},{"batb":[[2,1.01,39.49]],"ltp":0.0,"tv":0.0,"id":20893387}]}]}
{"op":"mcm","clk":"1344875643","pt":1588123126772,"mc":[{"id":"1.170349309","rc":[{"batb":[[2,1.02,5000]],"ltp":0.0,"tv":0.0,"id":24550116},{"batb":[[2,1.02,5000]],"ltp":0.0,"tv":0.0,"id":27138257},{"batb":[[2,1.02,5000]],"ltp":0.0,"tv":0.0,"id":26357500},{"batb":[[2,1.02,5000]],"ltp":0.0,"tv":0.0,"id":27129637},{"batb":[[2,1.02,5000]],"ltp":0.0,"tv":0.0,"id":20893387}]}]}
{"op":"mcm","clk":"1344877662","pt":1588123728848,"mc":[{"id":"1.170349309","rc":[{"batb":[[2,1.01,38.62]],"ltp":0.0,"tv":0.0,"id":24550116},{"batb":[[2,1.01,38.49]],"ltp":0.0,"tv":0.0,"id":27138257},{"batb":[[2,1.01,43.36]],"ltp":0.0,"tv":0.0,"id":26357500},{"batb":[[2,1.01,40.46]],"ltp":0.0,"tv":0.0,"id":27129637},{"batb":[[2,1.01,39.49]],"ltp":0.0,"tv":0.0,"id":20893387}]}]}
{"op":"mcm","clk":"1344877680","pt":1588123743740,"mc":[{"id":"1.170349309","rc":[{"batb":[[2,1.02,5000]],"ltp":0.0,"tv":0.0,"id":24550116},{"batb":[[2,1.02,5000]],"ltp":0.0,"tv":0.0,"id":27138257},{"batb":[[2,1.02,5000]],"ltp":0.0,"tv":0.0,"id":26357500},{"batb":[[2,1.02,5000]],"ltp":0.0,"tv":0.0,"id":27129637},{"batb":[[2,1.02,5000]],"ltp":0.0,"tv":0.0,"id":20893387}]}]}
{"op":"mcm","clk":"1344879029","pt":1588124346185,"mc":[{"id":"1.170349309","rc":[{"batb":[[2,1.01,38.62]],"ltp":0.0,"tv":0.0,"id":24550116},{"batb":[[2,1.01,38.49]],"ltp":0.0,"tv":0.0,"id":27138257},{"batb":[[2,1.01,43.36]],"ltp":0.0,"tv":0.0,"id":26357500},{"batb":[[2,1.01,40.46]],"ltp":0.0,"tv":0.0,"id":27129637},{"batb":[[2,1.01,39.49]],"ltp":0.0,"tv":0.0,"id":20893387}]}]}
{"op":"mcm","clk":"1344879737","pt":1588124361095,"mc":[{"id":"1.170349309","rc":[{"batb":[[2,1.02,5000]],"ltp":0.0,"tv":0.0,"id":24550116},{"batb":[[2,1.02,5000]],"ltp":0.0,"tv":0.0,"id":27138257},{"batb":[[2,1.02,5000]],"ltp":0.0,"tv":0.0,"id":26357500},{"batb":[[2,1.02,5000]],"ltp":0.0,"tv":0.0,"id":27129637},{"batb":[[2,1.02,5000]],"ltp":0.0,"tv":0.0,"id":20893387}]}]}
{"op":"mcm","clk":"1344881347","pt":1588124963462,"mc":[{"id":"1.170349309","rc":[{"batb":[[2,1.01,38.62]],"ltp":0.0,"tv":0.0,"id":24550116},{"batb":[[2,1.01,38.49]],"ltp":0.0,"tv":0.0,"id":27138257},{"batb":[[2,1.01,43.36]],"ltp":0.0,"tv":0.0,"id":26357500},{"batb":[[2,1.01,40.46]],"ltp":0.0,"tv":0.0,"id":27129637},{"batb":[[2,1.01,39.49]],"ltp":0.0,"tv":0.0,"id":20893387}]}]}
{"op":"mcm","clk":"1344881406","pt":1588124978388,"mc":[{"id":"1.170349309","rc":[{"batb":[[2,1.02,5000]],"ltp":0.0,"tv":0.0,"id":24550116},{"batb":[[2,1.02,5000]],"ltp":0.0,"tv":0.0,"id":27138257},{"batb":[[2,1.02,5000]],"ltp":0.0,"tv":0.0,"id":26357500},{"batb":[[2,1.02,5000]],"ltp":0.0,"tv":0.0,"id":27129637},{"batb":[[2,1.02,5000]],"ltp":0.0,"tv":0.0,"id":20893387}]}]}
{"op":"mcm","clk":"1344883664","pt":1588125580915,"mc":[{"id":"1.170349309","rc":[{"batb":[[2,1.01,38.62]],"ltp":0.0,"tv":0.0,"id":24550116},{"batb":[[2,1.01,38.49]],"ltp":0.0,"tv":0.0,"id":27138257},{"batb":[[2,1.01,43.36]],"ltp":0.0,"tv":0.0,"id":26357500},{"batb":[[2,1.01,40.46]],"ltp":0.0,"tv":0.0,"id":27129637},{"batb":[[2,1.01,39.49]],"ltp":0.0,"tv":0.0,"id":20893387}]}]}
{"op":"mcm","clk":"1344883703","pt":1588125595922,"mc":[{"id":"1.170349309","rc":[{"batb":[[2,1.02,5000]],"ltp":0.0,"tv":0.0,"id":24550116},{"batb":[[2,1.02,5000]],"ltp":0.0,"tv":0.0,"id":27138257},{"batb":[[2,1.02,5000]],"ltp":0.0,"tv":0.0,"id":26357500},{"batb":[[2,1.02,5000]],"ltp":0.0,"tv":0.0,"id":27129637},{"batb":[[2,1.02,5000]],"ltp":0.0,"tv":0.0,"id":20893387}]}]}
{"op":"mcm","clk":"1344886527","pt":1588126159495,"mc":[{"id":"1.170349309","rc":[{"batl":[[0,1000,1.52]],"ltp":0.0,"tv":0.0,"id":24550116},{"trd":[[1.09,3.48]],"batb":[[2,1.01,42.34]],"batl":[[1,1000,1.52]],"ltp":1.09,"tv":3.48,"id":27376858},{"batl":[[0,1000,1.53]],"ltp":0.0,"tv":0.0,"id":27138257},{"batb":[[2,1.01,38.73]],"batl":[[1,1000,1.53]],"ltp":0.0,"tv":0.0,"id":27661463},{"batl":[[1,1000,1.55]],"ltp":0.0,"tv":0.0,"id":26357500},{"batl":[[0,1000,1.52]],"ltp":0.0,"tv":0.0,"id":27129637},{"batb":[[2,1.01,41.58]],"batl":[[1,1000,1.52]],"ltp":0.0,"tv":0.0,"id":26148884},{"batl":[[0,1000,1.56]],"ltp":0.0,"tv":0.0,"id":20893387}],"tv":3.48}]}
{"op":"mcm","clk":"1344887348","pt":1588126198742,"mc":[{"id":"1.170349309","rc":[{"batb":[[2,1.01,38.55]],"ltp":0.0,"tv":0.0,"id":24550116},{"batb":[[2,1.01,38.41]],"ltp":0.0,"tv":0.0,"id":27138257},{"batb":[[2,1.01,43.28]],"ltp":0.0,"tv":0.0,"id":26357500},{"batb":[[2,1.01,40.38]],"ltp":0.0,"tv":0.0,"id":27129637},{"batb":[[2,1.01,39.42]],"ltp":0.0,"tv":0.0,"id":20893387}]}]}
{"op":"mcm","clk":"1344887512","pt":1588126213799,"mc":[{"id":"1.170349309","rc":[{"batb":[[2,1.02,5000]],"ltp":0.0,"tv":0.0,"id":24550116},{"batb":[[2,1.02,5000]],"ltp":0.0,"tv":0.0,"id":27138257},{"batb":[[2,1.02,5000]],"ltp":0.0,"tv":0.0,"id":26357500},{"batb":[[2,1.02,5000]],"ltp":0.0,"tv":0.0,"id":27129637},{"batb":[[2,1.02,5000]],"ltp":0.0,"tv":0.0,"id":20893387}]}]}
{"op":"mcm","clk":"1344894481","pt":1588126816857,"mc":[{"id":"1.170349309","rc":[{"batb":[[2,1.01,38.55]],"ltp":0.0,"tv":0.0,"id":24550116},{"batb":[[2,1.01,38.41]],"ltp":0.0,"tv":0.0,"id":27138257},{"batb":[[2,1.01,43.28]],"ltp":0.0,"tv":0.0,"id":26357500},{"batb":[[2,1.01,40.38]],"ltp":0.0,"tv":0.0,"id":27129637},{"batb":[[2,1.01,39.42]],"ltp":0.0,"tv":0.0,"id":20893387}]}]}
{"op":"mcm","clk":"1344894679","pt":1588126831818,"mc":[{"id":"1.170349309","rc":[{"batb":[[2,1.02,5000]],"ltp":0.0,"tv":0.0,"id":24550116},{"batb":[[2,1.02,5000]],"ltp":0.0,"tv":0.0,"id":27138257},{"batb":[[2,1.02,5000]],"ltp":0.0,"tv":0.0,"id":26357500},{"batb":[[2,1.02,5000]],"ltp":0.0,"tv":0.0,"id":27129637},{"batb":[[2,1.02,5000]],"ltp":0.0,"tv":0.0,"id":20893387}]}]}
{"op":"mcm","clk":"1344899384","pt":1588127434721,"mc":[{"id":"1.170349309","rc":[{"batb":[[2,1.01,38.55]],"ltp":0.0,"tv":0.0,"id":24550116},{"batb":[[2,1.01,38.41]],"ltp":0.0,"tv":0.0,"id":27138257},{"batb":[[2,1.01,43.28]],"ltp":0.0,"tv":0.0,"id":26357500},{"batb":[[2,1.01,40.38]],"ltp":0.0,"tv":0.0,"id":27129637},{"batb":[[2,1.01,39.42]],"ltp":0.0,"tv":0.0,"id":20893387}]}]}
{"op":"mcm","clk":"1344899561","pt":1588127449764,"mc":[{"id":"1.170349309","rc":[{"batb":[[2,1.02,5000]],"ltp":0.0,"tv":0.0,"id":24550116},{"batb":[[2,1.02,5000]],"ltp":0.0,"tv":0.0,"id":27138257},{"batb":[[2,1.02,5000]],"ltp":0.0,"tv":0.0,"id":26357500},{"batb":[[2,1.02,5000]],"ltp":0.0,"tv":0.0,"id":27129637},{"batb":[[2,1.02,5000]],"ltp":0.0,"tv":0.0,"id":20893387}]}]}
{"op":"mcm","clk":"1344906365","pt":1588128052325,"mc":[{"id":"1.170349309","rc":[{"batb":[[2,1.01,38.55]],"ltp":0.0,"tv":0.0,"id":24550116},{"batb":[[2,1.01,38.41]],"ltp":0.0,"tv":0.0,"id":27138257},{"batb":[[2,1.01,43.28]],"ltp":0.0,"tv":0.0,"id":26357500},{"batb":[[2,1.01,40.38]],"ltp":0.0,"tv":0.0,"id":27129637},{"batb":[[2,1.01,39.42]],"ltp":0.0,"tv":0.0,"id":20893387}]}]}
{"op":"mcm","clk":"1344906427","pt":1588128067223,"mc":[{"id":"1.170349309","rc":[{"batb":[[2,1.02,5000]],"ltp":0.0,"tv":0.0,"id":24550116},{"batb":[[2,1.02,5000]],"ltp":0.0,"tv":0.0,"id":27138257},{"batb":[[2,1.02,5000]],"ltp":0.0,"tv":0.0,"id":26357500},{"batb":[[2,1.02,5000]],"ltp":0.0,"tv":0.0,"id":27129637},{"batb":[[2,1.02,5000]],"ltp":0.0,"tv":0.0,"id":20893387}]}]}
{"op":"mcm","clk":"1344910503","pt":1588128669959,"mc":[{"id":"1.170349309","rc":[{"batb":[[2,1.01,38.55]],"ltp":0.0,"tv":0.0,"id":24550116},{"batb":[[2,1.01,38.41]],"ltp":0.0,"tv":0.0,"id":27138257},{"batb":[[2,1.01,43.28]],"ltp":0.0,"tv":0.0,"id":26357500},{"batb":[[2,1.01,40.38]],"ltp":0.0,"tv":0.0,"id":27129637},{"batb":[[2,1.01,39.42]],"ltp":0.0,"tv":0.0,"id":20893387}]}]}
{"op":"mcm","clk":"1344910684","pt":1588128684983,"mc":[{"id":"1.170349309","rc":[{"batb":[[2,1.02,5000]],"ltp":0.0,"tv":0.0,"id":24550116},{"batb":[[2,1.02,5000]],"ltp":0.0,"tv":0.0,"id":27138257},{"batb":[[2,1.02,5000]],"ltp":0.0,"tv":0.0,"id":26357500},{"batb":[[2,1.02,5000]],"ltp":0.0,"tv":0.0,"id":27129637},{"batb":[[2,1.02,5000]],"ltp":0.0,"tv":0.0,"id":20893387}]}]}
{"op":"mcm","clk":"1344915403","pt":1588129288211,"mc":[{"id":"1.170349309","rc":[{"batb":[[2,1.01,38.55]],"ltp":0.0,"tv":0.0,"id":24550116},{"batb":[[2,1.01,38.41]],"ltp":0.0,"tv":0.0,"id":27138257},{"batb":[[2,1.01,43.28]],"ltp":0.0,"tv":0.0,"id":26357500},{"batb":[[2,1.01,40.38]],"ltp":0.0,"tv":0.0,"id":27129637},{"batb":[[2,1.01,39.42]],"ltp":0.0,"tv":0.0,"id":20893387}]}]}
{"op":"mcm","clk":"1344915464","pt":1588129303206,"mc":[{"id":"1.170349309","rc":[{"batb":[[2,1.02,5000]],"ltp":0.0,"tv":0.0,"id":24550116},{"batb":[[2,1.02,5000]],"ltp":0.0,"tv":0.0,"id":27138257},{"batb":[[2,1.02,5000]],"ltp":0.0,"tv":0.0,"id":26357500},{"batb":[[2,1.02,5000]],"ltp":0.0,"tv":0.0,"id":27129637},{"batb":[[2,1.02,5000]],"ltp":0.0,"tv":0.0,"id":20893387}]}]}
{"op":"mcm","clk":"1344924481","pt":1588129906135,"mc":[{"id":"1.170349309","rc":[{"batb":[[2,1.01,38.55]],"ltp":0.0,"tv":0.0,"id":24550116},{"batb":[[2,1.01,38.41]],"ltp":0.0,"tv":0.0,"id":27138257},{"batb":[[2,1.01,43.28]],"ltp":0.0,"tv":0.0,"id":26357500},{"batb":[[2,1.01,40.38]],"ltp":0.0,"tv":0.0,"id":27129637},{"batb":[[2,1.01,39.42]],"ltp":0.0,"tv":0.0,"id":20893387}]}]}
{"op":"mcm","clk":"1344924753","pt":1588129921125,"mc":[{"id":"1.170349309","rc":[{"batb":[[2,1.02,5000]],"ltp":0.0,"tv":0.0,"id":24550116},{"batb":[[2,1.02,5000]],"ltp":0.0,"tv":0.0,"id":27138257},{"batb":[[2,1.02,5000]],"ltp":0.0,"tv":0.0,"id":26357500},{"batb":[[2,1.02,5000]],"ltp":0.0,"tv":0.0,"id":27129637},{"batb":[[2,1.02,5000]],"ltp":0.0,"tv":0.0,"id":20893387}]}]}
{"op":"mcm","clk":"1344933325","pt":1588130524263,"mc":[{"id":"1.170349309","rc":[{"batb":[[2,1.01,38.55]],"ltp":0.0,"tv":0.0,"id":24550116},{"batb":[[2,1.01,38.41]],"ltp":0.0,"tv":0.0,"id":27138257},{"batb":[[2,1.01,43.28]],"ltp":0.0,"tv":0.0,"id":26357500},{"batb":[[2,1.01,40.38]],"ltp":0.0,"tv":0.0,"id":27129637},{"batb":[[2,1.01,39.42]],"ltp":0.0,"tv":0.0,"id":20893387}]}]}
{"op":"mcm","clk":"1344933493","pt":1588130539336,"mc":[{"id":"1.170349309","rc":[{"batb":[[2,1.02,5000]],"ltp":0.0,"tv":0.0,"id":24550116},{"batb":[[2,1.02,5000]],"ltp":0.0,"tv":0.0,"id":27138257},{"batb":[[2,1.02,5000]],"ltp":0.0,"tv":0.0,"id":26357500},{"batb":[[2,1.02,5000]],"ltp":0.0,"tv":0.0,"id":27129637},{"batb":[[2,1.02,5000]],"ltp":0.0,"tv":0.0,"id":20893387}]}]}
{"op":"mcm","clk":"1344940789","pt":1588131142717,"mc":[{"id":"1.170349309","rc":[{"batb":[[2,1.01,38.55]],"ltp":0.0,"tv":0.0,"id":24550116},{"batb":[[2,1.01,38.41]],"ltp":0.0,"tv":0.0,"id":27138257},{"batb":[[2,1.01,43.28]],"ltp":0.0,"tv":0.0,"id":26357500},{"batb":[[2,1.01,40.38]],"ltp":0.0,"tv":0.0,"id":27129637},{"batb":[[2,1.01,39.42]],"ltp":0.0,"tv":0.0,"id":20893387}]}]}
{"op":"mcm","clk":"1344940908","pt":1588131157718,"mc":[{"id":"1.170349309","rc":[{"batb":[[2,1.02,5000]],"ltp":0.0,"tv":0.0,"id":24550116},{"batb":[[2,1.02,5000]],"ltp":0.0,"tv":0.0,"id":27138257},{"batb":[[2,1.02,5000]],"ltp":0.0,"tv":0.0,"id":26357500},{"batb":[[2,1.02,5000]],"ltp":0.0,"tv":0.0,"id":27129637},{"batb":[[2,1.02,5000]],"ltp":0.0,"tv":0.0,"id":20893387}]}]}
{"op":"mcm","clk":"1344947539","pt":1588131761264,"mc":[{"id":"1.170349309","rc":[{"batb":[[2,1.01,38.55]],"ltp":0.0,"tv":0.0,"id":24550116},{"batb":[[2,1.01,38.41]],"ltp":0.0,"tv":0.0,"id":27138257},{"batb":[[2,1.01,43.28]],"ltp":0.0,"tv":0.0,"id":26357500},{"batb":[[2,1.01,40.38]],"ltp":0.0,"tv":0.0,"id":27129637},{"batb":[[2,1.01,39.42]],"ltp":0.0,"tv":0.0,"id":20893387}]}]}
{"op":"mcm","clk":"1344947727","pt":1588131776154,"mc":[{"id":"1.170349309","rc":[{"batb":[[2,1.02,5000]],"ltp":0.0,"tv":0.0,"id":24550116},{"batb":[[2,1.02,5000]],"ltp":0.0,"tv":0.0,"id":27138257},{"batb":[[2,1.02,5000]],"ltp":0.0,"tv":0.0,"id":26357500},{"batb":[[2,1.02,5000]],"ltp":0.0,"tv":0.0,"id":27129637},{"batb":[[2,1.02,5000]],"ltp":0.0,"tv":0.0,"id":20893387}]}]}
{"op":"mcm","clk":"1344956002","pt":1588132379449,"mc":[{"id":"1.170349309","rc":[{"batb":[[2,1.01,38.55]],"ltp":0.0,"tv":0.0,"id":24550116},{"batb":[[2,1.01,38.41]],"ltp":0.0,"tv":0.0,"id":27138257},{"batb":[[2,1.01,43.28]],"ltp":0.0,"tv":0.0,"id":26357500},{"batb":[[2,1.01,40.38]],"ltp":0.0,"tv":0.0,"id":27129637},{"batb":[[2,1.01,39.42]],"ltp":0.0,"tv":0.0,"id":20893387}]}]}
{"op":"mcm","clk":"1344956251","pt":1588132394360,"mc":[{"id":"1.170349309","rc":[{"batb":[[2,1.02,5000]],"ltp":0.0,"tv":0.0,"id":24550116},{"batb":[[2,1.02,5000]],"ltp":0.0,"tv":0.0,"id":27138257},{"batb":[[2,1.02,5000]],"ltp":0.0,"tv":0.0,"id":26357500},{"batb":[[2,1.02,5000]],"ltp":0.0,"tv":0.0,"id":27129637},{"batb":[[2,1.02,5000]],"ltp":0.0,"tv":0.0,"id":20893387}]}]}
{"op":"mcm","clk":"1344963647","pt":1588132997645,"mc":[{"id":"1.170349309","rc":[{"batb":[[2,1.01,38.52]],"batl":[[0,1000,1.52]],"ltp":0.0,"tv":0.0,"id":24550116},{"trd":[[1.09,3.48]],"batb":[[2,1.01,42.31]],"batl":[[1,1000,1.52]],"ltp":1.09,"tv":3.47,"id":27376858},{"batb":[[2,1.01,38.38]],"batl":[[0,1000,1.53]],"ltp":0.0,"tv":0.0,"id":27138257},{"batb":[[2,1.01,38.69]],"batl":[[1,1000,1.53]],"ltp":0.0,"tv":0.0,"id":27661463},{"batb":[[2,1.01,43.25]],"batl":[[1,1000,1.55]],"ltp":0.0,"tv":0.0,"id":26357500},{"batb":[[2,1.01,40.35]],"batl":[[0,1000,1.52]],"ltp":0.0,"tv":0.0,"id":27129637},{"batb":[[2,1.01,41.54]],"batl":[[1,1000,1.52]],"ltp":0.0,"tv":0.0,"id":26148884},{"batb":[[2,1.01,39.39]],"batl":[[0,1000,1.56]],"ltp":0.0,"tv":0.0,"id":20893387}],"tv":3.47}]}
{"op":"mcm","clk":"1344963881","pt":1588133012658,"mc":[{"id":"1.170349309","rc":[{"batb":[[2,1.02,5000]],"ltp":0.0,"tv":0.0,"id":24550116},{"batb":[[2,1.02,5000]],"ltp":0.0,"tv":0.0,"id":27138257},{"batb":[[2,1.02,5000]],"ltp":0.0,"tv":0.0,"id":26357500},{"batb":[[2,1.02,5000]],"ltp":0.0,"tv":0.0,"id":27129637},{"batb":[[2,1.02,5000]],"ltp":0.0,"tv":0.0,"id":20893387}]}]}
{"op":"mcm","clk":"1344970311","pt":1588133615778,"mc":[{"id":"1.170349309","rc":[{"batb":[[2,1.01,38.52]],"ltp":0.0,"tv":0.0,"id":24550116},{"batb":[[2,1.01,38.38]],"ltp":0.0,"tv":0.0,"id":27138257},{"batb":[[2,1.01,43.25]],"ltp":0.0,"tv":0.0,"id":26357500},{"batb":[[2,1.01,40.35]],"ltp":0.0,"tv":0.0,"id":27129637},{"batb":[[2,1.01,39.39]],"ltp":0.0,"tv":0.0,"id":20893387}]}]}
{"op":"mcm","clk":"1344970488","pt":1588133630849,"mc":[{"id":"1.170349309","rc":[{"batb":[[2,1.02,5000]],"ltp":0.0,"tv":0.0,"id":24550116},{"batb":[[2,1.02,5000]],"ltp":0.0,"tv":0.0,"id":27138257},{"batb":[[2,1.02,5000]],"ltp":0.0,"tv":0.0,"id":26357500},{"batb":[[2,1.02,5000]],"ltp":0.0,"tv":0.0,"id":27129637},{"batb":[[2,1.02,5000]],"ltp":0.0,"tv":0.0,"id":20893387}]}]}
{"op":"mcm","clk":"1344978149","pt":1588134131791,"mc":[{"id":"1.170349309","rc":[{"batb":[[2,1.01,39.56]],"ltp":0.0,"tv":0.0,"id":27661463}]}]}
{"op":"mcm","clk":"1344978347","pt":1588134141398,"mc":[{"id":"1.170349309","rc":[{"batb":[[2,1.01,38.69]],"ltp":0.0,"tv":0.0,"id":27661463}]}]}
{"op":"mcm","clk":"1344979548","pt":1588134233937,"mc":[{"id":"1.170349309","rc":[{"batb":[[2,1.01,38.52]],"ltp":0.0,"tv":0.0,"id":24550116},{"batb":[[2,1.01,38.38]],"ltp":0.0,"tv":0.0,"id":27138257},{"batb":[[2,1.01,43.25]],"ltp":0.0,"tv":0.0,"id":26357500},{"batb":[[2,1.01,40.35]],"ltp":0.0,"tv":0.0,"id":27129637},{"batb":[[2,1.01,39.39]],"ltp":0.0,"tv":0.0,"id":20893387}]}]}
{"op":"mcm","clk":"1344979698","pt":1588134248973,"mc":[{"id":"1.170349309","rc":[{"batb":[[2,1.02,5000]],"ltp":0.0,"tv":0.0,"id":24550116},{"batb":[[2,1.02,5000]],"ltp":0.0,"tv":0.0,"id":27138257},{"batb":[[2,1.02,5000]],"ltp":0.0,"tv":0.0,"id":26357500},{"batb":[[2,1.02,5000]],"ltp":0.0,"tv":0.0,"id":27129637},{"batb":[[2,1.02,5000]],"ltp":0.0,"tv":0.0,"id":20893387}]}]}
{"op":"mcm","clk":"1344989654","pt":1588134852278,"mc":[{"id":"1.170349309","rc":[{"batb":[[2,1.01,38.52]],"ltp":0.0,"tv":0.0,"id":24550116},{"batb":[[2,1.01,38.38]],"ltp":0.0,"tv":0.0,"id":27138257},{"batb":[[2,1.01,43.25]],"ltp":0.0,"tv":0.0,"id":26357500},{"batb":[[2,1.01,40.35]],"ltp":0.0,"tv":0.0,"id":27129637},{"batb":[[2,1.01,39.39]],"ltp":0.0,"tv":0.0,"id":20893387}]}]}
{"op":"mcm","clk":"1344989824","pt":1588134867375,"mc":[{"id":"1.170349309","rc":[{"batb":[[2,1.02,5000]],"ltp":0.0,"tv":0.0,"id":24550116},{"batb":[[2,1.02,5000]],"ltp":0.0,"tv":0.0,"id":27138257},{"batb":[[2,1.02,5000]],"ltp":0.0,"tv":0.0,"id":26357500},{"batb":[[2,1.02,5000]],"ltp":0.0,"tv":0.0,"id":27129637},{"batb":[[2,1.02,5000]],"ltp":0.0,"tv":0.0,"id":20893387}]}]}
{"op":"mcm","clk":"1344996884","pt":1588135470795,"mc":[{"id":"1.170349309","rc":[{"batb":[[2,1.01,38.52]],"ltp":0.0,"tv":0.0,"id":24550116},{"batb":[[2,1.01,38.38]],"ltp":0.0,"tv":0.0,"id":27138257},{"batb":[[2,1.01,43.25]],"ltp":0.0,"tv":0.0,"id":26357500},{"batb":[[2,1.01,40.35]],"ltp":0.0,"tv":0.0,"id":27129637},{"batb":[[2,1.01,39.39]],"ltp":0.0,"tv":0.0,"id":20893387}]}]}
{"op":"mcm","clk":"1344996987","pt":1588135485805,"mc":[{"id":"1.170349309","rc":[{"batb":[[2,1.02,5000]],"ltp":0.0,"tv":0.0,"id":24550116},{"batb":[[2,1.02,5000]],"ltp":0.0,"tv":0.0,"id":27138257},{"batb":[[2,1.02,5000]],"ltp":0.0,"tv":0.0,"id":26357500},{"batb":[[2,1.02,5000]],"ltp":0.0,"tv":0.0,"id":27129637},{"batb":[[2,1.02,5000]],"ltp":0.0,"tv":0.0,"id":20893387}]}]}
{"op":"mcm","clk":"1345007077","pt":1588136089253,"mc":[{"id":"1.170349309","rc":[{"batb":[[2,1.01,38.52]],"ltp":0.0,"tv":0.0,"id":24550116},{"batb":[[2,1.01,38.38]],"ltp":0.0,"tv":0.0,"id":27138257},{"batb":[[2,1.01,43.25]],"ltp":0.0,"tv":0.0,"id":26357500},{"batb":[[2,1.01,40.35]],"ltp":0.0,"tv":0.0,"id":27129637},{"batb":[[2,1.01,39.39]],"ltp":0.0,"tv":0.0,"id":20893387}]}]}
{"op":"mcm","clk":"1345007485","pt":1588136104284,"mc":[{"id":"1.170349309","rc":[{"batb":[[2,1.02,5000]],"ltp":0.0,"tv":0.0,"id":24550116},{"batb":[[2,1.02,5000]],"ltp":0.0,"tv":0.0,"id":27138257},{"batb":[[2,1.02,5000]],"ltp":0.0,"tv":0.0,"id":26357500},{"batb":[[2,1.02,5000]],"ltp":0.0,"tv":0.0,"id":27129637},{"batb":[[2,1.02,5000]],"ltp":0.0,"tv":0.0,"id":20893387}]}]}
{"op":"mcm","clk":"1345020266","pt":1588136707313,"mc":[{"id":"1.170349309","rc":[{"batb":[[2,1.01,38.52]],"ltp":0.0,"tv":0.0,"id":24550116},{"batb":[[2,1.01,38.38]],"ltp":0.0,"tv":0.0,"id":27138257},{"batb":[[2,1.01,43.25]],"ltp":0.0,"tv":0.0,"id":26357500},{"batb":[[2,1.01,40.35]],"ltp":0.0,"tv":0.0,"id":27129637},{"batb":[[2,1.01,39.39]],"ltp":0.0,"tv":0.0,"id":20893387}]}]}
{"op":"mcm","clk":"1345020514","pt":1588136722348,"mc":[{"id":"1.170349309","rc":[{"batb":[[2,1.02,5000]],"ltp":0.0,"tv":0.0,"id":24550116},{"batb":[[2,1.02,5000]],"ltp":0.0,"tv":0.0,"id":27138257},{"batb":[[2,1.02,5000]],"ltp":0.0,"tv":0.0,"id":26357500},{"batb":[[2,1.02,5000]],"ltp":0.0,"tv":0.0,"id":27129637},{"batb":[[2,1.02,5000]],"ltp":0.0,"tv":0.0,"id":20893387}]}]}
{"op":"mcm","clk":"1345031478","pt":1588137325586,"mc":[{"id":"1.170349309","rc":[{"batb":[[2,1.01,38.52]],"ltp":0.0,"tv":0.0,"id":24550116},{"batb":[[2,1.01,38.38]],"ltp":0.0,"tv":0.0,"id":27138257},{"batb":[[2,1.01,43.25]],"ltp":0.0,"tv":0.0,"id":26357500},{"batb":[[2,1.01,40.35]],"ltp":0.0,"tv":0.0,"id":27129637},{"batb":[[2,1.01,39.39]],"ltp":0.0,"tv":0.0,"id":20893387}]}]}
{"op":"mcm","clk":"1345031804","pt":1588137340606,"mc":[{"id":"1.170349309","rc":[{"batb":[[2,1.02,5000]],"ltp":0.0,"tv":0.0,"id":24550116},{"batb":[[2,1.02,5000]],"ltp":0.0,"tv":0.0,"id":27138257},{"batb":[[2,1.02,5000]],"ltp":0.0,"tv":0.0,"id":26357500},{"batb":[[2,1.02,5000]],"ltp":0.0,"tv":0.0,"id":27129637},{"batb":[[2,1.02,5000]],"ltp":0.0,"tv":0.0,"id":20893387}]}]}
{"op":"mcm","clk":"1345041609","pt":1588137943856,"mc":[{"id":"1.170349309","rc":[{"batb":[[2,1.01,38.52]],"ltp":0.0,"tv":0.0,"id":24550116},{"batb":[[2,1.01,38.38]],"ltp":0.0,"tv":0.0,"id":27138257},{"batb":[[2,1.01,43.25]],"ltp":0.0,"tv":0.0,"id":26357500},{"batb":[[2,1.01,40.35]],"ltp":0.0,"tv":0.0,"id":27129637},{"batb":[[2,1.01,39.39]],"ltp":0.0,"tv":0.0,"id":20893387}]}]}
{"op":"mcm","clk":"1345041828","pt":1588137959000,"mc":[{"id":"1.170349309","rc":[{"batb":[[2,1.02,5000]],"ltp":0.0,"tv":0.0,"id":24550116},{"batb":[[2,1.02,5000]],"ltp":0.0,"tv":0.0,"id":27138257},{"batb":[[2,1.02,5000]],"ltp":0.0,"tv":0.0,"id":26357500},{"batb":[[2,1.02,5000]],"ltp":0.0,"tv":0.0,"id":27129637},{"batb":[[2,1.02,5000]],"ltp":0.0,"tv":0.0,"id":20893387}]}]}
{"op":"mcm","clk":"1345056309","pt":1588138562370,"mc":[{"id":"1.170349309","rc":[{"batb":[[2,1.01,38.52]],"ltp":0.0,"tv":0.0,"id":24550116},{"batb":[[2,1.01,38.38]],"ltp":0.0,"tv":0.0,"id":27138257},{"batb":[[2,1.01,43.25]],"ltp":0.0,"tv":0.0,"id":26357500},{"batb":[[2,1.01,40.35]],"ltp":0.0,"tv":0.0,"id":27129637},{"batb":[[2,1.01,39.39]],"ltp":0.0,"tv":0.0,"id":20893387}]}]}
{"op":"mcm","clk":"1345056651","pt":1588138577424,"mc":[{"id":"1.170349309","rc":[{"batb":[[2,1.02,5000]],"ltp":0.0,"tv":0.0,"id":24550116},{"batb":[[2,1.02,5000]],"ltp":0.0,"tv":0.0,"id":27138257},{"batb":[[2,1.02,5000]],"ltp":0.0,"tv":0.0,"id":26357500},{"batb":[[2,1.02,5000]],"ltp":0.0,"tv":0.0,"id":27129637},{"batb":[[2,1.02,5000]],"ltp":0.0,"tv":0.0,"id":20893387}]}]}
{"op":"mcm","clk":"1345068093","pt":1588139180541,"mc":[{"id":"1.170349309","rc":[{"batb":[[2,1.01,38.52]],"ltp":0.0,"tv":0.0,"id":24550116},{"batb":[[2,1.01,38.38]],"ltp":0.0,"tv":0.0,"id":27138257},{"batb":[[2,1.01,43.25]],"ltp":0.0,"tv":0.0,"id":26357500},{"batb":[[2,1.01,40.35]],"ltp":0.0,"tv":0.0,"id":27129637},{"batb":[[2,1.01,39.39]],"ltp":0.0,"tv":0.0,"id":20893387}]}]}
{"op":"mcm","clk":"1345068331","pt":1588139195593,"mc":[{"id":"1.170349309","rc":[{"batb":[[2,1.02,5000]],"ltp":0.0,"tv":0.0,"id":24550116},{"batb":[[2,1.02,5000]],"ltp":0.0,"tv":0.0,"id":27138257},{"batb":[[2,1.02,5000]],"ltp":0.0,"tv":0.0,"id":26357500},{"batb":[[2,1.02,5000]],"ltp":0.0,"tv":0.0,"id":27129637},{"batb":[[2,1.02,5000]],"ltp":0.0,"tv":0.0,"id":20893387}]}]}
{"op":"mcm","clk":"1345077408","pt":1588139798743,"mc":[{"id":"1.170349309","rc":[{"batb":[[2,1.01,38.52]],"ltp":0.0,"tv":0.0,"id":24550116},{"batb":[[2,1.01,38.38]],"ltp":0.0,"tv":0.0,"id":27138257},{"batb":[[2,1.01,43.25]],"ltp":0.0,"tv":0.0,"id":26357500},{"batb":[[2,1.01,40.35]],"ltp":0.0,"tv":0.0,"id":27129637},{"batb":[[2,1.01,39.39]],"ltp":0.0,"tv":0.0,"id":20893387}]}]}
{"op":"mcm","clk":"1345077676","pt":1588139813863,"mc":[{"id":"1.170349309","rc":[{"batb":[[2,1.02,5000]],"ltp":0.0,"tv":0.0,"id":24550116},{"batb":[[2,1.02,5000]],"ltp":0.0,"tv":0.0,"id":27138257},{"batb":[[2,1.02,5000]],"ltp":0.0,"tv":0.0,"id":26357500},{"batb":[[2,1.02,5000]],"ltp":0.0,"tv":0.0,"id":27129637},{"batb":[[2,1.02,5000]],"ltp":0.0,"tv":0.0,"id":20893387}]}]}
{"op":"mcm","clk":"1345087983","pt":1588140417026,"mc":[{"id":"1.170349309","rc":[{"batb":[[2,1.01,38.49]],"ltp":0.0,"tv":0.0,"id":24550116},{"batb":[[2,1.01,42.27]],"ltp":1.09,"tv":3.47,"id":27376858},{"batb":[[2,1.01,38.35]],"ltp":0.0,"tv":0.0,"id":27138257},{"batb":[[2,1.01,38.66]],"ltp":0.0,"tv":0.0,"id":27661463},{"batb":[[2,1.01,43.21]],"ltp":0.0,"tv":0.0,"id":26357500},{"batb":[[2,1.01,40.32]],"ltp":0.0,"tv":0.0,"id":27129637},{"batb":[[2,1.01,41.51]],"ltp":0.0,"tv":0.0,"id":26148884},{"batb":[[2,1.01,39.36]],"ltp":0.0,"tv":0.0,"id":20893387}]}]}
{"op":"mcm","clk":"1345088209","pt":1588140432040,"mc":[{"id":"1.170349309","rc":[{"batb":[[2,1.02,5000]],"ltp":0.0,"tv":0.0,"id":24550116},{"batb":[[2,1.02,5000]],"ltp":0.0,"tv":0.0,"id":27138257},{"batb":[[2,1.02,5000]],"ltp":0.0,"tv":0.0,"id":26357500},{"batb":[[2,1.02,5000]],"ltp":0.0,"tv":0.0,"id":27129637},{"batb":[[2,1.02,5000]],"ltp":0.0,"tv":0.0,"id":20893387}]}]}
{"op":"mcm","clk":"1345101934","pt":1588141035249,"mc":[{"id":"1.170349309","rc":[{"batb":[[2,1.01,38.49]],"ltp":0.0,"tv":0.0,"id":24550116},{"batb":[[2,1.01,38.35]],"ltp":0.0,"tv":0.0,"id":27138257},{"batb":[[2,1.01,43.21]],"ltp":0.0,"tv":0.0,"id":26357500},{"batb":[[2,1.01,40.32]],"ltp":0.0,"tv":0.0,"id":27129637},{"batb":[[2,1.01,39.36]],"ltp":0.0,"tv":0.0,"id":20893387}]}]}
{"op":"mcm","clk":"1345102163","pt":1588141050380,"mc":[{"id":"1.170349309","rc":[{"batb":[[2,1.02,5000]],"ltp":0.0,"tv":0.0,"id":24550116},{"batb":[[2,1.02,5000]],"ltp":0.0,"tv":0.0,"id":27138257},{"batb":[[2,1.02,5000]],"ltp":0.0,"tv":0.0,"id":26357500},{"batb":[[2,1.02,5000]],"ltp":0.0,"tv":0.0,"id":27129637},{"batb":[[2,1.02,5000]],"ltp":0.0,"tv":0.0,"id":20893387}]}]}
{"op":"mcm","clk":"1345114400","pt":1588141653289,"mc":[{"id":"1.170349309","rc":[{"batb":[[2,1.01,38.49]],"ltp":0.0,"tv":0.0,"id":24550116},{"batb":[[2,1.01,38.35]],"ltp":0.0,"tv":0.0,"id":27138257},{"batb":[[2,1.01,43.21]],"ltp":0.0,"tv":0.0,"id":26357500},{"batb":[[2,1.01,40.32]],"ltp":0.0,"tv":0.0,"id":27129637},{"batb":[[2,1.01,39.36]],"ltp":0.0,"tv":0.0,"id":20893387}]}]}
{"op":"mcm","clk":"1345114692","pt":1588141668282,"mc":[{"id":"1.170349309","rc":[{"batb":[[2,1.02,5000]],"ltp":0.0,"tv":0.0,"id":24550116},{"batb":[[2,1.02,5000]],"ltp":0.0,"tv":0.0,"id":27138257},{"batb":[[2,1.02,5000]],"ltp":0.0,"tv":0.0,"id":26357500},{"batb":[[2,1.02,5000]],"ltp":0.0,"tv":0.0,"id":27129637},{"batb":[[2,1.02,5000]],"ltp":0.0,"tv":0.0,"id":20893387}]}]}
{"op":"mcm","clk":"1345127032","pt":1588142222636,"mc":[{"id":"1.170349309","rc":[{"batb":[[1,1.02,5000],[2,1.01,38.49]],"ltp":0.0,"tv":0.0,"id":24550116},{"batb":[[1,1.01,42.27],[2,1.01,0]],"ltp":1.09,"tv":3.47,"id":27376858},{"batb":[[1,1.02,5000],[2,1.01,38.35]],"ltp":0.0,"tv":0.0,"id":27138257},{"batb":[[1,1.01,38.66],[2,1.01,0]],"ltp":0.0,"tv":0.0,"id":27661463},{"batb":[[1,1.02,5000],[2,1.01,43.21]],"ltp":0.0,"tv":0.0,"id":26357500},{"batb":[[1,1.02,5000],[2,1.01,40.32]],"ltp":0.0,"tv":0.0,"id":27129637},{"batb":[[1,1.01,41.51],[2,1.01,0]],"ltp":0.0,"tv":0.0,"id":26148884},{"batb":[[1,1.02,5000],[2,1.01,39.36]],"ltp":0.0,"tv":0.0,"id":20893387}]}]}
{"op":"mcm","clk":"1345128248","pt":1588142271188,"mc":[{"id":"1.170349309","rc":[{"batb":[[1,1.01,38.49],[2,1.01,0]],"ltp":0.0,"tv":0.0,"id":24550116},{"batb":[[1,1.01,38.35],[2,1.01,0]],"ltp":0.0,"tv":0.0,"id":27138257},{"batb":[[1,1.01,43.21],[2,1.01,0]],"ltp":0.0,"tv":0.0,"id":26357500},{"batb":[[1,1.01,40.32],[2,1.01,0]],"ltp":0.0,"tv":0.0,"id":27129637},{"batb":[[1,1.01,39.36],[2,1.01,0]],"ltp":0.0,"tv":0.0,"id":20893387}]}]}
{"op":"mcm","clk":"1345128487","pt":1588142286105,"mc":[{"id":"1.170349309","rc":[{"batb":[[1,1.02,5000],[2,1.01,38.49]],"ltp":0.0,"tv":0.0,"id":24550116},{"batb":[[1,1.02,5000],[2,1.01,38.35]],"ltp":0.0,"tv":0.0,"id":27138257},{"batb":[[1,1.02,5000],[2,1.01,43.21]],"ltp":0.0,"tv":0.0,"id":26357500},{"batb":[[1,1.02,5000],[2,1.01,40.32]],"ltp":0.0,"tv":0.0,"id":27129637},{"batb":[[1,1.02,5000],[2,1.01,39.36]],"ltp":0.0,"tv":0.0,"id":20893387}]}]}
{"op":"mcm","clk":"1345143215","pt":1588142889261,"mc":[{"id":"1.170349309","rc":[{"batb":[[1,1.01,38.49],[2,1.01,0]],"ltp":0.0,"tv":0.0,"id":24550116},{"batb":[[1,1.01,38.35],[2,1.01,0]],"ltp":0.0,"tv":0.0,"id":27138257},{"batb":[[1,1.01,43.21],[2,1.01,0]],"ltp":0.0,"tv":0.0,"id":26357500},{"batb":[[1,1.01,40.32],[2,1.01,0]],"ltp":0.0,"tv":0.0,"id":27129637},{"batb":[[1,1.01,39.36],[2,1.01,0]],"ltp":0.0,"tv":0.0,"id":20893387}]}]}
{"op":"mcm","clk":"1345143654","pt":1588142904250,"mc":[{"id":"1.170349309","rc":[{"batb":[[1,1.02,5000],[2,1.01,38.49]],"ltp":0.0,"tv":0.0,"id":24550116},{"batb":[[1,1.02,5000],[2,1.01,38.35]],"ltp":0.0,"tv":0.0,"id":27138257},{"batb":[[1,1.02,5000],[2,1.01,43.21]],"ltp":0.0,"tv":0.0,"id":26357500},{"batb":[[1,1.02,5000],[2,1.01,40.32]],"ltp":0.0,"tv":0.0,"id":27129637},{"batb":[[1,1.02,5000],[2,1.01,39.36]],"ltp":0.0,"tv":0.0,"id":20893387}]}]}
{"op":"mcm","clk":"1345159535","pt":1588143507770,"mc":[{"id":"1.170349309","rc":[{"batb":[[1,1.01,38.49],[2,1.01,0]],"ltp":0.0,"tv":0.0,"id":24550116},{"batb":[[1,1.01,38.35],[2,1.01,0]],"ltp":0.0,"tv":0.0,"id":27138257},{"batb":[[1,1.01,43.21],[2,1.01,0]],"ltp":0.0,"tv":0.0,"id":26357500},{"batb":[[1,1.01,40.32],[2,1.01,0]],"ltp":0.0,"tv":0.0,"id":27129637},{"batb":[[1,1.01,39.36],[2,1.01,0]],"ltp":0.0,"tv":0.0,"id":20893387}]}]}
{"op":"mcm","clk":"1345159892","pt":1588143522880,"mc":[{"id":"1.170349309","rc":[{"batb":[[1,1.02,5000],[2,1.01,38.49]],"ltp":0.0,"tv":0.0,"id":24550116},{"batb":[[1,1.02,5000],[2,1.01,38.35]],"ltp":0.0,"tv":0.0,"id":27138257},{"batb":[[1,1.02,5000],[2,1.01,43.21]],"ltp":0.0,"tv":0.0,"id":26357500},{"batb":[[1,1.02,5000],[2,1.01,40.32]],"ltp":0.0,"tv":0.0,"id":27129637},{"batb":[[1,1.02,5000],[2,1.01,39.36]],"ltp":0.0,"tv":0.0,"id":20893387}]}]}
{"op":"mcm","clk":"1345171749","pt":1588144126278,"mc":[{"id":"1.170349309","rc":[{"batb":[[1,1.01,38.49],[2,1.01,0]],"ltp":0.0,"tv":0.0,"id":24550116},{"batb":[[1,1.01,38.35],[2,1.01,0]],"ltp":0.0,"tv":0.0,"id":27138257},{"batb":[[1,1.01,43.21],[2,1.01,0]],"ltp":0.0,"tv":0.0,"id":26357500},{"batb":[[1,1.01,40.32],[2,1.01,0]],"ltp":0.0,"tv":0.0,"id":27129637},{"batb":[[1,1.01,39.36],[2,1.01,0]],"ltp":0.0,"tv":0.0,"id":20893387}]}]}
{"op":"mcm","clk":"1345172000","pt":1588144141294,"mc":[{"id":"1.170349309","rc":[{"batb":[[1,1.02,5000],[2,1.01,38.49]],"ltp":0.0,"tv":0.0,"id":24550116},{"batb":[[1,1.02,5000],[2,1.01,38.35]],"ltp":0.0,"tv":0.0,"id":27138257},{"batb":[[1,1.02,5000],[2,1.01,43.21]],"ltp":0.0,"tv":0.0,"id":26357500},{"batb":[[1,1.02,5000],[2,1.01,40.32]],"ltp":0.0,"tv":0.0,"id":27129637},{"batb":[[1,1.02,5000],[2,1.01,39.36]],"ltp":0.0,"tv":0.0,"id":20893387}]}]}
{"op":"mcm","clk":"1345187666","pt":1588144744515,"mc":[{"id":"1.170349309","rc":[{"batb":[[1,1.01,38.49],[2,1.01,0]],"ltp":0.0,"tv":0.0,"id":24550116},{"batb":[[1,1.01,38.35],[2,1.01,0]],"ltp":0.0,"tv":0.0,"id":27138257},{"batb":[[1,1.01,43.21],[2,1.01,0]],"ltp":0.0,"tv":0.0,"id":26357500},{"batb":[[1,1.01,40.32],[2,1.01,0]],"ltp":0.0,"tv":0.0,"id":27129637},{"batb":[[1,1.01,39.36],[2,1.01,0]],"ltp":0.0,"tv":0.0,"id":20893387}]}]}
{"op":"mcm","clk":"1345188156","pt":1588144759635,"mc":[{"id":"1.170349309","rc":[{"batb":[[1,1.02,5000],[2,1.01,38.49]],"ltp":0.0,"tv":0.0,"id":24550116},{"batb":[[1,1.02,5000],[2,1.01,38.35]],"ltp":0.0,"tv":0.0,"id":27138257},{"batb":[[1,1.02,5000],[2,1.01,43.21]],"ltp":0.0,"tv":0.0,"id":26357500},{"batb":[[1,1.02,5000],[2,1.01,40.32]],"ltp":0.0,"tv":0.0,"id":27129637},{"batb":[[1,1.02,5000],[2,1.01,39.36]],"ltp":0.0,"tv":0.0,"id":20893387}]}]}
{"op":"mcm","clk":"1345205392","pt":1588145362819,"mc":[{"id":"1.170349309","rc":[{"batb":[[1,1.01,38.49],[2,1.01,0]],"ltp":0.0,"tv":0.0,"id":24550116},{"batb":[[1,1.01,38.35],[2,1.01,0]],"ltp":0.0,"tv":0.0,"id":27138257},{"batb":[[1,1.01,43.21],[2,1.01,0]],"ltp":0.0,"tv":0.0,"id":26357500},{"batb":[[1,1.01,40.32],[2,1.01,0]],"ltp":0.0,"tv":0.0,"id":27129637},{"batb":[[1,1.01,39.36],[2,1.01,0]],"ltp":0.0,"tv":0.0,"id":20893387}]}]}
{"op":"mcm","clk":"1345205728","pt":1588145377936,"mc":[{"id":"1.170349309","rc":[{"batb":[[1,1.02,5000],[2,1.01,38.49]],"ltp":0.0,"tv":0.0,"id":24550116},{"batb":[[1,1.02,5000],[2,1.01,38.35]],"ltp":0.0,"tv":0.0,"id":27138257},{"batb":[[1,1.02,5000],[2,1.01,43.21]],"ltp":0.0,"tv":0.0,"id":26357500},{"batb":[[1,1.02,5000],[2,1.01,40.32]],"ltp":0.0,"tv":0.0,"id":27129637},{"batb":[[1,1.02,5000],[2,1.01,39.36]],"ltp":0.0,"tv":0.0,"id":20893387}]}]}
{"op":"mcm","clk":"1345219904","pt":1588145981131,"mc":[{"id":"1.170349309","rc":[{"batb":[[1,1.01,38.49],[2,1.01,0]],"ltp":0.0,"tv":0.0,"id":24550116},{"batb":[[1,1.01,38.35],[2,1.01,0]],"ltp":0.0,"tv":0.0,"id":27138257},{"batb":[[1,1.01,43.21],[2,1.01,0]],"ltp":0.0,"tv":0.0,"id":26357500},{"batb":[[1,1.01,40.32],[2,1.01,0]],"ltp":0.0,"tv":0.0,"id":27129637},{"batb":[[1,1.01,39.36],[2,1.01,0]],"ltp":0.0,"tv":0.0,"id":20893387}]}]}
{"op":"mcm","clk":"1345220309","pt":1588145996164,"mc":[{"id":"1.170349309","rc":[{"batb":[[1,1.02,5000],[2,1.01,38.49]],"ltp":0.0,"tv":0.0,"id":24550116},{"batb":[[1,1.02,5000],[2,1.01,38.35]],"ltp":0.0,"tv":0.0,"id":27138257},{"batb":[[1,1.02,5000],[2,1.01,43.21]],"ltp":0.0,"tv":0.0,"id":26357500},{"batb":[[1,1.02,5000],[2,1.01,40.32]],"ltp":0.0,"tv":0.0,"id":27129637},{"batb":[[1,1.02,5000],[2,1.01,39.36]],"ltp":0.0,"tv":0.0,"id":20893387}]}]}
{"op":"mcm","clk":"1345236339","pt":1588146599471,"mc":[{"id":"1.170349309","rc":[{"batb":[[1,1.01,38.49],[2,1.01,0]],"ltp":0.0,"tv":0.0,"id":24550116},{"batb":[[1,1.01,38.35],[2,1.01,0]],"ltp":0.0,"tv":0.0,"id":27138257},{"batb":[[1,1.01,43.21],[2,1.01,0]],"ltp":0.0,"tv":0.0,"id":26357500},{"batb":[[1,1.01,40.32],[2,1.01,0]],"ltp":0.0,"tv":0.0,"id":27129637},{"batb":[[1,1.01,39.36],[2,1.01,0]],"ltp":0.0,"tv":0.0,"id":20893387}]}]}
{"op":"mcm","clk":"1345236739","pt":1588146614493,"mc":[{"id":"1.170349309","rc":[{"batb":[[1,1.02,5000],[2,1.01,38.49]],"ltp":0.0,"tv":0.0,"id":24550116},{"batb":[[1,1.02,5000],[2,1.01,38.35]],"ltp":0.0,"tv":0.0,"id":27138257},{"batb":[[1,1.02,5000],[2,1.01,43.21]],"ltp":0.0,"tv":0.0,"id":26357500},{"batb":[[1,1.02,5000],[2,1.01,40.32]],"ltp":0.0,"tv":0.0,"id":27129637},{"batb":[[1,1.02,5000],[2,1.01,39.36]],"ltp":0.0,"tv":0.0,"id":20893387}]}]}
{"op":"mcm","clk":"1345252983","pt":1588147217873,"mc":[{"id":"1.170349309","rc":[{"batb":[[1,1.01,38.57],[2,1.01,0]],"batl":[[0,1000,1.52]],"ltp":0.0,"tv":0.0,"id":24550116},{"trd":[[1.09,3.48]],"batb":[[1,1.01,42.36]],"batl":[[1,1000,1.52]],"ltp":1.09,"tv":3.48,"id":27376858},{"batb":[[1,1.01,38.43],[2,1.01,0]],"batl":[[0,1000,1.53]],"ltp":0.0,"tv":0.0,"id":27138257},{"batb":[[1,1.01,38.74]],"batl":[[1,1000,1.53]],"ltp":0.0,"tv":0.0,"id":27661463},{"batb":[[1,1.01,43.3],[2,1.01,0]],"batl":[[1,1000,1.55]],"ltp":0.0,"tv":0.0,"id":26357500},{"batb":[[1,1.01,40.4],[2,1.01,0]],"batl":[[0,1000,1.52]],"ltp":0.0,"tv":0.0,"id":27129637},{"batb":[[1,1.01,41.59]],"batl":[[1,1000,1.52]],"ltp":0.0,"tv":0.0,"id":26148884},{"batb":[[1,1.01,39.44],[2,1.01,0]],"batl":[[0,1000,1.56]],"ltp":0.0,"tv":0.0,"id":20893387}],"tv":3.48}]}
{"op":"mcm","clk":"1345253419","pt":1588147232924,"mc":[{"id":"1.170349309","rc":[{"batb":[[1,1.02,5000],[2,1.01,38.57]],"ltp":0.0,"tv":0.0,"id":24550116},{"batb":[[1,1.02,5000],[2,1.01,38.43]],"ltp":0.0,"tv":0.0,"id":27138257},{"batb":[[1,1.02,5000],[2,1.01,43.3]],"ltp":0.0,"tv":0.0,"id":26357500},{"batb":[[1,1.02,5000],[2,1.01,40.4]],"ltp":0.0,"tv":0.0,"id":27129637},{"batb":[[1,1.02,5000],[2,1.01,39.44]],"ltp":0.0,"tv":0.0,"id":20893387}]}]}
{"op":"mcm","clk":"1345267547","pt":1588147835839,"mc":[{"id":"1.170349309","rc":[{"batb":[[1,1.01,38.57],[2,1.01,0]],"ltp":0.0,"tv":0.0,"id":24550116},{"batb":[[1,1.01,38.43],[2,1.01,0]],"ltp":0.0,"tv":0.0,"id":27138257},{"batb":[[1,1.01,43.3],[2,1.01,0]],"ltp":0.0,"tv":0.0,"id":26357500},{"batb":[[1,1.01,40.4],[2,1.01,0]],"ltp":0.0,"tv":0.0,"id":27129637},{"batb":[[1,1.01,39.44],[2,1.01,0]],"ltp":0.0,"tv":0.0,"id":20893387}]}]}
{"op":"mcm","clk":"1345267757","pt":1588147850843,"mc":[{"id":"1.170349309","rc":[{"batb":[[1,1.02,5000],[2,1.01,38.57]],"ltp":0.0,"tv":0.0,"id":24550116},{"batb":[[1,1.02,5000],[2,1.01,38.43]],"ltp":0.0,"tv":0.0,"id":27138257},{"batb":[[1,1.02,5000],[2,1.01,43.3]],"ltp":0.0,"tv":0.0,"id":26357500},{"batb":[[1,1.02,5000],[2,1.01,40.4]],"ltp":0.0,"tv":0.0,"id":27129637},{"batb":[[1,1.02,5000],[2,1.01,39.44]],"ltp":0.0,"tv":0.0,"id":20893387}]}]}
{"op":"mcm","clk":"1345280759","pt":1588148453842,"mc":[{"id":"1.170349309","rc":[{"batb":[[1,1.01,38.57],[2,1.01,0]],"ltp":0.0,"tv":0.0,"id":24550116},{"batb":[[1,1.01,38.43],[2,1.01,0]],"ltp":0.0,"tv":0.0,"id":27138257},{"batb":[[1,1.01,43.3],[2,1.01,0]],"ltp":0.0,"tv":0.0,"id":26357500},{"batb":[[1,1.01,40.4],[2,1.01,0]],"ltp":0.0,"tv":0.0,"id":27129637},{"batb":[[1,1.01,39.44],[2,1.01,0]],"ltp":0.0,"tv":0.0,"id":20893387}]}]}
{"op":"mcm","clk":"1345281073","pt":1588148468860,"mc":[{"id":"1.170349309","rc":[{"batb":[[1,1.02,5000],[2,1.01,38.57]],"ltp":0.0,"tv":0.0,"id":24550116},{"batb":[[1,1.02,5000],[2,1.01,38.43]],"ltp":0.0,"tv":0.0,"id":27138257},{"batb":[[1,1.02,5000],[2,1.01,43.3]],"ltp":0.0,"tv":0.0,"id":26357500},{"batb":[[1,1.02,5000],[2,1.01,40.4]],"ltp":0.0,"tv":0.0,"id":27129637},{"batb":[[1,1.02,5000],[2,1.01,39.44]],"ltp":0.0,"tv":0.0,"id":20893387}]}]}
{"op":"mcm","clk":"1345291996","pt":1588149072213,"mc":[{"id":"1.170349309","rc":[{"batb":[[1,1.01,38.57],[2,1.01,0]],"ltp":0.0,"tv":0.0,"id":24550116},{"batb":[[1,1.01,38.43],[2,1.01,0]],"ltp":0.0,"tv":0.0,"id":27138257},{"batb":[[1,1.01,43.3],[2,1.01,0]],"ltp":0.0,"tv":0.0,"id":26357500},{"batb":[[1,1.01,40.4],[2,1.01,0]],"ltp":0.0,"tv":0.0,"id":27129637},{"batb":[[1,1.01,39.44],[2,1.01,0]],"ltp":0.0,"tv":0.0,"id":20893387}]}]}
{"op":"mcm","clk":"1345292264","pt":1588149087275,"mc":[{"id":"1.170349309","rc":[{"batb":[[1,1.02,5000],[2,1.01,38.57]],"ltp":0.0,"tv":0.0,"id":24550116},{"batb":[[1,1.02,5000],[2,1.01,38.43]],"ltp":0.0,"tv":0.0,"id":27138257},{"batb":[[1,1.02,5000],[2,1.01,43.3]],"ltp":0.0,"tv":0.0,"id":26357500},{"batb":[[1,1.02,5000],[2,1.01,40.4]],"ltp":0.0,"tv":0.0,"id":27129637},{"batb":[[1,1.02,5000],[2,1.01,39.44]],"ltp":0.0,"tv":0.0,"id":20893387}]}]}
{"op":"mcm","clk":"1345305886","pt":1588149690218,"mc":[{"id":"1.170349309","rc":[{"batb":[[1,1.01,38.57],[2,1.01,0]],"ltp":0.0,"tv":0.0,"id":24550116},{"batb":[[1,1.01,38.43],[2,1.01,0]],"ltp":0.0,"tv":0.0,"id":27138257},{"batb":[[1,1.01,43.3],[2,1.01,0]],"ltp":0.0,"tv":0.0,"id":26357500},{"batb":[[1,1.01,40.4],[2,1.01,0]],"ltp":0.0,"tv":0.0,"id":27129637},{"batb":[[1,1.01,39.44],[2,1.01,0]],"ltp":0.0,"tv":0.0,"id":20893387}]}]}
{"op":"mcm","clk":"1345306309","pt":1588149705249,"mc":[{"id":"1.170349309","rc":[{"batb":[[1,1.02,5000],[2,1.01,38.57]],"ltp":0.0,"tv":0.0,"id":24550116},{"batb":[[1,1.02,5000],[2,1.01,38.43]],"ltp":0.0,"tv":0.0,"id":27138257},{"batb":[[1,1.02,5000],[2,1.01,43.3]],"ltp":0.0,"tv":0.0,"id":26357500},{"batb":[[1,1.02,5000],[2,1.01,40.4]],"ltp":0.0,"tv":0.0,"id":27129637},{"batb":[[1,1.02,5000],[2,1.01,39.44]],"ltp":0.0,"tv":0.0,"id":20893387}]}]}
{"op":"mcm","clk":"1345320379","pt":1588150308677,"mc":[{"id":"1.170349309","rc":[{"batb":[[1,1.01,38.57],[2,1.01,0]],"ltp":0.0,"tv":0.0,"id":24550116},{"batb":[[1,1.01,38.43],[2,1.01,0]],"ltp":0.0,"tv":0.0,"id":27138257},{"batb":[[1,1.01,43.3],[2,1.01,0]],"ltp":0.0,"tv":0.0,"id":26357500},{"batb":[[1,1.01,40.4],[2,1.01,0]],"ltp":0.0,"tv":0.0,"id":27129637},{"batb":[[1,1.01,39.44],[2,1.01,0]],"ltp":0.0,"tv":0.0,"id":20893387}]}]}
{"op":"mcm","clk":"1345320728","pt":1588150323564,"mc":[{"id":"1.170349309","rc":[{"batb":[[1,1.02,5000],[2,1.01,38.57]],"ltp":0.0,"tv":0.0,"id":24550116},{"batb":[[1,1.02,5000],[2,1.01,38.43]],"ltp":0.0,"tv":0.0,"id":27138257},{"batb":[[1,1.02,5000],[2,1.01,43.3]],"ltp":0.0,"tv":0.0,"id":26357500},{"batb":[[1,1.02,5000],[2,1.01,40.4]],"ltp":0.0,"tv":0.0,"id":27129637},{"batb":[[1,1.02,5000],[2,1.01,39.44]],"ltp":0.0,"tv":0.0,"id":20893387}]}]}
{"op":"mcm","clk":"1345329558","pt":1588150926876,"mc":[{"id":"1.170349309","rc":[{"batb":[[1,1.01,38.57],[2,1.01,0]],"ltp":0.0,"tv":0.0,"id":24550116},{"batb":[[1,1.01,38.43],[2,1.01,0]],"ltp":0.0,"tv":0.0,"id":27138257},{"batb":[[1,1.01,43.3],[2,1.01,0]],"ltp":0.0,"tv":0.0,"id":26357500},{"batb":[[1,1.01,40.4],[2,1.01,0]],"ltp":0.0,"tv":0.0,"id":27129637},{"batb":[[1,1.01,39.44],[2,1.01,0]],"ltp":0.0,"tv":0.0,"id":20893387}]}]}
{"op":"mcm","clk":"1345329652","pt":1588150941806,"mc":[{"id":"1.170349309","rc":[{"batb":[[1,1.02,5000],[2,1.01,38.57]],"ltp":0.0,"tv":0.0,"id":24550116},{"batb":[[1,1.02,5000],[2,1.01,38.43]],"ltp":0.0,"tv":0.0,"id":27138257},{"batb":[[1,1.02,5000],[2,1.01,43.3]],"ltp":0.0,"tv":0.0,"id":26357500},{"batb":[[1,1.02,5000],[2,1.01,40.4]],"ltp":0.0,"tv":0.0,"id":27129637},{"batb":[[1,1.02,5000],[2,1.01,39.44]],"ltp":0.0,"tv":0.0,"id":20893387}]}]}
{"op":"mcm","clk":"1345339907","pt":1588151545124,"mc":[{"id":"1.170349309","rc":[{"batb":[[1,1.01,38.57],[2,1.01,0]],"ltp":0.0,"tv":0.0,"id":24550116},{"batb":[[1,1.01,38.43],[2,1.01,0]],"ltp":0.0,"tv":0.0,"id":27138257},{"batb":[[1,1.01,43.3],[2,1.01,0]],"ltp":0.0,"tv":0.0,"id":26357500},{"batb":[[1,1.01,40.4],[2,1.01,0]],"ltp":0.0,"tv":0.0,"id":27129637},{"batb":[[1,1.01,39.44],[2,1.01,0]],"ltp":0.0,"tv":0.0,"id":20893387}]}]}
{"op":"mcm","clk":"1345340274","pt":1588151560276,"mc":[{"id":"1.170349309","rc":[{"batb":[[1,1.02,5000],[2,1.01,38.57]],"ltp":0.0,"tv":0.0,"id":24550116},{"batb":[[1,1.02,5000],[2,1.01,38.43]],"ltp":0.0,"tv":0.0,"id":27138257},{"batb":[[1,1.02,5000],[2,1.01,43.3]],"ltp":0.0,"tv":0.0,"id":26357500},{"batb":[[1,1.02,5000],[2,1.01,40.4]],"ltp":0.0,"tv":0.0,"id":27129637},{"batb":[[1,1.02,5000],[2,1.01,39.44]],"ltp":0.0,"tv":0.0,"id":20893387}]}]}
{"op":"mcm","clk":"1345351275","pt":1588152163398,"mc":[{"id":"1.170349309","rc":[{"batb":[[1,1.01,38.57],[2,1.01,0]],"ltp":0.0,"tv":0.0,"id":24550116},{"batb":[[1,1.01,38.43],[2,1.01,0]],"ltp":0.0,"tv":0.0,"id":27138257},{"batb":[[1,1.01,43.3],[2,1.01,0]],"ltp":0.0,"tv":0.0,"id":26357500},{"batb":[[1,1.01,40.4],[2,1.01,0]],"ltp":0.0,"tv":0.0,"id":27129637},{"batb":[[1,1.01,39.44],[2,1.01,0]],"ltp":0.0,"tv":0.0,"id":20893387}]}]}
{"op":"mcm","clk":"1345351412","pt":1588152178508,"mc":[{"id":"1.170349309","rc":[{"batb":[[1,1.02,5000],[2,1.01,38.57]],"ltp":0.0,"tv":0.0,"id":24550116},{"batb":[[1,1.02,5000],[2,1.01,38.43]],"ltp":0.0,"tv":0.0,"id":27138257},{"batb":[[1,1.02,5000],[2,1.01,43.3]],"ltp":0.0,"tv":0.0,"id":26357500},{"batb":[[1,1.02,5000],[2,1.01,40.4]],"ltp":0.0,"tv":0.0,"id":27129637},{"batb":[[1,1.02,5000],[2,1.01,39.44]],"ltp":0.0,"tv":0.0,"id":20893387}]}]}
{"op":"mcm","clk":"1345363668","pt":1588152781467,"mc":[{"id":"1.170349309","rc":[{"batb":[[1,1.01,38.57],[2,1.01,0]],"ltp":0.0,"tv":0.0,"id":24550116},{"batb":[[1,1.01,38.43],[2,1.01,0]],"ltp":0.0,"tv":0.0,"id":27138257},{"batb":[[1,1.01,43.3],[2,1.01,0]],"ltp":0.0,"tv":0.0,"id":26357500},{"batb":[[1,1.01,40.4],[2,1.01,0]],"ltp":0.0,"tv":0.0,"id":27129637},{"batb":[[1,1.01,39.44],[2,1.01,0]],"ltp":0.0,"tv":0.0,"id":20893387}]}]}
{"op":"mcm","clk":"1345364056","pt":1588152796595,"mc":[{"id":"1.170349309","rc":[{"batb":[[1,1.02,5000],[2,1.01,38.57]],"ltp":0.0,"tv":0.0,"id":24550116},{"batb":[[1,1.02,5000],[2,1.01,38.43]],"ltp":0.0,"tv":0.0,"id":27138257},{"batb":[[1,1.02,5000],[2,1.01,43.3]],"ltp":0.0,"tv":0.0,"id":26357500},{"batb":[[1,1.02,5000],[2,1.01,40.4]],"ltp":0.0,"tv":0.0,"id":27129637},{"batb":[[1,1.02,5000],[2,1.01,39.44]],"ltp":0.0,"tv":0.0,"id":20893387}]}]}
{"op":"mcm","clk":"1345374715","pt":1588153399961,"mc":[{"id":"1.170349309","rc":[{"batb":[[1,1.01,38.57],[2,1.01,0]],"ltp":0.0,"tv":0.0,"id":24550116},{"batb":[[1,1.01,38.43],[2,1.01,0]],"ltp":0.0,"tv":0.0,"id":27138257},{"batb":[[1,1.01,43.3],[2,1.01,0]],"ltp":0.0,"tv":0.0,"id":26357500},{"batb":[[1,1.01,40.4],[2,1.01,0]],"ltp":0.0,"tv":0.0,"id":27129637},{"batb":[[1,1.01,39.44],[2,1.01,0]],"ltp":0.0,"tv":0.0,"id":20893387}]}]}
{"op":"mcm","clk":"1345374863","pt":1588153415096,"mc":[{"id":"1.170349309","rc":[{"batb":[[1,1.02,5000],[2,1.01,38.57]],"ltp":0.0,"tv":0.0,"id":24550116},{"batb":[[1,1.02,5000],[2,1.01,38.43]],"ltp":0.0,"tv":0.0,"id":27138257},{"batb":[[1,1.02,5000],[2,1.01,43.3]],"ltp":0.0,"tv":0.0,"id":26357500},{"batb":[[1,1.02,5000],[2,1.01,40.4]],"ltp":0.0,"tv":0.0,"id":27129637},{"batb":[[1,1.02,5000],[2,1.01,39.44]],"ltp":0.0,"tv":0.0,"id":20893387}]}]}
{"op":"mcm","clk":"1345386475","pt":1588154018090,"mc":[{"id":"1.170349309","rc":[{"batb":[[1,1.01,38.57],[2,1.01,0]],"ltp":0.0,"tv":0.0,"id":24550116},{"batb":[[1,1.01,38.43],[2,1.01,0]],"ltp":0.0,"tv":0.0,"id":27138257},{"batb":[[1,1.01,43.3],[2,1.01,0]],"ltp":0.0,"tv":0.0,"id":26357500},{"batb":[[1,1.01,40.4],[2,1.01,0]],"ltp":0.0,"tv":0.0,"id":27129637},{"batb":[[1,1.01,39.44],[2,1.01,0]],"ltp":0.0,"tv":0.0,"id":20893387}]}]}
{"op":"mcm","clk":"1345386874","pt":1588154033106,"mc":[{"id":"1.170349309","rc":[{"batb":[[1,1.02,5000],[2,1.01,38.57]],"ltp":0.0,"tv":0.0,"id":24550116},{"batb":[[1,1.02,5000],[2,1.01,38.43]],"ltp":0.0,"tv":0.0,"id":27138257},{"batb":[[1,1.02,5000],[2,1.01,43.3]],"ltp":0.0,"tv":0.0,"id":26357500},{"batb":[[1,1.02,5000],[2,1.01,40.4]],"ltp":0.0,"tv":0.0,"id":27129637},{"batb":[[1,1.02,5000],[2,1.01,39.44]],"ltp":0.0,"tv":0.0,"id":20893387}]}]}
{"op":"mcm","clk":"1345397712","pt":1588154636327,"mc":[{"id":"1.170349309","rc":[{"batb":[[1,1.01,38.7],[2,1.01,0]],"batl":[[0,1000,1.52]],"ltp":0.0,"tv":0.0,"id":24550116},{"trd":[[1.09,3.49]],"batb":[[1,1.01,42.51]],"batl":[[1,1000,1.53]],"ltp":1.09,"tv":3.48,"id":27376858},{"batb":[[1,1.01,38.56],[2,1.01,0]],"batl":[[0,1000,1.54]],"ltp":0.0,"tv":0.0,"id":27138257},{"batb":[[1,1.01,38.88]],"batl":[[1,1000,1.54]],"ltp":0.0,"tv":0.0,"id":27661463},{"batb":[[1,1.01,43.45],[2,1.01,0]],"batl":[[1,1000,1.55]],"ltp":0.0,"tv":0.0,"id":26357500},{"batb":[[1,1.01,40.54],[2,1.01,0]],"batl":[[0,1000,1.52]],"ltp":0.0,"tv":0.0,"id":27129637},{"batb":[[1,1.01,41.74]],"batl":[[1,1000,1.53]],"ltp":0.0,"tv":0.0,"id":26148884},{"batb":[[1,1.01,39.57],[2,1.01,0]],"batl":[[0,1000,1.57]],"ltp":0.0,"tv":0.0,"id":20893387}],"tv":3.48}]}
{"op":"mcm","clk":"1345397851","pt":1588154651238,"mc":[{"id":"1.170349309","rc":[{"batb":[[1,1.02,5000],[2,1.01,38.7]],"ltp":0.0,"tv":0.0,"id":24550116},{"batb":[[1,1.02,5000],[2,1.01,38.56]],"ltp":0.0,"tv":0.0,"id":27138257},{"batb":[[1,1.02,5000],[2,1.01,43.45]],"ltp":0.0,"tv":0.0,"id":26357500},{"batb":[[1,1.02,5000],[2,1.01,40.54]],"ltp":0.0,"tv":0.0,"id":27129637},{"batb":[[1,1.02,5000],[2,1.01,39.57]],"ltp":0.0,"tv":0.0,"id":20893387}]}]}
{"op":"mcm","clk":"1345411209","pt":1588155254568,"mc":[{"id":"1.170349309","rc":[{"batb":[[1,1.01,38.7],[2,1.01,0]],"ltp":0.0,"tv":0.0,"id":24550116},{"batb":[[1,1.01,38.56],[2,1.01,0]],"ltp":0.0,"tv":0.0,"id":27138257},{"batb":[[1,1.01,43.45],[2,1.01,0]],"ltp":0.0,"tv":0.0,"id":26357500},{"batb":[[1,1.01,40.54],[2,1.01,0]],"ltp":0.0,"tv":0.0,"id":27129637},{"batb":[[1,1.01,39.57],[2,1.01,0]],"ltp":0.0,"tv":0.0,"id":20893387}]}]}
{"op":"mcm","clk":"1345411646","pt":1588155269688,"mc":[{"id":"1.170349309","rc":[{"batb":[[1,1.02,5000],[2,1.01,38.7]],"ltp":0.0,"tv":0.0,"id":24550116},{"batb":[[1,1.02,5000],[2,1.01,38.56]],"ltp":0.0,"tv":0.0,"id":27138257},{"batb":[[1,1.02,5000],[2,1.01,43.45]],"ltp":0.0,"tv":0.0,"id":26357500},{"batb":[[1,1.02,5000],[2,1.01,40.54]],"ltp":0.0,"tv":0.0,"id":27129637},{"batb":[[1,1.02,5000],[2,1.01,39.57]],"ltp":0.0,"tv":0.0,"id":20893387}]}]}
{"op":"mcm","clk":"1345423670","pt":1588155873112,"mc":[{"id":"1.170349309","rc":[{"batb":[[1,1.01,38.7],[2,1.01,0]],"ltp":0.0,"tv":0.0,"id":24550116},{"batb":[[1,1.01,38.56],[2,1.01,0]],"ltp":0.0,"tv":0.0,"id":27138257},{"batb":[[1,1.01,43.45],[2,1.01,0]],"ltp":0.0,"tv":0.0,"id":26357500},{"batb":[[1,1.01,40.54],[2,1.01,0]],"ltp":0.0,"tv":0.0,"id":27129637},{"batb":[[1,1.01,39.57],[2,1.01,0]],"ltp":0.0,"tv":0.0,"id":20893387}]}]}
{"op":"mcm","clk":"1345423972","pt":1588155887997,"mc":[{"id":"1.170349309","rc":[{"batb":[[1,1.02,5000],[2,1.01,38.7]],"ltp":0.0,"tv":0.0,"id":24550116},{"batb":[[1,1.02,5000],[2,1.01,38.56]],"ltp":0.0,"tv":0.0,"id":27138257},{"batb":[[1,1.02,5000],[2,1.01,43.45]],"ltp":0.0,"tv":0.0,"id":26357500},{"batb":[[1,1.02,5000],[2,1.01,40.54]],"ltp":0.0,"tv":0.0,"id":27129637},{"batb":[[1,1.02,5000],[2,1.01,39.57]],"ltp":0.0,"tv":0.0,"id":20893387}]}]}
{"op":"mcm","clk":"1345441969","pt":1588156491288,"mc":[{"id":"1.170349309","rc":[{"batb":[[1,1.01,38.7],[2,1.01,0]],"ltp":0.0,"tv":0.0,"id":24550116},{"batb":[[1,1.01,38.56],[2,1.01,0]],"ltp":0.0,"tv":0.0,"id":27138257},{"batb":[[1,1.01,43.45],[2,1.01,0]],"ltp":0.0,"tv":0.0,"id":26357500},{"batb":[[1,1.01,40.54],[2,1.01,0]],"ltp":0.0,"tv":0.0,"id":27129637},{"batb":[[1,1.01,39.57],[2,1.01,0]],"ltp":0.0,"tv":0.0,"id":20893387}]}]}
{"op":"mcm","clk":"1345442342","pt":1588156506214,"mc":[{"id":"1.170349309","rc":[{"batb":[[1,1.02,5000],[2,1.01,38.7]],"ltp":0.0,"tv":0.0,"id":24550116},{"batb":[[1,1.02,5000],[2,1.01,38.56]],"ltp":0.0,"tv":0.0,"id":27138257},{"batb":[[1,1.02,5000],[2,1.01,43.45]],"ltp":0.0,"tv":0.0,"id":26357500},{"batb":[[1,1.02,5000],[2,1.01,40.54]],"ltp":0.0,"tv":0.0,"id":27129637},{"batb":[[1,1.02,5000],[2,1.01,39.57]],"ltp":0.0,"tv":0.0,"id":20893387}]}]}
{"op":"mcm","clk":"1345454004","pt":1588157109381,"mc":[{"id":"1.170349309","rc":[{"batb":[[1,1.01,38.7],[2,1.01,0]],"ltp":0.0,"tv":0.0,"id":24550116},{"batb":[[1,1.01,38.56],[2,1.01,0]],"ltp":0.0,"tv":0.0,"id":27138257},{"batb":[[1,1.01,43.45],[2,1.01,0]],"ltp":0.0,"tv":0.0,"id":26357500},{"batb":[[1,1.01,40.54],[2,1.01,0]],"ltp":0.0,"tv":0.0,"id":27129637},{"batb":[[1,1.01,39.57],[2,1.01,0]],"ltp":0.0,"tv":0.0,"id":20893387}]}]}
{"op":"mcm","clk":"1345454297","pt":1588157124397,"mc":[{"id":"1.170349309","rc":[{"batb":[[1,1.02,5000],[2,1.01,38.7]],"ltp":0.0,"tv":0.0,"id":24550116},{"batb":[[1,1.02,5000],[2,1.01,38.56]],"ltp":0.0,"tv":0.0,"id":27138257},{"batb":[[1,1.02,5000],[2,1.01,43.45]],"ltp":0.0,"tv":0.0,"id":26357500},{"batb":[[1,1.02,5000],[2,1.01,40.54]],"ltp":0.0,"tv":0.0,"id":27129637},{"batb":[[1,1.02,5000],[2,1.01,39.57]],"ltp":0.0,"tv":0.0,"id":20893387}]}]}
{"op":"mcm","clk":"1345470148","pt":1588157727903,"mc":[{"id":"1.170349309","rc":[{"batb":[[1,1.01,38.7],[2,1.01,0]],"ltp":0.0,"tv":0.0,"id":24550116},{"batb":[[1,1.01,38.56],[2,1.01,0]],"ltp":0.0,"tv":0.0,"id":27138257},{"batb":[[1,1.01,43.45],[2,1.01,0]],"ltp":0.0,"tv":0.0,"id":26357500},{"batb":[[1,1.01,40.54],[2,1.01,0]],"ltp":0.0,"tv":0.0,"id":27129637},{"batb":[[1,1.01,39.57],[2,1.01,0]],"ltp":0.0,"tv":0.0,"id":20893387}]}]}
{"op":"mcm","clk":"1345470602","pt":1588157742929,"mc":[{"id":"1.170349309","rc":[{"batb":[[1,1.02,5000],[2,1.01,38.7]],"ltp":0.0,"tv":0.0,"id":24550116},{"batb":[[1,1.02,5000],[2,1.01,38.56]],"ltp":0.0,"tv":0.0,"id":27138257},{"batb":[[1,1.02,5000],[2,1.01,43.45]],"ltp":0.0,"tv":0.0,"id":26357500},{"batb":[[1,1.02,5000],[2,1.01,40.54]],"ltp":0.0,"tv":0.0,"id":27129637},{"batb":[[1,1.02,5000],[2,1.01,39.57]],"ltp":0.0,"tv":0.0,"id":20893387}]}]}
{"op":"mcm","clk":"1345483130","pt":1588158346259,"mc":[{"id":"1.170349309","rc":[{"batb":[[1,1.01,38.7],[2,1.01,0]],"ltp":0.0,"tv":0.0,"id":24550116},{"batb":[[1,1.01,38.56],[2,1.01,0]],"ltp":0.0,"tv":0.0,"id":27138257},{"batb":[[1,1.01,43.45],[2,1.01,0]],"ltp":0.0,"tv":0.0,"id":26357500},{"batb":[[1,1.01,40.54],[2,1.01,0]],"ltp":0.0,"tv":0.0,"id":27129637},{"batb":[[1,1.01,39.57],[2,1.01,0]],"ltp":0.0,"tv":0.0,"id":20893387}]}]}
{"op":"mcm","clk":"1345483371","pt":1588158361268,"mc":[{"id":"1.170349309","rc":[{"batb":[[1,1.02,5000],[2,1.01,38.7]],"ltp":0.0,"tv":0.0,"id":24550116},{"batb":[[1,1.02,5000],[2,1.01,38.56]],"ltp":0.0,"tv":0.0,"id":27138257},{"batb":[[1,1.02,5000],[2,1.01,43.45]],"ltp":0.0,"tv":0.0,"id":26357500},{"batb":[[1,1.02,5000],[2,1.01,40.54]],"ltp":0.0,"tv":0.0,"id":27129637},{"batb":[[1,1.02,5000],[2,1.01,39.57]],"ltp":0.0,"tv":0.0,"id":20893387}]}]}
{"op":"mcm","clk":"1345498272","pt":1588158964600,"mc":[{"id":"1.170349309","rc":[{"batb":[[1,1.01,38.7],[2,1.01,0]],"ltp":0.0,"tv":0.0,"id":24550116},{"batb":[[1,1.01,38.56],[2,1.01,0]],"ltp":0.0,"tv":0.0,"id":27138257},{"batb":[[1,1.01,43.45],[2,1.01,0]],"ltp":0.0,"tv":0.0,"id":26357500},{"batb":[[1,1.01,40.54],[2,1.01,0]],"ltp":0.0,"tv":0.0,"id":27129637},{"batb":[[1,1.01,39.57],[2,1.01,0]],"ltp":0.0,"tv":0.0,"id":20893387}]}]}
{"op":"mcm","clk":"1345498636","pt":1588158979598,"mc":[{"id":"1.170349309","rc":[{"batb":[[1,1.02,5000],[2,1.01,38.7]],"ltp":0.0,"tv":0.0,"id":24550116},{"batb":[[1,1.02,5000],[2,1.01,38.56]],"ltp":0.0,"tv":0.0,"id":27138257},{"batb":[[1,1.02,5000],[2,1.01,43.45]],"ltp":0.0,"tv":0.0,"id":26357500},{"batb":[[1,1.02,5000],[2,1.01,40.54]],"ltp":0.0,"tv":0.0,"id":27129637},{"batb":[[1,1.02,5000],[2,1.01,39.57]],"ltp":0.0,"tv":0.0,"id":20893387}]}]}
{"op":"mcm","clk":"1345512569","pt":1588159583065,"mc":[{"id":"1.170349309","rc":[{"batb":[[1,1.01,38.7],[2,1.01,0]],"ltp":0.0,"tv":0.0,"id":24550116},{"batb":[[1,1.01,38.56],[2,1.01,0]],"ltp":0.0,"tv":0.0,"id":27138257},{"batb":[[1,1.01,43.45],[2,1.01,0]],"ltp":0.0,"tv":0.0,"id":26357500},{"batb":[[1,1.01,40.54],[2,1.01,0]],"ltp":0.0,"tv":0.0,"id":27129637},{"batb":[[1,1.01,39.57],[2,1.01,0]],"ltp":0.0,"tv":0.0,"id":20893387}]}]}
{"op":"mcm","clk":"1345512896","pt":1588159598033,"mc":[{"id":"1.170349309","rc":[{"batb":[[1,1.02,5000],[2,1.01,38.7]],"ltp":0.0,"tv":0.0,"id":24550116},{"batb":[[1,1.02,5000],[2,1.01,38.56]],"ltp":0.0,"tv":0.0,"id":27138257},{"batb":[[1,1.02,5000],[2,1.01,43.45]],"ltp":0.0,"tv":0.0,"id":26357500},{"batb":[[1,1.02,5000],[2,1.01,40.54]],"ltp":0.0,"tv":0.0,"id":27129637},{"batb":[[1,1.02,5000],[2,1.01,39.57]],"ltp":0.0,"tv":0.0,"id":20893387}]}]}
{"op":"mcm","clk":"1345532252","pt":1588160201594,"mc":[{"id":"1.170349309","rc":[{"batb":[[1,1.01,38.7],[2,1.01,0]],"ltp":0.0,"tv":0.0,"id":24550116},{"batb":[[1,1.01,38.56],[2,1.01,0]],"ltp":0.0,"tv":0.0,"id":27138257},{"batb":[[1,1.01,43.45],[2,1.01,0]],"ltp":0.0,"tv":0.0,"id":26357500},{"batb":[[1,1.01,40.54],[2,1.01,0]],"ltp":0.0,"tv":0.0,"id":27129637},{"batb":[[1,1.01,39.57],[2,1.01,0]],"ltp":0.0,"tv":0.0,"id":20893387}]}]}
{"op":"mcm","clk":"1345532661","pt":1588160216578,"mc":[{"id":"1.170349309","rc":[{"batb":[[1,1.02,5000],[2,1.01,38.7]],"ltp":0.0,"tv":0.0,"id":24550116},{"batb":[[1,1.02,5000],[2,1.01,38.56]],"ltp":0.0,"tv":0.0,"id":27138257},{"batb":[[1,1.02,5000],[2,1.01,43.45]],"ltp":0.0,"tv":0.0,"id":26357500},{"batb":[[1,1.02,5000],[2,1.01,40.54]],"ltp":0.0,"tv":0.0,"id":27129637},{"batb":[[1,1.02,5000],[2,1.01,39.57]],"ltp":0.0,"tv":0.0,"id":20893387}]}]}
{"op":"mcm","clk":"1345547085","pt":1588160820231,"mc":[{"id":"1.170349309","rc":[{"batb":[[1,1.01,38.7],[2,1.01,0]],"ltp":0.0,"tv":0.0,"id":24550116},{"batb":[[1,1.01,38.56],[2,1.01,0]],"ltp":0.0,"tv":0.0,"id":27138257},{"batb":[[1,1.01,43.45],[2,1.01,0]],"ltp":0.0,"tv":0.0,"id":26357500},{"batb":[[1,1.01,40.54],[2,1.01,0]],"ltp":0.0,"tv":0.0,"id":27129637},{"batb":[[1,1.01,39.57],[2,1.01,0]],"ltp":0.0,"tv":0.0,"id":20893387}]}]}
{"op":"mcm","clk":"1345547304","pt":1588160835142,"mc":[{"id":"1.170349309","rc":[{"batb":[[1,1.02,5000],[2,1.01,38.7]],"ltp":0.0,"tv":0.0,"id":24550116},{"batb":[[1,1.02,5000],[2,1.01,38.56]],"ltp":0.0,"tv":0.0,"id":27138257},{"batb":[[1,1.02,5000],[2,1.01,43.45]],"ltp":0.0,"tv":0.0,"id":26357500},{"batb":[[1,1.02,5000],[2,1.01,40.54]],"ltp":0.0,"tv":0.0,"id":27129637},{"batb":[[1,1.02,5000],[2,1.01,39.57]],"ltp":0.0,"tv":0.0,"id":20893387}]}]}
{"op":"mcm","clk":"1345558214","pt":1588161438192,"mc":[{"id":"1.170349309","rc":[{"batb":[[1,1.01,38.7],[2,1.01,0]],"ltp":0.0,"tv":0.0,"id":24550116},{"batb":[[1,1.01,38.56],[2,1.01,0]],"ltp":0.0,"tv":0.0,"id":27138257},{"batb":[[1,1.01,43.45],[2,1.01,0]],"ltp":0.0,"tv":0.0,"id":26357500},{"batb":[[1,1.01,40.54],[2,1.01,0]],"ltp":0.0,"tv":0.0,"id":27129637},{"batb":[[1,1.01,39.57],[2,1.01,0]],"ltp":0.0,"tv":0.0,"id":20893387}]}]}
{"op":"mcm","clk":"1345558604","pt":1588161453122,"mc":[{"id":"1.170349309","rc":[{"batb":[[1,1.02,5000],[2,1.01,38.7]],"ltp":0.0,"tv":0.0,"id":24550116},{"batb":[[1,1.02,5000],[2,1.01,38.56]],"ltp":0.0,"tv":0.0,"id":27138257},{"batb":[[1,1.02,5000],[2,1.01,43.45]],"ltp":0.0,"tv":0.0,"id":26357500},{"batb":[[1,1.02,5000],[2,1.01,40.54]],"ltp":0.0,"tv":0.0,"id":27129637},{"batb":[[1,1.02,5000],[2,1.01,39.57]],"ltp":0.0,"tv":0.0,"id":20893387}]}]}
{"op":"mcm","clk":"1345569017","pt":1588162056352,"mc":[{"id":"1.170349309","rc":[{"batb":[[1,1.01,38.78],[2,1.01,0]],"batl":[[0,1000,1.52]],"ltp":0.0,"tv":0.0,"id":24550116},{"batb":[[1,1.01,42.59]],"batl":[[1,1000,1.53]],"ltp":1.09,"tv":3.48,"id":27376858},{"batb":[[1,1.01,38.64],[2,1.01,0]],"batl":[[0,1000,1.54]],"ltp":0.0,"tv":0.0,"id":27138257},{"batb":[[1,1.01,38.96]],"batl":[[1,1000,1.54]],"ltp":0.0,"tv":0.0,"id":27661463},{"batb":[[1,1.01,43.54],[2,1.01,0]],"batl":[[1,1000,1.56]],"ltp":0.0,"tv":0.0,"id":26357500},{"batb":[[1,1.01,40.63],[2,1.01,0]],"batl":[[0,1000,1.52]],"ltp":0.0,"tv":0.0,"id":27129637},{"batb":[[1,1.01,41.82]],"batl":[[1,1000,1.53]],"ltp":0.0,"tv":0.0,"id":26148884},{"batb":[[1,1.01,39.66],[2,1.01,0]],"batl":[[0,1000,1.57]],"ltp":0.0,"tv":0.0,"id":20893387}]}]}
{"op":"mcm","clk":"1345569215","pt":1588162071252,"mc":[{"id":"1.170349309","rc":[{"batb":[[1,1.02,5000],[2,1.01,38.78]],"ltp":0.0,"tv":0.0,"id":24550116},{"batb":[[1,1.02,5000],[2,1.01,38.64]],"ltp":0.0,"tv":0.0,"id":27138257},{"batb":[[1,1.02,5000],[2,1.01,43.54]],"ltp":0.0,"tv":0.0,"id":26357500},{"batb":[[1,1.02,5000],[2,1.01,40.63]],"ltp":0.0,"tv":0.0,"id":27129637},{"batb":[[1,1.02,5000],[2,1.01,39.66]],"ltp":0.0,"tv":0.0,"id":20893387}]}]}
{"op":"mcm","clk":"1345584456","pt":1588162674710,"mc":[{"id":"1.170349309","rc":[{"batb":[[1,1.01,38.78],[2,1.01,0]],"ltp":0.0,"tv":0.0,"id":24550116},{"batb":[[1,1.01,38.64],[2,1.01,0]],"ltp":0.0,"tv":0.0,"id":27138257},{"batb":[[1,1.01,43.54],[2,1.01,0]],"ltp":0.0,"tv":0.0,"id":26357500},{"batb":[[1,1.01,40.63],[2,1.01,0]],"ltp":0.0,"tv":0.0,"id":27129637},{"batb":[[1,1.01,39.66],[2,1.01,0]],"ltp":0.0,"tv":0.0,"id":20893387}]}]}
{"op":"mcm","clk":"1345584859","pt":1588162689736,"mc":[{"id":"1.170349309","rc":[{"batb":[[1,1.02,5000],[2,1.01,38.78]],"ltp":0.0,"tv":0.0,"id":24550116},{"batb":[[1,1.02,5000],[2,1.01,38.64]],"ltp":0.0,"tv":0.0,"id":27138257},{"batb":[[1,1.02,5000],[2,1.01,43.54]],"ltp":0.0,"tv":0.0,"id":26357500},{"batb":[[1,1.02,5000],[2,1.01,40.63]],"ltp":0.0,"tv":0.0,"id":27129637},{"batb":[[1,1.02,5000],[2,1.01,39.66]],"ltp":0.0,"tv":0.0,"id":20893387}]}]}
{"op":"mcm","clk":"1345602553","pt":1588163293262,"mc":[{"id":"1.170349309","rc":[{"batb":[[1,1.01,38.78],[2,1.01,0]],"ltp":0.0,"tv":0.0,"id":24550116},{"batb":[[1,1.01,38.64],[2,1.01,0]],"ltp":0.0,"tv":0.0,"id":27138257},{"batb":[[1,1.01,43.54],[2,1.01,0]],"ltp":0.0,"tv":0.0,"id":26357500},{"batb":[[1,1.01,40.63],[2,1.01,0]],"ltp":0.0,"tv":0.0,"id":27129637},{"batb":[[1,1.01,39.66],[2,1.01,0]],"ltp":0.0,"tv":0.0,"id":20893387}]}]}
{"op":"mcm","clk":"1345603000","pt":1588163308308,"mc":[{"id":"1.170349309","rc":[{"batb":[[1,1.02,5000],[2,1.01,38.78]],"ltp":0.0,"tv":0.0,"id":24550116},{"batb":[[1,1.02,5000],[2,1.01,38.64]],"ltp":0.0,"tv":0.0,"id":27138257},{"batb":[[1,1.02,5000],[2,1.01,43.54]],"ltp":0.0,"tv":0.0,"id":26357500},{"batb":[[1,1.02,5000],[2,1.01,40.63]],"ltp":0.0,"tv":0.0,"id":27129637},{"batb":[[1,1.02,5000],[2,1.01,39.66]],"ltp":0.0,"tv":0.0,"id":20893387}]}]}
{"op":"mcm","clk":"1345620157","pt":1588163911853,"mc":[{"id":"1.170349309","rc":[{"batb":[[1,1.01,38.78],[2,1.01,0]],"ltp":0.0,"tv":0.0,"id":24550116},{"batb":[[1,1.01,38.64],[2,1.01,0]],"ltp":0.0,"tv":0.0,"id":27138257},{"batb":[[1,1.01,43.54],[2,1.01,0]],"ltp":0.0,"tv":0.0,"id":26357500},{"batb":[[1,1.01,40.63],[2,1.01,0]],"ltp":0.0,"tv":0.0,"id":27129637},{"batb":[[1,1.01,39.66],[2,1.01,0]],"ltp":0.0,"tv":0.0,"id":20893387}]}]}
{"op":"mcm","clk":"1345620523","pt":1588163926765,"mc":[{"id":"1.170349309","rc":[{"batb":[[1,1.02,5000],[2,1.01,38.78]],"ltp":0.0,"tv":0.0,"id":24550116},{"batb":[[1,1.02,5000],[2,1.01,38.64]],"ltp":0.0,"tv":0.0,"id":27138257},{"batb":[[1,1.02,5000],[2,1.01,43.54]],"ltp":0.0,"tv":0.0,"id":26357500},{"batb":[[1,1.02,5000],[2,1.01,40.63]],"ltp":0.0,"tv":0.0,"id":27129637},{"batb":[[1,1.02,5000],[2,1.01,39.66]],"ltp":0.0,"tv":0.0,"id":20893387}]}]}
{"op":"mcm","clk":"1345632594","pt":1588164530470,"mc":[{"id":"1.170349309","rc":[{"batb":[[1,1.01,38.78],[2,1.01,0]],"ltp":0.0,"tv":0.0,"id":24550116},{"batb":[[1,1.01,38.64],[2,1.01,0]],"ltp":0.0,"tv":0.0,"id":27138257},{"batb":[[1,1.01,43.54],[2,1.01,0]],"ltp":0.0,"tv":0.0,"id":26357500},{"batb":[[1,1.01,40.63],[2,1.01,0]],"ltp":0.0,"tv":0.0,"id":27129637},{"batb":[[1,1.01,39.66],[2,1.01,0]],"ltp":0.0,"tv":0.0,"id":20893387}]}]}
{"op":"mcm","clk":"1345632870","pt":1588164545477,"mc":[{"id":"1.170349309","rc":[{"batb":[[1,1.02,5000],[2,1.01,38.78]],"ltp":0.0,"tv":0.0,"id":24550116},{"batb":[[1,1.02,5000],[2,1.01,38.64]],"ltp":0.0,"tv":0.0,"id":27138257},{"batb":[[1,1.02,5000],[2,1.01,43.54]],"ltp":0.0,"tv":0.0,"id":26357500},{"batb":[[1,1.02,5000],[2,1.01,40.63]],"ltp":0.0,"tv":0.0,"id":27129637},{"batb":[[1,1.02,5000],[2,1.01,39.66]],"ltp":0.0,"tv":0.0,"id":20893387}]}]}
{"op":"mcm","clk":"1345644142","pt":1588165149202,"mc":[{"id":"1.170349309","rc":[{"batb":[[1,1.01,38.78],[2,1.01,0]],"ltp":0.0,"tv":0.0,"id":24550116},{"batb":[[1,1.01,38.64],[2,1.01,0]],"ltp":0.0,"tv":0.0,"id":27138257},{"batb":[[1,1.01,43.54],[2,1.01,0]],"ltp":0.0,"tv":0.0,"id":26357500},{"batb":[[1,1.01,40.63],[2,1.01,0]],"ltp":0.0,"tv":0.0,"id":27129637},{"batb":[[1,1.01,39.66],[2,1.01,0]],"ltp":0.0,"tv":0.0,"id":20893387}]}]}
{"op":"mcm","clk":"1345644471","pt":1588165164185,"mc":[{"id":"1.170349309","rc":[{"batb":[[1,1.02,5000],[2,1.01,38.78]],"ltp":0.0,"tv":0.0,"id":24550116},{"batb":[[1,1.02,5000],[2,1.01,38.64]],"ltp":0.0,"tv":0.0,"id":27138257},{"batb":[[1,1.02,5000],[2,1.01,43.54]],"ltp":0.0,"tv":0.0,"id":26357500},{"batb":[[1,1.02,5000],[2,1.01,40.63]],"ltp":0.0,"tv":0.0,"id":27129637},{"batb":[[1,1.02,5000],[2,1.01,39.66]],"ltp":0.0,"tv":0.0,"id":20893387}]}]}
{"op":"mcm","clk":"1345658139","pt":1588165767731,"mc":[{"id":"1.170349309","rc":[{"batb":[[1,1.01,38.78],[2,1.01,0]],"ltp":0.0,"tv":0.0,"id":24550116},{"batb":[[1,1.01,38.64],[2,1.01,0]],"ltp":0.0,"tv":0.0,"id":27138257},{"batb":[[1,1.01,43.54],[2,1.01,0]],"ltp":0.0,"tv":0.0,"id":26357500},{"batb":[[1,1.01,40.63],[2,1.01,0]],"ltp":0.0,"tv":0.0,"id":27129637},{"batb":[[1,1.01,39.66],[2,1.01,0]],"ltp":0.0,"tv":0.0,"id":20893387}]}]}
{"op":"mcm","clk":"1345658436","pt":1588165782640,"mc":[{"id":"1.170349309","rc":[{"batb":[[1,1.02,5000],[2,1.01,38.78]],"ltp":0.0,"tv":0.0,"id":24550116},{"batb":[[1,1.02,5000],[2,1.01,38.64]],"ltp":0.0,"tv":0.0,"id":27138257},{"batb":[[1,1.02,5000],[2,1.01,43.54]],"ltp":0.0,"tv":0.0,"id":26357500},{"batb":[[1,1.02,5000],[2,1.01,40.63]],"ltp":0.0,"tv":0.0,"id":27129637},{"batb":[[1,1.02,5000],[2,1.01,39.66]],"ltp":0.0,"tv":0.0,"id":20893387}]}]}
{"op":"mcm","clk":"1345670911","pt":1588166386309,"mc":[{"id":"1.170349309","rc":[{"batb":[[1,1.01,38.78],[2,1.01,0]],"ltp":0.0,"tv":0.0,"id":24550116},{"batb":[[1,1.01,38.64],[2,1.01,0]],"ltp":0.0,"tv":0.0,"id":27138257},{"batb":[[1,1.01,43.54],[2,1.01,0]],"ltp":0.0,"tv":0.0,"id":26357500},{"batb":[[1,1.01,40.63],[2,1.01,0]],"ltp":0.0,"tv":0.0,"id":27129637},{"batb":[[1,1.01,39.66],[2,1.01,0]],"ltp":0.0,"tv":0.0,"id":20893387}]}]}
{"op":"mcm","clk":"1345671254","pt":1588166401336,"mc":[{"id":"1.170349309","rc":[{"batb":[[1,1.02,5000],[2,1.01,38.78]],"ltp":0.0,"tv":0.0,"id":24550116},{"batb":[[1,1.02,5000],[2,1.01,38.64]],"ltp":0.0,"tv":0.0,"id":27138257},{"batb":[[1,1.02,5000],[2,1.01,43.54]],"ltp":0.0,"tv":0.0,"id":26357500},{"batb":[[1,1.02,5000],[2,1.01,40.63]],"ltp":0.0,"tv":0.0,"id":27129637},{"batb":[[1,1.02,5000],[2,1.01,39.66]],"ltp":0.0,"tv":0.0,"id":20893387}]}]}
{"op":"mcm","clk":"1345684913","pt":1588167004534,"mc":[{"id":"1.170349309","rc":[{"batb":[[1,1.01,38.78],[2,1.01,0]],"ltp":0.0,"tv":0.0,"id":24550116},{"batb":[[1,1.01,38.64],[2,1.01,0]],"ltp":0.0,"tv":0.0,"id":27138257},{"batb":[[1,1.01,43.54],[2,1.01,0]],"ltp":0.0,"tv":0.0,"id":26357500},{"batb":[[1,1.01,40.63],[2,1.01,0]],"ltp":0.0,"tv":0.0,"id":27129637},{"batb":[[1,1.01,39.66],[2,1.01,0]],"ltp":0.0,"tv":0.0,"id":20893387}]}]}
{"op":"mcm","clk":"1345685228","pt":1588167019549,"mc":[{"id":"1.170349309","rc":[{"batb":[[1,1.02,5000],[2,1.01,38.78]],"ltp":0.0,"tv":0.0,"id":24550116},{"batb":[[1,1.02,5000],[2,1.01,38.64]],"ltp":0.0,"tv":0.0,"id":27138257},{"batb":[[1,1.02,5000],[2,1.01,43.54]],"ltp":0.0,"tv":0.0,"id":26357500},{"batb":[[1,1.02,5000],[2,1.01,40.63]],"ltp":0.0,"tv":0.0,"id":27129637},{"batb":[[1,1.02,5000],[2,1.01,39.66]],"ltp":0.0,"tv":0.0,"id":20893387}]}]}
{"op":"mcm","clk":"1345694957","pt":1588167668518,"mc":[{"id":"1.170349309","rc":[{"batb":[[1,1.01,38.78],[2,1.01,0]],"ltp":0.0,"tv":0.0,"id":24550116},{"batb":[[1,1.01,38.64],[2,1.01,0]],"ltp":0.0,"tv":0.0,"id":27138257},{"batb":[[1,1.01,43.54],[2,1.01,0]],"ltp":0.0,"tv":0.0,"id":26357500},{"batb":[[1,1.01,40.63],[2,1.01,0]],"ltp":0.0,"tv":0.0,"id":27129637},{"batb":[[1,1.01,39.66],[2,1.01,0]],"ltp":0.0,"tv":0.0,"id":20893387}]}]}
{"op":"mcm","clk":"1345695856","pt":1588167728813,"mc":[{"id":"1.170349309","rc":[{"batb":[[1,1.02,5000],[2,1.01,38.78]],"ltp":0.0,"tv":0.0,"id":24550116},{"batb":[[1,1.02,5000],[2,1.01,38.64]],"ltp":0.0,"tv":0.0,"id":27138257},{"batb":[[1,1.02,5000],[2,1.01,43.54]],"ltp":0.0,"tv":0.0,"id":26357500},{"batb":[[1,1.02,5000],[2,1.01,40.63]],"ltp":0.0,"tv":0.0,"id":27129637},{"batb":[[1,1.02,5000],[2,1.01,39.66]],"ltp":0.0,"tv":0.0,"id":20893387}]}]}
{"op":"mcm","clk":"1345706469","pt":1588168377855,"mc":[{"id":"1.170349309","rc":[{"batb":[[1,1.01,38.78],[2,1.01,0]],"ltp":0.0,"tv":0.0,"id":24550116},{"batb":[[1,1.01,38.64],[2,1.01,0]],"ltp":0.0,"tv":0.0,"id":27138257},{"batb":[[1,1.01,43.54],[2,1.01,0]],"ltp":0.0,"tv":0.0,"id":26357500},{"batb":[[1,1.01,40.63],[2,1.01,0]],"ltp":0.0,"tv":0.0,"id":27129637},{"batb":[[1,1.01,39.66],[2,1.01,0]],"ltp":0.0,"tv":0.0,"id":20893387}]}]}
{"op":"mcm","clk":"1345706605","pt":1588168392829,"mc":[{"id":"1.170349309","rc":[{"batb":[[1,1.02,5000],[2,1.01,38.78]],"ltp":0.0,"tv":0.0,"id":24550116},{"batb":[[1,1.02,5000],[2,1.01,38.64]],"ltp":0.0,"tv":0.0,"id":27138257},{"batb":[[1,1.02,5000],[2,1.01,43.54]],"ltp":0.0,"tv":0.0,"id":26357500},{"batb":[[1,1.02,5000],[2,1.01,40.63]],"ltp":0.0,"tv":0.0,"id":27129637},{"batb":[[1,1.02,5000],[2,1.01,39.66]],"ltp":0.0,"tv":0.0,"id":20893387}]}]}
{"op":"mcm","clk":"1345713327","pt":1588169041781,"mc":[{"id":"1.170349309","rc":[{"batb":[[1,1.01,38.94],[2,1.01,0]],"batl":[[0,1000,1.52]],"ltp":0.0,"tv":0.0,"id":24550116},{"trd":[[1.09,3.49]],"batb":[[1,1.01,42.77]],"batl":[[1,1000,1.53]],"ltp":1.09,"tv":3.48,"id":27376858},{"batb":[[1,1.01,38.8],[2,1.01,0]],"batl":[[0,1000,1.53]],"ltp":0.0,"tv":0.0,"id":27138257},{"batb":[[1,1.01,39.12]],"batl":[[1,1000,1.53]],"ltp":0.0,"tv":0.0,"id":27661463},{"batb":[[1,1.01,43.72],[2,1.01,0]],"batl":[[1,1000,1.55]],"ltp":0.0,"tv":0.0,"id":26357500},{"batb":[[1,1.01,40.79],[2,1.01,0]],"batl":[[0,1000,1.52]],"ltp":0.0,"tv":0.0,"id":27129637},{"batb":[[1,1.01,41.99]],"batl":[[1,1000,1.53]],"ltp":0.0,"tv":0.0,"id":26148884},{"batb":[[1,1.01,39.82],[2,1.01,0]],"batl":[[0,1000,1.57]],"ltp":0.0,"tv":0.0,"id":20893387}],"tv":3.48}]}
{"op":"mcm","clk":"1345713794","pt":1588169086913,"mc":[{"id":"1.170349309","rc":[{"batb":[[1,1.02,5000],[2,1.01,38.94]],"ltp":0.0,"tv":0.0,"id":24550116},{"batb":[[1,1.02,5000],[2,1.01,38.8]],"ltp":0.0,"tv":0.0,"id":27138257},{"batb":[[1,1.02,5000],[2,1.01,43.72]],"ltp":0.0,"tv":0.0,"id":26357500},{"batb":[[1,1.02,5000],[2,1.01,40.79]],"ltp":0.0,"tv":0.0,"id":27129637},{"batb":[[1,1.02,5000],[2,1.01,39.82]],"ltp":0.0,"tv":0.0,"id":20893387}]}]}
{"op":"mcm","clk":"1345721899","pt":1588169781157,"mc":[{"id":"1.170349309","rc":[{"batb":[[1,1.01,38.94],[2,1.01,0]],"ltp":0.0,"tv":0.0,"id":24550116},{"batb":[[1,1.01,38.8],[2,1.01,0]],"ltp":0.0,"tv":0.0,"id":27138257},{"batb":[[1,1.01,43.72],[2,1.01,0]],"ltp":0.0,"tv":0.0,"id":26357500},{"batb":[[1,1.01,40.79],[2,1.01,0]],"ltp":0.0,"tv":0.0,"id":27129637},{"batb":[[1,1.01,39.82],[2,1.01,0]],"ltp":0.0,"tv":0.0,"id":20893387}]}]}
{"op":"mcm","clk":"1345722931","pt":1588169886612,"mc":[{"id":"1.170349309","rc":[{"batb":[[1,1.02,5000],[2,1.01,38.94]],"ltp":0.0,"tv":0.0,"id":24550116},{"batb":[[1,1.02,5000],[2,1.01,38.8]],"ltp":0.0,"tv":0.0,"id":27138257},{"batb":[[1,1.02,5000],[2,1.01,43.72]],"ltp":0.0,"tv":0.0,"id":26357500},{"batb":[[1,1.02,5000],[2,1.01,40.79]],"ltp":0.0,"tv":0.0,"id":27129637},{"batb":[[1,1.02,5000],[2,1.01,39.82]],"ltp":0.0,"tv":0.0,"id":20893387}]}]}
{"op":"mcm","clk":"1345729233","pt":1588170505497,"mc":[{"id":"1.170349309","rc":[{"batb":[[1,1.01,38.94],[2,1.01,0]],"ltp":0.0,"tv":0.0,"id":24550116},{"batb":[[1,1.01,38.8],[2,1.01,0]],"ltp":0.0,"tv":0.0,"id":27138257},{"batb":[[1,1.01,43.72],[2,1.01,0]],"ltp":0.0,"tv":0.0,"id":26357500},{"batb":[[1,1.01,40.79],[2,1.01,0]],"ltp":0.0,"tv":0.0,"id":27129637},{"batb":[[1,1.01,39.82],[2,1.01,0]],"ltp":0.0,"tv":0.0,"id":20893387}]}]}
{"op":"mcm","clk":"1345729364","pt":1588170520412,"mc":[{"id":"1.170349309","rc":[{"batb":[[1,1.02,5000],[2,1.01,38.94]],"ltp":0.0,"tv":0.0,"id":24550116},{"batb":[[1,1.02,5000],[2,1.01,38.8]],"ltp":0.0,"tv":0.0,"id":27138257},{"batb":[[1,1.02,5000],[2,1.01,43.72]],"ltp":0.0,"tv":0.0,"id":26357500},{"batb":[[1,1.02,5000],[2,1.01,40.79]],"ltp":0.0,"tv":0.0,"id":27129637},{"batb":[[1,1.02,5000],[2,1.01,39.82]],"ltp":0.0,"tv":0.0,"id":20893387}]}]}
{"op":"mcm","clk":"1345735411","pt":1588171169374,"mc":[{"id":"1.170349309","rc":[{"batb":[[1,1.01,38.94],[2,1.01,0]],"ltp":0.0,"tv":0.0,"id":24550116},{"batb":[[1,1.01,38.8],[2,1.01,0]],"ltp":0.0,"tv":0.0,"id":27138257},{"batb":[[1,1.01,43.72],[2,1.01,0]],"ltp":0.0,"tv":0.0,"id":26357500},{"batb":[[1,1.01,40.79],[2,1.01,0]],"ltp":0.0,"tv":0.0,"id":27129637},{"batb":[[1,1.01,39.82],[2,1.01,0]],"ltp":0.0,"tv":0.0,"id":20893387}]}]}
{"op":"mcm","clk":"1345735519","pt":1588171184358,"mc":[{"id":"1.170349309","rc":[{"batb":[[1,1.02,5000],[2,1.01,38.94]],"ltp":0.0,"tv":0.0,"id":24550116},{"batb":[[1,1.02,5000],[2,1.01,38.8]],"ltp":0.0,"tv":0.0,"id":27138257},{"batb":[[1,1.02,5000],[2,1.01,43.72]],"ltp":0.0,"tv":0.0,"id":26357500},{"batb":[[1,1.02,5000],[2,1.01,40.79]],"ltp":0.0,"tv":0.0,"id":27129637},{"batb":[[1,1.02,5000],[2,1.01,39.82]],"ltp":0.0,"tv":0.0,"id":20893387}]}]}
{"op":"mcm","clk":"1345741064","pt":1588171818379,"mc":[{"id":"1.170349309","rc":[{"batb":[[1,1.01,38.94],[2,1.01,0]],"ltp":0.0,"tv":0.0,"id":24550116},{"batb":[[1,1.01,38.8],[2,1.01,0]],"ltp":0.0,"tv":0.0,"id":27138257},{"batb":[[1,1.01,43.72],[2,1.01,0]],"ltp":0.0,"tv":0.0,"id":26357500},{"batb":[[1,1.01,40.79],[2,1.01,0]],"ltp":0.0,"tv":0.0,"id":27129637},{"batb":[[1,1.01,39.82],[2,1.01,0]],"ltp":0.0,"tv":0.0,"id":20893387}]}]}
{"op":"mcm","clk":"1345741238","pt":1588171833408,"mc":[{"id":"1.170349309","rc":[{"batb":[[1,1.02,5000],[2,1.01,38.94]],"ltp":0.0,"tv":0.0,"id":24550116},{"batb":[[1,1.02,5000],[2,1.01,38.8]],"ltp":0.0,"tv":0.0,"id":27138257},{"batb":[[1,1.02,5000],[2,1.01,43.72]],"ltp":0.0,"tv":0.0,"id":26357500},{"batb":[[1,1.02,5000],[2,1.01,40.79]],"ltp":0.0,"tv":0.0,"id":27129637},{"batb":[[1,1.02,5000],[2,1.01,39.82]],"ltp":0.0,"tv":0.0,"id":20893387}]}]}
{"op":"mcm","clk":"1345745556","pt":1588172452280,"mc":[{"id":"1.170349309","rc":[{"batb":[[1,1.01,38.94],[2,1.01,0]],"ltp":0.0,"tv":0.0,"id":24550116},{"batb":[[1,1.01,38.8],[2,1.01,0]],"ltp":0.0,"tv":0.0,"id":27138257},{"batb":[[1,1.01,43.72],[2,1.01,0]],"ltp":0.0,"tv":0.0,"id":26357500},{"batb":[[1,1.01,40.79],[2,1.01,0]],"ltp":0.0,"tv":0.0,"id":27129637},{"batb":[[1,1.01,39.82],[2,1.01,0]],"ltp":0.0,"tv":0.0,"id":20893387}]}]}
{"op":"mcm","clk":"1345745605","pt":1588172467159,"mc":[{"id":"1.170349309","rc":[{"batb":[[1,1.02,5000],[2,1.01,38.94]],"ltp":0.0,"tv":0.0,"id":24550116},{"batb":[[1,1.02,5000],[2,1.01,38.8]],"ltp":0.0,"tv":0.0,"id":27138257},{"batb":[[1,1.02,5000],[2,1.01,43.72]],"ltp":0.0,"tv":0.0,"id":26357500},{"batb":[[1,1.02,5000],[2,1.01,40.79]],"ltp":0.0,"tv":0.0,"id":27129637},{"batb":[[1,1.02,5000],[2,1.01,39.82]],"ltp":0.0,"tv":0.0,"id":20893387}]}]}
{"op":"mcm","clk":"1345748799","pt":1588173116146,"mc":[{"id":"1.170349309","rc":[{"batb":[[1,1.01,38.94],[2,1.01,0]],"ltp":0.0,"tv":0.0,"id":24550116},{"batb":[[1,1.01,38.8],[2,1.01,0]],"ltp":0.0,"tv":0.0,"id":27138257},{"batb":[[1,1.01,43.72],[2,1.01,0]],"ltp":0.0,"tv":0.0,"id":26357500},{"batb":[[1,1.01,40.79],[2,1.01,0]],"ltp":0.0,"tv":0.0,"id":27129637},{"batb":[[1,1.01,39.82],[2,1.01,0]],"ltp":0.0,"tv":0.0,"id":20893387}]}]}
{"op":"mcm","clk":"1345748917","pt":1588173131179,"mc":[{"id":"1.170349309","rc":[{"batb":[[1,1.02,5000],[2,1.01,38.94]],"ltp":0.0,"tv":0.0,"id":24550116},{"batb":[[1,1.02,5000],[2,1.01,38.8]],"ltp":0.0,"tv":0.0,"id":27138257},{"batb":[[1,1.02,5000],[2,1.01,43.72]],"ltp":0.0,"tv":0.0,"id":26357500},{"batb":[[1,1.02,5000],[2,1.01,40.79]],"ltp":0.0,"tv":0.0,"id":27129637},{"batb":[[1,1.02,5000],[2,1.01,39.82]],"ltp":0.0,"tv":0.0,"id":20893387}]}]}
{"op":"mcm","clk":"1345753598","pt":1588173734861,"mc":[{"id":"1.170349309","rc":[{"batb":[[1,1.01,38.94],[2,1.01,0]],"ltp":0.0,"tv":0.0,"id":24550116},{"batb":[[1,1.01,38.8],[2,1.01,0]],"ltp":0.0,"tv":0.0,"id":27138257},{"batb":[[1,1.01,43.72],[2,1.01,0]],"ltp":0.0,"tv":0.0,"id":26357500},{"batb":[[1,1.01,40.79],[2,1.01,0]],"ltp":0.0,"tv":0.0,"id":27129637},{"batb":[[1,1.01,39.82],[2,1.01,0]],"ltp":0.0,"tv":0.0,"id":20893387}]}]}
{"op":"mcm","clk":"1345753728","pt":1588173749887,"mc":[{"id":"1.170349309","rc":[{"batb":[[1,1.02,5000],[2,1.01,38.94]],"ltp":0.0,"tv":0.0,"id":24550116},{"batb":[[1,1.02,5000],[2,1.01,38.8]],"ltp":0.0,"tv":0.0,"id":27138257},{"batb":[[1,1.02,5000],[2,1.01,43.72]],"ltp":0.0,"tv":0.0,"id":26357500},{"batb":[[1,1.02,5000],[2,1.01,40.79]],"ltp":0.0,"tv":0.0,"id":27129637},{"batb":[[1,1.02,5000],[2,1.01,39.82]],"ltp":0.0,"tv":0.0,"id":20893387}]}]}
{"op":"mcm","clk":"1345759429","pt":1588174353437,"mc":[{"id":"1.170349309","rc":[{"batb":[[1,1.01,38.94],[2,1.01,0]],"ltp":0.0,"tv":0.0,"id":24550116},{"batb":[[1,1.01,38.8],[2,1.01,0]],"ltp":0.0,"tv":0.0,"id":27138257},{"batb":[[1,1.01,43.72],[2,1.01,0]],"ltp":0.0,"tv":0.0,"id":26357500},{"batb":[[1,1.01,40.79],[2,1.01,0]],"ltp":0.0,"tv":0.0,"id":27129637},{"batb":[[1,1.01,39.82],[2,1.01,0]],"ltp":0.0,"tv":0.0,"id":20893387}]}]}
{"op":"mcm","clk":"1345759583","pt":1588174368439,"mc":[{"id":"1.170349309","rc":[{"batb":[[1,1.02,5000],[2,1.01,38.94]],"ltp":0.0,"tv":0.0,"id":24550116},{"batb":[[1,1.02,5000],[2,1.01,38.8]],"ltp":0.0,"tv":0.0,"id":27138257},{"batb":[[1,1.02,5000],[2,1.01,43.72]],"ltp":0.0,"tv":0.0,"id":26357500},{"batb":[[1,1.02,5000],[2,1.01,40.79]],"ltp":0.0,"tv":0.0,"id":27129637},{"batb":[[1,1.02,5000],[2,1.01,39.82]],"ltp":0.0,"tv":0.0,"id":20893387}]}]}
{"op":"mcm","clk":"1345765201","pt":1588174972003,"mc":[{"id":"1.170349309","rc":[{"batb":[[1,1.01,38.94],[2,1.01,0]],"ltp":0.0,"tv":0.0,"id":24550116},{"batb":[[1,1.01,38.8],[2,1.01,0]],"ltp":0.0,"tv":0.0,"id":27138257},{"batb":[[1,1.01,43.72],[2,1.01,0]],"ltp":0.0,"tv":0.0,"id":26357500},{"batb":[[1,1.01,40.79],[2,1.01,0]],"ltp":0.0,"tv":0.0,"id":27129637},{"batb":[[1,1.01,39.82],[2,1.01,0]],"ltp":0.0,"tv":0.0,"id":20893387}]}]}
{"op":"mcm","clk":"1345765318","pt":1588174987001,"mc":[{"id":"1.170349309","rc":[{"batb":[[1,1.02,5000],[2,1.01,38.94]],"ltp":0.0,"tv":0.0,"id":24550116},{"batb":[[1,1.02,5000],[2,1.01,38.8]],"ltp":0.0,"tv":0.0,"id":27138257},{"batb":[[1,1.02,5000],[2,1.01,43.72]],"ltp":0.0,"tv":0.0,"id":26357500},{"batb":[[1,1.02,5000],[2,1.01,40.79]],"ltp":0.0,"tv":0.0,"id":27129637},{"batb":[[1,1.02,5000],[2,1.01,39.82]],"ltp":0.0,"tv":0.0,"id":20893387}]}]}
{"op":"mcm","clk":"1345769825","pt":1588175590658,"mc":[{"id":"1.170349309","rc":[{"batb":[[1,1.01,38.94],[2,1.01,0]],"ltp":0.0,"tv":0.0,"id":24550116},{"batb":[[1,1.01,38.8],[2,1.01,0]],"ltp":0.0,"tv":0.0,"id":27138257},{"batb":[[1,1.01,43.72],[2,1.01,0]],"ltp":0.0,"tv":0.0,"id":26357500},{"batb":[[1,1.01,40.79],[2,1.01,0]],"ltp":0.0,"tv":0.0,"id":27129637},{"batb":[[1,1.01,39.82],[2,1.01,0]],"ltp":0.0,"tv":0.0,"id":20893387}]}]}
{"op":"mcm","clk":"1345769979","pt":1588175605698,"mc":[{"id":"1.170349309","rc":[{"batb":[[1,1.02,5000],[2,1.01,38.94]],"ltp":0.0,"tv":0.0,"id":24550116},{"batb":[[1,1.02,5000],[2,1.01,38.8]],"ltp":0.0,"tv":0.0,"id":27138257},{"batb":[[1,1.02,5000],[2,1.01,43.72]],"ltp":0.0,"tv":0.0,"id":26357500},{"batb":[[1,1.02,5000],[2,1.01,40.79]],"ltp":0.0,"tv":0.0,"id":27129637},{"batb":[[1,1.02,5000],[2,1.01,39.82]],"ltp":0.0,"tv":0.0,"id":20893387}]}]}
{"op":"mcm","clk":"1345776987","pt":1588176209434,"mc":[{"id":"1.170349309","rc":[{"batb":[[1,1.01,39.43],[2,1.01,0]],"batl":[[0,1000,1.52]],"ltp":0.0,"tv":0.0,"id":24550116},{"trd":[[1.09,3.49]],"batb":[[1,1.01,43.31]],"batl":[[1,1000,1.53]],"ltp":1.09,"tv":3.48,"id":27376858},{"batb":[[1,1.01,39.29],[2,1.01,0]],"batl":[[0,1000,1.54]],"ltp":0.0,"tv":0.0,"id":27138257},{"batb":[[1,1.01,39.61]],"batl":[[1,1000,1.54]],"ltp":0.0,"tv":0.0,"id":27661463},{"batb":[[1,1.01,44.27],[2,1.01,0]],"batl":[[1,1000,1.55]],"ltp":0.0,"tv":0.0,"id":26357500},{"batb":[[1,1.01,41.31],[2,1.01,0]],"batl":[[0,1000,1.52]],"ltp":0.0,"tv":0.0,"id":27129637},{"batb":[[1,1.01,42.52]],"batl":[[1,1000,1.53]],"ltp":0.0,"tv":0.0,"id":26148884},{"batb":[[1,1.01,40.32],[2,1.01,0]],"batl":[[0,1000,1.57]],"ltp":0.0,"tv":0.0,"id":20893387}],"tv":3.48}]}
{"op":"mcm","clk":"1345777136","pt":1588176224365,"mc":[{"id":"1.170349309","rc":[{"batb":[[1,1.02,5000],[2,1.01,39.43]],"ltp":0.0,"tv":0.0,"id":24550116},{"batb":[[1,1.02,5000],[2,1.01,39.29]],"ltp":0.0,"tv":0.0,"id":27138257},{"batb":[[1,1.02,5000],[2,1.01,44.27]],"ltp":0.0,"tv":0.0,"id":26357500},{"batb":[[1,1.02,5000],[2,1.01,41.31]],"ltp":0.0,"tv":0.0,"id":27129637},{"batb":[[1,1.02,5000],[2,1.01,40.32]],"ltp":0.0,"tv":0.0,"id":20893387}]}]}
{"op":"mcm","clk":"1345783681","pt":1588176828114,"mc":[{"id":"1.170349309","rc":[{"batb":[[1,1.01,39.43],[2,1.01,0]],"ltp":0.0,"tv":0.0,"id":24550116},{"batb":[[1,1.01,39.29],[2,1.01,0]],"ltp":0.0,"tv":0.0,"id":27138257},{"batb":[[1,1.01,44.27],[2,1.01,0]],"ltp":0.0,"tv":0.0,"id":26357500},{"batb":[[1,1.01,41.31],[2,1.01,0]],"ltp":0.0,"tv":0.0,"id":27129637},{"batb":[[1,1.01,40.32],[2,1.01,0]],"ltp":0.0,"tv":0.0,"id":20893387}]}]}
{"op":"mcm","clk":"1345783811","pt":1588176843269,"mc":[{"id":"1.170349309","rc":[{"batb":[[1,1.02,5000],[2,1.01,39.43]],"ltp":0.0,"tv":0.0,"id":24550116},{"batb":[[1,1.02,5000],[2,1.01,39.29]],"ltp":0.0,"tv":0.0,"id":27138257},{"batb":[[1,1.02,5000],[2,1.01,44.27]],"ltp":0.0,"tv":0.0,"id":26357500},{"batb":[[1,1.02,5000],[2,1.01,41.31]],"ltp":0.0,"tv":0.0,"id":27129637},{"batb":[[1,1.02,5000],[2,1.01,40.32]],"ltp":0.0,"tv":0.0,"id":20893387}]}]}
{"op":"mcm","clk":"1345789728","pt":1588177446758,"mc":[{"id":"1.170349309","rc":[{"batb":[[1,1.01,39.43],[2,1.01,0]],"ltp":0.0,"tv":0.0,"id":24550116},{"batb":[[1,1.01,39.29],[2,1.01,0]],"ltp":0.0,"tv":0.0,"id":27138257},{"batb":[[1,1.01,44.27],[2,1.01,0]],"ltp":0.0,"tv":0.0,"id":26357500},{"batb":[[1,1.01,41.31],[2,1.01,0]],"ltp":0.0,"tv":0.0,"id":27129637},{"batb":[[1,1.01,40.32],[2,1.01,0]],"ltp":0.0,"tv":0.0,"id":20893387}]}]}
{"op":"mcm","clk":"1345790562","pt":1588177461811,"mc":[{"id":"1.170349309","rc":[{"batb":[[1,1.02,5000],[2,1.01,39.43]],"ltp":0.0,"tv":0.0,"id":24550116},{"batb":[[1,1.02,5000],[2,1.01,39.29]],"ltp":0.0,"tv":0.0,"id":27138257},{"batb":[[1,1.02,5000],[2,1.01,44.27]],"ltp":0.0,"tv":0.0,"id":26357500},{"batb":[[1,1.02,5000],[2,1.01,41.31]],"ltp":0.0,"tv":0.0,"id":27129637},{"batb":[[1,1.02,5000],[2,1.01,40.32]],"ltp":0.0,"tv":0.0,"id":20893387}]}]}
{"op":"mcm","clk":"1345796424","pt":1588178065191,"mc":[{"id":"1.170349309","rc":[{"batb":[[1,1.01,39.43],[2,1.01,0]],"ltp":0.0,"tv":0.0,"id":24550116},{"batb":[[1,1.01,39.29],[2,1.01,0]],"ltp":0.0,"tv":0.0,"id":27138257},{"batb":[[1,1.01,44.27],[2,1.01,0]],"ltp":0.0,"tv":0.0,"id":26357500},{"batb":[[1,1.01,41.31],[2,1.01,0]],"ltp":0.0,"tv":0.0,"id":27129637},{"batb":[[1,1.01,40.32],[2,1.01,0]],"ltp":0.0,"tv":0.0,"id":20893387}]}]}
{"op":"mcm","clk":"1345796641","pt":1588178080191,"mc":[{"id":"1.170349309","rc":[{"batb":[[1,1.02,5000],[2,1.01,39.43]],"ltp":0.0,"tv":0.0,"id":24550116},{"batb":[[1,1.02,5000],[2,1.01,39.29]],"ltp":0.0,"tv":0.0,"id":27138257},{"batb":[[1,1.02,5000],[2,1.01,44.27]],"ltp":0.0,"tv":0.0,"id":26357500},{"batb":[[1,1.02,5000],[2,1.01,41.31]],"ltp":0.0,"tv":0.0,"id":27129637},{"batb":[[1,1.02,5000],[2,1.01,40.32]],"ltp":0.0,"tv":0.0,"id":20893387}]}]}
{"op":"mcm","clk":"1345804551","pt":1588178683924,"mc":[{"id":"1.170349309","rc":[{"batb":[[1,1.01,39.43],[2,1.01,0]],"ltp":0.0,"tv":0.0,"id":24550116},{"batb":[[1,1.01,39.29],[2,1.01,0]],"ltp":0.0,"tv":0.0,"id":27138257},{"batb":[[1,1.01,44.27],[2,1.01,0]],"ltp":0.0,"tv":0.0,"id":26357500},{"batb":[[1,1.01,41.31],[2,1.01,0]],"ltp":0.0,"tv":0.0,"id":27129637},{"batb":[[1,1.01,40.32],[2,1.01,0]],"ltp":0.0,"tv":0.0,"id":20893387}]}]}
{"op":"mcm","clk":"1345804742","pt":1588178698925,"mc":[{"id":"1.170349309","rc":[{"batb":[[1,1.02,5000],[2,1.01,39.43]],"ltp":0.0,"tv":0.0,"id":24550116},{"batb":[[1,1.02,5000],[2,1.01,39.29]],"ltp":0.0,"tv":0.0,"id":27138257},{"batb":[[1,1.02,5000],[2,1.01,44.27]],"ltp":0.0,"tv":0.0,"id":26357500},{"batb":[[1,1.02,5000],[2,1.01,41.31]],"ltp":0.0,"tv":0.0,"id":27129637},{"batb":[[1,1.02,5000],[2,1.01,40.32]],"ltp":0.0,"tv":0.0,"id":20893387}]}]}
{"op":"mcm","clk":"1345813936","pt":1588179302433,"mc":[{"id":"1.170349309","rc":[{"batb":[[1,1.01,39.43],[2,1.01,0]],"ltp":0.0,"tv":0.0,"id":24550116},{"batb":[[1,1.01,39.29],[2,1.01,0]],"ltp":0.0,"tv":0.0,"id":27138257},{"batb":[[1,1.01,44.27],[2,1.01,0]],"ltp":0.0,"tv":0.0,"id":26357500},{"batb":[[1,1.01,41.31],[2,1.01,0]],"ltp":0.0,"tv":0.0,"id":27129637},{"batb":[[1,1.01,40.32],[2,1.01,0]],"ltp":0.0,"tv":0.0,"id":20893387}]}]}
{"op":"mcm","clk":"1345814151","pt":1588179317557,"mc":[{"id":"1.170349309","rc":[{"batb":[[1,1.02,5000],[2,1.01,39.43]],"ltp":0.0,"tv":0.0,"id":24550116},{"batb":[[1,1.02,5000],[2,1.01,39.29]],"ltp":0.0,"tv":0.0,"id":27138257},{"batb":[[1,1.02,5000],[2,1.01,44.27]],"ltp":0.0,"tv":0.0,"id":26357500},{"batb":[[1,1.02,5000],[2,1.01,41.31]],"ltp":0.0,"tv":0.0,"id":27129637},{"batb":[[1,1.02,5000],[2,1.01,40.32]],"ltp":0.0,"tv":0.0,"id":20893387}]}]}
{"op":"mcm","clk":"1345824271","pt":1588179920923,"mc":[{"id":"1.170349309","rc":[{"batb":[[1,1.01,39.43],[2,1.01,0]],"ltp":0.0,"tv":0.0,"id":24550116},{"batb":[[1,1.01,39.29],[2,1.01,0]],"ltp":0.0,"tv":0.0,"id":27138257},{"batb":[[1,1.01,44.27],[2,1.01,0]],"ltp":0.0,"tv":0.0,"id":26357500},{"batb":[[1,1.01,41.31],[2,1.01,0]],"ltp":0.0,"tv":0.0,"id":27129637},{"batb":[[1,1.01,40.32],[2,1.01,0]],"ltp":0.0,"tv":0.0,"id":20893387}]}]}
{"op":"mcm","clk":"1345824493","pt":1588179935946,"mc":[{"id":"1.170349309","rc":[{"batb":[[1,1.02,5000],[2,1.01,39.43]],"ltp":0.0,"tv":0.0,"id":24550116},{"batb":[[1,1.02,5000],[2,1.01,39.29]],"ltp":0.0,"tv":0.0,"id":27138257},{"batb":[[1,1.02,5000],[2,1.01,44.27]],"ltp":0.0,"tv":0.0,"id":26357500},{"batb":[[1,1.02,5000],[2,1.01,41.31]],"ltp":0.0,"tv":0.0,"id":27129637},{"batb":[[1,1.02,5000],[2,1.01,40.32]],"ltp":0.0,"tv":0.0,"id":20893387}]}]}
{"op":"mcm","clk":"1345833779","pt":1588180539589,"mc":[{"id":"1.170349309","rc":[{"batb":[[1,1.01,39.43],[2,1.01,0]],"ltp":0.0,"tv":0.0,"id":24550116},{"batb":[[1,1.01,39.29],[2,1.01,0]],"ltp":0.0,"tv":0.0,"id":27138257},{"batb":[[1,1.01,44.27],[2,1.01,0]],"ltp":0.0,"tv":0.0,"id":26357500},{"batb":[[1,1.01,41.31],[2,1.01,0]],"ltp":0.0,"tv":0.0,"id":27129637},{"batb":[[1,1.01,40.32],[2,1.01,0]],"ltp":0.0,"tv":0.0,"id":20893387}]}]}
{"op":"mcm","clk":"1345834028","pt":1588180554596,"mc":[{"id":"1.170349309","rc":[{"batb":[[1,1.02,5000],[2,1.01,39.43]],"ltp":0.0,"tv":0.0,"id":24550116},{"batb":[[1,1.02,5000],[2,1.01,39.29]],"ltp":0.0,"tv":0.0,"id":27138257},{"batb":[[1,1.02,5000],[2,1.01,44.27]],"ltp":0.0,"tv":0.0,"id":26357500},{"batb":[[1,1.02,5000],[2,1.01,41.31]],"ltp":0.0,"tv":0.0,"id":27129637},{"batb":[[1,1.02,5000],[2,1.01,40.32]],"ltp":0.0,"tv":0.0,"id":20893387}]}]}
{"op":"mcm","clk":"1345844634","pt":1588181158150,"mc":[{"id":"1.170349309","rc":[{"batb":[[1,1.01,39.43],[2,1.01,0]],"ltp":0.0,"tv":0.0,"id":24550116},{"batb":[[1,1.01,39.29],[2,1.01,0]],"ltp":0.0,"tv":0.0,"id":27138257},{"batb":[[1,1.01,44.27],[2,1.01,0]],"ltp":0.0,"tv":0.0,"id":26357500},{"batb":[[1,1.01,41.31],[2,1.01,0]],"ltp":0.0,"tv":0.0,"id":27129637},{"batb":[[1,1.01,40.32],[2,1.01,0]],"ltp":0.0,"tv":0.0,"id":20893387}]}]}
{"op":"mcm","clk":"1345844878","pt":1588181173264,"mc":[{"id":"1.170349309","rc":[{"batb":[[1,1.02,5000],[2,1.01,39.43]],"ltp":0.0,"tv":0.0,"id":24550116},{"batb":[[1,1.02,5000],[2,1.01,39.29]],"ltp":0.0,"tv":0.0,"id":27138257},{"batb":[[1,1.02,5000],[2,1.01,44.27]],"ltp":0.0,"tv":0.0,"id":26357500},{"batb":[[1,1.02,5000],[2,1.01,41.31]],"ltp":0.0,"tv":0.0,"id":27129637},{"batb":[[1,1.02,5000],[2,1.01,40.32]],"ltp":0.0,"tv":0.0,"id":20893387}]}]}
{"op":"mcm","clk":"1345854808","pt":1588181776649,"mc":[{"id":"1.170349309","rc":[{"batb":[[1,1.01,39.43],[2,1.01,0]],"ltp":0.0,"tv":0.0,"id":24550116},{"batb":[[1,1.01,39.29],[2,1.01,0]],"ltp":0.0,"tv":0.0,"id":27138257},{"batb":[[1,1.01,44.27],[2,1.01,0]],"ltp":0.0,"tv":0.0,"id":26357500},{"batb":[[1,1.01,41.31],[2,1.01,0]],"ltp":0.0,"tv":0.0,"id":27129637},{"batb":[[1,1.01,40.32],[2,1.01,0]],"ltp":0.0,"tv":0.0,"id":20893387}]}]}
{"op":"mcm","clk":"1345855073","pt":1588181791767,"mc":[{"id":"1.170349309","rc":[{"batb":[[1,1.02,5000],[2,1.01,39.43]],"ltp":0.0,"tv":0.0,"id":24550116},{"batb":[[1,1.02,5000],[2,1.01,39.29]],"ltp":0.0,"tv":0.0,"id":27138257},{"batb":[[1,1.02,5000],[2,1.01,44.27]],"ltp":0.0,"tv":0.0,"id":26357500},{"batb":[[1,1.02,5000],[2,1.01,41.31]],"ltp":0.0,"tv":0.0,"id":27129637},{"batb":[[1,1.02,5000],[2,1.01,40.32]],"ltp":0.0,"tv":0.0,"id":20893387}]}]}
{"op":"mcm","clk":"1345867020","pt":1588182395247,"mc":[{"id":"1.170349309","rc":[{"batb":[[1,1.01,39.43],[2,1.01,0]],"ltp":0.0,"tv":0.0,"id":24550116},{"batb":[[1,1.01,39.29],[2,1.01,0]],"ltp":0.0,"tv":0.0,"id":27138257},{"batb":[[1,1.01,44.27],[2,1.01,0]],"ltp":0.0,"tv":0.0,"id":26357500},{"batb":[[1,1.01,41.31],[2,1.01,0]],"ltp":0.0,"tv":0.0,"id":27129637},{"batb":[[1,1.01,40.32],[2,1.01,0]],"ltp":0.0,"tv":0.0,"id":20893387}]}]}
{"op":"mcm","clk":"1345867332","pt":1588182410255,"mc":[{"id":"1.170349309","rc":[{"batb":[[1,1.02,5000],[2,1.01,39.43]],"ltp":0.0,"tv":0.0,"id":24550116},{"batb":[[1,1.02,5000],[2,1.01,39.29]],"ltp":0.0,"tv":0.0,"id":27138257},{"batb":[[1,1.02,5000],[2,1.01,44.27]],"ltp":0.0,"tv":0.0,"id":26357500},{"batb":[[1,1.02,5000],[2,1.01,41.31]],"ltp":0.0,"tv":0.0,"id":27129637},{"batb":[[1,1.02,5000],[2,1.01,40.32]],"ltp":0.0,"tv":0.0,"id":20893387}]}]}
{"op":"mcm","clk":"1345879499","pt":1588183013809,"mc":[{"id":"1.170349309","rc":[{"batb":[[1,1.01,39.43],[2,1.01,0]],"ltp":0.0,"tv":0.0,"id":24550116},{"batb":[[1,1.01,39.29],[2,1.01,0]],"ltp":0.0,"tv":0.0,"id":27138257},{"batb":[[1,1.01,44.27],[2,1.01,0]],"ltp":0.0,"tv":0.0,"id":26357500},{"batb":[[1,1.01,41.31],[2,1.01,0]],"ltp":0.0,"tv":0.0,"id":27129637},{"batb":[[1,1.01,40.32],[2,1.01,0]],"ltp":0.0,"tv":0.0,"id":20893387}]}]}
{"op":"mcm","clk":"1345879820","pt":1588183028883,"mc":[{"id":"1.170349309","rc":[{"batb":[[1,1.02,5000],[2,1.01,39.43]],"ltp":0.0,"tv":0.0,"id":24550116},{"batb":[[1,1.02,5000],[2,1.01,39.29]],"ltp":0.0,"tv":0.0,"id":27138257},{"batb":[[1,1.02,5000],[2,1.01,44.27]],"ltp":0.0,"tv":0.0,"id":26357500},{"batb":[[1,1.02,5000],[2,1.01,41.31]],"ltp":0.0,"tv":0.0,"id":27129637},{"batb":[[1,1.02,5000],[2,1.01,40.32]],"ltp":0.0,"tv":0.0,"id":20893387}]}]}
{"op":"mcm","clk":"1345892266","pt":1588183632397,"mc":[{"id":"1.170349309","rc":[{"batb":[[1,1.01,39.41],[2,1.01,0]],"batl":[[0,1000,1.52]],"ltp":0.0,"tv":0.0,"id":24550116},{"batb":[[1,1.01,43.28]],"batl":[[1,1000,1.53]],"ltp":1.09,"tv":3.48,"id":27376858},{"batb":[[1,1.01,39.26],[2,1.01,0]],"batl":[[0,1000,1.53]],"ltp":0.0,"tv":0.0,"id":27138257},{"batb":[[1,1.01,39.58]],"batl":[[1,1000,1.53]],"ltp":0.0,"tv":0.0,"id":27661463},{"batb":[[1,1.01,44.24],[2,1.01,0]],"batl":[[1,1000,1.55]],"ltp":0.0,"tv":0.0,"id":26357500},{"batb":[[1,1.01,41.28],[2,1.01,0]],"batl":[[0,1000,1.52]],"ltp":0.0,"tv":0.0,"id":27129637},{"batb":[[1,1.01,42.5]],"batl":[[1,1000,1.53]],"ltp":0.0,"tv":0.0,"id":26148884},{"batb":[[1,1.01,40.29],[2,1.01,0]],"batl":[[0,1000,1.57]],"ltp":0.0,"tv":0.0,"id":20893387}]}]}
{"op":"mcm","clk":"1345892525","pt":1588183647381,"mc":[{"id":"1.170349309","rc":[{"batb":[[1,1.02,5000],[2,1.01,39.41]],"ltp":0.0,"tv":0.0,"id":24550116},{"batb":[[1,1.02,5000],[2,1.01,39.26]],"ltp":0.0,"tv":0.0,"id":27138257},{"batb":[[1,1.02,5000],[2,1.01,44.24]],"ltp":0.0,"tv":0.0,"id":26357500},{"batb":[[1,1.02,5000],[2,1.01,41.28]],"ltp":0.0,"tv":0.0,"id":27129637},{"batb":[[1,1.02,5000],[2,1.01,40.29]],"ltp":0.0,"tv":0.0,"id":20893387}]}]}
{"op":"mcm","clk":"1345903816","pt":1588184250821,"mc":[{"id":"1.170349309","rc":[{"batb":[[1,1.01,39.41],[2,1.01,0]],"ltp":0.0,"tv":0.0,"id":24550116},{"batb":[[1,1.01,39.26],[2,1.01,0]],"ltp":0.0,"tv":0.0,"id":27138257},{"batb":[[1,1.01,44.24],[2,1.01,0]],"ltp":0.0,"tv":0.0,"id":26357500},{"batb":[[1,1.01,41.28],[2,1.01,0]],"ltp":0.0,"tv":0.0,"id":27129637},{"batb":[[1,1.01,40.29],[2,1.01,0]],"ltp":0.0,"tv":0.0,"id":20893387}]}]}
{"op":"mcm","clk":"1345904163","pt":1588184265926,"mc":[{"id":"1.170349309","rc":[{"batb":[[1,1.02,5000],[2,1.01,39.41]],"ltp":0.0,"tv":0.0,"id":24550116},{"batb":[[1,1.02,5000],[2,1.01,39.26]],"ltp":0.0,"tv":0.0,"id":27138257},{"batb":[[1,1.02,5000],[2,1.01,44.24]],"ltp":0.0,"tv":0.0,"id":26357500},{"batb":[[1,1.02,5000],[2,1.01,41.28]],"ltp":0.0,"tv":0.0,"id":27129637},{"batb":[[1,1.02,5000],[2,1.01,40.29]],"ltp":0.0,"tv":0.0,"id":20893387}]}]}
{"op":"mcm","clk":"1345916201","pt":1588184869669,"mc":[{"id":"1.170349309","rc":[{"batb":[[1,1.01,39.41],[2,1.01,0]],"ltp":0.0,"tv":0.0,"id":24550116},{"batb":[[1,1.01,39.26],[2,1.01,0]],"ltp":0.0,"tv":0.0,"id":27138257},{"batb":[[1,1.01,44.24],[2,1.01,0]],"ltp":0.0,"tv":0.0,"id":26357500},{"batb":[[1,1.01,41.28],[2,1.01,0]],"ltp":0.0,"tv":0.0,"id":27129637},{"batb":[[1,1.01,40.29],[2,1.01,0]],"ltp":0.0,"tv":0.0,"id":20893387}]}]}
{"op":"mcm","clk":"1345916513","pt":1588184884687,"mc":[{"id":"1.170349309","rc":[{"batb":[[1,1.02,5000],[2,1.01,39.41]],"ltp":0.0,"tv":0.0,"id":24550116},{"batb":[[1,1.02,5000],[2,1.01,39.26]],"ltp":0.0,"tv":0.0,"id":27138257},{"batb":[[1,1.02,5000],[2,1.01,44.24]],"ltp":0.0,"tv":0.0,"id":26357500},{"batb":[[1,1.02,5000],[2,1.01,41.28]],"ltp":0.0,"tv":0.0,"id":27129637},{"batb":[[1,1.02,5000],[2,1.01,40.29]],"ltp":0.0,"tv":0.0,"id":20893387}]}]}
{"op":"mcm","clk":"1345928613","pt":1588185488313,"mc":[{"id":"1.170349309","rc":[{"batb":[[1,1.01,39.41],[2,1.01,0]],"ltp":0.0,"tv":0.0,"id":24550116},{"batb":[[1,1.01,39.26],[2,1.01,0]],"ltp":0.0,"tv":0.0,"id":27138257},{"batb":[[1,1.01,44.24],[2,1.01,0]],"ltp":0.0,"tv":0.0,"id":26357500},{"batb":[[1,1.01,41.28],[2,1.01,0]],"ltp":0.0,"tv":0.0,"id":27129637},{"batb":[[1,1.01,40.29],[2,1.01,0]],"ltp":0.0,"tv":0.0,"id":20893387}]}]}
{"op":"mcm","clk":"1345928962","pt":1588185503336,"mc":[{"id":"1.170349309","rc":[{"batb":[[1,1.02,5000],[2,1.01,39.41]],"ltp":0.0,"tv":0.0,"id":24550116},{"batb":[[1,1.02,5000],[2,1.01,39.26]],"ltp":0.0,"tv":0.0,"id":27138257},{"batb":[[1,1.02,5000],[2,1.01,44.24]],"ltp":0.0,"tv":0.0,"id":26357500},{"batb":[[1,1.02,5000],[2,1.01,41.28]],"ltp":0.0,"tv":0.0,"id":27129637},{"batb":[[1,1.02,5000],[2,1.01,40.29]],"ltp":0.0,"tv":0.0,"id":20893387}]}]}
{"op":"mcm","clk":"1345944425","pt":1588186106640,"mc":[{"id":"1.170349309","rc":[{"batb":[[1,1.01,39.41],[2,1.01,0]],"ltp":0.0,"tv":0.0,"id":24550116},{"batb":[[1,1.01,39.26],[2,1.01,0]],"ltp":0.0,"tv":0.0,"id":27138257},{"batb":[[1,1.01,44.24],[2,1.01,0]],"ltp":0.0,"tv":0.0,"id":26357500},{"batb":[[1,1.01,41.28],[2,1.01,0]],"ltp":0.0,"tv":0.0,"id":27129637},{"batb":[[1,1.01,40.29],[2,1.01,0]],"ltp":0.0,"tv":0.0,"id":20893387}]}]}
{"op":"mcm","clk":"1345944815","pt":1588186121669,"mc":[{"id":"1.170349309","rc":[{"batb":[[1,1.02,5000],[2,1.01,39.41]],"ltp":0.0,"tv":0.0,"id":24550116},{"batb":[[1,1.02,5000],[2,1.01,39.26]],"ltp":0.0,"tv":0.0,"id":27138257},{"batb":[[1,1.02,5000],[2,1.01,44.24]],"ltp":0.0,"tv":0.0,"id":26357500},{"batb":[[1,1.02,5000],[2,1.01,41.28]],"ltp":0.0,"tv":0.0,"id":27129637},{"batb":[[1,1.02,5000],[2,1.01,40.29]],"ltp":0.0,"tv":0.0,"id":20893387}]}]}
{"op":"mcm","clk":"1345958514","pt":1588186725179,"mc":[{"id":"1.170349309","rc":[{"batb":[[1,1.01,39.41],[2,1.01,0]],"ltp":0.0,"tv":0.0,"id":24550116},{"batb":[[1,1.01,39.26],[2,1.01,0]],"ltp":0.0,"tv":0.0,"id":27138257},{"batb":[[1,1.01,44.24],[2,1.01,0]],"ltp":0.0,"tv":0.0,"id":26357500},{"batb":[[1,1.01,41.28],[2,1.01,0]],"ltp":0.0,"tv":0.0,"id":27129637},{"batb":[[1,1.01,40.29],[2,1.01,0]],"ltp":0.0,"tv":0.0,"id":20893387}]}]}
{"op":"mcm","clk":"1345958811","pt":1588186740220,"mc":[{"id":"1.170349309","rc":[{"batb":[[1,1.02,5000],[2,1.01,39.41]],"ltp":0.0,"tv":0.0,"id":24550116},{"batb":[[1,1.02,5000],[2,1.01,39.26]],"ltp":0.0,"tv":0.0,"id":27138257},{"batb":[[1,1.02,5000],[2,1.01,44.24]],"ltp":0.0,"tv":0.0,"id":26357500},{"batb":[[1,1.02,5000],[2,1.01,41.28]],"ltp":0.0,"tv":0.0,"id":27129637},{"batb":[[1,1.02,5000],[2,1.01,40.29]],"ltp":0.0,"tv":0.0,"id":20893387}]}]}
{"op":"mcm","clk":"1345969639","pt":1588187343666,"mc":[{"id":"1.170349309","rc":[{"batb":[[1,1.01,39.54],[2,1.01,0]],"ltp":0.0,"tv":0.0,"id":24550116},{"batb":[[1,1.01,43.43]],"ltp":1.09,"tv":3.48,"id":27376858},{"batb":[[1,1.01,39.4],[2,1.01,0]],"ltp":0.0,"tv":0.0,"id":27138257},{"batb":[[1,1.01,39.72]],"ltp":0.0,"tv":0.0,"id":27661463},{"batb":[[1,1.01,44.39],[2,1.01,0]],"ltp":0.0,"tv":0.0,"id":26357500},{"batb":[[1,1.01,41.42],[2,1.01,0]],"ltp":0.0,"tv":0.0,"id":27129637},{"batb":[[1,1.01,42.64]],"ltp":0.0,"tv":0.0,"id":26148884},{"batb":[[1,1.01,40.43],[2,1.01,0]],"ltp":0.0,"tv":0.0,"id":20893387}]}]}
{"op":"mcm","clk":"1345969952","pt":1588187358671,"mc":[{"id":"1.170349309","rc":[{"batb":[[1,1.02,5000],[2,1.01,39.54]],"ltp":0.0,"tv":0.0,"id":24550116},{"batb":[[1,1.02,5000],[2,1.01,39.4]],"ltp":0.0,"tv":0.0,"id":27138257},{"batb":[[1,1.02,5000],[2,1.01,44.39]],"ltp":0.0,"tv":0.0,"id":26357500},{"batb":[[1,1.02,5000],[2,1.01,41.42]],"ltp":0.0,"tv":0.0,"id":27129637},{"batb":[[1,1.02,5000],[2,1.01,40.43]],"ltp":0.0,"tv":0.0,"id":20893387}]}]}
{"op":"mcm","clk":"1345982128","pt":1588187962088,"mc":[{"id":"1.170349309","rc":[{"batb":[[1,1.01,39.54],[2,1.01,0]],"ltp":0.0,"tv":0.0,"id":24550116},{"batb":[[1,1.01,39.4],[2,1.01,0]],"ltp":0.0,"tv":0.0,"id":27138257},{"batb":[[1,1.01,44.39],[2,1.01,0]],"ltp":0.0,"tv":0.0,"id":26357500},{"batb":[[1,1.01,41.42],[2,1.01,0]],"ltp":0.0,"tv":0.0,"id":27129637},{"batb":[[1,1.01,40.43],[2,1.01,0]],"ltp":0.0,"tv":0.0,"id":20893387}]}]}
{"op":"mcm","clk":"1345982367","pt":1588187977069,"mc":[{"id":"1.170349309","rc":[{"batb":[[1,1.02,5000],[2,1.01,39.54]],"ltp":0.0,"tv":0.0,"id":24550116},{"batb":[[1,1.02,5000],[2,1.01,39.4]],"ltp":0.0,"tv":0.0,"id":27138257},{"batb":[[1,1.02,5000],[2,1.01,44.39]],"ltp":0.0,"tv":0.0,"id":26357500},{"batb":[[1,1.02,5000],[2,1.01,41.42]],"ltp":0.0,"tv":0.0,"id":27129637},{"batb":[[1,1.02,5000],[2,1.01,40.43]],"ltp":0.0,"tv":0.0,"id":20893387}]}]}
{"op":"mcm","clk":"1345991490","pt":1588188580539,"mc":[{"id":"1.170349309","rc":[{"batb":[[1,1.01,39.54],[2,1.01,0]],"ltp":0.0,"tv":0.0,"id":24550116},{"batb":[[1,1.01,39.4],[2,1.01,0]],"ltp":0.0,"tv":0.0,"id":27138257},{"batb":[[1,1.01,44.39],[2,1.01,0]],"ltp":0.0,"tv":0.0,"id":26357500},{"batb":[[1,1.01,41.42],[2,1.01,0]],"ltp":0.0,"tv":0.0,"id":27129637},{"batb":[[1,1.01,40.43],[2,1.01,0]],"ltp":0.0,"tv":0.0,"id":20893387}]}]}
{"op":"mcm","clk":"1345991717","pt":1588188595585,"mc":[{"id":"1.170349309","rc":[{"batb":[[1,1.02,5000],[2,1.01,39.54]],"ltp":0.0,"tv":0.0,"id":24550116},{"batb":[[1,1.02,5000],[2,1.01,39.4]],"ltp":0.0,"tv":0.0,"id":27138257},{"batb":[[1,1.02,5000],[2,1.01,44.39]],"ltp":0.0,"tv":0.0,"id":26357500},{"batb":[[1,1.02,5000],[2,1.01,41.42]],"ltp":0.0,"tv":0.0,"id":27129637},{"batb":[[1,1.02,5000],[2,1.01,40.43]],"ltp":0.0,"tv":0.0,"id":20893387}]}]}
{"op":"mcm","clk":"1345999505","pt":1588189198846,"mc":[{"id":"1.170349309","rc":[{"batb":[[1,1.01,39.54],[2,1.01,0]],"ltp":0.0,"tv":0.0,"id":24550116},{"batb":[[1,1.01,39.4],[2,1.01,0]],"ltp":0.0,"tv":0.0,"id":27138257},{"batb":[[1,1.01,44.39],[2,1.01,0]],"ltp":0.0,"tv":0.0,"id":26357500},{"batb":[[1,1.01,41.42],[2,1.01,0]],"ltp":0.0,"tv":0.0,"id":27129637},{"batb":[[1,1.01,40.43],[2,1.01,0]],"ltp":0.0,"tv":0.0,"id":20893387}]}]}
{"op":"mcm","clk":"1345999753","pt":1588189213956,"mc":[{"id":"1.170349309","rc":[{"batb":[[1,1.02,5000],[2,1.01,39.54]],"ltp":0.0,"tv":0.0,"id":24550116},{"batb":[[1,1.02,5000],[2,1.01,39.4]],"ltp":0.0,"tv":0.0,"id":27138257},{"batb":[[1,1.02,5000],[2,1.01,44.39]],"ltp":0.0,"tv":0.0,"id":26357500},{"batb":[[1,1.02,5000],[2,1.01,41.42]],"ltp":0.0,"tv":0.0,"id":27129637},{"batb":[[1,1.02,5000],[2,1.01,40.43]],"ltp":0.0,"tv":0.0,"id":20893387}]}]}
{"op":"mcm","clk":"1346007266","pt":1588189817012,"mc":[{"id":"1.170349309","rc":[{"batb":[[1,1.01,39.54],[2,1.01,0]],"ltp":0.0,"tv":0.0,"id":24550116},{"batb":[[1,1.01,39.4],[2,1.01,0]],"ltp":0.0,"tv":0.0,"id":27138257},{"batb":[[1,1.01,44.39],[2,1.01,0]],"ltp":0.0,"tv":0.0,"id":26357500},{"batb":[[1,1.01,41.42],[2,1.01,0]],"ltp":0.0,"tv":0.0,"id":27129637},{"batb":[[1,1.01,40.43],[2,1.01,0]],"ltp":0.0,"tv":0.0,"id":20893387}]}]}
{"op":"mcm","clk":"1346007512","pt":1588189832037,"mc":[{"id":"1.170349309","rc":[{"batb":[[1,1.02,5000],[2,1.01,39.54]],"ltp":0.0,"tv":0.0,"id":24550116},{"batb":[[1,1.02,5000],[2,1.01,39.4]],"ltp":0.0,"tv":0.0,"id":27138257},{"batb":[[1,1.02,5000],[2,1.01,44.39]],"ltp":0.0,"tv":0.0,"id":26357500},{"batb":[[1,1.02,5000],[2,1.01,41.42]],"ltp":0.0,"tv":0.0,"id":27129637},{"batb":[[1,1.02,5000],[2,1.01,40.43]],"ltp":0.0,"tv":0.0,"id":20893387}]}]}
{"op":"mcm","clk":"1346016402","pt":1588190435436,"mc":[{"id":"1.170349309","rc":[{"batb":[[1,1.01,39.54],[2,1.01,0]],"ltp":0.0,"tv":0.0,"id":24550116},{"batb":[[1,1.01,39.4],[2,1.01,0]],"ltp":0.0,"tv":0.0,"id":27138257},{"batb":[[1,1.01,44.39],[2,1.01,0]],"ltp":0.0,"tv":0.0,"id":26357500},{"batb":[[1,1.01,41.42],[2,1.01,0]],"ltp":0.0,"tv":0.0,"id":27129637},{"batb":[[1,1.01,40.43],[2,1.01,0]],"ltp":0.0,"tv":0.0,"id":20893387}]}]}
{"op":"mcm","clk":"1346016682","pt":1588190450574,"mc":[{"id":"1.170349309","rc":[{"batb":[[1,1.02,5000],[2,1.01,39.54]],"ltp":0.0,"tv":0.0,"id":24550116},{"batb":[[1,1.02,5000],[2,1.01,39.4]],"ltp":0.0,"tv":0.0,"id":27138257},{"batb":[[1,1.02,5000],[2,1.01,44.39]],"ltp":0.0,"tv":0.0,"id":26357500},{"batb":[[1,1.02,5000],[2,1.01,41.42]],"ltp":0.0,"tv":0.0,"id":27129637},{"batb":[[1,1.02,5000],[2,1.01,40.43]],"ltp":0.0,"tv":0.0,"id":20893387}]}]}
{"op":"mcm","clk":"1346031615","pt":1588191054131,"mc":[{"id":"1.170349309","rc":[{"batb":[[1,1.01,39.54],[2,1.01,0]],"ltp":0.0,"tv":0.0,"id":24550116},{"batb":[[1,1.01,39.4],[2,1.01,0]],"ltp":0.0,"tv":0.0,"id":27138257},{"batb":[[1,1.01,44.39],[2,1.01,0]],"ltp":0.0,"tv":0.0,"id":26357500},{"batb":[[1,1.01,41.42],[2,1.01,0]],"ltp":0.0,"tv":0.0,"id":27129637},{"batb":[[1,1.01,40.43],[2,1.01,0]],"ltp":0.0,"tv":0.0,"id":20893387}]}]}
{"op":"mcm","clk":"1346031963","pt":1588191069235,"mc":[{"id":"1.170349309","rc":[{"batb":[[1,1.02,5000],[2,1.01,39.54]],"ltp":0.0,"tv":0.0,"id":24550116},{"batb":[[1,1.02,5000],[2,1.01,39.4]],"ltp":0.0,"tv":0.0,"id":27138257},{"batb":[[1,1.02,5000],[2,1.01,44.39]],"ltp":0.0,"tv":0.0,"id":26357500},{"batb":[[1,1.02,5000],[2,1.01,41.42]],"ltp":0.0,"tv":0.0,"id":27129637},{"batb":[[1,1.02,5000],[2,1.01,40.43]],"ltp":0.0,"tv":0.0,"id":20893387}]}]}
{"op":"mcm","clk":"1346045201","pt":1588191672912,"mc":[{"id":"1.170349309","rc":[{"batb":[[1,1.01,39.54],[2,1.01,0]],"ltp":0.0,"tv":0.0,"id":24550116},{"batb":[[1,1.01,39.4],[2,1.01,0]],"ltp":0.0,"tv":0.0,"id":27138257},{"batb":[[1,1.01,44.39],[2,1.01,0]],"ltp":0.0,"tv":0.0,"id":26357500},{"batb":[[1,1.01,41.42],[2,1.01,0]],"ltp":0.0,"tv":0.0,"id":27129637},{"batb":[[1,1.01,40.43],[2,1.01,0]],"ltp":0.0,"tv":0.0,"id":20893387}]}]}
{"op":"mcm","clk":"1346045522","pt":1588191687922,"mc":[{"id":"1.170349309","rc":[{"batb":[[1,1.02,5000],[2,1.01,39.54]],"ltp":0.0,"tv":0.0,"id":24550116},{"batb":[[1,1.02,5000],[2,1.01,39.4]],"ltp":0.0,"tv":0.0,"id":27138257},{"batb":[[1,1.02,5000],[2,1.01,44.39]],"ltp":0.0,"tv":0.0,"id":26357500},{"batb":[[1,1.02,5000],[2,1.01,41.42]],"ltp":0.0,"tv":0.0,"id":27129637},{"batb":[[1,1.02,5000],[2,1.01,40.43]],"ltp":0.0,"tv":0.0,"id":20893387}]}]}
{"op":"mcm","clk":"1346052819","pt":1588192040327,"mc":[{"id":"1.170349309","rc":[{"trd":[[1.09,203.49]],"batb":[[0,1.09,170.48]],"ltp":1.09,"tv":203.48,"id":27376858},{"trd":[[1.28,160]],"batb":[[0,1.28,7.5]],"ltp":1.28,"tv":160.0,"id":27661463}],"tv":363.48}]}
{"op":"mcm","clk":"1346053724","pt":1588192089161,"mc":[{"id":"1.170349309","rc":[{"trd":[[7.4,4]],"batl":[[0,7.4,1.85]],"ltp":7.4,"tv":4.0,"id":26148884}],"tv":367.48}]}
{"op":"mcm","clk":"1346057204","pt":1588192291444,"mc":[{"id":"1.170349309","rc":[{"batb":[[1,1.01,39.54],[2,1.01,0]],"ltp":0.0,"tv":0.0,"id":24550116},{"batb":[[1,1.01,39.4],[2,1.01,0]],"ltp":0.0,"tv":0.0,"id":27138257},{"batb":[[1,1.01,44.39],[2,1.01,0]],"ltp":0.0,"tv":0.0,"id":26357500},{"batb":[[1,1.01,41.42],[2,1.01,0]],"ltp":0.0,"tv":0.0,"id":27129637},{"batb":[[1,1.01,40.43],[2,1.01,0]],"ltp":0.0,"tv":0.0,"id":20893387}]}]}
{"op":"mcm","clk":"1346057326","pt":1588192306440,"mc":[{"id":"1.170349309","rc":[{"batb":[[1,1.02,5000],[2,1.01,39.54]],"ltp":0.0,"tv":0.0,"id":24550116},{"batb":[[1,1.02,5000],[2,1.01,39.4]],"ltp":0.0,"tv":0.0,"id":27138257},{"batb":[[1,1.02,5000],[2,1.01,44.39]],"ltp":0.0,"tv":0.0,"id":26357500},{"batb":[[1,1.02,5000],[2,1.01,41.42]],"ltp":0.0,"tv":0.0,"id":27129637},{"batb":[[1,1.02,5000],[2,1.01,40.43]],"ltp":0.0,"tv":0.0,"id":20893387}]}]}
{"op":"mcm","clk":"1346057745","pt":1588192360427,"mc":[{"id":"1.170349309","rc":[{"batb":[[2,1.01,1.53]],"ltp":0.0,"tv":0.0,"id":24550116},{"batb":[[1,1.01,1.53]],"ltp":1.09,"tv":203.48,"id":27376858},{"batb":[[2,1.01,1.53]],"ltp":0.0,"tv":0.0,"id":27138257},{"batb":[[1,1.01,1.53]],"ltp":1.28,"tv":160.0,"id":27661463},{"batb":[[2,1.01,1.53]],"ltp":0.0,"tv":0.0,"id":26357500},{"batb":[[2,1.01,1.53]],"ltp":0.0,"tv":0.0,"id":27129637},{"batb":[[1,1.01,1.53]],"ltp":7.4,"tv":4.0,"id":26148884},{"batb":[[2,1.01,1.53]],"ltp":0.0,"tv":0.0,"id":20893387}]}]}
{"op":"mcm","clk":"1346067707","pt":1588192910139,"mc":[{"id":"1.170349309","rc":[{"batb":[[1,1.01,1.53],[2,1.01,0]],"ltp":0.0,"tv":0.0,"id":24550116},{"batb":[[1,1.01,1.53],[2,1.01,0]],"ltp":0.0,"tv":0.0,"id":27138257},{"batb":[[1,1.01,1.53],[2,1.01,0]],"ltp":0.0,"tv":0.0,"id":26357500},{"batb":[[1,1.01,1.53],[2,1.01,0]],"ltp":0.0,"tv":0.0,"id":27129637},{"batb":[[1,1.01,1.53],[2,1.01,0]],"ltp":0.0,"tv":0.0,"id":20893387}]}]}
{"op":"mcm","clk":"1346068011","pt":1588192925246,"mc":[{"id":"1.170349309","rc":[{"batb":[[1,1.02,5000],[2,1.01,1.53]],"ltp":0.0,"tv":0.0,"id":24550116},{"batb":[[1,1.02,5000],[2,1.01,1.53]],"ltp":0.0,"tv":0.0,"id":27138257},{"batb":[[1,1.02,5000],[2,1.01,1.53]],"ltp":0.0,"tv":0.0,"id":26357500},{"batb":[[1,1.02,5000],[2,1.01,1.53]],"ltp":0.0,"tv":0.0,"id":27129637},{"batb":[[1,1.02,5000],[2,1.01,1.53]],"ltp":0.0,"tv":0.0,"id":20893387}]}]}
{"op":"mcm","clk":"1346084680","pt":1588193528521,"mc":[{"id":"1.170349309","rc":[{"batb":[[1,1.01,1.53],[2,1.01,0]],"ltp":0.0,"tv":0.0,"id":24550116},{"batb":[[1,1.01,1.53],[2,1.01,0]],"ltp":0.0,"tv":0.0,"id":27138257},{"batb":[[1,1.01,1.53],[2,1.01,0]],"ltp":0.0,"tv":0.0,"id":26357500},{"batb":[[1,1.01,1.53],[2,1.01,0]],"ltp":0.0,"tv":0.0,"id":27129637},{"batb":[[1,1.01,1.53],[2,1.01,0]],"ltp":0.0,"tv":0.0,"id":20893387}]}]}
{"op":"mcm","clk":"1346085056","pt":1588193543620,"mc":[{"id":"1.170349309","rc":[{"batb":[[1,1.02,5000],[2,1.01,1.53]],"ltp":0.0,"tv":0.0,"id":24550116},{"batb":[[1,1.02,5000],[2,1.01,1.53]],"ltp":0.0,"tv":0.0,"id":27138257},{"batb":[[1,1.02,5000],[2,1.01,1.53]],"ltp":0.0,"tv":0.0,"id":26357500},{"batb":[[1,1.02,5000],[2,1.01,1.53]],"ltp":0.0,"tv":0.0,"id":27129637},{"batb":[[1,1.02,5000],[2,1.01,1.53]],"ltp":0.0,"tv":0.0,"id":20893387}]}]}
{"op":"mcm","clk":"1346100712","pt":1588194147256,"mc":[{"id":"1.170349309","rc":[{"batb":[[1,1.01,1.53],[2,1.01,0]],"batl":[[0,1000,1.52]],"ltp":0.0,"tv":0.0,"id":24550116},{"trd":[[1.09,203.48]],"batb":[[1,1.01,1.53]],"batl":[[1,1000,1.52]],"ltp":1.09,"tv":203.48,"id":27376858},{"batb":[[1,1.01,1.53],[2,1.01,0]],"batl":[[0,1000,1.53]],"ltp":0.0,"tv":0.0,"id":27138257},{"batb":[[1,1.01,1.53]],"batl":[[1,1000,1.53]],"ltp":1.28,"tv":160.0,"id":27661463},{"batb":[[1,1.01,1.53],[2,1.01,0]],"batl":[[1,1000,1.55]],"ltp":0.0,"tv":0.0,"id":26357500},{"batb":[[1,1.01,1.53],[2,1.01,0]],"batl":[[0,1000,1.52]],"ltp":0.0,"tv":0.0,"id":27129637},{"batb":[[1,1.01,1.53]],"batl":[[1,1000,1.52]],"ltp":7.4,"tv":4.0,"id":26148884},{"batb":[[1,1.01,1.53],[2,1.01,0]],"batl":[[0,1000,1.56]],"ltp":0.0,"tv":0.0,"id":20893387}],"tv":367.48}]}
{"op":"mcm","clk":"1346101110","pt":1588194162271,"mc":[{"id":"1.170349309","rc":[{"batb":[[1,1.02,5000],[2,1.01,1.53]],"ltp":0.0,"tv":0.0,"id":24550116},{"batb":[[1,1.02,5000],[2,1.01,1.53]],"ltp":0.0,"tv":0.0,"id":27138257},{"batb":[[1,1.02,5000],[2,1.01,1.53]],"ltp":0.0,"tv":0.0,"id":26357500},{"batb":[[1,1.02,5000],[2,1.01,1.53]],"ltp":0.0,"tv":0.0,"id":27129637},{"batb":[[1,1.02,5000],[2,1.01,1.53]],"ltp":0.0,"tv":0.0,"id":20893387}]}]}
{"op":"mcm","clk":"1346118778","pt":1588194765909,"mc":[{"id":"1.170349309","rc":[{"batb":[[1,1.01,1.53],[2,1.01,0]],"ltp":0.0,"tv":0.0,"id":24550116},{"batb":[[1,1.01,1.53],[2,1.01,0]],"ltp":0.0,"tv":0.0,"id":27138257},{"batb":[[1,1.01,1.53],[2,1.01,0]],"ltp":0.0,"tv":0.0,"id":26357500},{"batb":[[1,1.01,1.53],[2,1.01,0]],"ltp":0.0,"tv":0.0,"id":27129637},{"batb":[[1,1.01,1.53],[2,1.01,0]],"ltp":0.0,"tv":0.0,"id":20893387}]}]}
{"op":"mcm","clk":"1346119161","pt":1588194781038,"mc":[{"id":"1.170349309","rc":[{"batb":[[1,1.02,5000],[2,1.01,1.53]],"ltp":0.0,"tv":0.0,"id":24550116},{"batb":[[1,1.02,5000],[2,1.01,1.53]],"ltp":0.0,"tv":0.0,"id":27138257},{"batb":[[1,1.02,5000],[2,1.01,1.53]],"ltp":0.0,"tv":0.0,"id":26357500},{"batb":[[1,1.02,5000],[2,1.01,1.53]],"ltp":0.0,"tv":0.0,"id":27129637},{"batb":[[1,1.02,5000],[2,1.01,1.53]],"ltp":0.0,"tv":0.0,"id":20893387}]}]}
{"op":"mcm","clk":"1346131777","pt":1588195384504,"mc":[{"id":"1.170349309","rc":[{"batb":[[1,1.01,1.53],[2,1.01,0]],"ltp":0.0,"tv":0.0,"id":24550116},{"batb":[[1,1.01,1.53],[2,1.01,0]],"ltp":0.0,"tv":0.0,"id":27138257},{"batb":[[1,1.01,1.53],[2,1.01,0]],"ltp":0.0,"tv":0.0,"id":26357500},{"batb":[[1,1.01,1.53],[2,1.01,0]],"ltp":0.0,"tv":0.0,"id":27129637},{"batb":[[1,1.01,1.53],[2,1.01,0]],"ltp":0.0,"tv":0.0,"id":20893387}]}]}
{"op":"mcm","clk":"1346132099","pt":1588195399545,"mc":[{"id":"1.170349309","rc":[{"batb":[[1,1.02,5000],[2,1.01,1.53]],"ltp":0.0,"tv":0.0,"id":24550116},{"batb":[[1,1.02,5000],[2,1.01,1.53]],"ltp":0.0,"tv":0.0,"id":27138257},{"batb":[[1,1.02,5000],[2,1.01,1.53]],"ltp":0.0,"tv":0.0,"id":26357500},{"batb":[[1,1.02,5000],[2,1.01,1.53]],"ltp":0.0,"tv":0.0,"id":27129637},{"batb":[[1,1.02,5000],[2,1.01,1.53]],"ltp":0.0,"tv":0.0,"id":20893387}]}]}
{"op":"mcm","clk":"1346145749","pt":1588196003041,"mc":[{"id":"1.170349309","rc":[{"batb":[[1,1.01,1.53],[2,1.01,0]],"ltp":0.0,"tv":0.0,"id":24550116},{"batb":[[1,1.01,1.53],[2,1.01,0]],"ltp":0.0,"tv":0.0,"id":27138257},{"batb":[[1,1.01,1.53],[2,1.01,0]],"ltp":0.0,"tv":0.0,"id":26357500},{"batb":[[1,1.01,1.53],[2,1.01,0]],"ltp":0.0,"tv":0.0,"id":27129637},{"batb":[[1,1.01,1.53],[2,1.01,0]],"ltp":0.0,"tv":0.0,"id":20893387}]}]}
{"op":"mcm","clk":"1346145990","pt":1588196018051,"mc":[{"id":"1.170349309","rc":[{"batb":[[1,1.02,5000],[2,1.01,1.53]],"ltp":0.0,"tv":0.0,"id":24550116},{"batb":[[1,1.02,5000],[2,1.01,1.53]],"ltp":0.0,"tv":0.0,"id":27138257},{"batb":[[1,1.02,5000],[2,1.01,1.53]],"ltp":0.0,"tv":0.0,"id":26357500},{"batb":[[1,1.02,5000],[2,1.01,1.53]],"ltp":0.0,"tv":0.0,"id":27129637},{"batb":[[1,1.02,5000],[2,1.01,1.53]],"ltp":0.0,"tv":0.0,"id":20893387}]}]}
{"op":"mcm","clk":"1346157843","pt":1588196621911,"mc":[{"id":"1.170349309","rc":[{"batb":[[1,1.01,1.53],[2,1.01,0]],"ltp":0.0,"tv":0.0,"id":24550116},{"batb":[[1,1.01,1.53],[2,1.01,0]],"ltp":0.0,"tv":0.0,"id":27138257},{"batb":[[1,1.01,1.53],[2,1.01,0]],"ltp":0.0,"tv":0.0,"id":26357500},{"batb":[[1,1.01,1.53],[2,1.01,0]],"ltp":0.0,"tv":0.0,"id":27129637},{"batb":[[1,1.01,1.53],[2,1.01,0]],"ltp":0.0,"tv":0.0,"id":20893387}]}]}
{"op":"mcm","clk":"1346158165","pt":1588196636944,"mc":[{"id":"1.170349309","rc":[{"batb":[[1,1.02,5000],[2,1.01,1.53]],"ltp":0.0,"tv":0.0,"id":24550116},{"batb":[[1,1.02,5000],[2,1.01,1.53]],"ltp":0.0,"tv":0.0,"id":27138257},{"batb":[[1,1.02,5000],[2,1.01,1.53]],"ltp":0.0,"tv":0.0,"id":26357500},{"batb":[[1,1.02,5000],[2,1.01,1.53]],"ltp":0.0,"tv":0.0,"id":27129637},{"batb":[[1,1.02,5000],[2,1.01,1.53]],"ltp":0.0,"tv":0.0,"id":20893387}]}]}
{"op":"mcm","clk":"1346170675","pt":1588197240248,"mc":[{"id":"1.170349309","rc":[{"batb":[[1,1.01,1.53],[2,1.01,0]],"ltp":0.0,"tv":0.0,"id":24550116},{"batb":[[1,1.01,1.53],[2,1.01,0]],"ltp":0.0,"tv":0.0,"id":27138257},{"batb":[[1,1.01,1.53],[2,1.01,0]],"ltp":0.0,"tv":0.0,"id":26357500},{"batb":[[1,1.01,1.53],[2,1.01,0]],"ltp":0.0,"tv":0.0,"id":27129637},{"batb":[[1,1.01,1.53],[2,1.01,0]],"ltp":0.0,"tv":0.0,"id":20893387}]}]}
{"op":"mcm","clk":"1346170885","pt":1588197255266,"mc":[{"id":"1.170349309","rc":[{"batb":[[1,1.02,5000],[2,1.01,1.53]],"ltp":0.0,"tv":0.0,"id":24550116},{"batb":[[1,1.02,5000],[2,1.01,1.53]],"ltp":0.0,"tv":0.0,"id":27138257},{"batb":[[1,1.02,5000],[2,1.01,1.53]],"ltp":0.0,"tv":0.0,"id":26357500},{"batb":[[1,1.02,5000],[2,1.01,1.53]],"ltp":0.0,"tv":0.0,"id":27129637},{"batb":[[1,1.02,5000],[2,1.01,1.53]],"ltp":0.0,"tv":0.0,"id":20893387}]}]}
{"op":"mcm","clk":"1346180878","pt":1588197858892,"mc":[{"id":"1.170349309","rc":[{"batb":[[1,1.01,1.53],[2,1.01,0]],"ltp":0.0,"tv":0.0,"id":24550116},{"batb":[[1,1.01,1.53],[2,1.01,0]],"ltp":0.0,"tv":0.0,"id":27138257},{"batb":[[1,1.01,1.53],[2,1.01,0]],"ltp":0.0,"tv":0.0,"id":26357500},{"batb":[[1,1.01,1.53],[2,1.01,0]],"ltp":0.0,"tv":0.0,"id":27129637},{"batb":[[1,1.01,1.53],[2,1.01,0]],"ltp":0.0,"tv":0.0,"id":20893387}]}]}
{"op":"mcm","clk":"1346181210","pt":1588197873926,"mc":[{"id":"1.170349309","rc":[{"batb":[[1,1.02,5000],[2,1.01,1.53]],"ltp":0.0,"tv":0.0,"id":24550116},{"batb":[[1,1.02,5000],[2,1.01,1.53]],"ltp":0.0,"tv":0.0,"id":27138257},{"batb":[[1,1.02,5000],[2,1.01,1.53]],"ltp":0.0,"tv":0.0,"id":26357500},{"batb":[[1,1.02,5000],[2,1.01,1.53]],"ltp":0.0,"tv":0.0,"id":27129637},{"batb":[[1,1.02,5000],[2,1.01,1.53]],"ltp":0.0,"tv":0.0,"id":20893387}]}]}
{"op":"mcm","clk":"1346194707","pt":1588198477557,"mc":[{"id":"1.170349309","rc":[{"batb":[[1,1.01,1.53],[2,1.01,0]],"ltp":0.0,"tv":0.0,"id":24550116},{"batb":[[1,1.01,1.53],[2,1.01,0]],"ltp":0.0,"tv":0.0,"id":27138257},{"batb":[[1,1.01,1.53],[2,1.01,0]],"ltp":0.0,"tv":0.0,"id":26357500},{"batb":[[1,1.01,1.53],[2,1.01,0]],"ltp":0.0,"tv":0.0,"id":27129637},{"batb":[[1,1.01,1.53],[2,1.01,0]],"ltp":0.0,"tv":0.0,"id":20893387}]}]}
{"op":"mcm","clk":"1346195041","pt":1588198492586,"mc":[{"id":"1.170349309","rc":[{"batb":[[1,1.02,5000],[2,1.01,1.53]],"ltp":0.0,"tv":0.0,"id":24550116},{"batb":[[1,1.02,5000],[2,1.01,1.53]],"ltp":0.0,"tv":0.0,"id":27138257},{"batb":[[1,1.02,5000],[2,1.01,1.53]],"ltp":0.0,"tv":0.0,"id":26357500},{"batb":[[1,1.02,5000],[2,1.01,1.53]],"ltp":0.0,"tv":0.0,"id":27129637},{"batb":[[1,1.02,5000],[2,1.01,1.53]],"ltp":0.0,"tv":0.0,"id":20893387}]}]}
{"op":"mcm","clk":"1346204736","pt":1588199096074,"mc":[{"id":"1.170349309","rc":[{"batb":[[1,1.01,1.53],[2,1.01,0]],"ltp":0.0,"tv":0.0,"id":24550116},{"batb":[[1,1.01,1.53],[2,1.01,0]],"ltp":0.0,"tv":0.0,"id":27138257},{"batb":[[1,1.01,1.53],[2,1.01,0]],"ltp":0.0,"tv":0.0,"id":26357500},{"batb":[[1,1.01,1.53],[2,1.01,0]],"ltp":0.0,"tv":0.0,"id":27129637},{"batb":[[1,1.01,1.53],[2,1.01,0]],"ltp":0.0,"tv":0.0,"id":20893387}]}]}
{"op":"mcm","clk":"1346204945","pt":1588199110964,"mc":[{"id":"1.170349309","rc":[{"batb":[[1,1.02,5000],[2,1.01,1.53]],"ltp":0.0,"tv":0.0,"id":24550116},{"batb":[[1,1.02,5000],[2,1.01,1.53]],"ltp":0.0,"tv":0.0,"id":27138257},{"batb":[[1,1.02,5000],[2,1.01,1.53]],"ltp":0.0,"tv":0.0,"id":26357500},{"batb":[[1,1.02,5000],[2,1.01,1.53]],"ltp":0.0,"tv":0.0,"id":27129637},{"batb":[[1,1.02,5000],[2,1.01,1.53]],"ltp":0.0,"tv":0.0,"id":20893387}]}]}
{"op":"mcm","clk":"1346212642","pt":1588199714759,"mc":[{"id":"1.170349309","rc":[{"batb":[[1,1.01,1.53],[2,1.01,0]],"ltp":0.0,"tv":0.0,"id":24550116},{"batb":[[1,1.01,1.53],[2,1.01,0]],"ltp":0.0,"tv":0.0,"id":27138257},{"batb":[[1,1.01,1.53],[2,1.01,0]],"ltp":0.0,"tv":0.0,"id":26357500},{"batb":[[1,1.01,1.53],[2,1.01,0]],"ltp":0.0,"tv":0.0,"id":27129637},{"batb":[[1,1.01,1.53],[2,1.01,0]],"ltp":0.0,"tv":0.0,"id":20893387}]}]}
{"op":"mcm","clk":"1346212865","pt":1588199729765,"mc":[{"id":"1.170349309","rc":[{"batb":[[1,1.02,5000],[2,1.01,1.53]],"ltp":0.0,"tv":0.0,"id":24550116},{"batb":[[1,1.02,5000],[2,1.01,1.53]],"ltp":0.0,"tv":0.0,"id":27138257},{"batb":[[1,1.02,5000],[2,1.01,1.53]],"ltp":0.0,"tv":0.0,"id":26357500},{"batb":[[1,1.02,5000],[2,1.01,1.53]],"ltp":0.0,"tv":0.0,"id":27129637},{"batb":[[1,1.02,5000],[2,1.01,1.53]],"ltp":0.0,"tv":0.0,"id":20893387}]}]}
{"op":"mcm","clk":"1346221482","pt":1588200333239,"mc":[{"id":"1.170349309","rc":[{"batb":[[1,1.01,1.53],[2,1.01,0]],"ltp":0.0,"tv":0.0,"id":24550116},{"batb":[[1,1.01,1.53],[2,1.01,0]],"ltp":0.0,"tv":0.0,"id":27138257},{"batb":[[1,1.01,1.53],[2,1.01,0]],"ltp":0.0,"tv":0.0,"id":26357500},{"batb":[[1,1.01,1.53],[2,1.01,0]],"ltp":0.0,"tv":0.0,"id":27129637},{"batb":[[1,1.01,1.53],[2,1.01,0]],"ltp":0.0,"tv":0.0,"id":20893387}]}]}
{"op":"mcm","clk":"1346221679","pt":1588200348162,"mc":[{"id":"1.170349309","rc":[{"batb":[[1,1.02,5000],[2,1.01,1.53]],"ltp":0.0,"tv":0.0,"id":24550116},{"batb":[[1,1.02,5000],[2,1.01,1.53]],"ltp":0.0,"tv":0.0,"id":27138257},{"batb":[[1,1.02,5000],[2,1.01,1.53]],"ltp":0.0,"tv":0.0,"id":26357500},{"batb":[[1,1.02,5000],[2,1.01,1.53]],"ltp":0.0,"tv":0.0,"id":27129637},{"batb":[[1,1.02,5000],[2,1.01,1.53]],"ltp":0.0,"tv":0.0,"id":20893387}]}]}
{"op":"mcm","clk":"1346226292","pt":1588200950494,"mc":[{"id":"1.170349309","rc":[{"batb":[[1,1.01,1.53],[2,1.01,0]],"ltp":0.0,"tv":0.0,"id":24550116},{"batb":[[1,1.01,1.53],[2,1.01,0]],"ltp":0.0,"tv":0.0,"id":27138257},{"batb":[[1,1.01,1.53],[2,1.01,0]],"ltp":0.0,"tv":0.0,"id":26357500},{"batb":[[1,1.01,1.53],[2,1.01,0]],"ltp":0.0,"tv":0.0,"id":27129637},{"batb":[[1,1.01,1.53],[2,1.01,0]],"ltp":0.0,"tv":0.0,"id":20893387}]}]}
{"op":"mcm","clk":"1346226349","pt":1588200965622,"mc":[{"id":"1.170349309","rc":[{"batb":[[1,1.02,5000],[2,1.01,1.53]],"ltp":0.0,"tv":0.0,"id":24550116},{"batb":[[1,1.02,5000],[2,1.01,1.53]],"ltp":0.0,"tv":0.0,"id":27138257},{"batb":[[1,1.02,5000],[2,1.01,1.53]],"ltp":0.0,"tv":0.0,"id":26357500},{"batb":[[1,1.02,5000],[2,1.01,1.53]],"ltp":0.0,"tv":0.0,"id":27129637},{"batb":[[1,1.02,5000],[2,1.01,1.53]],"ltp":0.0,"tv":0.0,"id":20893387}]}]}
{"op":"mcm","clk":"1346227974","pt":1588201568771,"mc":[{"id":"1.170349309","rc":[{"batb":[[1,1.01,1.53],[2,1.01,0]],"ltp":0.0,"tv":0.0,"id":24550116},{"batb":[[1,1.01,1.53],[2,1.01,0]],"ltp":0.0,"tv":0.0,"id":27138257},{"batb":[[1,1.01,1.53],[2,1.01,0]],"ltp":0.0,"tv":0.0,"id":26357500},{"batb":[[1,1.01,1.53],[2,1.01,0]],"ltp":0.0,"tv":0.0,"id":27129637},{"batb":[[1,1.01,1.53],[2,1.01,0]],"ltp":0.0,"tv":0.0,"id":20893387}]}]}
{"op":"mcm","clk":"1346228059","pt":1588201583789,"mc":[{"id":"1.170349309","rc":[{"batb":[[1,1.02,5000],[2,1.01,1.53]],"ltp":0.0,"tv":0.0,"id":24550116},{"batb":[[1,1.02,5000],[2,1.01,1.53]],"ltp":0.0,"tv":0.0,"id":27138257},{"batb":[[1,1.02,5000],[2,1.01,1.53]],"ltp":0.0,"tv":0.0,"id":26357500},{"batb":[[1,1.02,5000],[2,1.01,1.53]],"ltp":0.0,"tv":0.0,"id":27129637},{"batb":[[1,1.02,5000],[2,1.01,1.53]],"ltp":0.0,"tv":0.0,"id":20893387}]}]}
{"op":"mcm","clk":"1346230762","pt":1588202186962,"mc":[{"id":"1.170349309","rc":[{"batb":[[1,1.01,1.53],[2,1.01,0]],"ltp":0.0,"tv":0.0,"id":24550116},{"batb":[[1,1.01,1.53],[2,1.01,0]],"ltp":0.0,"tv":0.0,"id":27138257},{"batb":[[1,1.01,1.53],[2,1.01,0]],"ltp":0.0,"tv":0.0,"id":26357500},{"batb":[[1,1.01,1.53],[2,1.01,0]],"ltp":0.0,"tv":0.0,"id":27129637},{"batb":[[1,1.01,1.53],[2,1.01,0]],"ltp":0.0,"tv":0.0,"id":20893387}]}]}
{"op":"mcm","clk":"1346230843","pt":1588202202071,"mc":[{"id":"1.170349309","rc":[{"batb":[[1,1.02,5000],[2,1.01,1.53]],"ltp":0.0,"tv":0.0,"id":24550116},{"batb":[[1,1.02,5000],[2,1.01,1.53]],"ltp":0.0,"tv":0.0,"id":27138257},{"batb":[[1,1.02,5000],[2,1.01,1.53]],"ltp":0.0,"tv":0.0,"id":26357500},{"batb":[[1,1.02,5000],[2,1.01,1.53]],"ltp":0.0,"tv":0.0,"id":27129637},{"batb":[[1,1.02,5000],[2,1.01,1.53]],"ltp":0.0,"tv":0.0,"id":20893387}]}]}
{"op":"mcm","clk":"1346233903","pt":1588202804844,"mc":[{"id":"1.170349309","rc":[{"batb":[[1,1.01,1.53],[2,1.01,0]],"ltp":0.0,"tv":0.0,"id":24550116},{"batb":[[1,1.01,1.53],[2,1.01,0]],"ltp":0.0,"tv":0.0,"id":27138257},{"batb":[[1,1.01,1.53],[2,1.01,0]],"ltp":0.0,"tv":0.0,"id":26357500},{"batb":[[1,1.01,1.53],[2,1.01,0]],"ltp":0.0,"tv":0.0,"id":27129637},{"batb":[[1,1.01,1.53],[2,1.01,0]],"ltp":0.0,"tv":0.0,"id":20893387}]}]}
{"op":"mcm","clk":"1346233970","pt":1588202819868,"mc":[{"id":"1.170349309","rc":[{"batb":[[1,1.02,5000],[2,1.01,1.53]],"ltp":0.0,"tv":0.0,"id":24550116},{"batb":[[1,1.02,5000],[2,1.01,1.53]],"ltp":0.0,"tv":0.0,"id":27138257},{"batb":[[1,1.02,5000],[2,1.01,1.53]],"ltp":0.0,"tv":0.0,"id":26357500},{"batb":[[1,1.02,5000],[2,1.01,1.53]],"ltp":0.0,"tv":0.0,"id":27129637},{"batb":[[1,1.02,5000],[2,1.01,1.53]],"ltp":0.0,"tv":0.0,"id":20893387}]}]}
{"op":"mcm","clk":"1346237391","pt":1588203422664,"mc":[{"id":"1.170349309","rc":[{"batb":[[1,1.01,1.53],[2,1.01,0]],"ltp":0.0,"tv":0.0,"id":24550116},{"batb":[[1,1.01,1.53],[2,1.01,0]],"ltp":0.0,"tv":0.0,"id":27138257},{"batb":[[1,1.01,1.53],[2,1.01,0]],"ltp":0.0,"tv":0.0,"id":26357500},{"batb":[[1,1.01,1.53],[2,1.01,0]],"ltp":0.0,"tv":0.0,"id":27129637},{"batb":[[1,1.01,1.53],[2,1.01,0]],"ltp":0.0,"tv":0.0,"id":20893387}]}]}
{"op":"mcm","clk":"1346237459","pt":1588203437755,"mc":[{"id":"1.170349309","rc":[{"batb":[[1,1.02,5000],[2,1.01,1.53]],"ltp":0.0,"tv":0.0,"id":24550116},{"batb":[[1,1.02,5000],[2,1.01,1.53]],"ltp":0.0,"tv":0.0,"id":27138257},{"batb":[[1,1.02,5000],[2,1.01,1.53]],"ltp":0.0,"tv":0.0,"id":26357500},{"batb":[[1,1.02,5000],[2,1.01,1.53]],"ltp":0.0,"tv":0.0,"id":27129637},{"batb":[[1,1.02,5000],[2,1.01,1.53]],"ltp":0.0,"tv":0.0,"id":20893387}]}]}
{"op":"mcm","clk":"1346243033","pt":1588204040654,"mc":[{"id":"1.170349309","rc":[{"batb":[[1,1.01,1.53],[2,1.01,0]],"ltp":0.0,"tv":0.0,"id":24550116},{"batb":[[1,1.01,1.53],[2,1.01,0]],"ltp":0.0,"tv":0.0,"id":27138257},{"batb":[[1,1.01,1.53],[2,1.01,0]],"ltp":0.0,"tv":0.0,"id":26357500},{"batb":[[1,1.01,1.53],[2,1.01,0]],"ltp":0.0,"tv":0.0,"id":27129637},{"batb":[[1,1.01,1.53],[2,1.01,0]],"ltp":0.0,"tv":0.0,"id":20893387}]}]}
{"op":"mcm","clk":"1346243181","pt":1588204055628,"mc":[{"id":"1.170349309","rc":[{"batb":[[1,1.02,5000],[2,1.01,1.53]],"ltp":0.0,"tv":0.0,"id":24550116},{"batb":[[1,1.02,5000],[2,1.01,1.53]],"ltp":0.0,"tv":0.0,"id":27138257},{"batb":[[1,1.02,5000],[2,1.01,1.53]],"ltp":0.0,"tv":0.0,"id":26357500},{"batb":[[1,1.02,5000],[2,1.01,1.53]],"ltp":0.0,"tv":0.0,"id":27129637},{"batb":[[1,1.02,5000],[2,1.01,1.53]],"ltp":0.0,"tv":0.0,"id":20893387}]}]}
{"op":"mcm","clk":"1346247414","pt":1588204658220,"mc":[{"id":"1.170349309","rc":[{"batb":[[1,1.01,1.53],[2,1.01,0]],"ltp":0.0,"tv":0.0,"id":24550116},{"batb":[[1,1.01,1.53],[2,1.01,0]],"ltp":0.0,"tv":0.0,"id":27138257},{"batb":[[1,1.01,1.53],[2,1.01,0]],"ltp":0.0,"tv":0.0,"id":26357500},{"batb":[[1,1.01,1.53],[2,1.01,0]],"ltp":0.0,"tv":0.0,"id":27129637},{"batb":[[1,1.01,1.53],[2,1.01,0]],"ltp":0.0,"tv":0.0,"id":20893387}]}]}
{"op":"mcm","clk":"1346247475","pt":1588204673360,"mc":[{"id":"1.170349309","rc":[{"batb":[[1,1.02,5000],[2,1.01,1.53]],"ltp":0.0,"tv":0.0,"id":24550116},{"batb":[[1,1.02,5000],[2,1.01,1.53]],"ltp":0.0,"tv":0.0,"id":27138257},{"batb":[[1,1.02,5000],[2,1.01,1.53]],"ltp":0.0,"tv":0.0,"id":26357500},{"batb":[[1,1.02,5000],[2,1.01,1.53]],"ltp":0.0,"tv":0.0,"id":27129637},{"batb":[[1,1.02,5000],[2,1.01,1.53]],"ltp":0.0,"tv":0.0,"id":20893387}]}]}
{"op":"mcm","clk":"1346250981","pt":1588205276430,"mc":[{"id":"1.170349309","rc":[{"batb":[[1,1.01,1.53],[2,1.01,0]],"ltp":0.0,"tv":0.0,"id":24550116},{"batb":[[1,1.01,1.53],[2,1.01,0]],"ltp":0.0,"tv":0.0,"id":27138257},{"batb":[[1,1.01,1.53],[2,1.01,0]],"ltp":0.0,"tv":0.0,"id":26357500},{"batb":[[1,1.01,1.53],[2,1.01,0]],"ltp":0.0,"tv":0.0,"id":27129637},{"batb":[[1,1.01,1.53],[2,1.01,0]],"ltp":0.0,"tv":0.0,"id":20893387}]}]}
{"op":"mcm","clk":"1346251086","pt":1588205291446,"mc":[{"id":"1.170349309","rc":[{"batb":[[1,1.02,5000],[2,1.01,1.53]],"ltp":0.0,"tv":0.0,"id":24550116},{"batb":[[1,1.02,5000],[2,1.01,1.53]],"ltp":0.0,"tv":0.0,"id":27138257},{"batb":[[1,1.02,5000],[2,1.01,1.53]],"ltp":0.0,"tv":0.0,"id":26357500},{"batb":[[1,1.02,5000],[2,1.01,1.53]],"ltp":0.0,"tv":0.0,"id":27129637},{"batb":[[1,1.02,5000],[2,1.01,1.53]],"ltp":0.0,"tv":0.0,"id":20893387}]}]}
{"op":"mcm","clk":"1346255808","pt":1588205894258,"mc":[{"id":"1.170349309","rc":[{"batb":[[1,1.01,1.53],[2,1.01,0]],"ltp":0.0,"tv":0.0,"id":24550116},{"batb":[[1,1.01,1.53],[2,1.01,0]],"ltp":0.0,"tv":0.0,"id":27138257},{"batb":[[1,1.01,1.53],[2,1.01,0]],"ltp":0.0,"tv":0.0,"id":26357500},{"batb":[[1,1.01,1.53],[2,1.01,0]],"ltp":0.0,"tv":0.0,"id":27129637},{"batb":[[1,1.01,1.53],[2,1.01,0]],"ltp":0.0,"tv":0.0,"id":20893387}]}]}
{"op":"mcm","clk":"1346255915","pt":1588205909281,"mc":[{"id":"1.170349309","rc":[{"batb":[[1,1.02,5000],[2,1.01,1.53]],"ltp":0.0,"tv":0.0,"id":24550116},{"batb":[[1,1.02,5000],[2,1.01,1.53]],"ltp":0.0,"tv":0.0,"id":27138257},{"batb":[[1,1.02,5000],[2,1.01,1.53]],"ltp":0.0,"tv":0.0,"id":26357500},{"batb":[[1,1.02,5000],[2,1.01,1.53]],"ltp":0.0,"tv":0.0,"id":27129637},{"batb":[[1,1.02,5000],[2,1.01,1.53]],"ltp":0.0,"tv":0.0,"id":20893387}]}]}
{"op":"mcm","clk":"1346260058","pt":1588206511998,"mc":[{"id":"1.170349309","rc":[{"batb":[[1,1.01,1.53],[2,1.01,0]],"ltp":0.0,"tv":0.0,"id":24550116},{"batb":[[1,1.01,1.53],[2,1.01,0]],"ltp":0.0,"tv":0.0,"id":27138257},{"batb":[[1,1.01,1.53],[2,1.01,0]],"ltp":0.0,"tv":0.0,"id":26357500},{"batb":[[1,1.01,1.53],[2,1.01,0]],"ltp":0.0,"tv":0.0,"id":27129637},{"batb":[[1,1.01,1.53],[2,1.01,0]],"ltp":0.0,"tv":0.0,"id":20893387}]}]}
{"op":"mcm","clk":"1346260153","pt":1588206527015,"mc":[{"id":"1.170349309","rc":[{"batb":[[1,1.02,5000],[2,1.01,1.53]],"ltp":0.0,"tv":0.0,"id":24550116},{"batb":[[1,1.02,5000],[2,1.01,1.53]],"ltp":0.0,"tv":0.0,"id":27138257},{"batb":[[1,1.02,5000],[2,1.01,1.53]],"ltp":0.0,"tv":0.0,"id":26357500},{"batb":[[1,1.02,5000],[2,1.01,1.53]],"ltp":0.0,"tv":0.0,"id":27129637},{"batb":[[1,1.02,5000],[2,1.01,1.53]],"ltp":0.0,"tv":0.0,"id":20893387}]}]}
{"op":"mcm","clk":"1346265096","pt":1588207130162,"mc":[{"id":"1.170349309","rc":[{"batb":[[1,1.01,1.53],[2,1.01,0]],"ltp":0.0,"tv":0.0,"id":24550116},{"batb":[[1,1.01,1.53],[2,1.01,0]],"ltp":0.0,"tv":0.0,"id":27138257},{"batb":[[1,1.01,1.53],[2,1.01,0]],"ltp":0.0,"tv":0.0,"id":26357500},{"batb":[[1,1.01,1.53],[2,1.01,0]],"ltp":0.0,"tv":0.0,"id":27129637},{"batb":[[1,1.01,1.53],[2,1.01,0]],"ltp":0.0,"tv":0.0,"id":20893387}]}]}
{"op":"mcm","clk":"1346265194","pt":1588207145199,"mc":[{"id":"1.170349309","rc":[{"batb":[[1,1.02,5000],[2,1.01,1.53]],"ltp":0.0,"tv":0.0,"id":24550116},{"batb":[[1,1.02,5000],[2,1.01,1.53]],"ltp":0.0,"tv":0.0,"id":27138257},{"batb":[[1,1.02,5000],[2,1.01,1.53]],"ltp":0.0,"tv":0.0,"id":26357500},{"batb":[[1,1.02,5000],[2,1.01,1.53]],"ltp":0.0,"tv":0.0,"id":27129637},{"batb":[[1,1.02,5000],[2,1.01,1.53]],"ltp":0.0,"tv":0.0,"id":20893387}]}]}
{"op":"mcm","clk":"1346273778","pt":1588207748417,"mc":[{"id":"1.170349309","rc":[{"batb":[[1,1.01,1.53],[2,1.01,0]],"ltp":0.0,"tv":0.0,"id":24550116},{"batb":[[1,1.01,1.53],[2,1.01,0]],"ltp":0.0,"tv":0.0,"id":27138257},{"batb":[[1,1.01,1.53],[2,1.01,0]],"ltp":0.0,"tv":0.0,"id":26357500},{"batb":[[1,1.01,1.53],[2,1.01,0]],"ltp":0.0,"tv":0.0,"id":27129637},{"batb":[[1,1.01,1.53],[2,1.01,0]],"ltp":0.0,"tv":0.0,"id":20893387}]}]}
{"op":"mcm","clk":"1346274024","pt":1588207763452,"mc":[{"id":"1.170349309","rc":[{"batb":[[1,1.02,5000],[2,1.01,1.53]],"ltp":0.0,"tv":0.0,"id":24550116},{"batb":[[1,1.02,5000],[2,1.01,1.53]],"ltp":0.0,"tv":0.0,"id":27138257},{"batb":[[1,1.02,5000],[2,1.01,1.53]],"ltp":0.0,"tv":0.0,"id":26357500},{"batb":[[1,1.02,5000],[2,1.01,1.53]],"ltp":0.0,"tv":0.0,"id":27129637},{"batb":[[1,1.02,5000],[2,1.01,1.53]],"ltp":0.0,"tv":0.0,"id":20893387}]}]}
{"op":"mcm","clk":"1346284143","pt":1588208366143,"mc":[{"id":"1.170349309","rc":[{"batb":[[1,1.01,1.53],[2,1.01,0]],"ltp":0.0,"tv":0.0,"id":24550116},{"batb":[[1,1.01,1.53],[2,1.01,0]],"ltp":0.0,"tv":0.0,"id":27138257},{"batb":[[1,1.01,1.53],[2,1.01,0]],"ltp":0.0,"tv":0.0,"id":26357500},{"batb":[[1,1.01,1.53],[2,1.01,0]],"ltp":0.0,"tv":0.0,"id":27129637},{"batb":[[1,1.01,1.53],[2,1.01,0]],"ltp":0.0,"tv":0.0,"id":20893387}]}]}
{"op":"mcm","clk":"1346284358","pt":1588208381276,"mc":[{"id":"1.170349309","rc":[{"batb":[[1,1.02,5000],[2,1.01,1.53]],"ltp":0.0,"tv":0.0,"id":24550116},{"batb":[[1,1.02,5000],[2,1.01,1.53]],"ltp":0.0,"tv":0.0,"id":27138257},{"batb":[[1,1.02,5000],[2,1.01,1.53]],"ltp":0.0,"tv":0.0,"id":26357500},{"batb":[[1,1.02,5000],[2,1.01,1.53]],"ltp":0.0,"tv":0.0,"id":27129637},{"batb":[[1,1.02,5000],[2,1.01,1.53]],"ltp":0.0,"tv":0.0,"id":20893387}]}]}
{"op":"mcm","clk":"1346297548","pt":1588208959484,"mc":[{"id":"1.170349309","rc":[{"batb":[[2,1.01,1.53]],"batl":[[0,1000,1.52]],"ltp":0.0,"tv":0.0,"id":24550116},{"trd":[[1.09,203.49]],"batb":[[1,1.01,1.53]],"batl":[[1,1000,1.53]],"ltp":1.09,"tv":203.48,"id":27376858},{"batb":[[2,1.01,1.53]],"batl":[[0,1000,1.53]],"ltp":0.0,"tv":0.0,"id":27138257},{"batb":[[1,1.01,1.53]],"batl":[[1,1000,1.53]],"ltp":1.28,"tv":160.0,"id":27661463},{"batb":[[2,1.01,1.53]],"batl":[[1,1000,1.55]],"ltp":0.0,"tv":0.0,"id":26357500},{"batb":[[2,1.01,1.53]],"batl":[[0,1000,1.52]],"ltp":0.0,"tv":0.0,"id":27129637},{"batb":[[1,1.01,1.53]],"batl":[[1,1000,1.53]],"ltp":7.4,"tv":4.0,"id":26148884},{"batb":[[2,1.01,1.53]],"batl":[[0,1000,1.57]],"ltp":0.0,"tv":0.0,"id":20893387}],"tv":367.48}]}
{"op":"mcm","clk":"1346298590","pt":1588208984162,"mc":[{"id":"1.170349309","rc":[{"batb":[[1,1.01,1.53],[2,1.01,0]],"ltp":0.0,"tv":0.0,"id":24550116},{"batb":[[1,1.01,1.53],[2,1.01,0]],"ltp":0.0,"tv":0.0,"id":27138257},{"batb":[[1,1.01,1.53],[2,1.01,0]],"ltp":0.0,"tv":0.0,"id":26357500},{"batb":[[1,1.01,1.53],[2,1.01,0]],"ltp":0.0,"tv":0.0,"id":27129637},{"batb":[[1,1.01,1.53],[2,1.01,0]],"ltp":0.0,"tv":0.0,"id":20893387}]}]}
{"op":"mcm","clk":"1346298913","pt":1588208999274,"mc":[{"id":"1.170349309","rc":[{"batb":[[1,1.02,5000],[2,1.01,1.53]],"ltp":0.0,"tv":0.0,"id":24550116},{"batb":[[1,1.02,5000],[2,1.01,1.53]],"ltp":0.0,"tv":0.0,"id":27138257},{"batb":[[1,1.02,5000],[2,1.01,1.53]],"ltp":0.0,"tv":0.0,"id":26357500},{"batb":[[1,1.02,5000],[2,1.01,1.53]],"ltp":0.0,"tv":0.0,"id":27129637},{"batb":[[1,1.02,5000],[2,1.01,1.53]],"ltp":0.0,"tv":0.0,"id":20893387}]}]}
{"op":"mcm","clk":"1346320042","pt":1588209963860,"mc":[{"id":"1.170349309","rc":[{"batb":[[1,1.01,1.53],[2,1.01,0]],"ltp":0.0,"tv":0.0,"id":24550116},{"batb":[[1,1.01,1.53],[2,1.01,0]],"ltp":0.0,"tv":0.0,"id":27138257},{"batb":[[1,1.01,1.53],[2,1.01,0]],"ltp":0.0,"tv":0.0,"id":26357500},{"batb":[[1,1.01,1.53],[2,1.01,0]],"ltp":0.0,"tv":0.0,"id":27129637},{"batb":[[1,1.01,1.53],[2,1.01,0]],"ltp":0.0,"tv":0.0,"id":20893387}]}]}
{"op":"mcm","clk":"1346320356","pt":1588209978801,"mc":[{"id":"1.170349309","rc":[{"batb":[[1,1.02,5000],[2,1.01,1.53]],"ltp":0.0,"tv":0.0,"id":24550116},{"batb":[[1,1.02,5000],[2,1.01,1.53]],"ltp":0.0,"tv":0.0,"id":27138257},{"batb":[[1,1.02,5000],[2,1.01,1.53]],"ltp":0.0,"tv":0.0,"id":26357500},{"batb":[[1,1.02,5000],[2,1.01,1.53]],"ltp":0.0,"tv":0.0,"id":27129637},{"batb":[[1,1.02,5000],[2,1.01,1.53]],"ltp":0.0,"tv":0.0,"id":20893387}]}]}
{"op":"mcm","clk":"1346332020","pt":1588210581234,"mc":[{"id":"1.170349309","rc":[{"batb":[[1,1.01,1.53],[2,1.01,0]],"ltp":0.0,"tv":0.0,"id":24550116},{"batb":[[1,1.01,1.53],[2,1.01,0]],"ltp":0.0,"tv":0.0,"id":27138257},{"batb":[[1,1.01,1.53],[2,1.01,0]],"ltp":0.0,"tv":0.0,"id":26357500},{"batb":[[1,1.01,1.53],[2,1.01,0]],"ltp":0.0,"tv":0.0,"id":27129637},{"batb":[[1,1.01,1.53],[2,1.01,0]],"ltp":0.0,"tv":0.0,"id":20893387}]}]}
{"op":"mcm","clk":"1346332310","pt":1588210596131,"mc":[{"id":"1.170349309","rc":[{"batb":[[1,1.02,5000],[2,1.01,1.53]],"ltp":0.0,"tv":0.0,"id":24550116},{"batb":[[1,1.02,5000],[2,1.01,1.53]],"ltp":0.0,"tv":0.0,"id":27138257},{"batb":[[1,1.02,5000],[2,1.01,1.53]],"ltp":0.0,"tv":0.0,"id":26357500},{"batb":[[1,1.02,5000],[2,1.01,1.53]],"ltp":0.0,"tv":0.0,"id":27129637},{"batb":[[1,1.02,5000],[2,1.01,1.53]],"ltp":0.0,"tv":0.0,"id":20893387}]}]}
{"op":"mcm","clk":"1346344038","pt":1588211199261,"mc":[{"id":"1.170349309","rc":[{"batb":[[1,1.01,1.53],[2,1.01,0]],"ltp":0.0,"tv":0.0,"id":24550116},{"batb":[[1,1.01,1.53],[2,1.01,0]],"ltp":0.0,"tv":0.0,"id":27138257},{"batb":[[1,1.01,1.53],[2,1.01,0]],"ltp":0.0,"tv":0.0,"id":26357500},{"batb":[[1,1.01,1.53],[2,1.01,0]],"ltp":0.0,"tv":0.0,"id":27129637},{"batb":[[1,1.01,1.53],[2,1.01,0]],"ltp":0.0,"tv":0.0,"id":20893387}]}]}
{"op":"mcm","clk":"1346344349","pt":1588211214294,"mc":[{"id":"1.170349309","rc":[{"batb":[[1,1.02,5000],[2,1.01,1.53]],"ltp":0.0,"tv":0.0,"id":24550116},{"batb":[[1,1.02,5000],[2,1.01,1.53]],"ltp":0.0,"tv":0.0,"id":27138257},{"batb":[[1,1.02,5000],[2,1.01,1.53]],"ltp":0.0,"tv":0.0,"id":26357500},{"batb":[[1,1.02,5000],[2,1.01,1.53]],"ltp":0.0,"tv":0.0,"id":27129637},{"batb":[[1,1.02,5000],[2,1.01,1.53]],"ltp":0.0,"tv":0.0,"id":20893387}]}]}
{"op":"mcm","clk":"1346354417","pt":1588211817270,"mc":[{"id":"1.170349309","rc":[{"batb":[[1,1.01,1.53],[2,1.01,0]],"ltp":0.0,"tv":0.0,"id":24550116},{"batb":[[1,1.01,1.53],[2,1.01,0]],"ltp":0.0,"tv":0.0,"id":27138257},{"batb":[[1,1.01,1.53],[2,1.01,0]],"ltp":0.0,"tv":0.0,"id":26357500},{"batb":[[1,1.01,1.53],[2,1.01,0]],"ltp":0.0,"tv":0.0,"id":27129637},{"batb":[[1,1.01,1.53],[2,1.01,0]],"ltp":0.0,"tv":0.0,"id":20893387}]}]}
{"op":"mcm","clk":"1346354709","pt":1588211832266,"mc":[{"id":"1.170349309","rc":[{"batb":[[1,1.02,5000],[2,1.01,1.53]],"ltp":0.0,"tv":0.0,"id":24550116},{"batb":[[1,1.02,5000],[2,1.01,1.53]],"ltp":0.0,"tv":0.0,"id":27138257},{"batb":[[1,1.02,5000],[2,1.01,1.53]],"ltp":0.0,"tv":0.0,"id":26357500},{"batb":[[1,1.02,5000],[2,1.01,1.53]],"ltp":0.0,"tv":0.0,"id":27129637},{"batb":[[1,1.02,5000],[2,1.01,1.53]],"ltp":0.0,"tv":0.0,"id":20893387}]}]}
{"op":"mcm","clk":"1346367460","pt":1588212435063,"mc":[{"id":"1.170349309","rc":[{"batb":[[1,1.01,1.53],[2,1.01,0]],"ltp":0.0,"tv":0.0,"id":24550116},{"batb":[[1,1.01,1.53],[2,1.01,0]],"ltp":0.0,"tv":0.0,"id":27138257},{"batb":[[1,1.01,1.53],[2,1.01,0]],"ltp":0.0,"tv":0.0,"id":26357500},{"batb":[[1,1.01,1.53],[2,1.01,0]],"ltp":0.0,"tv":0.0,"id":27129637},{"batb":[[1,1.01,1.53],[2,1.01,0]],"ltp":0.0,"tv":0.0,"id":20893387}]}]}
{"op":"mcm","clk":"1346367811","pt":1588212450018,"mc":[{"id":"1.170349309","rc":[{"batb":[[1,1.02,5000],[2,1.01,1.53]],"ltp":0.0,"tv":0.0,"id":24550116},{"batb":[[1,1.02,5000],[2,1.01,1.53]],"ltp":0.0,"tv":0.0,"id":27138257},{"batb":[[1,1.02,5000],[2,1.01,1.53]],"ltp":0.0,"tv":0.0,"id":26357500},{"batb":[[1,1.02,5000],[2,1.01,1.53]],"ltp":0.0,"tv":0.0,"id":27129637},{"batb":[[1,1.02,5000],[2,1.01,1.53]],"ltp":0.0,"tv":0.0,"id":20893387}]}]}
{"op":"mcm","clk":"1346381507","pt":1588213052713,"mc":[{"id":"1.170349309","rc":[{"batb":[[1,1.01,1.53],[2,1.01,0]],"ltp":0.0,"tv":0.0,"id":24550116},{"batb":[[1,1.01,1.53],[2,1.01,0]],"ltp":0.0,"tv":0.0,"id":27138257},{"batb":[[1,1.01,1.53],[2,1.01,0]],"ltp":0.0,"tv":0.0,"id":26357500},{"batb":[[1,1.01,1.53],[2,1.01,0]],"ltp":0.0,"tv":0.0,"id":27129637},{"batb":[[1,1.01,1.53],[2,1.01,0]],"ltp":0.0,"tv":0.0,"id":20893387}]}]}
{"op":"mcm","clk":"1346381829","pt":1588213067632,"mc":[{"id":"1.170349309","rc":[{"batb":[[1,1.02,5000],[2,1.01,1.53]],"ltp":0.0,"tv":0.0,"id":24550116},{"batb":[[1,1.02,5000],[2,1.01,1.53]],"ltp":0.0,"tv":0.0,"id":27138257},{"batb":[[1,1.02,5000],[2,1.01,1.53]],"ltp":0.0,"tv":0.0,"id":26357500},{"batb":[[1,1.02,5000],[2,1.01,1.53]],"ltp":0.0,"tv":0.0,"id":27129637},{"batb":[[1,1.02,5000],[2,1.01,1.53]],"ltp":0.0,"tv":0.0,"id":20893387}]}]}
{"op":"mcm","clk":"1346394628","pt":1588213670125,"mc":[{"id":"1.170349309","rc":[{"batb":[[1,1.01,1.53],[2,1.01,0]],"ltp":0.0,"tv":0.0,"id":24550116},{"batb":[[1,1.01,1.53],[2,1.01,0]],"ltp":0.0,"tv":0.0,"id":27138257},{"batb":[[1,1.01,1.53],[2,1.01,0]],"ltp":0.0,"tv":0.0,"id":26357500},{"batb":[[1,1.01,1.53],[2,1.01,0]],"ltp":0.0,"tv":0.0,"id":27129637},{"batb":[[1,1.01,1.53],[2,1.01,0]],"ltp":0.0,"tv":0.0,"id":20893387}]}]}
{"op":"mcm","clk":"1346394929","pt":1588213685164,"mc":[{"id":"1.170349309","rc":[{"batb":[[1,1.02,5000],[2,1.01,1.53]],"ltp":0.0,"tv":0.0,"id":24550116},{"batb":[[1,1.02,5000],[2,1.01,1.53]],"ltp":0.0,"tv":0.0,"id":27138257},{"batb":[[1,1.02,5000],[2,1.01,1.53]],"ltp":0.0,"tv":0.0,"id":26357500},{"batb":[[1,1.02,5000],[2,1.01,1.53]],"ltp":0.0,"tv":0.0,"id":27129637},{"batb":[[1,1.02,5000],[2,1.01,1.53]],"ltp":0.0,"tv":0.0,"id":20893387}]}]}
{"op":"mcm","clk":"1346407264","pt":1588214287642,"mc":[{"id":"1.170349309","rc":[{"batb":[[1,1.01,1.53],[2,1.01,0]],"ltp":0.0,"tv":0.0,"id":24550116},{"batb":[[1,1.01,1.53],[2,1.01,0]],"ltp":0.0,"tv":0.0,"id":27138257},{"batb":[[1,1.01,1.53],[2,1.01,0]],"ltp":0.0,"tv":0.0,"id":26357500},{"batb":[[1,1.01,1.53],[2,1.01,0]],"ltp":0.0,"tv":0.0,"id":27129637},{"batb":[[1,1.01,1.53],[2,1.01,0]],"ltp":0.0,"tv":0.0,"id":20893387}]}]}
{"op":"mcm","clk":"1346407603","pt":1588214302661,"mc":[{"id":"1.170349309","rc":[{"batb":[[1,1.02,5000],[2,1.01,1.53]],"ltp":0.0,"tv":0.0,"id":24550116},{"batb":[[1,1.02,5000],[2,1.01,1.53]],"ltp":0.0,"tv":0.0,"id":27138257},{"batb":[[1,1.02,5000],[2,1.01,1.53]],"ltp":0.0,"tv":0.0,"id":26357500},{"batb":[[1,1.02,5000],[2,1.01,1.53]],"ltp":0.0,"tv":0.0,"id":27129637},{"batb":[[1,1.02,5000],[2,1.01,1.53]],"ltp":0.0,"tv":0.0,"id":20893387}]}]}
{"op":"mcm","clk":"1346417805","pt":1588214905729,"mc":[{"id":"1.170349309","rc":[{"batb":[[1,1.01,1.53],[2,1.01,0]],"ltp":0.0,"tv":0.0,"id":24550116},{"batb":[[1,1.01,1.53],[2,1.01,0]],"ltp":0.0,"tv":0.0,"id":27138257},{"batb":[[1,1.01,1.53],[2,1.01,0]],"ltp":0.0,"tv":0.0,"id":26357500},{"batb":[[1,1.01,1.53],[2,1.01,0]],"ltp":0.0,"tv":0.0,"id":27129637},{"batb":[[1,1.01,1.53],[2,1.01,0]],"ltp":0.0,"tv":0.0,"id":20893387}]}]}
{"op":"mcm","clk":"1346418111","pt":1588214920726,"mc":[{"id":"1.170349309","rc":[{"batb":[[1,1.02,5000],[2,1.01,1.53]],"ltp":0.0,"tv":0.0,"id":24550116},{"batb":[[1,1.02,5000],[2,1.01,1.53]],"ltp":0.0,"tv":0.0,"id":27138257},{"batb":[[1,1.02,5000],[2,1.01,1.53]],"ltp":0.0,"tv":0.0,"id":26357500},{"batb":[[1,1.02,5000],[2,1.01,1.53]],"ltp":0.0,"tv":0.0,"id":27129637},{"batb":[[1,1.02,5000],[2,1.01,1.53]],"ltp":0.0,"tv":0.0,"id":20893387}]}]}
{"op":"mcm","clk":"1346429883","pt":1588215523776,"mc":[{"id":"1.170349309","rc":[{"batb":[[1,1.01,1.53],[2,1.01,0]],"ltp":0.0,"tv":0.0,"id":24550116},{"batb":[[1,1.01,1.53],[2,1.01,0]],"ltp":0.0,"tv":0.0,"id":27138257},{"batb":[[1,1.01,1.53],[2,1.01,0]],"ltp":0.0,"tv":0.0,"id":26357500},{"batb":[[1,1.01,1.53],[2,1.01,0]],"ltp":0.0,"tv":0.0,"id":27129637},{"batb":[[1,1.01,1.53],[2,1.01,0]],"ltp":0.0,"tv":0.0,"id":20893387}]}]}
{"op":"mcm","clk":"1346430213","pt":1588215538726,"mc":[{"id":"1.170349309","rc":[{"batb":[[1,1.02,5000],[2,1.01,1.53]],"ltp":0.0,"tv":0.0,"id":24550116},{"batb":[[1,1.02,5000],[2,1.01,1.53]],"ltp":0.0,"tv":0.0,"id":27138257},{"batb":[[1,1.02,5000],[2,1.01,1.53]],"ltp":0.0,"tv":0.0,"id":26357500},{"batb":[[1,1.02,5000],[2,1.01,1.53]],"ltp":0.0,"tv":0.0,"id":27129637},{"batb":[[1,1.02,5000],[2,1.01,1.53]],"ltp":0.0,"tv":0.0,"id":20893387}]}]}
{"op":"mcm","clk":"1346439690","pt":1588216141519,"mc":[{"id":"1.170349309","rc":[{"batb":[[1,1.01,1.53],[2,1.01,0]],"ltp":0.0,"tv":0.0,"id":24550116},{"batb":[[1,1.01,1.53]],"ltp":1.09,"tv":203.48,"id":27376858},{"batb":[[1,1.01,1.53],[2,1.01,0]],"ltp":0.0,"tv":0.0,"id":27138257},{"batb":[[1,1.01,1.53]],"ltp":1.28,"tv":160.0,"id":27661463},{"batb":[[1,1.01,1.53],[2,1.01,0]],"ltp":0.0,"tv":0.0,"id":26357500},{"batb":[[1,1.01,1.53],[2,1.01,0]],"ltp":0.0,"tv":0.0,"id":27129637},{"batb":[[1,1.01,1.53]],"ltp":7.4,"tv":4.0,"id":26148884},{"batb":[[1,1.01,1.53],[2,1.01,0]],"batl":[[0,1000,1.57]],"ltp":0.0,"tv":0.0,"id":20893387}]}]}
{"op":"mcm","clk":"1346439920","pt":1588216156555,"mc":[{"id":"1.170349309","rc":[{"batb":[[1,1.02,5000],[2,1.01,1.53]],"ltp":0.0,"tv":0.0,"id":24550116},{"batb":[[1,1.02,5000],[2,1.01,1.53]],"ltp":0.0,"tv":0.0,"id":27138257},{"batb":[[1,1.02,5000],[2,1.01,1.53]],"ltp":0.0,"tv":0.0,"id":26357500},{"batb":[[1,1.02,5000],[2,1.01,1.53]],"ltp":0.0,"tv":0.0,"id":27129637},{"batb":[[1,1.02,5000],[2,1.01,1.53]],"ltp":0.0,"tv":0.0,"id":20893387}]}]}
{"op":"mcm","clk":"1346450373","pt":1588216759309,"mc":[{"id":"1.170349309","rc":[{"batb":[[1,1.01,1.53],[2,1.01,0]],"ltp":0.0,"tv":0.0,"id":24550116},{"batb":[[1,1.01,1.53],[2,1.01,0]],"ltp":0.0,"tv":0.0,"id":27138257},{"batb":[[1,1.01,1.53],[2,1.01,0]],"ltp":0.0,"tv":0.0,"id":26357500},{"batb":[[1,1.01,1.53],[2,1.01,0]],"ltp":0.0,"tv":0.0,"id":27129637},{"batb":[[1,1.01,1.53],[2,1.01,0]],"ltp":0.0,"tv":0.0,"id":20893387}]}]}
{"op":"mcm","clk":"1346450571","pt":1588216774331,"mc":[{"id":"1.170349309","rc":[{"batb":[[1,1.02,5000],[2,1.01,1.53]],"ltp":0.0,"tv":0.0,"id":24550116},{"batb":[[1,1.02,5000],[2,1.01,1.53]],"ltp":0.0,"tv":0.0,"id":27138257},{"batb":[[1,1.02,5000],[2,1.01,1.53]],"ltp":0.0,"tv":0.0,"id":26357500},{"batb":[[1,1.02,5000],[2,1.01,1.53]],"ltp":0.0,"tv":0.0,"id":27129637},{"batb":[[1,1.02,5000],[2,1.01,1.53]],"ltp":0.0,"tv":0.0,"id":20893387}]}]}
{"op":"mcm","clk":"1346457590","pt":1588217377339,"mc":[{"id":"1.170349309","rc":[{"batb":[[1,1.01,1.53],[2,1.01,0]],"ltp":0.0,"tv":0.0,"id":24550116},{"batb":[[1,1.01,1.53],[2,1.01,0]],"ltp":0.0,"tv":0.0,"id":27138257},{"batb":[[1,1.01,1.53],[2,1.01,0]],"ltp":0.0,"tv":0.0,"id":26357500},{"batb":[[1,1.01,1.53],[2,1.01,0]],"ltp":0.0,"tv":0.0,"id":27129637},{"batb":[[1,1.01,1.53],[2,1.01,0]],"ltp":0.0,"tv":0.0,"id":20893387}]}]}
{"op":"mcm","clk":"1346457792","pt":1588217392458,"mc":[{"id":"1.170349309","rc":[{"batb":[[1,1.02,5000],[2,1.01,1.53]],"ltp":0.0,"tv":0.0,"id":24550116},{"batb":[[1,1.02,5000],[2,1.01,1.53]],"ltp":0.0,"tv":0.0,"id":27138257},{"batb":[[1,1.02,5000],[2,1.01,1.53]],"ltp":0.0,"tv":0.0,"id":26357500},{"batb":[[1,1.02,5000],[2,1.01,1.53]],"ltp":0.0,"tv":0.0,"id":27129637},{"batb":[[1,1.02,5000],[2,1.01,1.53]],"ltp":0.0,"tv":0.0,"id":20893387}]}]}
{"op":"mcm","clk":"1346469103","pt":1588217995658,"mc":[{"id":"1.170349309","rc":[{"batb":[[1,1.01,1.53],[2,1.01,0]],"ltp":0.0,"tv":0.0,"id":24550116},{"batb":[[1,1.01,1.53],[2,1.01,0]],"ltp":0.0,"tv":0.0,"id":27138257},{"batb":[[1,1.01,1.53],[2,1.01,0]],"ltp":0.0,"tv":0.0,"id":26357500},{"batb":[[1,1.01,1.53],[2,1.01,0]],"ltp":0.0,"tv":0.0,"id":27129637},{"batb":[[1,1.01,1.53],[2,1.01,0]],"ltp":0.0,"tv":0.0,"id":20893387}]}]}
{"op":"mcm","clk":"1346469328","pt":1588218010633,"mc":[{"id":"1.170349309","rc":[{"batb":[[1,1.02,5000],[2,1.01,1.53]],"ltp":0.0,"tv":0.0,"id":24550116},{"batb":[[1,1.02,5000],[2,1.01,1.53]],"ltp":0.0,"tv":0.0,"id":27138257},{"batb":[[1,1.02,5000],[2,1.01,1.53]],"ltp":0.0,"tv":0.0,"id":26357500},{"batb":[[1,1.02,5000],[2,1.01,1.53]],"ltp":0.0,"tv":0.0,"id":27129637},{"batb":[[1,1.02,5000],[2,1.01,1.53]],"ltp":0.0,"tv":0.0,"id":20893387}]}]}
{"op":"mcm","clk":"1346479691","pt":1588218613227,"mc":[{"id":"1.170349309","rc":[{"batb":[[1,1.01,1.53],[2,1.01,0]],"ltp":0.0,"tv":0.0,"id":24550116},{"batb":[[1,1.01,1.53],[2,1.01,0]],"ltp":0.0,"tv":0.0,"id":27138257},{"batb":[[1,1.01,1.53],[2,1.01,0]],"ltp":0.0,"tv":0.0,"id":26357500},{"batb":[[1,1.01,1.53],[2,1.01,0]],"ltp":0.0,"tv":0.0,"id":27129637},{"batb":[[1,1.01,1.53],[2,1.01,0]],"ltp":0.0,"tv":0.0,"id":20893387}]}]}
{"op":"mcm","clk":"1346479981","pt":1588218628221,"mc":[{"id":"1.170349309","rc":[{"batb":[[1,1.02,5000],[2,1.01,1.53]],"ltp":0.0,"tv":0.0,"id":24550116},{"batb":[[1,1.02,5000],[2,1.01,1.53]],"ltp":0.0,"tv":0.0,"id":27138257},{"batb":[[1,1.02,5000],[2,1.01,1.53]],"ltp":0.0,"tv":0.0,"id":26357500},{"batb":[[1,1.02,5000],[2,1.01,1.53]],"ltp":0.0,"tv":0.0,"id":27129637},{"batb":[[1,1.02,5000],[2,1.01,1.53]],"ltp":0.0,"tv":0.0,"id":20893387}]}]}
{"op":"mcm","clk":"1346489539","pt":1588219230964,"mc":[{"id":"1.170349309","rc":[{"batb":[[1,1.01,1.53],[2,1.01,0]],"ltp":0.0,"tv":0.0,"id":24550116},{"batb":[[1,1.01,1.53],[2,1.01,0]],"ltp":0.0,"tv":0.0,"id":27138257},{"batb":[[1,1.01,1.53],[2,1.01,0]],"ltp":0.0,"tv":0.0,"id":26357500},{"batb":[[1,1.01,1.53],[2,1.01,0]],"ltp":0.0,"tv":0.0,"id":27129637},{"batb":[[1,1.01,1.53],[2,1.01,0]],"ltp":0.0,"tv":0.0,"id":20893387}]}]}
{"op":"mcm","clk":"1346489791","pt":1588219245973,"mc":[{"id":"1.170349309","rc":[{"batb":[[1,1.02,5000],[2,1.01,1.53]],"ltp":0.0,"tv":0.0,"id":24550116},{"batb":[[1,1.02,5000],[2,1.01,1.53]],"ltp":0.0,"tv":0.0,"id":27138257},{"batb":[[1,1.02,5000],[2,1.01,1.53]],"ltp":0.0,"tv":0.0,"id":26357500},{"batb":[[1,1.02,5000],[2,1.01,1.53]],"ltp":0.0,"tv":0.0,"id":27129637},{"batb":[[1,1.02,5000],[2,1.01,1.53]],"ltp":0.0,"tv":0.0,"id":20893387}]}]}
{"op":"mcm","clk":"1346500412","pt":1588219848384,"mc":[{"id":"1.170349309","rc":[{"batb":[[1,1.01,1.53],[2,1.01,0]],"ltp":0.0,"tv":0.0,"id":24550116},{"batb":[[1,1.01,1.53],[2,1.01,0]],"ltp":0.0,"tv":0.0,"id":27138257},{"batb":[[1,1.01,1.53],[2,1.01,0]],"ltp":0.0,"tv":0.0,"id":26357500},{"batb":[[1,1.01,1.53],[2,1.01,0]],"ltp":0.0,"tv":0.0,"id":27129637},{"batb":[[1,1.01,1.53],[2,1.01,0]],"ltp":0.0,"tv":0.0,"id":20893387}]}]}
{"op":"mcm","clk":"1346500815","pt":1588219863431,"mc":[{"id":"1.170349309","rc":[{"batb":[[1,1.02,5000],[2,1.01,1.53]],"ltp":0.0,"tv":0.0,"id":24550116},{"batb":[[1,1.02,5000],[2,1.01,1.53]],"ltp":0.0,"tv":0.0,"id":27138257},{"batb":[[1,1.02,5000],[2,1.01,1.53]],"ltp":0.0,"tv":0.0,"id":26357500},{"batb":[[1,1.02,5000],[2,1.01,1.53]],"ltp":0.0,"tv":0.0,"id":27129637},{"batb":[[1,1.02,5000],[2,1.01,1.53]],"ltp":0.0,"tv":0.0,"id":20893387}]}]}
{"op":"mcm","clk":"1346514069","pt":1588220465879,"mc":[{"id":"1.170349309","rc":[{"batb":[[1,1.01,1.53],[2,1.01,0]],"ltp":0.0,"tv":0.0,"id":24550116},{"batb":[[1,1.01,1.53],[2,1.01,0]],"ltp":0.0,"tv":0.0,"id":27138257},{"batb":[[1,1.01,1.53],[2,1.01,0]],"ltp":0.0,"tv":0.0,"id":26357500},{"batb":[[1,1.01,1.53],[2,1.01,0]],"ltp":0.0,"tv":0.0,"id":27129637},{"batb":[[1,1.01,1.53],[2,1.01,0]],"ltp":0.0,"tv":0.0,"id":20893387}]}]}
{"op":"mcm","clk":"1346514263","pt":1588220480916,"mc":[{"id":"1.170349309","rc":[{"batb":[[1,1.02,5000],[2,1.01,1.53]],"ltp":0.0,"tv":0.0,"id":24550116},{"batb":[[1,1.02,5000],[2,1.01,1.53]],"ltp":0.0,"tv":0.0,"id":27138257},{"batb":[[1,1.02,5000],[2,1.01,1.53]],"ltp":0.0,"tv":0.0,"id":26357500},{"batb":[[1,1.02,5000],[2,1.01,1.53]],"ltp":0.0,"tv":0.0,"id":27129637},{"batb":[[1,1.02,5000],[2,1.01,1.53]],"ltp":0.0,"tv":0.0,"id":20893387}]}]}
{"op":"mcm","clk":"1346522049","pt":1588221083396,"mc":[{"id":"1.170349309","rc":[{"batb":[[1,1.01,1.53],[2,1.01,0]],"ltp":0.0,"tv":0.0,"id":24550116},{"batb":[[1,1.01,1.53],[2,1.01,0]],"ltp":0.0,"tv":0.0,"id":27138257},{"batb":[[1,1.01,1.53],[2,1.01,0]],"ltp":0.0,"tv":0.0,"id":26357500},{"batb":[[1,1.01,1.53],[2,1.01,0]],"ltp":0.0,"tv":0.0,"id":27129637},{"batb":[[1,1.01,1.53],[2,1.01,0]],"ltp":0.0,"tv":0.0,"id":20893387}]}]}
{"op":"mcm","clk":"1346522316","pt":1588221098539,"mc":[{"id":"1.170349309","rc":[{"batb":[[1,1.02,5000],[2,1.01,1.53]],"ltp":0.0,"tv":0.0,"id":24550116},{"batb":[[1,1.02,5000],[2,1.01,1.53]],"ltp":0.0,"tv":0.0,"id":27138257},{"batb":[[1,1.02,5000],[2,1.01,1.53]],"ltp":0.0,"tv":0.0,"id":26357500},{"batb":[[1,1.02,5000],[2,1.01,1.53]],"ltp":0.0,"tv":0.0,"id":27129637},{"batb":[[1,1.02,5000],[2,1.01,1.53]],"ltp":0.0,"tv":0.0,"id":20893387}]}]}
{"op":"mcm","clk":"1346533311","pt":1588221701202,"mc":[{"id":"1.170349309","rc":[{"batb":[[1,1.01,1.53],[2,1.01,0]],"ltp":0.0,"tv":0.0,"id":24550116},{"batb":[[1,1.01,1.53],[2,1.01,0]],"ltp":0.0,"tv":0.0,"id":27138257},{"batb":[[1,1.01,1.53],[2,1.01,0]],"ltp":0.0,"tv":0.0,"id":26357500},{"batb":[[1,1.01,1.53],[2,1.01,0]],"ltp":0.0,"tv":0.0,"id":27129637},{"batb":[[1,1.01,1.53],[2,1.01,0]],"ltp":0.0,"tv":0.0,"id":20893387}]}]}
{"op":"mcm","clk":"1346533515","pt":1588221716331,"mc":[{"id":"1.170349309","rc":[{"batb":[[1,1.02,5000],[2,1.01,1.53]],"ltp":0.0,"tv":0.0,"id":24550116},{"batb":[[1,1.02,5000],[2,1.01,1.53]],"ltp":0.0,"tv":0.0,"id":27138257},{"batb":[[1,1.02,5000],[2,1.01,1.53]],"ltp":0.0,"tv":0.0,"id":26357500},{"batb":[[1,1.02,5000],[2,1.01,1.53]],"ltp":0.0,"tv":0.0,"id":27129637},{"batb":[[1,1.02,5000],[2,1.01,1.53]],"ltp":0.0,"tv":0.0,"id":20893387}]}]}
{"op":"mcm","clk":"1346540567","pt":1588222318971,"mc":[{"id":"1.170349309","rc":[{"batb":[[1,1.01,1.53],[2,1.01,0]],"ltp":0.0,"tv":0.0,"id":24550116},{"batb":[[1,1.01,1.53],[2,1.01,0]],"ltp":0.0,"tv":0.0,"id":27138257},{"batb":[[1,1.01,1.53],[2,1.01,0]],"ltp":0.0,"tv":0.0,"id":26357500},{"batb":[[1,1.01,1.53],[2,1.01,0]],"ltp":0.0,"tv":0.0,"id":27129637},{"batb":[[1,1.01,1.53],[2,1.01,0]],"ltp":0.0,"tv":0.0,"id":20893387}]}]}
{"op":"mcm","clk":"1346540868","pt":1588222334019,"mc":[{"id":"1.170349309","rc":[{"batb":[[1,1.02,5000],[2,1.01,1.53]],"ltp":0.0,"tv":0.0,"id":24550116},{"batb":[[1,1.02,5000],[2,1.01,1.53]],"ltp":0.0,"tv":0.0,"id":27138257},{"batb":[[1,1.02,5000],[2,1.01,1.53]],"ltp":0.0,"tv":0.0,"id":26357500},{"batb":[[1,1.02,5000],[2,1.01,1.53]],"ltp":0.0,"tv":0.0,"id":27129637},{"batb":[[1,1.02,5000],[2,1.01,1.53]],"ltp":0.0,"tv":0.0,"id":20893387}]}]}
{"op":"mcm","clk":"1346551246","pt":1588222936637,"mc":[{"id":"1.170349309","rc":[{"batb":[[1,1.01,1.53],[2,1.01,0]],"batl":[[0,1000,1.52]],"ltp":0.0,"tv":0.0,"id":24550116},{"trd":[[1.09,203.48]],"batb":[[1,1.01,1.53]],"batl":[[1,1000,1.52]],"ltp":1.09,"tv":203.48,"id":27376858},{"batb":[[1,1.01,1.53],[2,1.01,0]],"batl":[[0,1000,1.53]],"ltp":0.0,"tv":0.0,"id":27138257},{"batb":[[1,1.01,1.53]],"batl":[[1,1000,1.53]],"ltp":1.28,"tv":160.0,"id":27661463},{"batb":[[1,1.01,1.53],[2,1.01,0]],"batl":[[1,1000,1.55]],"ltp":0.0,"tv":0.0,"id":26357500},{"batb":[[1,1.01,1.53],[2,1.01,0]],"batl":[[0,1000,1.52]],"ltp":0.0,"tv":0.0,"id":27129637},{"batb":[[1,1.01,1.53]],"batl":[[1,1000,1.52]],"ltp":7.4,"tv":4.0,"id":26148884},{"batb":[[1,1.01,1.53],[2,1.01,0]],"batl":[[0,1000,1.56]],"ltp":0.0,"tv":0.0,"id":20893387}],"tv":367.48}]}
{"op":"mcm","clk":"1346551362","pt":1588222951661,"mc":[{"id":"1.170349309","rc":[{"batb":[[1,1.02,5000],[2,1.01,1.53]],"ltp":0.0,"tv":0.0,"id":24550116},{"batb":[[1,1.02,5000],[2,1.01,1.53]],"ltp":0.0,"tv":0.0,"id":27138257},{"batb":[[1,1.02,5000],[2,1.01,1.53]],"ltp":0.0,"tv":0.0,"id":26357500},{"batb":[[1,1.02,5000],[2,1.01,1.53]],"ltp":0.0,"tv":0.0,"id":27129637},{"batb":[[1,1.02,5000],[2,1.01,1.53]],"ltp":0.0,"tv":0.0,"id":20893387}]}]}
{"op":"mcm","clk":"1346559244","pt":1588223554510,"mc":[{"id":"1.170349309","rc":[{"batb":[[1,1.01,1.53],[2,1.01,0]],"ltp":0.0,"tv":0.0,"id":24550116},{"batb":[[1,1.01,1.53],[2,1.01,0]],"ltp":0.0,"tv":0.0,"id":27138257},{"batb":[[1,1.01,1.53],[2,1.01,0]],"ltp":0.0,"tv":0.0,"id":26357500},{"batb":[[1,1.01,1.53],[2,1.01,0]],"ltp":0.0,"tv":0.0,"id":27129637},{"batb":[[1,1.01,1.53],[2,1.01,0]],"ltp":0.0,"tv":0.0,"id":20893387}]}]}
{"op":"mcm","clk":"1346559545","pt":1588223569611,"mc":[{"id":"1.170349309","rc":[{"batb":[[1,1.02,5000],[2,1.01,1.53]],"ltp":0.0,"tv":0.0,"id":24550116},{"batb":[[1,1.02,5000],[2,1.01,1.53]],"ltp":0.0,"tv":0.0,"id":27138257},{"batb":[[1,1.02,5000],[2,1.01,1.53]],"ltp":0.0,"tv":0.0,"id":26357500},{"batb":[[1,1.02,5000],[2,1.01,1.53]],"ltp":0.0,"tv":0.0,"id":27129637},{"batb":[[1,1.02,5000],[2,1.01,1.53]],"ltp":0.0,"tv":0.0,"id":20893387}]}]}
{"op":"mcm","clk":"1346570454","pt":1588224171857,"mc":[{"id":"1.170349309","rc":[{"batb":[[1,1.01,1.53],[2,1.01,0]],"ltp":0.0,"tv":0.0,"id":24550116},{"batb":[[1,1.01,1.53],[2,1.01,0]],"ltp":0.0,"tv":0.0,"id":27138257},{"batb":[[1,1.01,1.53],[2,1.01,0]],"ltp":0.0,"tv":0.0,"id":26357500},{"batb":[[1,1.01,1.53],[2,1.01,0]],"ltp":0.0,"tv":0.0,"id":27129637},{"batb":[[1,1.01,1.53],[2,1.01,0]],"ltp":0.0,"tv":0.0,"id":20893387}]}]}
{"op":"mcm","clk":"1346570567","pt":1588224186963,"mc":[{"id":"1.170349309","rc":[{"batb":[[1,1.02,5000],[2,1.01,1.53]],"ltp":0.0,"tv":0.0,"id":24550116},{"batb":[[1,1.02,5000],[2,1.01,1.53]],"ltp":0.0,"tv":0.0,"id":27138257},{"batb":[[1,1.02,5000],[2,1.01,1.53]],"ltp":0.0,"tv":0.0,"id":26357500},{"batb":[[1,1.02,5000],[2,1.01,1.53]],"ltp":0.0,"tv":0.0,"id":27129637},{"batb":[[1,1.02,5000],[2,1.01,1.53]],"ltp":0.0,"tv":0.0,"id":20893387}]}]}
{"op":"mcm","clk":"1346577179","pt":1588224789591,"mc":[{"id":"1.170349309","rc":[{"batb":[[1,1.01,1.53],[2,1.01,0]],"ltp":0.0,"tv":0.0,"id":24550116},{"batb":[[1,1.01,1.53],[2,1.01,0]],"ltp":0.0,"tv":0.0,"id":27138257},{"batb":[[1,1.01,1.53],[2,1.01,0]],"ltp":0.0,"tv":0.0,"id":26357500},{"batb":[[1,1.01,1.53],[2,1.01,0]],"ltp":0.0,"tv":0.0,"id":27129637},{"batb":[[1,1.01,1.53],[2,1.01,0]],"ltp":0.0,"tv":0.0,"id":20893387}]}]}
{"op":"mcm","clk":"1346577518","pt":1588224804619,"mc":[{"id":"1.170349309","rc":[{"batb":[[1,1.02,5000],[2,1.01,1.53]],"ltp":0.0,"tv":0.0,"id":24550116},{"batb":[[1,1.02,5000],[2,1.01,1.53]],"ltp":0.0,"tv":0.0,"id":27138257},{"batb":[[1,1.02,5000],[2,1.01,1.53]],"ltp":0.0,"tv":0.0,"id":26357500},{"batb":[[1,1.02,5000],[2,1.01,1.53]],"ltp":0.0,"tv":0.0,"id":27129637},{"batb":[[1,1.02,5000],[2,1.01,1.53]],"ltp":0.0,"tv":0.0,"id":20893387}]}]}
{"op":"mcm","clk":"1346590035","pt":1588225407340,"mc":[{"id":"1.170349309","rc":[{"batb":[[1,1.01,1.53],[2,1.01,0]],"ltp":0.0,"tv":0.0,"id":24550116},{"batb":[[1,1.01,1.53],[2,1.01,0]],"ltp":0.0,"tv":0.0,"id":27138257},{"batb":[[1,1.01,1.53],[2,1.01,0]],"ltp":0.0,"tv":0.0,"id":26357500},{"batb":[[1,1.01,1.53],[2,1.01,0]],"ltp":0.0,"tv":0.0,"id":27129637},{"batb":[[1,1.01,1.53],[2,1.01,0]],"ltp":0.0,"tv":0.0,"id":20893387}]}]}
{"op":"mcm","clk":"1346590095","pt":1588225422390,"mc":[{"id":"1.170349309","rc":[{"batb":[[1,1.02,5000],[2,1.01,1.53]],"ltp":0.0,"tv":0.0,"id":24550116},{"batb":[[1,1.02,5000],[2,1.01,1.53]],"ltp":0.0,"tv":0.0,"id":27138257},{"batb":[[1,1.02,5000],[2,1.01,1.53]],"ltp":0.0,"tv":0.0,"id":26357500},{"batb":[[1,1.02,5000],[2,1.01,1.53]],"ltp":0.0,"tv":0.0,"id":27129637},{"batb":[[1,1.02,5000],[2,1.01,1.53]],"ltp":0.0,"tv":0.0,"id":20893387}]}]}
{"op":"mcm","clk":"1346598871","pt":1588226025107,"mc":[{"id":"1.170349309","rc":[{"batb":[[1,1.01,1.53],[2,1.01,0]],"ltp":0.0,"tv":0.0,"id":24550116},{"batb":[[1,1.01,1.53],[2,1.01,0]],"ltp":0.0,"tv":0.0,"id":27138257},{"batb":[[1,1.01,1.53],[2,1.01,0]],"ltp":0.0,"tv":0.0,"id":26357500},{"batb":[[1,1.01,1.53],[2,1.01,0]],"ltp":0.0,"tv":0.0,"id":27129637},{"batb":[[1,1.01,1.53],[2,1.01,0]],"ltp":0.0,"tv":0.0,"id":20893387}]}]}
{"op":"mcm","clk":"1346599215","pt":1588226040166,"mc":[{"id":"1.170349309","rc":[{"batb":[[1,1.02,5000],[2,1.01,1.53]],"ltp":0.0,"tv":0.0,"id":24550116},{"batb":[[1,1.02,5000],[2,1.01,1.53]],"ltp":0.0,"tv":0.0,"id":27138257},{"batb":[[1,1.02,5000],[2,1.01,1.53]],"ltp":0.0,"tv":0.0,"id":26357500},{"batb":[[1,1.02,5000],[2,1.01,1.53]],"ltp":0.0,"tv":0.0,"id":27129637},{"batb":[[1,1.02,5000],[2,1.01,1.53]],"ltp":0.0,"tv":0.0,"id":20893387}]}]}
{"op":"mcm","clk":"1346608660","pt":1588226642355,"mc":[{"id":"1.170349309","rc":[{"batb":[[1,1.01,1.53],[2,1.01,0]],"ltp":0.0,"tv":0.0,"id":24550116},{"batb":[[1,1.01,1.53],[2,1.01,0]],"ltp":0.0,"tv":0.0,"id":27138257},{"batb":[[1,1.01,1.53],[2,1.01,0]],"ltp":0.0,"tv":0.0,"id":26357500},{"batb":[[1,1.01,1.53],[2,1.01,0]],"ltp":0.0,"tv":0.0,"id":27129637},{"batb":[[1,1.01,1.53],[2,1.01,0]],"ltp":0.0,"tv":0.0,"id":20893387}]}]}
{"op":"mcm","clk":"1346608752","pt":1588226657371,"mc":[{"id":"1.170349309","rc":[{"batb":[[1,1.02,5000],[2,1.01,1.53]],"ltp":0.0,"tv":0.0,"id":24550116},{"batb":[[1,1.02,5000],[2,1.01,1.53]],"ltp":0.0,"tv":0.0,"id":27138257},{"batb":[[1,1.02,5000],[2,1.01,1.53]],"ltp":0.0,"tv":0.0,"id":26357500},{"batb":[[1,1.02,5000],[2,1.01,1.53]],"ltp":0.0,"tv":0.0,"id":27129637},{"batb":[[1,1.02,5000],[2,1.01,1.53]],"ltp":0.0,"tv":0.0,"id":20893387}]}]}
{"op":"mcm","clk":"1346618915","pt":1588227259717,"mc":[{"id":"1.170349309","rc":[{"batb":[[1,1.01,1.53],[2,1.01,0]],"ltp":0.0,"tv":0.0,"id":24550116},{"batb":[[1,1.01,1.53],[2,1.01,0]],"ltp":0.0,"tv":0.0,"id":27138257},{"batb":[[1,1.01,1.53],[2,1.01,0]],"ltp":0.0,"tv":0.0,"id":26357500},{"batb":[[1,1.01,1.53],[2,1.01,0]],"ltp":0.0,"tv":0.0,"id":27129637},{"batb":[[1,1.01,1.53],[2,1.01,0]],"ltp":0.0,"tv":0.0,"id":20893387}]}]}
{"op":"mcm","clk":"1346619243","pt":1588227274764,"mc":[{"id":"1.170349309","rc":[{"batb":[[1,1.02,5000],[2,1.01,1.53]],"ltp":0.0,"tv":0.0,"id":24550116},{"batb":[[1,1.02,5000],[2,1.01,1.53]],"ltp":0.0,"tv":0.0,"id":27138257},{"batb":[[1,1.02,5000],[2,1.01,1.53]],"ltp":0.0,"tv":0.0,"id":26357500},{"batb":[[1,1.02,5000],[2,1.01,1.53]],"ltp":0.0,"tv":0.0,"id":27129637},{"batb":[[1,1.02,5000],[2,1.01,1.53]],"ltp":0.0,"tv":0.0,"id":20893387}]}]}
{"op":"mcm","clk":"1346629790","pt":1588227877307,"mc":[{"id":"1.170349309","rc":[{"batb":[[1,1.01,1.53],[2,1.01,0]],"ltp":0.0,"tv":0.0,"id":24550116},{"batb":[[1,1.01,1.53],[2,1.01,0]],"ltp":0.0,"tv":0.0,"id":27138257},{"batb":[[1,1.01,1.53],[2,1.01,0]],"ltp":0.0,"tv":0.0,"id":26357500},{"batb":[[1,1.01,1.53],[2,1.01,0]],"ltp":0.0,"tv":0.0,"id":27129637},{"batb":[[1,1.01,1.53],[2,1.01,0]],"ltp":0.0,"tv":0.0,"id":20893387}]}]}
{"op":"mcm","clk":"1346630060","pt":1588227892374,"mc":[{"id":"1.170349309","rc":[{"batb":[[1,1.02,5000],[2,1.01,1.53]],"ltp":0.0,"tv":0.0,"id":24550116},{"batb":[[1,1.02,5000],[2,1.01,1.53]],"ltp":0.0,"tv":0.0,"id":27138257},{"batb":[[1,1.02,5000],[2,1.01,1.53]],"ltp":0.0,"tv":0.0,"id":26357500},{"batb":[[1,1.02,5000],[2,1.01,1.53]],"ltp":0.0,"tv":0.0,"id":27129637},{"batb":[[1,1.02,5000],[2,1.01,1.53]],"ltp":0.0,"tv":0.0,"id":20893387}]}]}
{"op":"mcm","clk":"1346639181","pt":1588228495001,"mc":[{"id":"1.170349309","rc":[{"batb":[[1,1.01,1.53],[2,1.01,0]],"ltp":0.0,"tv":0.0,"id":24550116},{"batb":[[1,1.01,1.53],[2,1.01,0]],"ltp":0.0,"tv":0.0,"id":27138257},{"batb":[[1,1.01,1.53],[2,1.01,0]],"ltp":0.0,"tv":0.0,"id":26357500},{"batb":[[1,1.01,1.53],[2,1.01,0]],"ltp":0.0,"tv":0.0,"id":27129637},{"batb":[[1,1.01,1.53],[2,1.01,0]],"ltp":0.0,"tv":0.0,"id":20893387}]}]}
{"op":"mcm","clk":"1346639395","pt":1588228510120,"mc":[{"id":"1.170349309","rc":[{"batb":[[1,1.02,5000],[2,1.01,1.53]],"ltp":0.0,"tv":0.0,"id":24550116},{"batb":[[1,1.02,5000],[2,1.01,1.53]],"ltp":0.0,"tv":0.0,"id":27138257},{"batb":[[1,1.02,5000],[2,1.01,1.53]],"ltp":0.0,"tv":0.0,"id":26357500},{"batb":[[1,1.02,5000],[2,1.01,1.53]],"ltp":0.0,"tv":0.0,"id":27129637},{"batb":[[1,1.02,5000],[2,1.01,1.53]],"ltp":0.0,"tv":0.0,"id":20893387}]}]}
{"op":"mcm","clk":"1346651207","pt":1588229113105,"mc":[{"id":"1.170349309","rc":[{"batb":[[1,1.01,1.53],[2,1.01,0]],"ltp":0.0,"tv":0.0,"id":24550116},{"batb":[[1,1.01,1.53],[2,1.01,0]],"ltp":0.0,"tv":0.0,"id":27138257},{"batb":[[1,1.01,1.53],[2,1.01,0]],"ltp":0.0,"tv":0.0,"id":26357500},{"batb":[[1,1.01,1.53],[2,1.01,0]],"ltp":0.0,"tv":0.0,"id":27129637},{"batb":[[1,1.01,1.53],[2,1.01,0]],"ltp":0.0,"tv":0.0,"id":20893387}]}]}
{"op":"mcm","clk":"1346651479","pt":1588229128317,"mc":[{"id":"1.170349309","rc":[{"batb":[[1,1.02,5000],[2,1.01,1.53]],"ltp":0.0,"tv":0.0,"id":24550116},{"batb":[[1,1.02,5000],[2,1.01,1.53]],"ltp":0.0,"tv":0.0,"id":27138257},{"batb":[[1,1.02,5000],[2,1.01,1.53]],"ltp":0.0,"tv":0.0,"id":26357500},{"batb":[[1,1.02,5000],[2,1.01,1.53]],"ltp":0.0,"tv":0.0,"id":27129637},{"batb":[[1,1.02,5000],[2,1.01,1.53]],"ltp":0.0,"tv":0.0,"id":20893387}]}]}
{"op":"mcm","clk":"1346663479","pt":1588229731245,"mc":[{"id":"1.170349309","rc":[{"batb":[[1,1.01,1.53],[2,1.01,0]],"ltp":0.0,"tv":0.0,"id":24550116},{"batb":[[1,1.01,1.53],[2,1.01,0]],"ltp":0.0,"tv":0.0,"id":27138257},{"batb":[[1,1.01,1.53],[2,1.01,0]],"ltp":0.0,"tv":0.0,"id":26357500},{"batb":[[1,1.01,1.53],[2,1.01,0]],"ltp":0.0,"tv":0.0,"id":27129637},{"batb":[[1,1.01,1.53],[2,1.01,0]],"ltp":0.0,"tv":0.0,"id":20893387}]}]}
{"op":"mcm","clk":"1346663762","pt":1588229746272,"mc":[{"id":"1.170349309","rc":[{"batb":[[1,1.02,5000],[2,1.01,1.53]],"ltp":0.0,"tv":0.0,"id":24550116},{"batb":[[1,1.02,5000],[2,1.01,1.53]],"ltp":0.0,"tv":0.0,"id":27138257},{"batb":[[1,1.02,5000],[2,1.01,1.53]],"ltp":0.0,"tv":0.0,"id":26357500},{"batb":[[1,1.02,5000],[2,1.01,1.53]],"ltp":0.0,"tv":0.0,"id":27129637},{"batb":[[1,1.02,5000],[2,1.01,1.53]],"ltp":0.0,"tv":0.0,"id":20893387}]}]}
{"op":"mcm","clk":"1346676508","pt":1588230348884,"mc":[{"id":"1.170349309","rc":[{"batb":[[1,1.01,1.53],[2,1.01,0]],"ltp":0.0,"tv":0.0,"id":24550116},{"trd":[[1.09,203.49]],"ltp":1.09,"tv":203.48,"id":27376858},{"batb":[[1,1.01,1.53],[2,1.01,0]],"ltp":0.0,"tv":0.0,"id":27138257},{"batb":[[1,1.01,1.53],[2,1.01,0]],"ltp":0.0,"tv":0.0,"id":26357500},{"batb":[[1,1.01,1.53],[2,1.01,0]],"ltp":0.0,"tv":0.0,"id":27129637},{"batb":[[1,1.01,1.53],[2,1.01,0]],"ltp":0.0,"tv":0.0,"id":20893387}],"tv":367.48}]}
{"op":"mcm","clk":"1346676958","pt":1588230363894,"mc":[{"id":"1.170349309","rc":[{"batb":[[1,1.02,5000],[2,1.01,1.53]],"ltp":0.0,"tv":0.0,"id":24550116},{"batb":[[1,1.02,5000],[2,1.01,1.53]],"ltp":0.0,"tv":0.0,"id":27138257},{"batb":[[1,1.02,5000],[2,1.01,1.53]],"ltp":0.0,"tv":0.0,"id":26357500},{"batb":[[1,1.02,5000],[2,1.01,1.53]],"ltp":0.0,"tv":0.0,"id":27129637},{"batb":[[1,1.02,5000],[2,1.01,1.53]],"ltp":0.0,"tv":0.0,"id":20893387}]}]}
{"op":"mcm","clk":"1346699847","pt":1588230967048,"mc":[{"id":"1.170349309","rc":[{"batb":[[1,1.01,1.53],[2,1.01,0]],"ltp":0.0,"tv":0.0,"id":24550116},{"batb":[[1,1.01,1.53],[2,1.01,0]],"ltp":0.0,"tv":0.0,"id":27138257},{"batb":[[1,1.01,1.53],[2,1.01,0]],"ltp":0.0,"tv":0.0,"id":26357500},{"batb":[[1,1.01,1.53],[2,1.01,0]],"ltp":0.0,"tv":0.0,"id":27129637},{"batb":[[1,1.01,1.53],[2,1.01,0]],"ltp":0.0,"tv":0.0,"id":20893387}]}]}
{"op":"mcm","clk":"1346700304","pt":1588230981979,"mc":[{"id":"1.170349309","rc":[{"batb":[[1,1.02,5000],[2,1.01,1.53]],"ltp":0.0,"tv":0.0,"id":24550116},{"batb":[[1,1.02,5000],[2,1.01,1.53]],"ltp":0.0,"tv":0.0,"id":27138257},{"batb":[[1,1.02,5000],[2,1.01,1.53]],"ltp":0.0,"tv":0.0,"id":26357500},{"batb":[[1,1.02,5000],[2,1.01,1.53]],"ltp":0.0,"tv":0.0,"id":27129637},{"batb":[[1,1.02,5000],[2,1.01,1.53]],"ltp":0.0,"tv":0.0,"id":20893387}]}]}
{"op":"mcm","clk":"1346719307","pt":1588231584810,"mc":[{"id":"1.170349309","rc":[{"batb":[[1,1.01,1.53],[2,1.01,0]],"ltp":0.0,"tv":0.0,"id":24550116},{"batb":[[1,1.01,1.53],[2,1.01,0]],"ltp":0.0,"tv":0.0,"id":27138257},{"batb":[[1,1.01,1.53],[2,1.01,0]],"ltp":0.0,"tv":0.0,"id":26357500},{"batb":[[1,1.01,1.53],[2,1.01,0]],"ltp":0.0,"tv":0.0,"id":27129637},{"batb":[[1,1.01,1.53],[2,1.01,0]],"ltp":0.0,"tv":0.0,"id":20893387}]}]}
{"op":"mcm","clk":"1346719805","pt":1588231599736,"mc":[{"id":"1.170349309","rc":[{"batb":[[1,1.02,5000],[2,1.01,1.53]],"ltp":0.0,"tv":0.0,"id":24550116},{"batb":[[1,1.02,5000],[2,1.01,1.53]],"ltp":0.0,"tv":0.0,"id":27138257},{"batb":[[1,1.02,5000],[2,1.01,1.53]],"ltp":0.0,"tv":0.0,"id":26357500},{"batb":[[1,1.02,5000],[2,1.01,1.53]],"ltp":0.0,"tv":0.0,"id":27129637},{"batb":[[1,1.02,5000],[2,1.01,1.53]],"ltp":0.0,"tv":0.0,"id":20893387}]}]}
{"op":"mcm","clk":"1346740027","pt":1588232202439,"mc":[{"id":"1.170349309","rc":[{"batb":[[1,1.01,1.53],[2,1.01,0]],"ltp":0.0,"tv":0.0,"id":24550116},{"batb":[[1,1.01,1.53],[2,1.01,0]],"ltp":0.0,"tv":0.0,"id":27138257},{"batb":[[1,1.01,1.53],[2,1.01,0]],"ltp":0.0,"tv":0.0,"id":26357500},{"batb":[[1,1.01,1.53],[2,1.01,0]],"ltp":0.0,"tv":0.0,"id":27129637},{"batb":[[1,1.01,1.53],[2,1.01,0]],"ltp":0.0,"tv":0.0,"id":20893387}]}]}
{"op":"mcm","clk":"1346740489","pt":1588232217395,"mc":[{"id":"1.170349309","rc":[{"batb":[[1,1.02,5000],[2,1.01,1.53]],"ltp":0.0,"tv":0.0,"id":24550116},{"batb":[[1,1.02,5000],[2,1.01,1.53]],"ltp":0.0,"tv":0.0,"id":27138257},{"batb":[[1,1.02,5000],[2,1.01,1.53]],"ltp":0.0,"tv":0.0,"id":26357500},{"batb":[[1,1.02,5000],[2,1.01,1.53]],"ltp":0.0,"tv":0.0,"id":27129637},{"batb":[[1,1.02,5000],[2,1.01,1.53]],"ltp":0.0,"tv":0.0,"id":20893387}]}]}
{"op":"mcm","clk":"1346766098","pt":1588232820237,"mc":[{"id":"1.170349309","rc":[{"batb":[[1,1.01,1.53],[2,1.01,0]],"ltp":0.0,"tv":0.0,"id":24550116},{"batb":[[1,1.01,1.53],[2,1.01,0]],"ltp":0.0,"tv":0.0,"id":27138257},{"batb":[[1,1.01,1.53],[2,1.01,0]],"ltp":0.0,"tv":0.0,"id":26357500},{"batb":[[1,1.01,1.53],[2,1.01,0]],"ltp":0.0,"tv":0.0,"id":27129637},{"batb":[[1,1.01,1.53],[2,1.01,0]],"ltp":0.0,"tv":0.0,"id":20893387}]}]}
